Workbook
Name DT.10: #REF!
Name DT.11: #REF!
Name vlookup: #REF!
Name 主小区MR详细信息AGPS: #REF!
Name 主小区MR详细信息全量室内外: #REF!

Sheet 导航
A1: 编号 | B1: 索引 | C1: 项目名称 | D1: 数据层级 | E1: 主题域 | F1: 表英文名 | G1: 表中文名 | H1: 数据描述 | I1: 汇聚维度 | J1: 数据时间粒度 | K1: 最小时间分区 | L1: 计算位置 | M1: 是否同步 | N1: 生命周期（存储周期单位：天） | O1: 前向表 | P1: 支撑应用/系统 | Q1: 新建/升级 新建(升级)：表结构与字段沿用原表，表名称调整 | R1: 备注 | S1: 同步数据库 | T1: 开发人员 | U1: 开发状态
A2: 0.1 | B2: =HYPERLINK("#"&A2&"!A1",A2) -> 0.1 | C2: 网络数据处理系统 | D2: 中间层 | E2: 质量稽核 | F2: dq_ods_4gdpi_http_e2e_telecom_q | G2: 4G_DPI_HTTP源数据接入质量稽核任务 | H2: 4G_DPI_HTTP源数据接入质量稽核任务 | I2: 省 | J2: 天 | K2: 天 | L2: 前置 | M2: 否 | N2: 30 | O2: ods_4gdpi_http_e2e_telecom_q | Q2: 升级
A3: 1 | B3: =HYPERLINK("#"&A3&"!A1",A3) -> 1 | C3: 网络数据处理系统 | D3: 整合层 | E3: / | F3: fact_lte_dpi_http_q | G3: 4G_DPI_http整合层15分钟表 | H3: =G3 -> 4G_DPI_http整合层15分钟表 | I3: 详单 | J3: 详单 | K3: 15分钟 | L3: 前置 | M3: 否 | N3: 3 | O3: ods_4gdpi_http_e2e_telecom_q|lte_cm_projdata_refactor|cfg_topweb_first_screen_host_list|cfg_http_status_type | Q3: 新建
A4: 2 | B4: =HYPERLINK("#"&A4&"!A1",A4) -> 2 | C4: 网络数据处理系统 | D4: 中间层 | E4: 数据感知 | F4: aggr_lte_dpi_http_base_q | G4: 4G_DPI_http基础维度15分钟表 | H4: =G4 -> 4G_DPI_http基础维度15分钟表 | I4: 用户|小区|app|apn|源IP类型 | J4: 15分钟 | K4: 15分钟 | L4: 前置 | M4: 是 | N4: 前置:7；核心:14 | O4: fact_lte_dpi_http_q | Q4: 新建
A5: 3 | B5: =HYPERLINK("#"&A5&"!A1",A5) -> 3 | C5: 网络数据处理系统 | D5: 中间层 | E5: 数据感知 | F5: aggr_lte_dpi_http_base_h | G5: 4G_DPI_http基础维度小时表 | H5: =G5 -> 4G_DPI_http基础维度小时表 | I5: 用户|小区|app|apn|源IP类型 | J5: 小时 | K5: 小时 | L5: 核心 | M5: / | N5: 14 | O5: aggr_lte_dpi_http_base_q | Q5: 新建
A6: 4 | B6: =HYPERLINK("#"&A6&"!A1",A6) -> 4 | C6: 网络数据处理系统 | D6: 中间层 | E6: 数据感知 | F6: aggr_lte_dpi_http_index_reduce_base_h | G6: 4G_DPI_http基础维度指标裁剪小时表 | H6: =G6 -> 4G_DPI_http基础维度指标裁剪小时表 | I6: 用户|小区|app|apn|源IP类型 | J6: 小时 | K6: 小时 | L6: 核心 | M6: / | N6: 14 | O6: aggr_lte_dpi_http_base_h | P6: 移动业务感知保障系统 | Q6: 新建(升级) | R6: 沿用共享移动业务感知保障系统表aggr_4gdpi_http_base_reduce_h表结构及字段名称
A7: 5 | B7: =HYPERLINK("#"&A7&"!A1",A7) -> 5 | C7: 网络数据处理系统 | D7: 中间层 | E7: 数据感知 | F7: aggr_lte_dpi_http_usrappcel_h | G7: 4G_DPI_http用户小区app维度小时表 | H7: =G7 -> 4G_DPI_http用户小区app维度小时表 | I7: 用户|小区|app | J7: 小时 | K7: 小时 | L7: 核心 | M7: / | N7: 14 | O7: aggr_lte_dpi_http_base_h | Q7: 新建
A8: 6 | B8: =HYPERLINK("#"&A8&"!A1",A8) -> 6 | C8: 网络数据处理系统 | D8: 中间层 | E8: 数据感知 | F8: aggr_lte_dpi_http_usrapp_h | G8: 4G_DPI_http用户app维度小时表 | H8: =G8 -> 4G_DPI_http用户app维度小时表 | I8: 用户|app | J8: 小时 | K8: 小时 | L8: 核心 | M8: / | N8: 14 | O8: aggr_lte_dpi_http_usrappcel_h | Q8: 新建
A9: 7 | B9: =HYPERLINK("#"&A9&"!A1",A9) -> 7 | C9: 网络数据处理系统 | D9: 中间层 | E9: 数据感知 | F9: aggr_lte_dpi_http_usrapp_d | G9: 4G_DPI_http用户app维度天表 | H9: =G9 -> 4G_DPI_http用户app维度天表 | I9: 用户|app | J9: 天 | K9: 天 | L9: 核心 | M9: / | N9: 30 | O9: aggr_lte_dpi_http_usrapp_h | Q9: 新建
A10: 8 | B10: =HYPERLINK("#"&A10&"!A1",A10) -> 8 | C10: 网络数据处理系统 | D10: 中间层 | E10: 数据感知 | F10: aggr_lte_iov_http_usrappcel_refactor_h | G10: 4G_DPI_http车联网用户小区app维度小时表 | H10: =G10 -> 4G_DPI_http车联网用户小区app维度小时表 | I10: 用户|小区|app | J10: 小时 | K10: 小时 | L10: 核心 | M10: / | N10: 14 | O10: aggr_lte_dpi_http_usrappcel_h|cfg_dpi_servicetype|cfg_iov_usr_list | P10: 5G定制网 | Q10: 新建(升级) | R10: 沿用共享给5G定制网表aggr_lte_iov_http_usrappcel_h表结构及字段名称
A11: 9 | B11: =HYPERLINK("#"&A11&"!A1",A11) -> 9 | C11: 网络数据处理系统 | D11: 中间层 | E11: 数据感知 | F11: aggr_lte_dpi_http_appcel_h | G11: 4G_DPI_http小区app维度小时表 | H11: =G11 -> 4G_DPI_http小区app维度小时表 | I11: 小区|app | J11: 小时 | K11: 小时 | L11: 核心 | M11: / | N11: 14 | O11: aggr_lte_dpi_http_usrappcel_h | Q11: 新建
A12: 10 | B12: =HYPERLINK("#"&A12&"!A1",A12) -> 10 | C12: 网络数据处理系统 | D12: 中间层 | E12: 数据感知 | F12: aggr_lte_dpi_http_appcel_d | G12: 4G_DPI_http小区app维度天表 | H12: =G12 -> 4G_DPI_http小区app维度天表 | I12: 小区|app | J12: 天 | K12: 天 | L12: 核心 | M12: / | N12: 30 | O12: aggr_lte_dpi_http_appcel_h | Q12: 新建
A13: 11 | B13: =HYPERLINK("#"&A13&"!A1",A13) -> 11 | C13: 网络数据处理系统 | D13: 中间层 | E13: 数据感知 | F13: aggr_lte_dpi_http_cel_d | G13: 4G_DPI_http小区维度天表 | H13: =G13 -> 4G_DPI_http小区维度天表 | I13: 小区 | J13: 天 | K13: 天 | L13: 核心 | M13: / | N13: 30 | O13: aggr_lte_dpi_http_appcel_d | Q13: 新建
A14: 12 | B14: =HYPERLINK("#"&A14&"!A1",A14) -> 12 | C14: 网络数据处理系统 | D14: 中间层 | E14: 数据感知 | F14: aggr_lte_dpi_web_appcel_h | G14: 4G_DPI_web小区app维度小时表 | H14: =G14 -> 4G_DPI_web小区app维度小时表 | I14: 小区|app | J14: 小时 | K14: 小时 | L14: 核心 | M14: / | N14: 14 | O14: aggr_lte_dpi_http_appcel_h | P14: 建维优 | Q14: 新建
A15: 13 | B15: =HYPERLINK("#"&A15&"!A1",A15) -> 13 | C15: 网络数据处理系统 | D15: 中间层 | E15: 数据感知 | F15: aggr_lte_dpi_web_appcel_d | G15: 4G_DPI_web小区app维度天表 | H15: =G15 -> 4G_DPI_web小区app维度天表 | I15: 小区|app | J15: 天 | K15: 天 | L15: 核心 | M15: / | N15: 30 | O15: aggr_lte_dpi_web_appcel_h | P15: 建维优 | Q15: 新建
A16: 14 | B16: =HYPERLINK("#"&A16&"!A1",A16) -> 14 | C16: 网络数据处理系统 | D16: 中间层 | E16: 数据感知 | F16: aggr_lte_dpi_web_cel_h | G16: 4G_DPI_web小区维度小时表 | H16: =G16 -> 4G_DPI_web小区维度小时表 | I16: 小区 | J16: 小时 | K16: 小时 | L16: 核心 | M16: / | N16: 14 | O16: aggr_lte_dpi_web_appcel_h | Q16: 新建
A17: 15 | B17: =HYPERLINK("#"&A17&"!A1",A17) -> 15 | C17: 网络数据处理系统 | D17: 中间层 | E17: 数据感知 | F17: aggr_lte_dpi_web_cel_d | G17: 4G_DPI_web小区维度天表 | H17: =G17 -> 4G_DPI_web小区维度天表 | I17: 小区 | J17: 天 | K17: 天 | L17: 核心 | M17: / | N17: 30 | O17: aggr_lte_dpi_web_cel_h | P17: 建维优 | Q17: 新建 | R17: 保留下来的字段沿用表aggr_4g_web_cel_e2e_d字段名称
A18: 16 | B18: =HYPERLINK("#"&A18&"!A1",A18) -> 16 | C18: 网络数据处理系统 | D18: 中间层 | E18: 数据感知 | F18: aggr_lte_dpi_im_appcel_h | G18: 4G_DPI_im小区app维度小时表 | H18: =G18 -> 4G_DPI_im小区app维度小时表 | I18: 小区|app | J18: 小时 | K18: 小时 | L18: 核心 | M18: / | N18: 14 | O18: aggr_lte_dpi_http_appcel_h | P18: 建维优 | Q18: 新建
A19: 17 | B19: =HYPERLINK("#"&A19&"!A1",A19) -> 17 | C19: 网络数据处理系统 | D19: 中间层 | E19: 数据感知 | F19: aggr_lte_dpi_im_appcel_d | G19: 4G_DPI_im小区app维度天表 | H19: =G19 -> 4G_DPI_im小区app维度天表 | I19: 小区|app | J19: 天 | K19: 天 | L19: 核心 | M19: / | N19: 30 | O19: aggr_lte_dpi_im_appcel_h | P19: 建维优 | Q19: 新建
A20: 18 | B20: =HYPERLINK("#"&A20&"!A1",A20) -> 18 | C20: 网络数据处理系统 | D20: 中间层 | E20: 数据感知 | F20: aggr_lte_dpi_im_cel_h | G20: 4G_DPI_im小区维度小时表 | H20: =G20 -> 4G_DPI_im小区维度小时表 | I20: 小区 | J20: 小时 | K20: 小时 | L20: 核心 | M20: / | N20: 14 | O20: aggr_lte_dpi_im_appcel_h | P20: 建维优 | Q20: 新建
A21: 19 | B21: =HYPERLINK("#"&A21&"!A1",A21) -> 19 | C21: 网络数据处理系统 | D21: 中间层 | E21: 数据感知 | F21: aggr_lte_dpi_im_cel_d | G21: 4G_DPI_im小区维度天表 | H21: =G21 -> 4G_DPI_im小区维度天表 | I21: 小区 | J21: 天 | K21: 天 | L21: 核心 | M21: / | N21: 30 | O21: aggr_lte_dpi_im_cel_h | P21: 建维优 | Q21: 新建 | R21: 保留下来的字段沿用表aggr_4g_im_cel_e2e_d字段名称
A22: 20 | B22: =HYPERLINK("#"&A22&"!A1",A22) -> 20 | C22: 网络数据处理系统 | D22: 中间层 | E22: 数据感知 | F22: aggr_lte_dpi_game_appcel_h | G22: 4G_DPI_game小区app维度小时表 | H22: =G22 -> 4G_DPI_game小区app维度小时表 | I22: 小区|app | J22: 小时 | K22: 小时 | L22: 核心 | M22: / | N22: 14 | O22: aggr_lte_dpi_http_appcel_h | P22: 建维优 | Q22: 新建
A23: 21 | B23: =HYPERLINK("#"&A23&"!A1",A23) -> 21 | C23: 网络数据处理系统 | D23: 中间层 | E23: 数据感知 | F23: aggr_lte_dpi_game_appcel_d | G23: 4G_DPI_game小区app维度天表 | H23: =G23 -> 4G_DPI_game小区app维度天表 | I23: 小区|app | J23: 天 | K23: 天 | L23: 核心 | M23: / | N23: 30 | O23: aggr_lte_dpi_game_appcel_h | P23: 建维优 | Q23: 新建 | T23: 张玉同 | U23: 已开发
A24: 22 | B24: =HYPERLINK("#"&A24&"!A1",A24) -> 22 | C24: 网络数据处理系统 | D24: 中间层 | E24: 数据感知 | F24: aggr_lte_dpi_game_cel_h | G24: 4G_DPI_game小区维度小时表 | H24: =G24 -> 4G_DPI_game小区维度小时表 | I24: 小区 | J24: 小时 | K24: 小时 | L24: 核心 | M24: / | N24: 14 | O24: aggr_lte_dpi_game_appcel_h | P24: 建维优 | Q24: 新建 | T24: 张玉同 | U24: 已开发
A25: 23 | B25: =HYPERLINK("#"&A25&"!A1",A25) -> 23 | C25: 网络数据处理系统 | D25: 中间层 | E25: 数据感知 | F25: aggr_lte_dpi_game_cel_d | G25: 4G_DPI_game小区维度天表 | H25: =G25 -> 4G_DPI_game小区维度天表 | I25: 小区 | J25: 天 | K25: 天 | L25: 核心 | M25: / | N25: 30 | O25: aggr_lte_dpi_game_cel_h | P25: 建维优 | Q25: 新建 | R25: 保留下来的字段沿用表aggr_4g_game_cel_e2e_d字段名称 | T25: 张玉同 | U25: 已开发
A26: 24 | B26: =HYPERLINK("#"&A26&"!A1",A26) -> 24 | C26: 网络数据处理系统 | D26: 中间层 | E26: 数据感知 | F26: aggr_lte_dpi_http_apptype_usrcel_h | G26: 4G_DPI_http协议app类型用户小区维度小时表 | H26: =G26 -> 4G_DPI_http协议app类型用户小区维度小时表 | I26: 用户|小区|app类型 | J26: 小时 | K26: 小时 | L26: 核心 | M26: / | N26: 14 | O26: aggr_lte_dpi_http_usrappcel_h | Q26: 新建 | T26: 张玉同 | U26: 已开发
A27: 25 | B27: =HYPERLINK("#"&A27&"!A1",A27) -> 25 | C27: 网络数据处理系统 | D27: 中间层 | E27: 数据感知 | F27: aggr_lte_dpi_web_usrcel_d | G27: 4G_DPI_web用户小区维度天表 | H27: =G27 -> 4G_DPI_web用户小区维度天表 | I27: 用户|小区 | J27: 天 | K27: 天 | L27: 核心 | M27: / | N27: 30 | O27: aggr_lte_dpi_http_apptype_usrcel_h | P27: 建维优 | Q27: 新建 | R27: 保留下来的字段沿用表aggr_4g_web_cel_e2e_d字段名称 | T27: 张玉同 | U27: 已开发
A28: 26 | B28: =HYPERLINK("#"&A28&"!A1",A28) -> 26 | C28: 网络数据处理系统 | D28: 中间层 | E28: 数据感知 | F28: aggr_lte_dpi_web_usr_h | G28: 4G_DPI_web用户小区维度天表 | H28: =G28 -> 4G_DPI_web用户小区维度天表 | I28: 用户|小区 | J28: 天 | K28: 天 | L28: 核心 | M28: / | N28: 14 | O28: aggr_lte_dpi_http_apptype_usrcel_h | P28: 建维优 | Q28: 新建 | T28: 张玉同 | U28: 已开发
A29: 27 | B29: =HYPERLINK("#"&A29&"!A1",A29) -> 27 | C29: 网络数据处理系统 | D29: 中间层 | E29: 数据感知 | F29: aggr_lte_dpi_web_usr_d | G29: 4G_DPI_web用户维度天表 | H29: =G29 -> 4G_DPI_web用户维度天表 | I29: 用户 | J29: 天 | K29: 天 | L29: 核心 | M29: / | N29: 30 | O29: aggr_lte_dpi_web_usr_h | P29: 建维优 | Q29: 新建 | R29: 保留下来的字段沿用表aggr_4g_web_cel_e2e_d字段名称 | T29: 张玉同 | U29: 已开发
A30: 28 | B30: =HYPERLINK("#"&A30&"!A1",A30) -> 28 | C30: 网络数据处理系统 | D30: 中间层 | E30: 数据感知 | F30: aggr_lte_dpi_im_usrcel_d | G30: 4G_DPI_im用户小区维度天表 | H30: =G30 -> 4G_DPI_im用户小区维度天表 | I30: 用户|小区 | J30: 天 | K30: 天 | L30: 核心 | M30: / | N30: 30 | O30: aggr_lte_dpi_http_apptype_usrcel_h | P30: 建维优 | Q30: 新建 | R30: 保留下来的字段沿用表aggr_4g_im_cel_e2e_d字段名称 | T30: 张玉同 | U30: 已开发
A31: 29 | B31: =HYPERLINK("#"&A31&"!A1",A31) -> 29 | C31: 网络数据处理系统 | D31: 中间层 | E31: 数据感知 | F31: aggr_lte_dpi_im_usr_h | G31: 4G_DPI_im用户小区维度天表 | H31: =G31 -> 4G_DPI_im用户小区维度天表 | I31: 用户|小区 | J31: 天 | K31: 天 | L31: 核心 | M31: / | N31: 14 | O31: aggr_lte_dpi_http_apptype_usrcel_h | P31: 建维优 | Q31: 新建 | T31: 张玉同 | U31: 已开发
A32: 30 | B32: =HYPERLINK("#"&A32&"!A1",A32) -> 30 | C32: 网络数据处理系统 | D32: 中间层 | E32: 数据感知 | F32: aggr_lte_dpi_im_usr_d | G32: 4G_DPI_im用户维度天表 | H32: =G32 -> 4G_DPI_im用户维度天表 | I32: 用户 | J32: 天 | K32: 天 | L32: 核心 | M32: / | N32: 30 | O32: aggr_lte_dpi_im_usr_h | P32: 建维优 | Q32: 新建 | R32: 保留下来的字段沿用表aggr_4g_im_cel_e2e_d字段名称 | T32: 张玉同 | U32: 已开发
A33: 31 | B33: =HYPERLINK("#"&A33&"!A1",A33) -> 31 | C33: 网络数据处理系统 | D33: 中间层 | E33: 数据感知 | F33: aggr_lte_wechat_payment_usrcel_d | G33: 4G微信支付用户小区天表 | H33: =G33 -> 4G微信支付用户小区天表 | I33: 用户|小区 | J33: 天 | K33: 天 | L33: 核心 | M33: / | N33: 30 | O33: aggr_lte_dpi_im_usrcel_d | P33: 建维优 | Q33: 新建(升级) | R33: 沿用表aggr_lte_wechat_scan_code_payment_noc_usrcel_d表结构与字段名称 | T33: 张玉同 | U33: 已开发
A34: 33 | B34: =HYPERLINK("#"&A34&"!A1",A34) -> 33 | C34: 网络数据处理系统 | D34: 中间层 | E34: 数据感知 | F34: aggr_lte_dpi_game_usrcel_d | G34: 4G_DPI_game用户小区维度天表 | H34: =G34 -> 4G_DPI_game用户小区维度天表 | I34: 用户|小区 | J34: 天 | K34: 天 | L34: 核心 | M34: / | N34: 30 | O34: aggr_lte_dpi_http_apptype_usrcel_h | P34: 建维优 | Q34: 新建 | R34: 保留下来的字段沿用表aggr_4g_game_cel_e2e_d字段名称 | T34: 张玉同 | U34: 已开发
A35: 34 | B35: =HYPERLINK("#"&A35&"!A1",A35) -> 34 | C35: 网络数据处理系统 | D35: 中间层 | E35: 数据感知 | F35: aggr_lte_dpi_game_usr_h | G35: 4G_DPI_game用户小区维度天表 | H35: =G35 -> 4G_DPI_game用户小区维度天表 | I35: 用户|小区 | J35: 天 | K35: 天 | L35: 核心 | M35: / | N35: 14 | O35: aggr_lte_dpi_http_apptype_usrcel_h | P35: 建维优 | Q35: 新建 | T35: 张玉同 | U35: 已开发
A36: 35 | B36: =HYPERLINK("#"&A36&"!A1",A36) -> 35 | C36: 网络数据处理系统 | D36: 中间层 | E36: 数据感知 | F36: aggr_lte_dpi_game_usr_d | G36: 4G_DPI_game用户维度天表 | H36: =G36 -> 4G_DPI_game用户维度天表 | I36: 用户 | J36: 天 | K36: 天 | L36: 核心 | M36: / | N36: 30 | O36: aggr_lte_dpi_game_usrcel_d | P36: 建维优 | Q36: 新建 | R36: 保留下来的字段沿用表aggr_4g_game_cel_e2e_d字段名称 | T36: 张玉同 | U36: 已开发
A37: 36 | B37: =HYPERLINK("#"&A37&"!A1",A37) -> 36 | C37: 网络数据处理系统 | D37: 中间层 | E37: 数据感知 | F37: aggr_lte_dpi_web_index_reduce_cel_d | G37: 4G_DPI_web小区维度指标裁剪天表 | H37: =G37 -> 4G_DPI_web小区维度指标裁剪天表 | I37: 小区 | J37: 天 | K37: 天 | L37: 核心 | M37: / | N37: 30 | O37: aggr_lte_dpi_web_cel_d | P37: 核心系统(CEM感知) | Q37: 新建(升级) | R37: 对应共享给核心系统的aggr_lteci_web_qoekqi_day，保留下来的字段按照现网名称设计 | T37: 张玉同 | U37: 已开发
A38: 37 | B38: =HYPERLINK("#"&A38&"!A1",A38) -> 37 | C38: 网络数据处理系统 | D38: 中间层 | E38: 数据感知 | F38: aggr_lte_dpi_im_index_reduce_cel_d | G38: 4G_DPI_im小区维度指标裁剪天表 | H38: =G38 -> 4G_DPI_im小区维度指标裁剪天表 | I38: 小区 | J38: 天 | K38: 天 | L38: 核心 | M38: / | N38: 30 | O38: aggr_lte_dpi_im_cel_d | P38: 核心系统(CEM感知) | Q38: 新建(升级) | R38: 对应共享给核心系统的aggr_lteci_im_qoekqi_day，保留下来的字段按照现网名称设计 | T38: 张玉同 | U38: 已开发
A39: 38 | B39: =HYPERLINK("#"&A39&"!A1",A39) -> 38 | C39: 网络数据处理系统 | D39: 中间层 | E39: 数据感知 | F39: aggr_lte_dpi_game_index_reduce_cel_d | G39: 4G_DPI_game小区维度指标裁剪天表 | H39: =G39 -> 4G_DPI_game小区维度指标裁剪天表 | I39: 小区 | J39: 天 | K39: 天 | L39: 核心 | M39: / | N39: 30 | O39: aggr_lte_dpi_game_cel_d | P39: 核心系统(CEM感知) | Q39: 新建(升级) | R39: 对应共享给核心系统的aggr_lteci_game_qoekqi_day，保留下来的字段按照现网名称设计 | T39: 张玉同 | U39: 已开发
A40: 39 | B40: =HYPERLINK("#"&A40&"!A1",A40) -> 39 | C40: 网络数据处理系统 | D40: 中间层 | E40: 数据感知 | F40: aggr_lte_dpi_web_index_reduce_usr_d | G40: 4G_DPI_web用户维度指标裁剪天表 | H40: =G40 -> 4G_DPI_web用户维度指标裁剪天表 | I40: 用户 | J40: 天 | K40: 天 | L40: 核心 | M40: / | N40: 30 | O40: aggr_lte_dpi_web_usr_d | P40: 核心系统(CEM感知) | Q40: 新建(升级) | R40: 对应共享给核心系统的aggr_user_web_qoekqi_day，保留下来的字段按照现网名称设计 | T40: 张玉同 | U40: 已开发
...

Sheet 1
B1: =HYPERLINK("#导航!a2","返回") -> 返回
B3: 目标表基本信息描述
B4: 主题域 | C4: 目标表英文名 | D4: 目标表中文名 | E4: 数据频度 | F4: 模型主键 | G4: 数据描述 | H4: 推送数据库
B5: / | C5: fact_lte_dpi_http_q | D5: 4G_DPI_http整合层15分钟表 | E5: quarter
B7: 源表基本信息描述
B8: 来源系统 | C8: 源表英文名 | D8: 源表中文名 | E8: 别名 | F8: 任务描述 | G8: 备注 | H8: 是否主表
C9: ods_4gdpi_http_e2e_telecom_q | D9: 4G_DPI_http贴源层详单表 | E9: A | H9: 是
C10: lte_cm_projdata_refactor | D10: 4G电联工参 | E10: B | G10: A.cellkey=B.reportcellkey
C11: cfg_topweb_first_screen_host_list | D11: TOP网址首屏时延分析URL配置表 | E11: C | G11: A.host=C.host
C12: cfg_http_status_type | D12: http-status状态码表 | E12: D | G12: A.httpstatus=D.status_code
B14: 详细字段信息
B15: 详细字段信息
B16: PDM字段英文名 | C16: PDM字段类型 | D16: PDM字段中文名（说明） | E16: 源表名 | F16: 源字段英文名 | G16: 算法加工逻辑 | H16: 关联与过滤条件 | I16: 备注 | J16: 字段属性 | K16: 单位 | L16: 取值范围
B17: interface | C17: string | D17: 接口类型：1、S1-U，4、S11，6、S5/S8，100、N3 | E17: A | F17: interface | G17: 直取 | J17: 详单 | K17: 无 | L17: 无
B18: imsi | C18: string | D18: 国际移动用户识别码 | E18: A | F18: imsi | G18: 直取 | J18: 详单 | K18: 无 | L18: 无
B19: msisdn | C19: string | D19: 用户号码 | E19: A | G19: regexp_replace(trim(msisdn),'^86','') | J19: 详单 | K19: 无 | L19: 无
B20: imei | C20: string | D20: 国际移动设备识别码 | E20: A | F20: imei | G20: 直取 | J20: 详单 | K20: 无 | L20: 无
B21: apn | C21: string | D21: 网络接入技术 | E21: A | F21: apn | G21: 直取 | J21: 详单 | K21: 无 | L21: 无
B22: destinationip | C22: string | D22: 用户访问的目标 IPv4或IPv6 地址 | E22: A | F22: destinationip | G22: 直取 | J22: 详单 | K22: 无 | L22: 无
B23: destinationport | C23: int | D23: 用户访问的目标端口号 | E23: A | F23: destinationport | G23: 直取 | J23: 详单 | K23: 无 | L23: 无
B24: sourceip | C24: string | D24: 用户访问外部网络时使用的 IPv4 或 IPv6 地址 | E24: A | F24: sourceip | G24: 直取 | J24: 详单 | K24: 无 | L24: 无
B25: sourceport | C25: int | D25: 用户访问外部网络时使用的端口号 | E25: A | F25: sourceport | G25: 直取 | J25: 详单 | K25: 无 | L25: 无
B26: sgwip | C26: string | D26: SGW的IPv4或IPv6 地址 | E26: A | F26: sgwip | G26: 直取 | J26: 详单 | K26: 无 | L26: 无
B27: mmeip | C27: string | D27: MME的IPv4或IPv6地址 | E27: A | F27: mmeip | G27: 直取 | J27: 详单 | K27: 无 | L27: 无
B28: pgwip | C28: string | D28: PGW的IPv4或IPv6地址 | E28: A | F28: pgwip | G28: 直取 | J28: 详单 | K28: 无 | L28: 无
B29: ecgi | C29: string | D29: 小区唯一标识 | E29: A | F29: ecgi | G29: 直取 | I29: ecgi： 460-11-4992624 | J29: 详单 | K29: 无 | L29: 无
B30: tai | C30: string | D30: 跟踪区标识 | E30: A | F30: tai | G30: 直取 | I30: tai：460-11-48502 | J30: 详单 | K30: 无 | L30: 无
B31: visitedplmnid | C31: string | D31: 拜访网络标识 | E31: A | F31: visitedplmnid | G31: 直取 | J31: 详单 | K31: 无 | L31: 无
B32: rattype | C32: int | D32: 无线接入类型 | E32: A | F32: rattype | G32: 直取 | J32: 详单 | K32: 无 | L32: 无
B33: protocolid | C33: int | D33: 协议类型 | E33: A | F33: protocolid | G33: 直取 | J33: 详单 | K33: 无 | L33: 无
B34: servicetype | C34: string | D34: 业务应用分类ID | E34: A | G34: case when destination_url like '%short.pay.weixin.qq.com%' then 88888888 else servicetype end | J34: 详单 | K34: 无 | L34: 无
B35: starttime | C35: string | D35: 格式为"yyyy-MM-dd HH:mm:sss"的日期时间 | E35: A | F35: starttime | G35: 直取 | J35: 详单 | K35: 无 | L35: 无
B36: endtime | C36: string | D36: 格式为"yyyy-MM-dd HH:mm:sss"的日期时间 | E36: A | F36: endtime | G36: 直取 | J36: 详单 | K36: 无 | L36: 无
B37: duration | C37: bigint | D37: 业务时长 | E37: A | F37: duration | G37: 直取 | J37: 详单 | K37: 无 | L37: 无
B38: inputoctets | C38: bigint | D38: 发给用户的业务字节数 | E38: A | F38: inputoctets | G38: 直取 | J38: 详单 | K38: 无 | L38: 无
B39: outputoctets | C39: bigint | D39: 用户发出的业务字节数 | E39: A | F39: outputoctets | G39: 直取 | J39: 详单 | K39: 无 | L39: 无
B40: inputpacket | C40: bigint | D40: 发给用户的业务数据包数量 | E40: A | F40: inputpacket | G40: 直取 | J40: 详单 | K40: 无 | L40: 无
B41: outputpacket | C41: bigint | D41: 用户发出的业务数据包数量 | E41: A | F41: outputpacket | G41: 直取 | J41: 详单 | K41: 无 | L41: 无
B42: pdnconnectionid | C42: bigint | D42: PDN 连接的ID标识号 | E42: A | F42: pdnconnectionid | G42: 直取 | J42: 详单 | K42: 无 | L42: 无
B43: bearerid | C43: bigint | D43: 承载标识号 | E43: A | F43: bearerid | G43: 直取 | J43: 详单 | K43: 无 | L43: 无
...

Sheet 2
B1: =HYPERLINK("#导航!a2","返回") -> 返回
B3: 目标表基本信息描述
B4: 主题域 | C4: 目标表英文名 | D4: 目标表中文名 | E4: 数据频度 | F4: 模型主键 | G4: 数据描述 | H4: 推送数据库
B5: 数据感知 | C5: aggr_lte_dpi_http_base_q | D5: 4G_DPI_http基础维度15分钟表 | E5: quarter
B7: 源表基本信息描述
B8: 来源系统 | C8: 源表英文名 | D8: 源表中文名 | E8: 别名 | F8: 任务描述 | G8: 备注 | H8: 是否主表
C9: fact_lte_dpi_http_q | D9: 4G_DPI_http整合层15分钟表 | E9: A | H9: 是
B11: 详细字段信息
B12: 详细字段信息
B13: PDM字段英文名 | C13: PDM字段类型 | D13: PDM字段中文名（说明） | E13: 源表名 | F13: 源字段英文名 | G13: 算法加工逻辑 | H13: 关联与过滤条件 | I13: 备注 | J13: 字段属性 | K13: 单位 | L13: 取值范围
B14: day | C14: string | D14: 日期 | E14: A | F14: p_date | G14: 直取 | J14: 维度 | K14: 无 | L14: yyyy-mm-dd
B15: hour | C15: int | D15: 小时 | E15: A | F15: p_hour | G15: 直取 | J15: 维度 | K15: 无 | L15: 0~23
B16: quarter | C16: int | D16: 15分钟 | E16: A | F16: p_quarter | G16: 直取 | J16: 维度 | K16: 无 | L16: 0~3
B17: interface | C17: int | D17: 接口类型 | E17: A | F17: interface | G17: 直取 | J17: 维度 | K17: 无 | L17: <=101
B18: rattype | C18: int | D18: 网络类型（4G：6；5G：10） | E18: A | F18: rattype | G18: 直取 | J18: 维度 | K18: 无 | L18: 6,10
B19: provincecode | C19: int | D19: 省编码 | E19: A | F19: p_provincecode | G19: 直取 | J19: 维度 | K19: 无 | L19: 6位数编码
B20: citycode | C20: int | D20: 市编码 | E20: A | F20: citycode | G20: 直取 | J20: 维度 | K20: 无 | L20: 6位数编码
B21: districtcode | C21: int | D21: 区编码 | E21: A | F21: districtcode | G21: 直取 | J21: 维度 | K21: 无 | L21: 6位数编码
B22: province | C22: string | D22: 省名称 | E22: A | F22: province | G22: 直取 | J22: 维度 | K22: 无 | L22: 无
B23: city | C23: string | D23: 地市名称 | E23: A | F23: city | G23: 直取 | J23: 维度 | K23: 无 | L23: 无
B24: district | C24: string | D24: 区县名称 | E24: A | F24: district | G24: 直取 | J24: 维度 | K24: 无 | L24: 无
B25: cellkey | C25: string | D25: 小区cellkey | E25: A | F25: cellkey | G25: 直取 | J25: 维度 | K25: 无 | L25: 无
... B29: apn | C29: string | D29: 网络接入技术 | E29: A | F29: apn | G29: 直取 | J29: 维度 | K29: 无 | L29: 无
B30: sgwip | C30: string | D30: SGW在GTP-U上的IP地址 | E30: A | F30: =B30 -> sgwip | G30: 直取 | J30: 维度 | K30: 无 | L30: 无
B31: mmeip | C31: string | D31: MME在GTP-C上的IP地址 | E31: A | F31: =B31 -> mmeip | G31: 直取 | J31: 维度 | K31: 无 | L31: 无
B32: pgwip | C32: string | D32: 用户在GTP-U和PMIPv6会话时使用的PGW IP地址。如[RFC 2002]定义 | E32: A | F32: =B32 -> pgwip | G32: 直取 | J32: 维度 | K32: 无 | L32: 无
B33: servicetype | C33: string | D33: 业务应用 | E33: A | F33: servicetype | G33: 直取 | J33: 维度 | K33: 无 | L33: 无
B34: business_type | C34: string | D34: 业务类型（im、web、game、video、other） | E34: A | F34: business_type | G34: 直取 | J34: 维度 | K34: 无 | L34: im,web,game,video,other
B35: enbip | C35: string | D35: ENB的IPv4或IPv6地址 | E35: A | F35: =B35 -> enbip | G35: 直取 | J35: 维度 | K35: 无 | L35: 无
B36: home_province | C36: string | D36: 归属省份 | E36: A | F36: home_province | G36: 直取 | J36: 维度 | K36: 无 | L36: 6位数编码
B37: l4protocol | C37: int | D37: L4协议类型： 0：TCP；1：UDP | E37: A | F37: l4protocol | G37: 直取 | J37: 维度 | K37: 无 | L37: 0,1
B38: bearer_qci | C38: int | D38: 当前业务流所属承载的QCI。 | E38: A | F38: =B38 -> bearer_qci | G38: 直取 | J38: 维度 | K38: 无 | L38: 无
B39: sourceip_type | C39: string | D39: 用户访问外部网络时使用的IP类型（IPv4/IPv6） | E39: A | F39: sourceip_type | G39: 直取 | J39: 维度 | K39: 无 | L39: 无
B40: httpstatus | C40: int | D40: http状态码 | E40: A | F40: httpstatus | G40: 直取 | J40: 维度 | K40: 无 | L40: 无
B41: is_core_delimit | C41: int | D41: 是否核心网问题 | E41: A | F41: is_core_delimit | G41: 直取 | J41: 维度 | K41: 无 | L41: 0,1
B42: is_wireless_delimit | C42: int | D42: 是否无线网络问题 | E42: A | F42: is_wireless_delimit | G42: 直取 | J42: 维度 | K42: 无 | L42: 0,1
B43: is_usr_delimit | C43: int | D43: 是否用户问题 | E43: A | F43: is_usr_delimit | G43: 直取 | J43: 维度 | K43: 无 | L43: 0,1
B44: is_sp_delimit | C44: int | D44: 是否sp服务器问题 | E44: A | F44: is_sp_delimit | G44: 直取 | J44: 维度 | K44: 无 | L44: 0,1
B45: httpstatus_position | C45: string | D45: http状态码原因定位 | E45: A | F45: httpstatus_position | G45: 直取 | J45: 维度 | K45: 无 | L45: 0,1
B46: abnormal_cnt | C46: bigint | D46: 质差话单数量 | E46: A | G46: sum(is_abnormal) | J46: 指标 | K46: 无 | L46: >=0
...

Sheet 3
B1: =HYPERLINK("#导航!a2","返回") -> 返回
B3: 目标表基本信息描述
B4: 主题域 | C4: 目标表英文名 | D4: 目标表中文名 | E4: 数据频度 | F4: 模型主键 | G4: 数据描述 | H4: 推送数据库
B5: 数据感知 | C5: aggr_lte_dpi_http_base_h | D5: 4G_DPI_http基础维度小时表 | E5: hour
B7: 源表基本信息描述
B8: 来源系统 | C8: 源表英文名 | D8: 源表中文名 | E8: 别名 | F8: 任务描述 | G8: 备注 | H8: 是否主表
C9: aggr_lte_dpi_http_base_q | D9: 4G_DPI_http基础维度15分钟表 | E9: A | H9: 是
B11: 详细字段信息
B12: 详细字段信息
B13: PDM字段英文名 | C13: PDM字段类型 | D13: PDM字段中文名（说明） | E13: 源表名 | F13: 源字段英文名 | G13: 算法加工逻辑 | H13: 关联与过滤条件 | I13: 备注 | J13: 字段属性 | K13: 单位 | L13: 取值范围
B14: day | C14: string | D14: 日期 | E14: A | F14: p_date | G14: 直取 | J14: 维度 | K14: 无 | L14: yyyy-mm-dd
B15: hour | C15: int | D15: 小时 | E15: A | F15: p_hour | G15: 直取 | J15: 维度 | K15: 无 | L15: 0~23
B16: interface | C16: int | D16: 接口类型 | E16: A | F16: interface | G16: 直取 | J16: 维度 | K16: 无 | L16: <=101
B17: rattype | C17: int | D17: 网络类型（4G：6；5G：10） | E17: A | F17: rattype | G17: 直取 | J17: 维度 | K17: 无 | L17: 6,10
B18: provincecode | C18: int | D18: 省编码 | E18: A | F18: p_provincecode | G18: 直取 | J18: 维度 | K18: 无 | L18: 6位数编码
B19: citycode | C19: int | D19: 市编码 | E19: A | F19: citycode | G19: 直取 | J19: 维度 | K19: 无 | L19: 6位数编码
B20: districtcode | C20: int | D20: 区编码 | E20: A | F20: districtcode | G20: 直取 | J20: 维度 | K20: 无 | L20: 6位数编码
B21: province | C21: string | D21: 省名称 | E21: A | F21: province | G21: 直取 | J21: 维度 | K21: 无 | L21: 无
B22: city | C22: string | D22: 地市名称 | E22: A | F22: city | G22: 直取 | J22: 维度 | K22: 无 | L22: 无
B23: district | C23: string | D23: 区县名称 | E23: A | F23: district | G23: 直取 | J23: 维度 | K23: 无 | L23: 无
B24: cellkey | C24: string | D24: 小区cellkey | E24: A | F24: cellkey | G24: 直取 | J24: 维度 | K24: 无 | L24: 无
B25: imsi | C25: string | D25: 用户imsi | E25: A | F25: imsi | G25: 直取 | J25: 维度 | K25: 无 | L25: 无
... B28: apn | C28: string | D28: 网络接入技术 | E28: A | F28: apn | G28: 直取 | J28: 维度 | K28: 无 | L28: 无
B29: sgwip | C29: string | D29: SGW在GTP-U上的IP地址 | E29: A | F29: =B29 -> sgwip | G29: 直取 | J29: 维度 | K29: 无 | L29: 无
B30: mmeip | C30: string | D30: MME在GTP-C上的IP地址 | E30: A | F30: =B30 -> mmeip | G30: 直取 | J30: 维度 | K30: 无 | L30: 无
B31: pgwip | C31: string | D31: 用户在GTP-U和PMIPv6会话时使用的PGW IP地址。如[RFC 2002]定义 | E31: A | F31: =B31 -> pgwip | G31: 直取 | J31: 维度 | K31: 无 | L31: 无
B32: servicetype | C32: string | D32: 业务应用 | E32: A | F32: servicetype | G32: 直取 | J32: 维度 | K32: 无 | L32: 无
B33: business_type | C33: string | D33: 业务类型（im、web、game、video、other） | E33: A | F33: business_type | G33: 直取 | J33: 维度 | K33: 无 | L33: im,web,game,video,other
B34: enbip | C34: string | D34: ENB的IPv4或IPv6地址 | E34: A | F34: =B34 -> enbip | G34: 直取 | J34: 维度 | K34: 无 | L34: 无
B35: home_province | C35: string | D35: 归属省份 | E35: A | F35: home_province | G35: 直取 | J35: 维度 | K35: 无 | L35: 6位数编码
B36: l4protocol | C36: int | D36: L4协议类型： 0：TCP；1：UDP | E36: A | F36: l4protocol | G36: 直取 | J36: 维度 | K36: 无 | L36: 0,1
B37: bearer_qci | C37: int | D37: 当前业务流所属承载的QCI。 | E37: A | F37: =B37 -> bearer_qci | G37: 直取 | J37: 维度 | K37: 无 | L37: 无
B38: sourceip_type | C38: string | D38: 用户访问外部网络时使用的IP类型（IPv4/IPv6） | E38: A | F38: sourceip_type | G38: 直取 | J38: 维度 | K38: 无 | L38: 无
B39: httpstatus | C39: int | D39: http状态码 | E39: A | F39: httpstatus | G39: 直取 | J39: 维度 | K39: 无 | L39: 无
B40: is_core_delimit | C40: int | D40: 是否核心网问题 | E40: A | F40: is_core_delimit | G40: 直取 | J40: 维度 | K40: 无 | L40: 0,1
B41: is_wireless_delimit | C41: int | D41: 是否无线网络问题 | E41: A | F41: is_wireless_delimit | G41: 直取 | J41: 维度 | K41: 无 | L41: 0,1
B42: is_usr_delimit | C42: int | D42: 是否用户问题 | E42: A | F42: is_usr_delimit | G42: 直取 | J42: 维度 | K42: 无 | L42: 0,1
B43: is_sp_delimit | C43: int | D43: 是否sp服务器问题 | E43: A | F43: is_sp_delimit | G43: 直取 | J43: 维度 | K43: 无 | L43: 0,1
B44: httpstatus_position | C44: string | D44: http状态码原因定位 | E44: A | F44: httpstatus_position | G44: 直取 | J44: 维度 | K44: 无 | L44: 0,1
B45: abnormal_cnt | C45: bigint | D45: 质差话单数量 | E45: A | G45: sum(abnormal_cnt) | J45: 指标 | K45: 无 | L45: >=0
...

Sheet 4
B1: =HYPERLINK("#导航!a2","返回") -> 返回
B3: 目标表基本信息描述
B4: 主题域 | C4: 目标表英文名 | D4: 目标表中文名 | E4: 数据频度 | F4: 模型主键 | G4: 数据描述 | H4: 推送数据库
B5: 数据感知 | C5: aggr_lte_dpi_http_index_reduce_base_h | D5: 4G_DPI_http基础维度指标裁剪小时表 | E5: hour
B7: 源表基本信息描述
B8: 来源系统 | C8: 源表英文名 | D8: 源表中文名 | E8: 别名 | F8: 任务描述 | G8: 备注 | H8: 是否主表
C9: aggr_lte_dpi_http_base_h | D9: 4G_DPI_http基础维度小时表 | E9: A | H9: 是
B11: 详细字段信息
B12: 详细字段信息
B13: PDM字段英文名 | C13: PDM字段类型 | D13: PDM字段中文名（说明） | E13: 源表名 | F13: 源字段英文名 | G13: 算法加工逻辑 | H13: 关联与过滤条件 | I13: 备注 | J13: 字段属性 | K13: 单位 | L13: 取值范围
B14: day | C14: string | D14: 上报时间，具体到天 | E14: A | F14: p_date | G14: 直取 | J14: 维度 | K14: 无 | L14: yyyy-mm-dd
B15: hour | C15: int | D15: 记录所在的小时 | E15: A | F15: p_hour | G15: 直取 | J15: 维度 | K15: 无 | L15: 0~23
B16: provincecode | C16: int | D16: 拜访地省份 | E16: A | F16: p_provincecode | G16: 直取 | J16: 维度 | K16: 无 | L16: 6位数编码
B17: citycode | C17: int | D17: 拜访地地市 | E17: A | F17: citycode | G17: 直取 | J17: 维度 | K17: 无 | L17: 6位数编码
B18: home_province | C18: int | D18: 漫入用户的归属地省份 | E18: A | F18: home_province | G18: 直取 | J18: 维度 | K18: 无 | L18: 6位数编码
B19: interface | C19: int | D19: 接口类型1：s1-u；6、S5/S8；7：s2a | E19: A | F19: interface | G19: 直取 | J19: 维度 | K19: 无 | L19: <=101
B20: rattype | C20: int | D20: 无线接入类型 | E20: A | F20: rattype | G20: 直取 | J20: 维度 | K20: 无 | L20: 6,10
B21: enodebid | C21: bigint | D21: 4G eNodeBID/5G gNBID | E21: A | G21: split(cellkey,"_")[0] | J21: 维度 | K21: 无 | L21: 无
B22: cellid | C22: bigint | D22: 小区ID | E22: A | G22: split(cellkey,"_")[1] | J22: 维度 | K22: 无 | L22: 无
B23: cellkey | C23: string | D23: 小区cellkey | E23: A | F23: cellkey | G23: 直取 | J23: 维度 | K23: 无 | L23: 无
B24: imsi | C24: string | D24: 永久用户标识，永久用户标识。4G 填写用户IMSI。 | E24: A | F24: imsi | G24: 直取 | J24: 维度 | K24: 无 | L24: 无
B25: msisdn | C25: string | D25: MS International PSTN/ISDN Number (ISDN) | E25: A | F25: msisdn | G25: 直取 | J25: 维度 | K25: 无 | L25: 无
B26: sourceip_type | C26: string | D26: 用户访问外部网络时使用的IP类型（IPv4/IPv6） | E26: A | F26: sourceip_type | G26: 直取 | J26: 维度 | K26: 无 | L26: 无
B27: imei | C27: string | D27: 终端imei | E27: A | F27: imei | G27: 直取 | J27: 维度 | K27: 无 | L27: 无
B28: sgwip | C28: string | D28: SGWIP | E28: A | F28: sgwip | G28: 直取 | J28: 维度 | K28: 无 | L28: 无
B29: enbip | C29: string | D29: ENB的IPv4或IPv6地址 | E29: A | F29: enbip | G29: 直取 | J29: 维度 | K29: 无 | L29: 无
B30: apn | C30: string | D30: 网络接入标识 | E30: A | F30: apn | G30: 直取 | J30: 维度 | K30: 无 | L30: 无
B31: servicetype | C31: int | D31: 业务应用 | E31: A | F31: servicetype | G31: 直取 | J31: 维度 | K31: 无 | L31: 无
B32: outputoctets_sum | C32: bigint | D32: 上行流量(byte) | E32: A | G32: sum(outputoctets) | J32: 指标 | K32: byte | L32: >=0
B33: inputoctets_sum | C33: bigint | D33: 下行流量(byte) | E33: A | G33: sum(inputoctets) | J33: 指标 | K33: byte | L33: >=0
B34: outputoctets_above500_sum | C34: bigint | D34: 上行流量(byte)-大于500KB | E34: A | G34: sum(outputoctets_above500) | J34: 指标 | K34: byte | L34: >=0
B35: outputoctets_above500_cnt_sum | C35: bigint | D35: 上行大包条数(>=500KB) | E35: A | G35: sum(outputoctets_above500_cnt) | J35: 指标 | K35: 无 | L35: >=0
B36: outputoctets_above500_highdelay_sum | C36: bigint | D36: 上行大包高时延条数（>100ms） | E36: A | G36: sum(outputoctets_above500_highdelay_cnt) | J36: 指标 | K36: 无 | L36: >=0
B37: inputoctets_above500_sum | C37: bigint | D37: 下行流量(byte)-大于500KB | E37: A | G37: sum(inputoctets_above500) | J37: 指标 | K37: byte | L37: >=0
B38: inputoctets_above500_cnt_sum | C38: bigint | D38: 下行大包条数(>=500KB) | E38: A | G38: sum(inputoctets_above500_cnt) | J38: 指标 | K38: 无 | L38: >=0
B39: inputoctets_above500_highdelay_sum | C39: bigint | D39: 下行大包高时延条数（>100ms） | E39: A | G39: sum(inputoctets_above500_highdelay_cnt) | J39: 指标 | K39: 无 | L39: >=0
B40: inputpacket_sum | C40: bigint | D40: 发给用户的业务数据包数量 | E40: A | G40: sum(inputpacket) | J40: 指标 | K40: 无 | L40: >=0
B41: outputpacket_sum | C41: bigint | D41: 用户发出的业务数据包数量 | E41: A | G41: sum(outputpacket) | J41: 指标 | K41: 无 | L41: >=0
B42: ultcpreorderingpacket_sum | C42: bigint | D42: 上行TCP乱序报文数，L4协议，非TCP传输时，此字段填0 | E42: A | G42: sum(ultcpreorderingpacket) | J42: 指标 | K42: 无 | L42: >=0
B43: dltcpreorderingpacket_sum | C43: bigint | D43: 下行TCP乱序报文数，非TCP传输时，此字段填0 | E43: A | G43: sum(dltcpreorderingpacket) | J43: 指标 | K43: 无 | L43: >=0
...

Sheet 5
B1: =HYPERLINK("#导航!a2","返回") -> 返回
B3: 目标表基本信息描述
B4: 主题域 | C4: 目标表英文名 | D4: 目标表中文名 | E4: 数据频度 | F4: 模型主键 | G4: 数据描述 | H4: 推送数据库
B5: 数据感知 | C5: aggr_lte_dpi_http_usrappcel_h | D5: 4G_DPI_http用户小区app维度小时表 | E5: hour
B7: 源表基本信息描述
B8: 来源系统 | C8: 源表英文名 | D8: 源表中文名 | E8: 别名 | F8: 任务描述 | G8: 备注 | H8: 是否主表
C9: aggr_lte_dpi_http_base_h | D9: 4G_DPI_http基础维度小时表 | E9: A | H9: 是
B11: 详细字段信息
B12: 详细字段信息
B13: PDM字段英文名 | C13: PDM字段类型 | D13: PDM字段中文名（说明） | E13: 源表名 | F13: 源字段英文名 | G13: 算法加工逻辑 | H13: 关联与过滤条件 | I13: 备注 | J13: 字段属性 | K13: 单位 | L13: 取值范围
B14: day | C14: string | D14: 日期 | E14: A | F14: p_date | G14: 直取 | J14: 维度 | K14: 无 | L14: yyyy-mm-dd
B15: hour | C15: int | D15: 小时 | E15: A | F15: p_hour | G15: 直取 | J15: 维度 | K15: 无 | L15: 0~23
B16: interface | C16: int | D16: 接口类型 | E16: A | F16: interface | G16: 直取 | J16: 维度 | K16: 无 | L16: <=101
B17: rattype | C17: int | D17: 网络类型（4G：6；5G：10） | E17: A | F17: rattype | G17: 直取 | J17: 维度 | K17: 无 | L17: 6,10
B18: provincecode | C18: int | D18: 省编码 | E18: A | F18: p_provincecode | G18: 直取 | J18: 维度 | K18: 无 | L18: 6位数编码
B19: citycode | C19: int | D19: 市编码 | E19: A | F19: citycode | G19: 直取 | J19: 维度 | K19: 无 | L19: 6位数编码
B20: districtcode | C20: int | D20: 区编码 | E20: A | F20: districtcode | G20: 直取 | J20: 维度 | K20: 无 | L20: 6位数编码
B21: province | C21: string | D21: 省名称 | E21: A | F21: province | G21: 直取 | J21: 维度 | K21: 无 | L21: 无
B22: city | C22: string | D22: 地市名称 | E22: A | F22: city | G22: 直取 | J22: 维度 | K22: 无 | L22: 无
B23: district | C23: string | D23: 区县名称 | E23: A | F23: district | G23: 直取 | J23: 维度 | K23: 无 | L23: 无
B24: cellkey | C24: string | D24: 小区cellkey | E24: A | F24: cellkey | G24: 直取 | J24: 维度 | K24: 无 | L24: 无
B25: imsi | C25: string | D25: 用户imsi | E25: A | F25: imsi | G25: 直取 | J25: 维度 | K25: 无 | L25: 无
... B30: home_province | C30: string | D30: 归属省份 | E30: A | F30: home_province | G30: 直取 | J30: 维度 | K30: 无 | L30: 6位数编码
B31: abnormal_cnt | C31: bigint | D31: 质差话单数量 | E31: A | G31: sum(abnormal_cnt) | J31: 指标 | K31: 无 | L31: >=0
B32: record_cnt | C32: bigint | D32: 记录数 | E32: A | G32: sum(record_cnt) | J32: 指标 | K32: 无 | L32: >=0
B33: speedlimit_cnt | C33: bigint | D33: 限速记录数 | E33: A | G33: sum(speedlimit_cnt) | J33: 指标 | K33: 无 | L33: >=0
B34: duration | C34: bigint | D34: 持续时间，单位毫秒 | E34: A | G34: sum(duration) | J34: 指标 | K34: ms | L34: >=0
B35: outputoctets | C35: bigint | D35: 上行流量(byte) | E35: A | G35: sum(outputoctets) | J35: 指标 | K35: byte | L35: >=0
B36: inputoctets | C36: bigint | D36: 下行流量(byte) | E36: A | G36: sum(inputoctets) | J36: 指标 | K36: byte | L36: >=0
B37: outputoctets_above500 | C37: bigint | D37: 上行大包业务流量(>=500KB) | E37: A | G37: sum(outputoctets_above500) | J37: 指标 | K37: byte | L37: >=0
B38: outputoctets_above500_cnt | C38: bigint | D38: 上行大包条数(>=500KB) | E38: A | G38: sum(outputoctets_above500_cnt) | J38: 指标 | K38: 无 | L38: >=0
B39: outputoctets_above500_highdelay_cnt | C39: bigint | D39: 上行大包高时延条数（>100ms） | E39: A | G39: sum(outputoctets_above500_highdelay_cnt) | J39: 指标 | K39: 无 | L39: >=0
B40: inputoctets_above500 | C40: bigint | D40: 下行大包业务流量(>=500KB) | E40: A | G40: sum(inputoctets_above500) | J40: 指标 | K40: byte | L40: >=0
B41: inputoctets_above500_cnt | C41: bigint | D41: 下行大包条数(>=500KB) | E41: A | G41: sum(inputoctets_above500_cnt) | J41: 指标 | K41: 无 | L41: >=0
B42: inputoctets_above500_highdelay_cnt | C42: bigint | D42: 下行大包高时延条数（>100ms） | E42: A | G42: sum(inputoctets_above500_highdelay_cnt) | J42: 指标 | K42: 无 | L42: >=0
... B132: wellgamedelay_cnt | C132: bigint | D132: 游戏交互时延良好次数 | E132: A | G132: sum(wellgamedelay_cnt) | J132: 指标 | K132: 无 | L132: >=0
B133: min_starttime | C133: string | D133: 最小开始时间 | E133: A | G133: min(min_starttime) | I133: 20250415101139 | J133: 指标 | K133: 无 | L133: >0
B134: max_endtime | C134: string | D134: 最大结束时间 | E134: A | G134: max(max_endtime) | I134: 20250415101024 | J134: 指标 | K134: 无 | L134: >0
B135: p_provincecode | C135: int | D135: 省分区
B136: p_date | C136: string | D136: 天分区
...

Sheet 6
B1: =HYPERLINK("#导航!a2","返回") -> 返回
B3: 目标表基本信息描述
B4: 主题域 | C4: 目标表英文名 | D4: 目标表中文名 | E4: 数据频度 | F4: 模型主键 | G4: 数据描述 | H4: 推送数据库
B5: 数据感知 | C5: aggr_lte_dpi_http_usrapp_h | D5: 4G_DPI_http用户app维度小时表 | E5: hour
B7: 源表基本信息描述
B8: 来源系统 | C8: 源表英文名 | D8: 源表中文名 | E8: 别名 | F8: 任务描述 | G8: 备注 | H8: 是否主表
C9: aggr_lte_dpi_http_usrappcel_h | D9: 4G_DPI_http用户小区app维度小时表 | E9: A | H9: 是
B11: 详细字段信息
B12: 详细字段信息
B13: PDM字段英文名 | C13: PDM字段类型 | D13: PDM字段中文名（说明） | E13: 源表名 | F13: 源字段英文名 | G13: 算法加工逻辑 | H13: 关联与过滤条件 | I13: 备注 | J13: 字段属性 | K13: 单位 | L13: 取值范围
B14: day | C14: string | D14: 日期 | E14: A | F14: p_date | G14: 直取 | J14: 维度 | K14: 无 | L14: yyyy-mm-dd
B15: hour | C15: int | D15: 小时 | E15: A | F15: p_hour | G15: 直取 | J15: 维度 | K15: 无 | L15: 0~23
B16: interface | C16: int | D16: 接口类型 | E16: A | F16: interface | G16: 直取 | J16: 维度 | K16: 无 | L16: <=101
B17: rattype | C17: int | D17: 网络类型（4G：6；5G：10） | E17: A | F17: rattype | G17: 直取 | J17: 维度 | K17: 无 | L17: 6,10
B18: provincecode | C18: int | D18: 省编码 | E18: A | F18: p_provincecode | G18: 直取 | J18: 维度 | K18: 无 | L18: 6位数编码
B19: citycode | C19: int | D19: 市编码 | E19: A | F19: citycode | G19: 直取 | J19: 维度 | K19: 无 | L19: 6位数编码
B20: districtcode | C20: int | D20: 区编码 | E20: A | F20: districtcode | G20: 直取 | J20: 维度 | K20: 无 | L20: 6位数编码
B21: province | C21: string | D21: 省名称 | E21: A | F21: province | G21: 直取 | J21: 维度 | K21: 无 | L21: 无
B22: city | C22: string | D22: 地市名称 | E22: A | F22: city | G22: 直取 | J22: 维度 | K22: 无 | L22: 无
B23: district | C23: string | D23: 区县名称 | E23: A | F23: district | G23: 直取 | J23: 维度 | K23: 无 | L23: 无
B24: imsi | C24: string | D24: 用户imsi | E24: A | F24: imsi | G24: 直取 | J24: 维度 | K24: 无 | L24: 无
B25: msisdn | C25: string | D25: 用户号码 | E25: A | F25: msisdn | G25: 直取 | J25: 维度 | K25: 无 | L25: 无
... B29: home_province | C29: string | D29: 归属省份 | E29: A | F29: home_province | G29: 直取 | J29: 维度 | K29: 无 | L29: 6位数编码
B30: abnormal_cnt | C30: bigint | D30: 质差话单数量 | E30: A | G30: sum(abnormal_cnt) | J30: 指标 | K30: 无 | L30: >=0
B31: record_cnt | C31: bigint | D31: 记录数 | E31: A | G31: sum(record_cnt) | J31: 指标 | K31: 无 | L31: >=0
B32: speedlimit_cnt | C32: bigint | D32: 限速记录数 | E32: A | G32: sum(speedlimit_cnt) | J32: 指标 | K32: 无 | L32: >=0
B33: duration | C33: bigint | D33: 持续时间，单位毫秒 | E33: A | G33: sum(duration) | J33: 指标 | K33: ms | L33: >=0
B34: outputoctets | C34: bigint | D34: 上行流量(byte) | E34: A | G34: sum(outputoctets) | J34: 指标 | K34: byte | L34: >=0
B35: inputoctets | C35: bigint | D35: 下行流量(byte) | E35: A | G35: sum(inputoctets) | J35: 指标 | K35: byte | L35: >=0
B36: outputoctets_above500 | C36: bigint | D36: 上行大包业务流量(>=500KB) | E36: A | G36: sum(outputoctets_above500) | J36: 指标 | K36: byte | L36: >=0
B37: outputoctets_above500_cnt | C37: bigint | D37: 上行大包条数(>=500KB) | E37: A | G37: sum(outputoctets_above500_cnt) | J37: 指标 | K37: 无 | L37: >=0
B38: outputoctets_above500_highdelay_cnt | C38: bigint | D38: 上行大包高时延条数（>100ms） | E38: A | G38: sum(outputoctets_above500_highdelay_cnt) | J38: 指标 | K38: 无 | L38: >=0
B39: inputoctets_above500 | C39: bigint | D39: 下行大包业务流量(>=500KB) | E39: A | G39: sum(inputoctets_above500) | J39: 指标 | K39: byte | L39: >=0
B40: inputoctets_above500_cnt | C40: bigint | D40: 下行大包条数(>=500KB) | E40: A | G40: sum(inputoctets_above500_cnt) | J40: 指标 | K40: 无 | L40: >=0
B41: inputoctets_above500_highdelay_cnt | C41: bigint | D41: 下行大包高时延条数（>100ms） | E41: A | G41: sum(inputoctets_above500_highdelay_cnt) | J41: 指标 | K41: 无 | L41: >=0
... B131: wellgamedelay_cnt | C131: bigint | D131: 游戏交互时延良好次数 | E131: A | G131: sum(wellgamedelay_cnt) | J131: 指标 | K131: 无 | L131: >=0
B132: min_starttime | C132: string | D132: 最小开始时间 | E132: A | G132: min(min_starttime) | I132: 20250415101139 | J132: 指标 | K132: 无 | L132: >0
B133: max_endtime | C133: string | D133: 最大结束时间 | E133: A | G133: max(max_endtime) | I133: 20250415101024 | J133: 指标 | K133: 无 | L133: >0
B134: p_provincecode | C134: int | D134: 省分区
B135: p_date | C135: string | D135: 天分区
...

Sheet 7
B1: =HYPERLINK("#导航!a2","返回") -> 返回
B3: 目标表基本信息描述
B4: 主题域 | C4: 目标表英文名 | D4: 目标表中文名 | E4: 数据频度 | F4: 模型主键 | G4: 数据描述 | H4: 推送数据库
B5: 数据感知 | C5: aggr_lte_dpi_http_usrapp_d | D5: 4G_DPI_http用户app维度天表 | E5: day
B7: 源表基本信息描述
B8: 来源系统 | C8: 源表英文名 | D8: 源表中文名 | E8: 别名 | F8: 任务描述 | G8: 备注 | H8: 是否主表
C9: aggr_lte_dpi_http_usrapp_h | D9: 4G_DPI_http用户app维度小时表 | E9: A | H9: 是
B11: 详细字段信息
B12: 详细字段信息
B13: PDM字段英文名 | C13: PDM字段类型 | D13: PDM字段中文名（说明） | E13: 源表名 | F13: 源字段英文名 | G13: 算法加工逻辑 | H13: 关联与过滤条件 | I13: 备注 | J13: 字段属性 | K13: 单位 | L13: 取值范围
B14: day | C14: string | D14: 日期 | E14: A | F14: p_date | G14: 直取 | J14: 维度 | K14: 无 | L14: yyyy-mm-dd
B15: interface | C15: int | D15: 接口类型 | E15: A | F15: interface | G15: 直取 | J15: 维度 | K15: 无 | L15: <=101
B16: rattype | C16: int | D16: 网络类型（4G：6；5G：10） | E16: A | F16: rattype | G16: 直取 | J16: 维度 | K16: 无 | L16: 6,10
B17: provincecode | C17: int | D17: 省编码 | E17: A | F17: p_provincecode | G17: 直取 | J17: 维度 | K17: 无 | L17: 6位数编码
B18: citycode | C18: int | D18: 市编码 | E18: A | F18: citycode | G18: 直取 | J18: 维度 | K18: 无 | L18: 6位数编码
B19: districtcode | C19: int | D19: 区编码 | E19: A | F19: districtcode | G19: 直取 | J19: 维度 | K19: 无 | L19: 6位数编码
B20: province | C20: string | D20: 省名称 | E20: A | F20: province | G20: 直取 | J20: 维度 | K20: 无 | L20: 无
B21: city | C21: string | D21: 地市名称 | E21: A | F21: city | G21: 直取 | J21: 维度 | K21: 无 | L21: 无
B22: district | C22: string | D22: 区县名称 | E22: A | F22: district | G22: 直取 | J22: 维度 | K22: 无 | L22: 无
B23: imsi | C23: string | D23: 用户imsi | E23: A | F23: imsi | G23: 直取 | J23: 维度 | K23: 无 | L23: 无
B24: msisdn | C24: string | D24: 用户号码 | E24: A | F24: msisdn | G24: 直取 | J24: 维度 | K24: 无 | L24: 无
B25: imei | C25: string | D25: 用户终端 | E25: A | F25: imei | G25: 直取 | J25: 维度 | K25: 无 | L25: 无
... B28: home_province | C28: string | D28: 归属省份 | E28: A | F28: home_province | G28: 直取 | J28: 维度 | K28: 无 | L28: 6位数编码
B29: abnormal_cnt | C29: bigint | D29: 质差话单数量 | E29: A | G29: sum(abnormal_cnt) | J29: 指标 | K29: 无 | L29: >=0
B30: record_cnt | C30: bigint | D30: 记录数 | E30: A | G30: sum(record_cnt) | J30: 指标 | K30: 无 | L30: >=0
B31: speedlimit_cnt | C31: bigint | D31: 限速记录数 | E31: A | G31: sum(speedlimit_cnt) | J31: 指标 | K31: 无 | L31: >=0
B32: duration | C32: bigint | D32: 持续时间，单位毫秒 | E32: A | G32: sum(duration) | J32: 指标 | K32: ms | L32: >=0
B33: outputoctets | C33: bigint | D33: 上行流量(byte) | E33: A | G33: sum(outputoctets) | J33: 指标 | K33: byte | L33: >=0
B34: inputoctets | C34: bigint | D34: 下行流量(byte) | E34: A | G34: sum(inputoctets) | J34: 指标 | K34: byte | L34: >=0
B35: outputoctets_above500 | C35: bigint | D35: 上行大包业务流量(>=500KB) | E35: A | G35: sum(outputoctets_above500) | J35: 指标 | K35: byte | L35: >=0
B36: outputoctets_above500_cnt | C36: bigint | D36: 上行大包条数(>=500KB) | E36: A | G36: sum(outputoctets_above500_cnt) | J36: 指标 | K36: 无 | L36: >=0
B37: outputoctets_above500_highdelay_cnt | C37: bigint | D37: 上行大包高时延条数（>100ms） | E37: A | G37: sum(outputoctets_above500_highdelay_cnt) | J37: 指标 | K37: 无 | L37: >=0
B38: inputoctets_above500 | C38: bigint | D38: 下行大包业务流量(>=500KB) | E38: A | G38: sum(inputoctets_above500) | J38: 指标 | K38: byte | L38: >=0
B39: inputoctets_above500_cnt | C39: bigint | D39: 下行大包条数(>=500KB) | E39: A | G39: sum(inputoctets_above500_cnt) | J39: 指标 | K39: 无 | L39: >=0
B40: inputoctets_above500_highdelay_cnt | C40: bigint | D40: 下行大包高时延条数（>100ms） | E40: A | G40: sum(inputoctets_above500_highdelay_cnt) | J40: 指标 | K40: 无 | L40: >=0
... B130: wellgamedelay_cnt | C130: bigint | D130: 游戏交互时延良好次数 | E130: A | G130: sum(wellgamedelay_cnt) | J130: 指标 | K130: 无 | L130: >=0
B131: min_starttime | C131: string | D131: 最小开始时间 | E131: A | G131: min(min_starttime) | I131: 20250415101139 | J131: 指标 | K131: 无 | L131: >0
B132: max_endtime | C132: string | D132: 最大结束时间 | E132: A | G132: max(max_endtime) | I132: 20250415101024 | J132: 指标 | K132: 无 | L132: >0
B133: p_provincecode | C133: int | D133: 省分区
B134: p_date | C134: string | D134: 天分区

Sheet 8
B1: =HYPERLINK("#导航!a2","返回") -> 返回
B3: 目标表基本信息描述
B4: 主题域 | C4: 目标表英文名 | D4: 目标表中文名 | E4: 数据频度 | F4: 模型主键 | G4: 数据描述 | H4: 推送数据库
B5: 数据感知 | C5: aggr_lte_iov_http_usrappcel_refactor_h | D5: 4G_DPI_http车联网用户小区app维度小时表 | E5: hour
B7: 源表基本信息描述
B8: 来源系统 | C8: 源表英文名 | D8: 源表中文名 | E8: 别名 | F8: 任务描述 | G8: 备注 | H8: 是否主表
C9: aggr_lte_dpi_http_usrappcel_h | D9: 4G_DPI_http用户小区app维度小时表 | E9: A | H9: 是
C10: cfg_dpi_servicetype | D10: DPI业务码表 | E10: B | F10: A left join B，关联条件：A.servicetype = B.servicetype
C11: cfg_iov_usr_list | D11: 车联网用户清单配置表 | E11: C | F11: A inner join C，关联条件：A.msisdn = C.msisdn
B13: 详细字段信息
B14: 详细字段信息
B15: PDM字段英文名 | C15: PDM字段类型 | D15: PDM字段中文名（说明） | E15: 源表名 | F15: 源字段英文名 | G15: 算法加工逻辑 | H15: 关联与过滤条件 | I15: 备注 | J15: 字段属性 | K15: 单位 | L15: 取值范围
B16: day | C16: string | D16: 日期 | E16: A | F16: p_date | G16: 直取 | J16: 维度 | K16: 无 | L16: 无
B17: hour | C17: int | D17: 小时 | E17: A | F17: p_hour | G17: 直取 | J17: 维度 | K17: 无 | L17: 无
B18: provincecode | C18: int | D18: 省编码 | E18: A | F18: p_provincecode | G18: 直取 | J18: 维度 | K18: 无 | L18: 无
B19: citycode | C19: int | D19: 市编码 | E19: A | F19: citycode | G19: 直取 | J19: 维度 | K19: 无 | L19: 无
B20: districtcode | C20: int | D20: 区县编码 | E20: A | F20: districtcode | G20: 直取 | J20: 维度 | K20: 无 | L20: 无
B21: cellkey | C21: string | D21: 小区唯一标识："小区基站号"_"小区编号" | E21: A | F21: cellkey | G21: 直取 | J21: 维度 | K21: 无 | L21: 无
B22: imsi | C22: string | D22: 国际移动用户识别码 | E22: A | F22: imsi | G22: 直取 | J22: 维度 | K22: 无 | L22: 无
B23: msisdn | C23: string | D23: 用户号码 | E23: A | F23: msisdn | G23: 直取 | J23: 维度 | K23: 无 | L23: 无
B24: imei | C24: string | D24: 终端识别码 | E24: A | F24: imei | G24: 直取 | J24: 维度 | K24: 无 | L24: 无
B25: servicetype | C25: string | D25: 业务应用分类ID | E25: A | F25: servicetype | G25: 直取 | J25: 维度 | K25: 无 | L25: 无
B26: app_type | C26: string | D26: 业务应用大类 | E26: A | G26: substr(servicetype,1,2) | J26: 维度 | K26: 无 | L26: 无
B27: app_name | C27: string | D27: 业务名称 | E27: B | F27: servicetype_name | G27: 直取 | J27: 维度 | K27: 无 | L27: 无
B28: min_starttime | C28: string | D28: 最小开始时间 | E28: A | G28: min(min_starttime) | J28: 指标 | K28: 无 | L28: 无
B29: max_endtime | C29: string | D29: 最大结束时间 | E29: A | G29: max(max_endtime) | J29: 指标 | K29: 无 | L29: 无
B30: total_cnt | C30: bigint | D30: 总话单数 | E30: A | G30: sum(record_cnt) | J30: 指标 | K30: 无 | L30: >=0
B31: abnormal_cnt | C31: bigint | D31: 总质差话单数 | E31: A | G31: sum(abnormal_cnt) | J31: 指标 | K31: 无 | L31: >=0
B32: abnormal_rate | C32: double | D32: 总质差话单占比 | E32: A | G32: sum(abnormal_cnt)/sum(record_cnt) | J32: 指标 | K32: 无 | L32: [0,1]
B33: duration | C33: bigint | D33: 业务时长(ms) | E33: A | G33: sum(duration) | J33: 指标 | K33: ms | L33: >=0
B34: flux | C34: bigint | D34: 业务流量(byte) | E34: A | G34: sum(nvl(outputoctets,0)+nvl(inputoctets,0)) | J34: 指标 | K34: byte | L34: >=0
B35: p_provincecode | C35: int | D35: 省分区
B36: p_date | C36: string | D36: 天分区
B37: p_hour | C37: int | D37: 小时分区

Sheet 9
B1: =HYPERLINK("#导航!a2","返回") -> 返回
B3: 目标表基本信息描述
B4: 主题域 | C4: 目标表英文名 | D4: 目标表中文名 | E4: 数据频度 | F4: 模型主键 | G4: 数据描述 | H4: 推送数据库
B5: 数据感知 | C5: aggr_lte_dpi_http_appcel_h | D5: 4G_DPI_http小区app维度小时表 | E5: hour
B7: 源表基本信息描述
B8: 来源系统 | C8: 源表英文名 | D8: 源表中文名 | E8: 别名 | F8: 任务描述 | G8: 备注 | H8: 是否主表
C9: aggr_lte_dpi_http_usrappcel_h | D9: 4G_DPI_http用户小区app维度小时表 | E9: A | H9: 是
B11: 详细字段信息
B12: 详细字段信息
B13: PDM字段英文名 | C13: PDM字段类型 | D13: PDM字段中文名（说明） | E13: 源表名 | F13: 源字段英文名 | G13: 算法加工逻辑 | H13: 关联与过滤条件 | I13: 备注 | J13: 字段属性 | K13: 单位 | L13: 取值范围
B14: day | C14: string | D14: 日期 | E14: A | F14: p_date | G14: 直取 | J14: 维度 | K14: 无 | L14: yyyy-mm-dd
B15: hour | C15: int | D15: 小时 | E15: A | F15: p_hour | G15: 直取 | J15: 维度 | K15: 无 | L15: 0~23
B16: interface | C16: int | D16: 接口类型 | E16: A | F16: interface | G16: 直取 | J16: 维度 | K16: 无 | L16: <=101
B17: rattype | C17: int | D17: 网络类型（4G：6；5G：10） | E17: A | F17: rattype | G17: 直取 | J17: 维度 | K17: 无 | L17: 6,10
B18: provincecode | C18: int | D18: 省编码 | E18: A | F18: p_provincecode | G18: 直取 | J18: 维度 | K18: 无 | L18: 6位数编码
B19: citycode | C19: int | D19: 市编码 | E19: A | F19: citycode | G19: 直取 | J19: 维度 | K19: 无 | L19: 6位数编码
B20: districtcode | C20: int | D20: 区编码 | E20: A | F20: districtcode | G20: 直取 | J20: 维度 | K20: 无 | L20: 6位数编码
B21: province | C21: string | D21: 省名称 | E21: A | F21: province | G21: 直取 | J21: 维度 | K21: 无 | L21: 无
B22: city | C22: string | D22: 地市名称 | E22: A | F22: city | G22: 直取 | J22: 维度 | K22: 无 | L22: 无
B23: district | C23: string | D23: 区县名称 | E23: A | F23: district | G23: 直取 | J23: 维度 | K23: 无 | L23: 无
B24: cellkey | C24: string | D24: 小区cellkey | E24: A | F24: cellkey | G24: 直取 | J24: 维度 | K24: 无 | L24: 无
B25: servicetype | C25: string | D25: 业务应用 | E25: A | F25: servicetype | G25: 直取 | J25: 维度 | K25: 无 | L25: 无
B26: business_type | C26: string | D26: 业务类型（im、web、game、video、other） | E26: A | F26: business_type | G26: 直取 | J26: 维度 | K26: 无 | L26: im,web,game,video,other
B27: abnormal_cnt | C27: bigint | D27: 质差话单数量 | E27: A | G27: sum(abnormal_cnt) | J27: 指标 | K27: 无 | L27: >=0
B28: record_cnt | C28: bigint | D28: 记录数 | E28: A | G28: sum(record_cnt) | J28: 指标 | K28: 无 | L28: >=0
B29: speedlimit_cnt | C29: bigint | D29: 限速记录数 | E29: A | G29: sum(speedlimit_cnt) | J29: 指标 | K29: 无 | L29: >=0
B30: duration | C30: bigint | D30: 持续时间，单位毫秒 | E30: A | G30: sum(duration) | J30: 指标 | K30: ms | L30: >=0
B31: outputoctets | C31: bigint | D31: 上行流量(byte) | E31: A | G31: sum(outputoctets) | J31: 指标 | K31: byte | L31: >=0
B32: inputoctets | C32: bigint | D32: 下行流量(byte) | E32: A | G32: sum(inputoctets) | J32: 指标 | K32: byte | L32: >=0
B33: outputoctets_above500 | C33: bigint | D33: 上行大包业务流量(>=500KB) | E33: A | G33: sum(outputoctets_above500) | J33: 指标 | K33: byte | L33: >=0
B34: outputoctets_above500_cnt | C34: bigint | D34: 上行大包条数(>=500KB) | E34: A | G34: sum(outputoctets_above500_cnt) | J34: 指标 | K34: 无 | L34: >=0
B35: outputoctets_above500_highdelay_cnt | C35: bigint | D35: 上行大包高时延条数（>100ms） | E35: A | G35: sum(outputoctets_above500_highdelay_cnt) | J35: 指标 | K35: 无 | L35: >=0
B36: inputoctets_above500 | C36: bigint | D36: 下行大包业务流量(>=500KB) | E36: A | G36: sum(inputoctets_above500) | J36: 指标 | K36: byte | L36: >=0
B37: inputoctets_above500_cnt | C37: bigint | D37: 下行大包条数(>=500KB) | E37: A | G37: sum(inputoctets_above500_cnt) | J37: 指标 | K37: 无 | L37: >=0
B38: inputoctets_above500_highdelay_cnt | C38: bigint | D38: 下行大包高时延条数（>100ms） | E38: A | G38: sum(inputoctets_above500_highdelay_cnt) | J38: 指标 | K38: 无 | L38: >=0
... B128: wellgamedelay_cnt | C128: bigint | D128: 游戏交互时延良好次数 | E128: A | G128: sum(wellgamedelay_cnt) | J128: 指标 | K128: 无 | L128: >=0
B129: min_starttime | C129: string | D129: 最小开始时间 | E129: A | G129: min(min_starttime) | I129: 20250415101139 | J129: 指标 | K129: 无 | L129: >0
B130: max_endtime | C130: string | D130: 最大结束时间 | E130: A | G130: max(max_endtime) | I130: 20250415101024 | J130: 指标 | K130: 无 | L130: >0
B131: p_provincecode | C131: int | D131: 省分区
B132: p_date | C132: string | D132: 天分区
...

Sheet 10
B1: =HYPERLINK("#导航!a2","返回") -> 返回
B3: 目标表基本信息描述
B4: 主题域 | C4: 目标表英文名 | D4: 目标表中文名 | E4: 数据频度 | F4: 模型主键 | G4: 数据描述 | H4: 推送数据库
B5: 数据感知 | C5: aggr_lte_dpi_http_appcel_d | D5: 4G_DPI_http小区app维度天表 | E5: day
B7: 源表基本信息描述
B8: 来源系统 | C8: 源表英文名 | D8: 源表中文名 | E8: 别名 | F8: 任务描述 | G8: 备注 | H8: 是否主表
C9: aggr_lte_dpi_http_appcel_h | D9: 4G_DPI_http小区app维度小时表 | E9: A | H9: 是
B11: 详细字段信息
B12: 详细字段信息
B13: PDM字段英文名 | C13: PDM字段类型 | D13: PDM字段中文名（说明） | E13: 源表名 | F13: 源字段英文名 | G13: 算法加工逻辑 | H13: 关联与过滤条件 | I13: 备注 | J13: 字段属性 | K13: 单位 | L13: 取值范围
B14: day | C14: string | D14: 日期 | E14: A | F14: p_date | G14: 直取 | J14: 维度 | K14: 无 | L14: yyyy-mm-dd
B15: interface | C15: int | D15: 接口类型 | E15: A | F15: interface | G15: 直取 | J15: 维度 | K15: 无 | L15: <=101
B16: rattype | C16: int | D16: 网络类型（4G：6；5G：10） | E16: A | F16: rattype | G16: 直取 | J16: 维度 | K16: 无 | L16: 6,10
B17: provincecode | C17: int | D17: 省编码 | E17: A | F17: p_provincecode | G17: 直取 | J17: 维度 | K17: 无 | L17: 6位数编码
B18: citycode | C18: int | D18: 市编码 | E18: A | F18: citycode | G18: 直取 | J18: 维度 | K18: 无 | L18: 6位数编码
B19: districtcode | C19: int | D19: 区编码 | E19: A | F19: districtcode | G19: 直取 | J19: 维度 | K19: 无 | L19: 6位数编码
B20: province | C20: string | D20: 省名称 | E20: A | F20: province | G20: 直取 | J20: 维度 | K20: 无 | L20: 无
B21: city | C21: string | D21: 地市名称 | E21: A | F21: city | G21: 直取 | J21: 维度 | K21: 无 | L21: 无
B22: district | C22: string | D22: 区县名称 | E22: A | F22: district | G22: 直取 | J22: 维度 | K22: 无 | L22: 无
B23: cellkey | C23: string | D23: 小区cellkey | E23: A | F23: cellkey | G23: 直取 | J23: 维度 | K23: 无 | L23: 无
B24: servicetype | C24: string | D24: 业务应用 | E24: A | F24: servicetype | G24: 直取 | J24: 维度 | K24: 无 | L24: 无
B25: business_type | C25: string | D25: 业务类型（im、web、game、video、other） | E25: A | F25: business_type | G25: 直取 | J25: 维度 | K25: 无 | L25: im,web,game,video,other
B26: abnormal_cnt | C26: bigint | D26: 质差话单数量 | E26: A | G26: sum(abnormal_cnt) | J26: 指标 | K26: 无 | L26: >=0
B27: record_cnt | C27: bigint | D27: 记录数 | E27: A | G27: sum(record_cnt) | J27: 指标 | K27: 无 | L27: >=0
B28: speedlimit_cnt | C28: bigint | D28: 限速记录数 | E28: A | G28: sum(speedlimit_cnt) | J28: 指标 | K28: 无 | L28: >=0
B29: duration | C29: bigint | D29: 持续时间，单位毫秒 | E29: A | G29: sum(duration) | J29: 指标 | K29: ms | L29: >=0
B30: outputoctets | C30: bigint | D30: 上行流量(byte) | E30: A | G30: sum(outputoctets) | J30: 指标 | K30: byte | L30: >=0
B31: inputoctets | C31: bigint | D31: 下行流量(byte) | E31: A | G31: sum(inputoctets) | J31: 指标 | K31: byte | L31: >=0
B32: outputoctets_above500 | C32: bigint | D32: 上行大包业务流量(>=500KB) | E32: A | G32: sum(outputoctets_above500) | J32: 指标 | K32: byte | L32: >=0
B33: outputoctets_above500_cnt | C33: bigint | D33: 上行大包条数(>=500KB) | E33: A | G33: sum(outputoctets_above500_cnt) | J33: 指标 | K33: 无 | L33: >=0
B34: outputoctets_above500_highdelay_cnt | C34: bigint | D34: 上行大包高时延条数（>100ms） | E34: A | G34: sum(outputoctets_above500_highdelay_cnt) | J34: 指标 | K34: 无 | L34: >=0
B35: inputoctets_above500 | C35: bigint | D35: 下行大包业务流量(>=500KB) | E35: A | G35: sum(inputoctets_above500) | J35: 指标 | K35: byte | L35: >=0
B36: inputoctets_above500_cnt | C36: bigint | D36: 下行大包条数(>=500KB) | E36: A | G36: sum(inputoctets_above500_cnt) | J36: 指标 | K36: 无 | L36: >=0
B37: inputoctets_above500_highdelay_cnt | C37: bigint | D37: 下行大包高时延条数（>100ms） | E37: A | G37: sum(inputoctets_above500_highdelay_cnt) | J37: 指标 | K37: 无 | L37: >=0
... B127: wellgamedelay_cnt | C127: bigint | D127: 游戏交互时延良好次数 | E127: A | G127: sum(wellgamedelay_cnt) | J127: 指标 | K127: 无 | L127: >=0
B128: p_provincecode | C128: int | D128: 省分区
B129: p_date | C129: string | D129: 天分区

Sheet 11
B1: =HYPERLINK("#导航!a2","返回") -> 返回
B3: 目标表基本信息描述
B4: 主题域 | C4: 目标表英文名 | D4: 目标表中文名 | E4: 数据频度 | F4: 模型主键 | G4: 数据描述 | H4: 推送数据库
B5: 数据感知 | C5: aggr_lte_dpi_http_cel_d | D5: 4G_DPI_http小区维度天表 | E5: day
B7: 源表基本信息描述
B8: 来源系统 | C8: 源表英文名 | D8: 源表中文名 | E8: 别名 | F8: 任务描述 | G8: 备注 | H8: 是否主表
C9: aggr_lte_dpi_http_appcel_d | D9: 4G_DPI_http小区app维度天表 | E9: A | H9: 是
B11: 详细字段信息
B12: 详细字段信息
B13: PDM字段英文名 | C13: PDM字段类型 | D13: PDM字段中文名（说明） | E13: 源表名 | F13: 源字段英文名 | G13: 算法加工逻辑 | H13: 关联与过滤条件 | I13: 备注 | J13: 字段属性 | K13: 单位 | L13: 取值范围
B14: day | C14: string | D14: 日期 | E14: A | F14: p_date | G14: 直取 | J14: 维度 | K14: 无 | L14: yyyy-mm-dd
B15: interface | C15: int | D15: 接口类型 | E15: A | F15: interface | G15: 直取 | J15: 维度 | K15: 无 | L15: <=101
B16: rattype | C16: int | D16: 网络类型（4G：6；5G：10） | E16: A | F16: rattype | G16: 直取 | J16: 维度 | K16: 无 | L16: 6,10
B17: provincecode | C17: int | D17: 省编码 | E17: A | F17: p_provincecode | G17: 直取 | J17: 维度 | K17: 无 | L17: 6位数编码
B18: citycode | C18: int | D18: 市编码 | E18: A | F18: citycode | G18: 直取 | J18: 维度 | K18: 无 | L18: 6位数编码
B19: districtcode | C19: int | D19: 区编码 | E19: A | F19: districtcode | G19: 直取 | J19: 维度 | K19: 无 | L19: 6位数编码
B20: province | C20: string | D20: 省名称 | E20: A | F20: province | G20: 直取 | J20: 维度 | K20: 无 | L20: 无
B21: city | C21: string | D21: 地市名称 | E21: A | F21: city | G21: 直取 | J21: 维度 | K21: 无 | L21: 无
B22: district | C22: string | D22: 区县名称 | E22: A | F22: district | G22: 直取 | J22: 维度 | K22: 无 | L22: 无
B23: cellkey | C23: string | D23: 小区cellkey | E23: A | F23: cellkey | G23: 直取 | J23: 维度 | K23: 无 | L23: 无
B24: abnormal_cnt | C24: bigint | D24: 质差话单数量 | E24: A | G24: sum(abnormal_cnt) | J24: 指标 | K24: 无 | L24: >=0
B25: record_cnt | C25: bigint | D25: 记录数 | E25: A | G25: sum(record_cnt) | J25: 指标 | K25: 无 | L25: >=0
B26: speedlimit_cnt | C26: bigint | D26: 限速记录数 | E26: A | G26: sum(speedlimit_cnt) | J26: 指标 | K26: 无 | L26: >=0
B27: duration | C27: bigint | D27: 持续时间，单位毫秒 | E27: A | G27: sum(duration) | J27: 指标 | K27: ms | L27: >=0
B28: outputoctets | C28: bigint | D28: 上行流量(byte) | E28: A | G28: sum(outputoctets) | J28: 指标 | K28: byte | L28: >=0
B29: inputoctets | C29: bigint | D29: 下行流量(byte) | E29: A | G29: sum(inputoctets) | J29: 指标 | K29: byte | L29: >=0
B30: outputoctets_above500 | C30: bigint | D30: 上行大包业务流量(>=500KB) | E30: A | G30: sum(outputoctets_above500) | J30: 指标 | K30: byte | L30: >=0
B31: outputoctets_above500_cnt | C31: bigint | D31: 上行大包条数(>=500KB) | E31: A | G31: sum(outputoctets_above500_cnt) | J31: 指标 | K31: 无 | L31: >=0
B32: outputoctets_above500_highdelay_cnt | C32: bigint | D32: 上行大包高时延条数（>100ms） | E32: A | G32: sum(outputoctets_above500_highdelay_cnt) | J32: 指标 | K32: 无 | L32: >=0
B33: inputoctets_above500 | C33: bigint | D33: 下行大包业务流量(>=500KB) | E33: A | G33: sum(inputoctets_above500) | J33: 指标 | K33: byte | L33: >=0
B34: inputoctets_above500_cnt | C34: bigint | D34: 下行大包条数(>=500KB) | E34: A | G34: sum(inputoctets_above500_cnt) | J34: 指标 | K34: 无 | L34: >=0
B35: inputoctets_above500_highdelay_cnt | C35: bigint | D35: 下行大包高时延条数（>100ms） | E35: A | G35: sum(inputoctets_above500_highdelay_cnt) | J35: 指标 | K35: 无 | L35: >=0
... B125: wellgamedelay_cnt | C125: bigint | D125: 游戏交互时延良好次数 | E125: A | G125: sum(wellgamedelay_cnt) | J125: 指标 | K125: 无 | L125: >=0
B126: p_provincecode | C126: int | D126: 省分区
B127: p_date | C127: string | D127: 天分区

Sheet 12
B1: =HYPERLINK("#导航!a2","返回") -> 返回
B3: 目标表基本信息描述
B4: 主题域 | C4: 目标表英文名 | D4: 目标表中文名 | E4: 数据频度 | F4: 模型主键 | G4: 数据描述 | H4: 推送数据库
B5: 数据感知 | C5: aggr_lte_dpi_web_appcel_h | D5: 4G_DPI_web小区app维度小时表 | E5: hour
B7: 源表基本信息描述
B8: 来源系统 | C8: 源表英文名 | D8: 源表中文名 | E8: 别名 | F8: 任务描述 | G8: 备注 | H8: 是否主表
C9: aggr_lte_dpi_http_appcel_h | D9: 4G_DPI_http小区app维度小时表 | E9: A | G9: 过滤条件：business_type='web' | H9: 是
B11: 详细字段信息
B12: 详细字段信息
B13: PDM字段英文名 | C13: PDM字段类型 | D13: PDM字段中文名（说明） | E13: 源表名 | F13: 源字段英文名 | G13: 算法加工逻辑 | H13: 关联与过滤条件 | I13: 备注 | J13: 字段属性 | K13: 单位 | L13: 取值范围
B14: day | C14: string | D14: 日期 | E14: A | F14: p_date | G14: 直取 | J14: 维度 | K14: 无 | L14: yyyy-mm-dd
B15: hour | C15: int | D15: 小时 | E15: A | F15: p_hour | G15: 直取 | J15: 维度 | K15: 无 | L15: 0~23
B16: interface | C16: int | D16: 接口类型 | E16: A | F16: interface | G16: 直取 | J16: 维度 | K16: 无 | L16: <=101
B17: rattype | C17: int | D17: 网络类型（4G：6；5G：10） | E17: A | F17: rattype | G17: 直取 | J17: 维度 | K17: 无 | L17: 6,10
B18: provincecode | C18: int | D18: 省编码 | E18: A | F18: p_provincecode | G18: 直取 | J18: 维度 | K18: 无 | L18: 6位数编码
B19: citycode | C19: int | D19: 市编码 | E19: A | F19: citycode | G19: 直取 | J19: 维度 | K19: 无 | L19: 6位数编码
B20: districtcode | C20: int | D20: 区编码 | E20: A | F20: districtcode | G20: 直取 | J20: 维度 | K20: 无 | L20: 6位数编码
B21: province | C21: string | D21: 省名称 | E21: A | F21: province | G21: 直取 | J21: 维度 | K21: 无 | L21: 无
B22: city | C22: string | D22: 地市名称 | E22: A | F22: city | G22: 直取 | J22: 维度 | K22: 无 | L22: 无
B23: district | C23: string | D23: 区县名称 | E23: A | F23: district | G23: 直取 | J23: 维度 | K23: 无 | L23: 无
B24: cellkey | C24: string | D24: 小区cellkey | E24: A | F24: cellkey | G24: 直取 | J24: 维度 | K24: 无 | L24: 无
B25: servicetype | C25: string | D25: 业务应用 | E25: A | F25: servicetype | G25: 直取 | J25: 维度 | K25: 无 | L25: 无
B26: abnormal_cnt | C26: bigint | D26: 质差话单数量 | E26: A | G26: sum(abnormal_cnt) | J26: 指标 | K26: 无 | L26: >=0
B27: record_cnt | C27: bigint | D27: 记录数 | E27: A | G27: sum(record_cnt) | J27: 指标 | K27: 无 | L27: >=0
B28: speedlimit_cnt | C28: bigint | D28: 限速记录数 | E28: A | G28: sum(speedlimit_cnt) | J28: 指标 | K28: 无 | L28: >=0
B29: duration | C29: bigint | D29: 持续时间，单位毫秒 | E29: A | G29: sum(duration) | J29: 指标 | K29: ms | L29: >=0
B30: outputoctets | C30: bigint | D30: 上行流量(byte) | E30: A | G30: sum(outputoctets) | J30: 指标 | K30: byte | L30: >=0
B31: inputoctets | C31: bigint | D31: 下行流量(byte) | E31: A | G31: sum(inputoctets) | J31: 指标 | K31: byte | L31: >=0
B32: outputoctets_above500 | C32: bigint | D32: 上行大包业务流量(>=500KB) | E32: A | G32: sum(outputoctets_above500) | J32: 指标 | K32: byte | L32: >=0
B33: outputoctets_above500_cnt | C33: bigint | D33: 上行大包条数(>=500KB) | E33: A | G33: sum(outputoctets_above500_cnt) | J33: 指标 | K33: 无 | L33: >=0
B34: outputoctets_above500_highdelay_cnt | C34: bigint | D34: 上行大包高时延条数（>100ms） | E34: A | G34: sum(outputoctets_above500_highdelay_cnt) | J34: 指标 | K34: 无 | L34: >=0
B35: inputoctets_above500 | C35: bigint | D35: 下行大包业务流量(>=500KB) | E35: A | G35: sum(inputoctets_above500) | J35: 指标 | K35: byte | L35: >=0
B36: inputoctets_above500_cnt | C36: bigint | D36: 下行大包条数(>=500KB) | E36: A | G36: sum(inputoctets_above500_cnt) | J36: 指标 | K36: 无 | L36: >=0
B37: inputoctets_above500_highdelay_cnt | C37: bigint | D37: 下行大包高时延条数（>100ms） | E37: A | G37: sum(inputoctets_above500_highdelay_cnt) | J37: 指标 | K37: 无 | L37: >=0
... B124: wellcmpltdelay_cnt | C124: bigint | D124: 打开时延良好次数 | E124: A | G124: sum(wellcmpltdelay_cnt) | J124: 指标 | K124: 无 | L124: >=0
B125: p_provincecode | C125: int | D125: 省分区
B126: p_date | C126: string | D126: 天分区
B127: p_hour | C127: int | D127: 小时分区

Sheet 13
B1: =HYPERLINK("#导航!a2","返回") -> 返回
B3: 目标表基本信息描述
B4: 主题域 | C4: 目标表英文名 | D4: 目标表中文名 | E4: 数据频度 | F4: 模型主键 | G4: 数据描述 | H4: 推送数据库
B5: 数据感知 | C5: aggr_lte_dpi_web_appcel_d | D5: 4G_DPI_web小区app维度天表 | E5: day
B7: 源表基本信息描述
B8: 来源系统 | C8: 源表英文名 | D8: 源表中文名 | E8: 别名 | F8: 任务描述 | G8: 备注 | H8: 是否主表
C9: aggr_lte_dpi_web_appcel_h | D9: 4G_DPI_web小区app维度小时表 | E9: A | H9: 是
B11: 详细字段信息
B12: 详细字段信息
B13: PDM字段英文名 | C13: PDM字段类型 | D13: PDM字段中文名（说明） | E13: 源表名 | F13: 源字段英文名 | G13: 算法加工逻辑 | H13: 关联与过滤条件 | I13: 备注 | J13: 字段属性 | K13: 单位 | L13: 取值范围
B14: day | C14: string | D14: 日期 | E14: A | F14: p_date | G14: 直取 | J14: 维度 | K14: 无 | L14: yyyy-mm-dd
B15: interface | C15: int | D15: 接口类型 | E15: A | F15: interface | G15: 直取 | J15: 维度 | K15: 无 | L15: <=101
