Workbook

Sheet 导航
A1: 内部编号 | B1: 索引 | C1: 项目名称 | D1: 数据层级 | E1: 主题域 | F1: 表英文名 | G1: 表中文名 | H1: 数据描述 | I1: 汇聚维度 | J1: 数据时间粒度 | K1: 最小时间分区 | L1: 计算位置 | M1: 是否同步 | N1: 生命周期（存储周期单位：天） | O1: 前向表 | P1: 支撑应用/系统 | Q1: 新建/升级 | R1: 备注 | S1: 同步数据库
A2: 1 | B2: =HYPERLINK("#"&A2&"!A1",A2) -> 1 | C2: 网络数据处理系统 | D2: 贴源层 | E2: / | F2: ods_lte_mro_analysis_q | G2: 4G电联MRO解析详单表 | H2: 4G电联MRO解析详单表 | I2: / | J2: 详单 | K2: 15分钟 | L2: 前置 | N2: 3 | O2: 原始数据解析 | Q2: 新建
A3: 2 | B3: =HYPERLINK("#"&A3&"!A1",A3) -> 2 | C3: 网络数据处理系统 | D3: 整合层 | E3: / | F3: fact_lte_mro_location_q | G3: 4G电联MRO位置定位详单表 | H3: 4G电联MRO位置定位详单表 | I3: / | J3: 详单 | K3: 15分钟 | L3: 前置 | N3: 3 | O3: ods_lte_mro_analysis_q | Q3: 新建
A4: 3 | B4: =HYPERLINK("#"&A4&"!A1",A4) -> 3 | C4: 网络数据处理系统 | D4: 整合层 | E4: / | F4: fact_lte_mro_usrbackfill_q | G4: 4G电联MRO用户回填详单表 | H4: 4G电联MRO用户回填详单表 | I4: / | J4: 详单 | K4: 15分钟 | L4: 前置 | N4: 3 | O4: fact_lte_mro_location_q、ods_pscp_s1mme_front_5min | P4: 建维优 | Q4: 新建
A5: 3.2 | B5: =HYPERLINK("#"&A5&"!A1",A5) -> 3.2 | C5: 网络数据处理系统 | D5: 整合层 | E5: / | F5: fact_lte_mro_iov_refactor_q | G5: 4G电联车载用户MRO事实表 | H5: 4G电联车载用户MRO事实表 | I5: / | J5: 详单 | K5: 15分钟 | L5: 前置 | M5: 是 | N5: 3 | O5: fact_lte_mro_usrbackfill_q、cfg_iov_usr_list | Q5: 新建
A6: 4 | B6: =HYPERLINK("#"&A6&"!A1",A6) -> 4 | C6: 网络数据处理系统 | D6: 整合层 | E6: / | F6: fact_lte_mro_neighbor_q | G6: 4G电联MRO邻区事实表 | H6: 4G电联MRO邻区事实表 | I6: / | J6: 详单 | K6: 15分钟 | L6: 前置 | N6: 3 | O6: fact_lte_mro_usrbackfill_q、lte_cm_projdata、lte_cucc_cm_projdata | Q6: 新建
A7: 5 | B7: =HYPERLINK("#"&A7&"!A1",A7) -> 5 | C7: 网络数据处理系统 | D7: 整合层 | E7: / | F7: ods_lte_mro_q_location | G7: 4G电信经纬度详单表 | H7: 4G电联经纬度详单表 | I7: / | J7: 详单 | K7: 15分钟 | L7: 前置 | M7: 是 | N7: 3 | O7: fact_lte_mro_usrbackfill_q | P7: 位置能力系统 | Q7: 升级
A8: 7 | B8: =HYPERLINK("#"&A8&"!A1",A8) -> 7 | C8: 网络数据处理系统 | D8: 中间层 | E8: 覆盖分析 | F8: aggr_lte_sncell_problem_h | G8: MR数据主邻小区对覆盖问题分析汇聚小时表(重叠覆盖与MOD3) | H8: MR数据主邻小区对重叠覆盖分析汇聚小时表 | I8: 邻区对 | J8: 小时 | K8: 小时 | L8: 前置 | M8: 是 | N8: 7 | O8: fact_lte_mro_neighbor_q、lte_cm_projdata、lte_cucc_cm_projdata | Q8: 新建
A9: 8 | B9: =HYPERLINK("#"&A9&"!A1",A9) -> 8 | C9: 网络数据处理系统 | D9: 中间层 | E9: 覆盖分析 | F9: aggr_lte_sncell_problem_d | G9: MR数据主邻小区对覆盖问题分析汇聚天表(重叠覆盖与MOD3) | H9: MR数据主邻小区对重叠覆盖分析汇聚天表 | I9: 邻区对 | J9: 天 | K9: 天 | L9: 核心 | N9: 30 | O9: aggr_lte_sncell_problem_h | P9: 建维优 | Q9: 新建
A10: 12 | B10: =HYPERLINK("#"&A10&"!A1",A10) -> 12 | C10: 网络数据处理系统 | D10: 中间层 | E10: 覆盖分析 | F10: aggr_lte_coverage_problem_usrcelgrd_q | G10: 4G MR主小区覆盖问题汇聚指标15分钟表 | H10: 4G MR主小区覆盖问题汇聚指标15分钟表 | I10: 用户小区栅格 | J10: 15分钟 | K10: 15分钟 | L10: 前置 | N10: 7 | O10: fact_lte_mro_neighbor_q | Q10: 新建
A11: 13 | B11: =HYPERLINK("#"&A11&"!A1",A11) -> 13 | C11: 网络数据处理系统 | D11: 中间层 | E11: 覆盖分析 | F11: aggr_lte_coverage_base_q | G11: 4G MR用户小区栅格覆盖指标15分钟表(无问题打标) | H11: 4G MR用户小区栅格覆盖指标15分钟表(无问题打标) | I11: 用户小区栅格 | J11: 15分钟 | K11: 15分钟 | L11: 前置 | N11: 7 | O11: fact_lte_mro_usrbackfill_q、lte_cm_projdata、lte_cucc_cm_projdata | Q11: 新建
A12: 14 | B12: =HYPERLINK("#"&A12&"!A1",A12) -> 14 | C12: 网络数据处理系统 | D12: 中间层 | E12: 覆盖分析 | F12: aggr_lte_coverage_base_usr_refactor_q | G12: 4G MR用户小区栅格覆盖指标15分钟表 | H12: 4G MR用户小区栅格覆盖指标15分钟表 | I12: 用户小区栅格 | J12: 15分钟 | K12: 15分钟 | L12: 前置 | M12: 是 | N12: 7 | O12: aggr_lte_coverage_base_q、aggr_lte_coverage_problem_usrcelgrd_q | Q12: 升级
A13: 15 | B13: =HYPERLINK("#"&A13&"!A1",A13) -> 15 | C13: 网络数据处理系统 | D13: 中间层 | E13: 覆盖分析 | F13: aggr_lte_coverage_base_usr_refactor_h | G13: 4G MR用户小区栅格覆盖指标小时表 | H13: 4G MR用户小区栅格覆盖指标小时表 | I13: 用户小区栅格 | J13: 小时 | K13: 小时 | L13: 核心 | N13: 14 | O13: aggr_lte_coverage_base_usr_refactor_q | P13: 建维优 | Q13: 升级
A14: 17 | B14: =HYPERLINK("#"&A14&"!A1",A14) -> 17 | C14: 网络数据处理系统 | D14: 中间层 | E14: 覆盖分析 | F14: aggr_lte_coverage_base_refactor_h | G14: 4G MR小区栅格覆盖指标小时表 | H14: 4G MR小区栅格覆盖指标小时表 | I14: 小区栅格 | J14: 小时 | K14: 小时 | L14: 核心 | N14: 14 | O14: aggr_lte_coverage_base_usr_refactor_h | P14: 建维优 | Q14: 升级
A15: 17.1 | B15: =HYPERLINK("#"&A15&"!A1",A15) -> 17.1 | C15: 网络数据处理系统 | D15: 中间层 | E15: 覆盖分析 | F15: aggr_lte_coverage_grd_h | G15: 4G MR栅格覆盖指标小时表 | H15: 4G MR栅格覆盖指标小时表 | I15: 栅格 | J15: 小时 | K15: 小时 | L15: 核心 | N15: 14 | O15: aggr_lte_coverage_base_refactor_h | P15: 建维优 | Q15: 新建
A16: 18 | B16: =HYPERLINK("#"&A16&"!A1",A16) -> 18 | C16: 网络数据处理系统 | D16: 中间层 | E16: 覆盖分析 | F16: aggr_lte_coverage_base_refactor_d | G16: 4G MR小区栅格覆盖指标天表 | H16: 4G MR小区栅格覆盖指标天表 | I16: 小区栅格 | J16: 天 | K16: 天 | L16: 核心 | N16: 30 | O16: aggr_lte_coverage_base_refactor_h | P16: 建维优 | Q16: 升级
A17: 19 | B17: =HYPERLINK("#"&A17&"!A1",A17) -> 19 | C17: 网络数据处理系统 | D17: 中间层 | E17: 覆盖分析 | F17: aggr_lte_coverage_reduce_usrcelgrd_q | G17: 4G MR用户小区栅格覆盖指标裁剪15分钟表 | H17: 4G MR用户小区栅格覆盖指标裁剪15分钟表 | I17: 用户小区栅格 | J17: 15分钟 | K17: 15分钟 | L17: 核心 | N17: 14 | O17: aggr_lte_coverage_base_usr_refactor_q | Q17: 新建
A18: 19.1 | B18: =HYPERLINK("#"&A18&"!A1",A18) -> 19.1 | C18: 网络数据处理系统 | D18: 中间层 | E18: 覆盖分析 | F18: aggr_lte_coverage_reduce_usrcelgrd_h | G18: 4G MR用户小区栅格覆盖指标裁剪小时表 | H18: 4G MR用户小区栅格覆盖指标裁剪小时表 | I18: 用户小区栅格 | J18: 小时 | K18: 小时 | L18: 核心 | N18: 14 | O18: aggr_lte_coverage_reduce_usrcelgrd_q | Q18: 新建
A19: 19.2 | B19: =HYPERLINK("#"&A19&"!A1",A19) -> 19.2 | C19: 网络数据处理系统 | D19: 中间层 | E19: 用户常驻 | F19: aggr_lte_coverage_resident_usrgrd_d | G19: 4G MR用户常驻栅格覆盖指标天表 | H19: 4G MR用户常驻栅格覆盖指标天表 | I19: 用户栅格 | J19: 天 | K19: 天 | L19: 核心 | N19: 30 | O19: aggr_lte_coverage_reduce_usrcelgrd_h | Q19: 新建
A20: 20 | B20: =HYPERLINK("#"&A20&"!A1",A20) -> 20 | C20: 网络数据处理系统 | D20: 中间层 | E20: 用户常驻 | F20: aggr_lte_usrareagrd_d | G20: 4G用户区域栅格聚区天表 | H20: 4G用户区域栅格聚区天表 | I20: 用户区域栅格 | J20: 天 | K20: 天 | L20: 核心 | N20: 30 | O20: aggr_lte_coverage_resident_usrgrd_d | Q20: 新建
A21: 21 | B21: =HYPERLINK("#"&A21&"!A1",A21) -> 21 | C21: 网络数据处理系统 | D21: 中间层 | E21: 用户级感知 | F21: aggr_lte_usrareatime_cel_refactor_d | G21: 4G MR用户聚区区域用户小区天表 | H21: 4G MR用户聚区区域用户小区天表 | I21: 用户小区栅格 | J21: 15分钟 | K21: 天 | L21: 核心 | N21: 30 | O21: aggr_lte_usrareagrd_d、aggr_lte_coverage_reduce_usrcelgrd_q | P21: 建维优 | Q21: 升级
A22: 21.1 | B22: =HYPERLINK("#"&A22&"!A1",A22) -> 21.1 | C22: 网络数据处理系统 | D22: 中间层 | E22: 用户级感知 | F22: aggr_lte_usrarea_coverarea_cel_refactor_d | G22: 4G用户区域小区覆盖天表 | H22: 4G用户区域小区覆盖天表 | I22: 用户小区区域 | J22: 天 | K22: 天 | L22: 核心 | N22: 30 | O22: aggr_lte_usrareatime_cel_refactor_d | Q22: 升级
A23: 21.2 | B23: =HYPERLINK("#"&A23&"!A1",A23) -> 21.2 | C23: 网络数据处理系统 | D23: 中间层 | E23: 用户级感知 | F23: aggr_lte_usrarea_coverarea_refactor_d | G23: 4G用户区域覆盖天表 | H23: 4G用户区域覆盖天表 | I23: 用户区域 | J23: 天 | K23: 天 | L23: 核心 | N23: 30 | O23: aggr_lte_usrarea_coverarea_cel_refactor_d | Q23: 升级
A24: 22 | B24: =HYPERLINK("#"&A24&"!A1",A24) -> 22 | C24: 网络数据处理系统 | D24: 中间层 | E24: 覆盖分析 | F24: aggr_lte_coverage_cel_refactor_d | G24: 4G MR小区覆盖指标天表 | H24: 4G MR小区覆盖指标天表 | I24: 小区 | J24: 天 | K24: 天 | L24: 核心 | N24: 30 | O24: aggr_lte_coverage_base_refactor_d | P24: 共建共享、5GR、客户感知CEM、建维优 | Q24: 升级
A25: 23 | B25: =HYPERLINK("#"&A25&"!A1",A25) -> 23 | C25: 网络数据处理系统 | D25: 中间层 | E25: 覆盖分析 | F25: aggr_lte_coverage_grd_refactor_d | G25: 4G MR栅格覆盖指标天表 | H25: 4G MR栅格覆盖指标天表 | I25: 栅格 | J25: 天 | K25: 天 | L25: 核心 | N25: 30 | O25: aggr_lte_coverage_base_refactor_d | P25: 5GR、建维优 | Q25: 升级
A26: 24 | B26: =HYPERLINK("#"&A26&"!A1",A26) -> 24 | C26: 网络数据处理系统 | D26: 中间层 | E26: 覆盖分析 | F26: aggr_lte_coverage_reduce_base_refactor_d | G26: 4G MR小区栅格覆盖指标裁剪天表 | H26: 4G MR小区栅格覆盖指标裁剪天表 | I26: 小区栅格 | J26: 天 | K26: 天 | L26: 核心 | N26: 30 | O26: aggr_lte_coverage_base_refactor_d | P26: 共建共享 | Q26: 升级
A27: 25 | B27: =HYPERLINK("#"&A27&"!A1",A27) -> 25 | C27: 网络数据处理系统 | D27: 中间层 | E27: 覆盖分析 | F27: aggr_lte_coverage_base_reduce_refactor_d | G27: 4G电信用户产生的MR小区栅格覆盖指标裁剪天表 | H27: 4G电信用户产生的MR小区栅格覆盖指标裁剪天表 | I27: 小区栅格 | J27: 天 | K27: 天 | L27: 核心 | N27: 30 | O27: aggr_lte_coverage_reduce_base_refactor_d | P27: 5G定制网 | Q27: 升级
A28: 26 | B28: =HYPERLINK("#"&A28&"!A1",A28) -> 26 | C28: 网络数据处理系统 | D28: 中间层 | E28: 覆盖分析 | F28: aggr_lte_coverageagps_base_refactor_d | G28: 4G AGPS MR小区栅格覆盖指标天表 | H28: 4G AGPS MR小区栅格覆盖指标天表 | I28: 小区栅格 | J28: 天 | K28: 天 | L28: 核心 | N28: 30 | O28: aggr_lte_coverage_base_refactor_d | P28: 建维优 | Q28: 升级
A29: 27 | B29: =HYPERLINK("#"&A29&"!A1",A29) -> 27 | C29: 网络数据处理系统 | D29: 中间层 | E29: 覆盖分析 | F29: aggr_lte_coverageagps_cel_d | G29: 4G AGPS MR小区覆盖指标天表 | H29: 4G AGPS MR小区覆盖指标天表 | I29: 小区 | J29: 天 | K29: 天 | L29: 核心 | N29: 30 | O29: aggr_lte_coverageagps_base_refactor_d | P29: 建维优 | Q29: 新建
A30: 28 | B30: =HYPERLINK("#"&A30&"!A1",A30) -> 28 | C30: 网络数据处理系统 | D30: 中间层 | E30: 覆盖分析 | F30: ts_glc_coverageagps_celgrd_refactor_d | G30: 4G AGPS MR小区栅格共享天表 | H30: 4G AGPS MR小区栅格共享天表 | I30: 小区栅格 | J30: 天 | K30: 天 | L30: 核心 | N30: 30 | O30: aggr_lte_coverageagps_base_refactor_d | P30: 基站节能 | Q30: 升级
A31: 29 | B31: =HYPERLINK("#"&A31&"!A1",A31) -> 29 | C31: 网络数据处理系统 | D31: 中间层 | E31: 覆盖分析 | F31: aggr_lte_coverage_usrcel_h | G31: 4G MR用户小区覆盖小时表 | H31: 4G MR用户小区覆盖小时表 | I31: 用户小区 | J31: 小时 | K31: 小时 | L31: 核心 | N31: 14 | O31: aggr_lte_coverage_base_usr_refactor_h | Q31: 新建
A32: 29.0 | B32: =HYPERLINK("#"&A32&"!A1",A32) -> 29.0 | C32: 网络数据处理系统 | D32: 中间层 | E32: 覆盖分析 | F32: aggr_lte_iov_coverage_usrcel_h | G32: 4G车联网用户小区覆盖分析小时表 | H32: 4G车联网用户小区覆盖分析小时表 | I32: 用户小区 | J32: 小时 | K32: 小时 | L32: 核心 | N32: 14 | O32: aggr_lte_coverage_usrcel_h、cfg_iov_usr_list | Q32: 升级
A33: 29.1 | B33: =HYPERLINK("#"&A33&"!A1",A33) -> 29.1 | C33: 网络数据处理系统 | D33: 中间层 | E33: 覆盖分析 | F33: aggr_lte_coverage_base_reduce_refactor_h | G33: 4G MR小区指标裁剪天表 | H33: 4G MR小区指标裁剪天表 | I33: 小区 | J33: 天 | K33: 天 | L33: 核心 | N33: 14 | O33: aggr_lte_coverage_cel_h | P33: 移动业务感知保障系统 | Q33: 升级
A34: 29.2 | B34: =HYPERLINK("#"&A34&"!A1",A34) -> 29.2 | C34: 网络数据处理系统 | D34: 中间层 | E34: 覆盖分析 | F34: aggr_lte_coverage_usr_h | G34: 4G MR用户覆盖小时表 | H34: 4G MR用户覆盖小时表 | I34: 用户 | J34: 小时 | K34: 小时 | L34: 核心 | N34: 14 | O34: aggr_lte_coverage_usrcel_h | Q34: 新建
A35: 29.3 | B35: =HYPERLINK("#"&A35&"!A1",A35) -> 29.3 | C35: 网络数据处理系统 | D35: 中间层 | E35: 覆盖分析 | F35: aggr_lte_coverage_cel_h | G35: 4G MR小区覆盖小时表 | H35: 4G MR小区覆盖小时表 | I35: 小区 | J35: 小时 | K35: 小时 | L35: 核心 | N35: 14 | O35: aggr_lte_coverage_usrcel_h | P35: 建维优 | Q35: 新建
A36: 30 | B36: =HYPERLINK("#"&A36&"!A1",A36) -> 30 | C36: 网络数据处理系统 | D36: 中间层 | E36: 覆盖分析 | F36: aggr_lte_coverage_usrcel_refactor_d | G36: 4G MR用户小区覆盖天表 | H36: 4G MR用户小区覆盖天表 | I36: 用户小区 | J36: 天 | K36: 天 | L36: 核心 | N36: 30 | O36: aggr_lte_coverage_usrcel_h | P36: 建维优 | Q36: 升级
A37: 31 | B37: =HYPERLINK("#"&A37&"!A1",A37) -> 31 | C37: 网络数据处理系统 | D37: 中间层 | E37: 覆盖分析 | F37: aggr_lte_coverage_usr_refactor_d | G37: 4G MR用户覆盖天表 | H37: 4G MR用户覆盖天表 | I37: 用户 | J37: 天 | K37: 天 | L37: 核心 | N37: 30 | O37: aggr_lte_coverage_usrcel_refactor_d | Q37: 升级
A38: 32 | B38: =HYPERLINK("#"&A38&"!A1",A38) -> 32 | C38: 网络数据处理系统 | D38: 中间层 | E38: 覆盖分析 | F38: aggr_lte_coverage_imsi_refactor_d | G38: 4G MR用户覆盖共享天表 | H38: 4G MR用户覆盖共享天表 | I38: 用户 | J38: 天 | K38: 天 | L38: 核心 | N38: 30 | O38: aggr_lte_coverage_usr_refactor_d | P38: 核心系统 | Q38: 升级
A39: 33 | B39: =HYPERLINK("#"&A39&"!A1",A39) -> 33 | C39: 网络数据处理系统 | D39: 中间层 | E39: 覆盖分析 | F39: aggr_lte_coverage_usrgrd_h | G39: 4G MR用户栅格覆盖小时表 | H39: 4G MR用户栅格覆盖小时表 | I39: 用户栅格 | J39: 天 | K39: 天 | L39: 核心 | N39: 14 | O39: aggr_lte_coverage_base_usr_refactor_h | P39: 建维优 | Q39: 新建
A40: 34 | B40: =HYPERLINK("#"&A40&"!A1",A40) -> 34 | C40: 网络数据处理系统 | D40: 中间层 | E40: 覆盖分析 | F40: aggr_lte_coverage_usrgrd_refactor_d | G40: 4G MR用户栅格覆盖天表 | H40: 4G MR用户栅格覆盖天表 | I40: 用户栅格 | J40: 天 | K40: 天 | L40: 核心 | N40: 30 | O40: aggr_lte_coverage_usrgrd_h | P40: 建维优 | Q40: 升级
...

Sheet 1
B1: =HYPERLINK("#导航!a2","返回") -> 返回
B3: 目标表基本信息描述
B4: 主题域 | C4: 目标表英文名 | D4: 目标表中文名 | E4: 数据频度 | F4: 模型主键 | G4: 数据描述 | H4: 推送数据库
B5: / | C5: ods_lte_mro_analysis_q | D5: 4G电联MRO解析详单表 | E5: quarter
B7: 源表基本信息描述
B8: 来源系统 | C8: 源表英文名 | D8: 源表中文名 | E8: 别名 | F8: 任务描述 | G8: 备注 | H8: 是否主表
B11: 详细字段信息
B12: 详细字段信息
B13: PDM字段英文名 | C13: PDM字段类型 | D13: PDM字段中文名（说明） | E13: 源表名 | F13: 电信MR源字段英文名-ZX | G13: 电信MR源字段英文名-HW | H13: 电信MR源字段英文名-NK | I13: 电信MR源字段英文名-ER | J13: 电信MR源字段英文名-DT | K13: 联通MR源字段英文名-ZX | L13: 联通MR源字段英文名-HW | M13: 联通MR源字段英文名-NK | N13: 联通MR源字段英文名-ER | O13: 联通MR源字段英文名-DT
B14: datetime | C14: string | D14: 样本数据测量对象UE的样本测量时间，UTC时间格式。对MRO文件，取值为测量采样周期的整数倍，上报时间采用 UTC 时间进行计算。 | F14: MR.TimeStamp | G14: TimeStamp | H14: TimeStamp | I14: TimeStamp | J14: TimeStamp | K14: TimeStamp | L14: TimeStamp | M14: TimeStamp | N14: TimeStamp | O14: TimeStamp
B15: enodebid | C15: int | D15: 字符串，取值为eNodeB Id。 | F15: MR.eNBId | G15: eNB id | H15: eNB id | I15: id | J15: eNB id | K15: eNB id | L15: eNB id | M15: eNB id | N15: eNB id | O15: eNB id
B16: cellid | C16: string | D16: 标识具体的测量对象。若为小区对象，则采用CellId (8bit)表示；若为子帧对象，则采用“CellId:Earfcn:SubFrameNbr”表示；若为PRB对象，则采用“CellId:Earfcn:SubFrameNbr:PRBNbr”表示。表示测量报告样本数据时，采用主服务小区CellId或子帧对象进行标识。 | F16: MR.objectId | G16: id | H16: object id | I16: object id%256 | J16: object id%256 | K16: object id%256 | L16: split(id,"-")[1] | M16: id%256 | N16: object id%256 | O16: object id%256
B17: ulsinr | C17: array<smallint> | D17: 服务小区接收的上行信号的信噪比。 | F17: MR.LteScSinrUL | G17: MR.LteScSinrUL | H17: MR.LteScSinrUL | I17: MR.LteScSinrUL | J17: MR.LteScSinrUL | K17: MR.LteScSinrUL | L17: MR.LteScSinrUL | M17: MR.LteScSinrUL | N17: MR.LteScSinrUL | O17: MR.LteScSinrUL
B18: phr | C18: array<smallint> | D18: 服务小区发射功率余量，指UE发射信号功率对发射功率上限的余量的测量值。取值范围[0,63]。 | F18: MR.LteScPHR | G18: MR.LteScPHR | H18: MR.LteScPHR | I18: MR.LteScPHR | J18: MR.LteScPHR | K18: MR.LteScPHR | L18: MR.LteScPHR | M18: MR.LteScPHR | N18: MR.LteScPHR | O18: MR.LteScPHR
B19: aoa | C19: array<smallint> | D19: 天线到达角,指UE相对服务小区天线的参考方位角。 | F19: MR.LteScAOA | G19: MR.LteScAOA | H19: MR.LteScAOA | I19: MR.LteScAOA | J19: MR.LteScAOA | K19: MR.LteScAOA | L19: MR.LteScAOA | M19: MR.LteScAOA | N19: MR.LteScAOA | O19: MR.LteScAOA
B20: recvbsr | C20: array<bigint> | D20: 后台显示名RecvBsr,上报周期内BSR平均值，多个承载时， 选择最大平均值上报，CMAC上报该值 | F20: MR.LteScBSR | G20: MR.LteScBSR | H20: MR.LteScBSR | I20: 置空 | J20: MR.LteScBSR | K20: 置空 | L20: 置空 | M20: 置空 | N20: 置空 | O20: 置空
B21: puschprbnum | C21: array<int> | D21: UE PUSCH信道占用PRB数。 | F21: MR.LteScPUSCHPRBNum | G21: MR.LteScPUSCHPRBNum | H21: MR.LteScPUSCHPRBNum | I21: MR.LteScPUSCHPRBNum | J21: MR.LteScPUSCHPRBNum | K21: 置空 | L21: 置空 | M21: 置空 | N21: 置空 | O21: 置空
B22: pdschprbnum | C22: array<int> | D22: UE PDSCH信道占用PRB数。 | F22: MR.LteScPDSCHPRBNum | G22: MR.LteScPDSCHPRBNum | H22: MR.LteScPDSCHPRBNum | I22: MR.LteScPDSCHPRBNum | J22: MR.LteScPDSCHPRBNum | K22: 置空 | L22: 置空 | M22: 置空 | N22: 置空 | O22: 置空
B23: rsrp | C23: array<smallint> | D23: UE收到服务小区的参考信号接收功率。小区专属参考信号R0 将用于决定RSRP。如果UE能可靠地检测到小区专属参考信号R1 可用，那么可以使用R0 和R1 决定RSRP。如果 UE 使用接收分集，报告值应该不低于任一独立分集分支的相应RSRP值。取值范围0-97。 | F23: MR.LteScRSRP | G23: MR.LteScRSRP | H23: MR.LteScRSRP | I23: MR.LteScRSRP | J23: MR.LteScRSRP | K23: MR.LteScRSRP | L23: MR.LteScRSRP | M23: MR.LteScRSRP | N23: MR.LteScRSRP | O23: MR.LteScRSRP
B24: dlearfcn | C24: array<int> | D24: UE服务小区的载波号Earfcn。 | F24: MR.LteScEarfcn | G24: MR.LteScEarfcn | H24: MR.LteScEarfcn | I24: MR.LteScEarfcn | J24: MR.LteScEarfcn | K24: MR.LteScEarfcn | L24: MR.LteScEarfcn | M24: MR.LteScEarfcn | N24: MR.LteScEarfcn | O24: MR.LteScEarfcn
B25: pci | C25: array<smallint> | D25: UE服务小区的物理小区识别码。 | F25: MR.LteScPci | G25: MR.LteScPci | H25: MR.LteScPci | I25: MR.LteScPci | J25: MR.LteScPci | K25: MR.LteScPci | L25: MR.LteScPci | M25: MR.LteScPci | N25: MR.LteScPci | O25: MR.LteScPci
... B40: data_type | C40: int | D40: 数据来源(电信独享：2；电信共享：3；联通共享：1) | F40: 根据数据来源赋值(unshare：2；share：3) | G40: 根据数据来源赋值(unshare：2；share：3) | H40: 根据数据来源赋值(unshare：2；share：3) | I40: 根据数据来源赋值(unshare：2；share：3) | J40: 根据数据来源赋值(unshare：2；share：3) | K40: 直接赋值：1 | L40: 直接赋值：1 | M40: 直接赋值：1 | N40: 直接赋值：1 | O40: 直接赋值：1
B41: p_provincecode | C41: int | D41: 省分区
B42: p_date | C42: string | D42: 天分区
B43: p_hour | C43: int | D43: 小时分区
B44: p_region | C44: int | D44: 厂家分区：100001:中兴|100002:华为|100003:诺基亚|100004:爱立信|100005:大唐
B45: p_quarter | C45: int | D45: 15分钟分区

Sheet 2
B1: =HYPERLINK("#导航!a2","返回") -> 返回
B3: 目标表基本信息描述
B4: 主题域 | C4: 目标表英文名 | D4: 目标表中文名 | E4: 数据频度 | F4: 模型主键 | G4: 数据描述 | H4: 推送数据库
B5: / | C5: fact_lte_mro_location_q | D5: 4G电联MRO位置定位详单表 | E5: quarter | I5: =VLOOKUP(C5,导航!F:Q,12,0) -> 新建
B7: 源表基本信息描述
B8: 来源系统 | C8: 源表英文名 | D8: 源表中文名 | E8: 别名 | F8: 任务描述 | G8: 备注 | H8: 是否主表
C9: ods_lte_mro_analysis_q | D9: 4G电联MRO解析详单表 | E9: A
B12: 详细字段信息
B13: 详细字段信息
B14: PDM字段英文名 | C14: PDM字段类型 | D14: PDM字段中文名（说明） | E14: 源表名 | F14: 源字段英文名 | G14: 算法加工逻辑 | H14: 关联与过滤条件 | I14: 备注 | J14: 字段属性 | K14: 单位 | L14: 取值范围
B15: datetime | C15: string | D15: 样本数据测量对象UE的样本测量时间，UTC时间格式。对MRO文件，取值为测量采样周期的整数倍，上报时间采用 UTC 时间进行计算。 | F15: datetime | G15: 直取 | J15: 详单 | K15: 无 | L15: 无
B16: enodebid | C16: int | D16: 基站标识 | F16: enodebid | G16: 直取 | J16: 详单 | K16: 无 | L16: 无
B17: cellid | C17: int | D17: 小区标识 | G17: case when data_type=1 and p_region=100002 then split(cellid,"-")[1] else cast (cellid%256 as int) end | J17: 详单 | K17: 无 | L17: 无
B18: dlearfcn | C18: int | D18: UE服务小区的载波号Earfcn。 | F18: dlearfcn | G18: 直取 | J18: 详单 | K18: 无 | L18: 无
B19: pci | C19: smallint | D19: UE服务小区的物理小区识别码。 | F19: pci | G19: 直取 | J19: 详单 | K19: 无 | L19: 无
B20: ulsinr | C20: smallint | D20: 服务小区接收的上行信号的信噪比。 | F20: ulsinr | G20: 直取 | J20: 详单 | K20: 无 | L20: 无
B21: phr | C21: smallint | D21: 服务小区发射功率余量，指UE发射信号功率对发射功率上限的余量的测量值。取值范围[0,63]。 | F21: phr | G21: 直取 | J21: 详单 | K21: 无 | L21: 无
B22: aoa | C22: smallint | D22: 天线到达角,指UE相对服务小区天线的参考方位角。 | F22: aoa | G22: 直取 | J22: 详单 | K22: 无 | L22: 无
B23: recvbsr | C23: bigint | D23: 后台显示名RecvBsr,上报周期内BSR平均值，多个承载时， 选择最大平均值上报，CMAC上报该值 | F23: recvbsr | G23: 直取 | J23: 详单 | K23: 无 | L23: 无
B24: puschprbnum | C24: int | D24: UE PUSCH信道占用PRB数。 | F24: puschprbnum | G24: 直取 | J24: 详单 | K24: 无 | L24: 无
B25: pdschprbnum | C25: int | D25: UE PDSCH信道占用PRB数。 | F25: pdschprbnum | G25: 直取 | J25: 详单 | K25: 无 | L25: 无
B26: rsrp | C26: smallint | D26: UE收到服务小区的参考信号接收功率。小区专属参考信号R0 将用于决定RSRP。如果UE能可靠地检测到小区专属参考信号R1 可用，那么可以使用R0 和R1 决定RSRP。如果 UE 使用接收分集，报告值应该不低于任一独立分集分支的相应RSRP值。取值范围0-97。 | F26: rsrp | G26: 直取 | J26: 详单 | K26: 无 | L26: 无
B27: rsrq | C27: tinyint | D27: UE收到服务小区的参考信号接收质量。取值范围0-34。 | F27: rsrq | G27: 直取 | J27: 详单 | K27: 无 | L27: 无
B28: ta | C28: int | D28: 服务小区时间提前量，指UE到服务基站的信号传播时间。 | F28: ta | G28: 直取 | J28: 详单 | K28: 无 | L28: 无
B29: cqi | C29: tinyint | D29: 信道质量指示。取值为上报时刻的瞬时值，取值范围[0，15]。 | F29: cqi | G29: 直取 | J29: 详单 | K29: 无 | L29: 无
... B36: mrlat | C36: double | D36: UE周期性触发测量上报时的地理纬度（北纬）信息。单位为度，取值精确到小数点后6位。 | F36: mrlat | G36: 定位回填 | J36: 详单 | K36: 无 | L36: 无
B37: ncellcount | C37: tinyint | D37: 邻区个数 | G37: 根据neighpci数组包含数量回填邻区个数 | J37: 详单 | K37: 无 | L37: 无
B38: nearfcn | C38: array<int> | D38: UE测量到的邻小区的载波号Earfcn。 | F38: nearfcn | G38: 直取 | J38: 详单 | K38: 无 | L38: 无
B39: npci | C39: array<int> | D39: UE测量到的邻小区的物理小区识别码。取值范围[0，503]。 | F39: npci | G39: 直取 | J39: 详单 | K39: 无 | L39: 无
B40: nrsrp | C40: array<int> | D40: UE处在某一个服务小区下接收到的邻区参考信号接收功率。取值范围0-97。 | F40: nrsrp | G40: 直取 | J40: 详单 | K40: 无 | L40: 无
B41: nrsrq | C41: array<int> | D41: UE处在某一个服务小区下接收到的已定义邻区关系和未定义邻区关系的邻区参考信号的接收质量。取值范围0-34。 | F41: nrsrq | G41: 直取 | J41: 详单 | K41: 无 | L41: 无
B42: nenbid | C42: array<int> | D42: 邻区enodebid列表 | G42: 定位回填 | J42: 详单 | K42: 无 | L42: 无
B43: ncellid | C43: array<int> | D43: 邻区cellid列表 | G43: 定位回填 | J43: 详单 | K43: 无 | L43: 无
B44: regionid | C44: int | D44: 栅格ID | G44: 定位回填 | J44: 详单 | K44: 无 | L44: 无
B45: x_offset_original | C45: int | D45: X偏移(1米栅格) | G45: 定位回填 | J45: 详单 | K45: 无 | L45: 无
B46: y_offset_original | C46: int | D46: Y偏移(1米栅格) | G46: 定位回填 | J46: 详单 | K46: 无 | L46: 无
B47: x_offset_20 | C47: int | D47: X偏移(20米栅格) | G47: 定位回填 | J47: 详单 | K47: 无 | L47: 无
B48: y_offset_20 | C48: int | D48: Y偏移(20米栅格) | G48: 定位回填 | J48: 详单 | K48: 无 | L48: 无
B49: positionmark | C49: tinyint | D49: 根据定位精度确定室内外类型：0-室内；1-室外；2-未知 | G49: 定位回填 | J49: 详单 | K49: 无 | L49: 无
B50: locationtype | C50: int | D50: 定位类型 | G50: 定位回填 | J50: 详单 | K50: 无 | L50: 无
...

Sheet 3
B1: =HYPERLINK("#导航!a2","返回") -> 返回
B3: 目标表基本信息描述
B4: 主题域 | C4: 目标表英文名 | D4: 目标表中文名 | E4: 数据频度 | F4: 模型主键 | G4: 数据描述 | H4: 推送数据库
B5: / | C5: fact_lte_mro_usrbackfill_q | D5: 4G电联MRO用户回填详单表 | E5: quarter | G5: 主小区RSRP/SINR/RSRQ值已转换，邻小区RSRP/RSRQ值未转换，做后向邻区表时需注意 | I5: =VLOOKUP(C5,导航!F:Q,12,0) -> 新建
B7: 源表基本信息描述
B8: 来源系统 | C8: 源表英文名 | D8: 源表中文名 | E8: 别名 | F8: 任务描述 | G8: 备注 | H8: 是否主表
C9: fact_lte_mro_location_q | D9: 4G电联MRO位置定位详单表 | E9: A | F9: 关联回填用户信息，可参考任务temp_ods_lte_mro_q关联逻辑 | H9: 是
C10: ods_pscp_s1mme_front_5min | D10: 4G S1MME接口层详单表 | E10: B
B12: 详细字段信息
B13: 详细字段信息
B14: PDM字段英文名 | C14: PDM字段类型 | D14: PDM字段中文名（说明） | E14: 源表名 | F14: 源字段英文名 | G14: 算法加工逻辑 | H14: 关联与过滤条件 | I14: 备注 | J14: 字段属性 | K14: 单位 | L14: 取值范围
B15: datetime | C15: string | D15: 样本数据测量对象UE的样本测量时间，UTC时间格式。对MRO文件，取值为测量采样周期的整数倍，上报时间采用 UTC 时间进行计算。 | E15: A | F15: datetime | G15: 直取 | J15: 详单 | K15: 无 | L15: 无
A16: =ROW()-1 -> 15 | B16: mrkey | C16: bigint | D16: MR的唯一主键 | E16: A | G16: cast(concat(substring(datetime,15,2), substring(datetime,18,2), substring(datetime,21,3), cast(rand()*100000000000 as bigint)) as bigint) | J16: 详单 | K16: 无 | L16: 无
B17: enodebid | C17: int | D17: 基站标识 | E17: A | F17: enodebid | G17: 直取 | J17: 详单 | K17: 无 | L17: 无
B18: cellid | C18: int | D18: 小区标识 | E18: A | F18: cellid | G18: 直取 | J18: 详单 | K18: 无 | L18: 无
B19: dlearfcn | C19: int | D19: UE服务小区的载波号Earfcn。 | E19: A | F19: dlearfcn | G19: 直取 | J19: 详单 | K19: 无 | L19: 无
B20: pci | C20: int | D20: UE服务小区的物理小区识别码。 | E20: A | F20: pci | G20: 直取 | J20: 详单 | K20: 无 | L20: 无
B21: imsi | C21: string | D21: 用户IMSI串号 | E21: B | F21: imsi | G21: 关联S1MME回填imsi | H21: 回填时只需要考虑plmn=46011的详单数据，plmn!=46011的可置空 | J21: 详单 | K21: 无 | L21: 无
B22: msisdn | C22: string | D22: 用户电话号码 | E22: B | F22: msisdn | G22: 关联S1MME回填msisdn | J22: 详单 | K22: 无 | L22: 无
B23: imei | C23: string | D23: 国际移动设备识别码 | E23: B | F23: imei | G23: 关联S1MME回填imei | J23: 详单 | K23: 无 | L23: 无
B24: ulsinr | C24: int | D24: 服务小区接收的上行信号的信噪比。 | E24: A | G24: ulsinr-10 | J24: 详单 | K24: 无 | L24: 无
B25: phr | C25: int | D25: 服务小区发射功率余量，指UE发射信号功率对发射功率上限的余量的测量值。取值范围[0,63]。 | E25: A | G25: phr-23 | J25: 详单 | K25: 无 | L25: 无
B26: txpower | C26: int | D26: 发射功率 | E26: A | G26: 46-phr | J26: 详单 | K26: 无 | L26: 无
B27: aoa | C27: int | D27: 天线到达角,指UE相对服务小区天线的参考方位角。 | E27: A | F27: aoa | G27: 直取 | J27: 详单 | K27: 无 | L27: 无
B28: recvbsr | C28: bigint | D28: 后台显示名RecvBsr,上报周期内BSR平均值，多个承载时， 选择最大平均值上报，CMAC上报该值 | E28: A | F28: recvbsr | G28: 直取 | J28: 详单 | K28: 无 | L28: 无
B29: puschprbnum | C29: int | D29: UE PUSCH信道占用PRB数。 | E29: A | F29: puschprbnum | G29: 直取 | J29: 详单 | K29: 无 | L29: 无
B30: pdschprbnum | C30: int | D30: UE PDSCH信道占用PRB数。 | E30: A | F30: pdschprbnum | G30: 直取 | J30: 详单 | K30: 无 | L30: 无
B31: rsrp | C31: int | D31: UE收到服务小区的参考信号接收功率。小区专属参考信号R0 将用于决定RSRP。如果UE能可靠地检测到小区专属参考信号R1 可用，那么可以使用R0 和R1 决定RSRP。如果 UE 使用接收分集，报告值应该不低于任一独立分集分支的相应RSRP值。取值范围0-97。 | E31: A | G31: rsrp-140 | J31: 详单 | K31: 无 | L31: 无
B32: rsrq | C32: double | D32: UE收到服务小区的参考信号接收质量。取值范围0-34。 | E32: A | G32: (rsrq-40)/2 | J32: 详单 | K32: 无 | L32: 无
B33: ta | C33: int | D33: 服务小区时间提前量，指UE到服务基站的信号传播时间。 | E33: A | F33: ta | G33: 直取 | J33: 详单 | K33: 无 | L33: 无
B34: cqi | C34: int | D34: 信道质量指示。取值为上报时刻的瞬时值，取值范围[0，15]。 | E34: A | F34: cqi | G34: 直取 | J34: 详单 | K34: 无 | L34: 无
B35: mmecode | C35: tinyint | D35: MME UE S1应用程序标识，用于UE的标识，32位比特。 | E35: A | F35: mmecode | G35: 直取 | J35: 详单 | K35: 无 | L35: 无
B36: mmes1apid | C36: bigint | D36: MME组的标识，16位比特。 | E36: A | F36: mmes1apid | G36: 直取 | J36: 详单 | K36: 无 | L36: 无
B37: mmegroupid | C37: int | D37: 字符串，内容为8位比特，用于MME组内的MME标识。 | E37: A | F37: mmegroupid | G37: 直取 | J37: 详单 | K37: 无 | L37: 无
B38: enbues1apid | C38: bigint | D38: MME范围内基站的唯一ID | E38: A | F38: enbues1apid | G38: 直取 | J38: 详单 | K38: 无 | L38: 无
B39: plmn | C39: string | D39: UE接入E-utran网络使用的PLMN号。 | E39: A | F39: plmn | G39: 直取 | J39: 详单 | K39: 无 | L39: 无
B40: mrlon | C40: double | D40: UE周期性触发测量上报时的地理经度(东经)信息。单位为度，取值精确到小数点后6位。 | E40: A | F40: mrlon | G40: 直取 | J40: 详单 | K40: 无 | L40: 无
B41: mrlat | C41: double | D41: UE周期性触发测量上报时的地理纬度（北纬）信息。单位为度，取值精确到小数点后6位。 | E41: A | F41: mrlat | G41: 直取 | J41: 详单 | K41: 无 | L41: 无
B42: ncellcount | C42: int | D42: 邻区个数 | E42: A | F42: ncellcount | G42: 直取 | J42: 详单 | K42: 无 | L42: 无
B43: nearfcn | C43: array<int> | D43: UE测量到的邻小区的载波号Earfcn。 | E43: A | F43: nearfcn | G43: 直取 | J43: 详单 | K43: 无 | L43: 无
...

Sheet 3.2
B1: =HYPERLINK("#导航!a2","返回") -> 返回
B3: 目标表基本信息描述
B4: 主题域 | C4: 目标表英文名 | D4: 目标表中文名 | E4: 数据频度 | F4: 模型主键 | G4: 数据描述 | H4: 推送数据库
B5: / | C5: fact_lte_mro_iov_refactor_q | D5: 电联4G车载用户MRO事实表 | E5: 15分钟 | G5: 根据车载的用户清单，过滤筛选4G电联MRO位置清单
B7: 源表基本信息描述
B8: 来源系统 | C8: 源表英文名 | D8: 源表中文名 | E8: 别名 | F8: 任务描述 | G8: 备注 | H8: 是否主表
C9: fact_lte_mro_usrbackfill_q | D9: 4G电联MRO用户回填详单表 | E9: A
C10: cfg_iov_usr_list | D10: 车联网用户清单配置表 | E10: B | F10: A inner join B，关联条件：A.msisdn = B.msisdn
B12: 详细字段信息
B13: 详细字段信息
B14: PDM字段英文名 | C14: PDM字段类型 | D14: PDM字段中文名（说明） | E14: 源表名 | F14: 源字段英文名 | G14: 算法加工逻辑 | H14: 关联与过滤条件 | I14: 备注 | J14: 字段属性 | K14: 单位 | L14: 取值范围
B15: datetime | C15: string | D15: 样本数据测量对象UE的样本测量时间，UTC时间格式。对MRO文件，取值为测量采样周期的整数倍，上报时间采用 UTC 时间进行计算。 | E15: A | F15: datetime | G15: 直取
B16: enodebid | C16: int | D16: 字符串，取值为eNodeB Id。 | E16: A | F16: enodebid | G16: 直取
B17: cellid | C17: int | D17: 标识具体的测量对象。若为小区对象，则采用CellId (8bit)表示；若为子帧对象，则采用“CellId:Earfcn:SubFrameNbr”表示；若为PRB对象，则采用“CellId:Earfcn:SubFrameNbr:PRBNbr”表示。表示测量报告样本数据时，采用主服务小区CellId或子帧对象进行标识。 | E17: A | F17: cellid | G17: 直取
B18: imsi | C18: string | D18: 用户IMSI串号 | E18: A | F18: imsi | G18: 直取
B19: mdn | C19: string | D19: 用户电话号码 | E19: A | F19: mdn | G19: REGEXP_REPLACE(CAST(mdn AS STRING), '^86', '')
B20: rsrp | C20: smallint | D20: UE收到服务小区的参考信号接收功率。小区专属参考信号R0 将用于决定RSRP。如果UE能可靠地检测到小区专属参考信号R1 可用，那么可以使用R0 和R1 决定RSRP。如果 UE 使用接收分集，报告值应该不低于任一独立分集分支的相应RSRP值。取值范围0-97。 | E20: A | F20: rsrp | G20: rsrp+140
B21: rsrq | C21: tinyint | D21: UE收到服务小区的参考信号接收质量。取值范围0-34。 | E21: A | F21: rsrq | G21: rsrq*2+40
B22: ta | C22: int | D22: 服务小区时间提前量，指UE到服务基站的信号传播时间。 | E22: A | F22: ta | G22: 直取
B23: plmn | C23: string | D23: UE接入E-utran网络使用的PLMN号。 | E23: A | F23: plmn | G23: 直取
B24: mrlon | C24: double | D24: MR 经度 非AGPS数据定位回填 | E24: A | F24: mrlon | G24: 直取
B25: mrlat | C25: double | D25: MR 纬度 非AGPS数据定位回填 | E25: A | F25: mrlat | G25: 直取
B26: locationtype | C26: int | D26: 定位类型 | E26: A | F26: locationtype | G26: 直取
... B29: y_offset_original | C29: int | D29: Y偏移 | E29: A | F29: y_offset_original | G29: 直取
B31: p_provincecode | C31: integer | D31: 省分区
B32: p_date | C32: string | D32: 天分区
B33: p_hour | C33: integer | D33: 小时分区
B34: p_region | C34: integer | D34: 厂家分区 | F34: vendor | G34: 直取 | L34: 100001:中兴|100002:华为|100003:诺基亚|100004:爱立信|100005:大唐
B35: p_quarter | C35: integer | D35: 15分钟分区

Sheet 4
B1: =HYPERLINK("#导航!a2","返回") -> 返回
B3: 目标表基本信息描述
B4: 主题域 | C4: 目标表英文名 | D4: 目标表中文名 | E4: 数据频度 | F4: 模型主键 | G4: 数据描述 | H4: 推送数据库
B5: / | C5: fact_lte_mro_neighbor_q | D5: 4G电联MRO邻区事实表 | E5: quarter | I5: =VLOOKUP(C5,导航!F:Q,12,0) -> 新建
B7: 源表基本信息描述
B8: 来源系统 | C8: 源表英文名 | D8: 源表中文名 | E8: 别名 | F8: 任务描述 | G8: 备注 | H8: 是否主表
C9: fact_lte_mro_usrbackfill_q | D9: 4G电联MRO用户回填详单表 | E9: A | H9: 是
C10: lte_cm_projdata | D10: 4G电信工参 | E10: B | G10: B与B1表先union合并后，取关键字段用于与A表关联
C11: lte_cucc_cm_projdata | D11: 4G联通工参 | E11: B1
B13: 详细字段信息
B14: 详细字段信息
B15: PDM字段英文名 | C15: PDM字段类型 | D15: PDM字段中文名（说明） | E15: 源表名 | F15: 源字段英文名 | G15: 算法加工逻辑 | H15: 关联与过滤条件 | I15: 备注 | J15: 字段属性 | K15: 单位 | L15: 取值范围
B16: mrkey | C16: bigint | D16: MR的唯一主键 | E16: A | F16: =B16 -> mrkey | G16: 直取 | J16: 详单 | K16: 无 | L16: 无
A17: =ROW()-1 -> 16 | B17: plmn | C17: string | D17: UE接入E-utran网络使用的PLMN号。 | E17: A | F17: =B17 -> plmn | G17: 直取 | J17: 详单 | K17: 无 | L17: 无
B18: data_source | C18: int | D18: 数据类型标识，根据数据来源打标。 电信承建：0 联通承建：1 | E18: A | F18: data_source | G18: 直取 | J18: 详单 | K18: 无 | L18: 无
B19: imsi | C19: string | D19: 业务过程用户IMSI号码 | E19: A | F19: =B19 -> imsi | G19: 直取 | J19: 详单 | K19: 无 | L19: 无
B20: msisdn | C20: string | D20: 电话号码 | E20: A | F20: =B20 -> msisdn | G20: 直取 | J20: 详单 | K20: 无 | L20: 无
B21: imei | C21: string | D21: 用户终端imei | E21: A | F21: =B21 -> imei | G21: 直取 | J21: 详单 | K21: 无 | L21: 无
B22: enodebid | C22: int | D22: 主小区的基站ID | E22: A | F22: =B22 -> enodebid | G22: 直取 | J22: 详单 | K22: 无 | L22: 无
B23: cellid | C23: int | D23: 主小区ID | E23: A | F23: =B23 -> cellid | G23: 直取 | J23: 详单 | K23: 无 | L23: 无
B24: cellkey | C24: string | D24: 小区cellkey | E24: A | G24: concat(enodebid,"_",cellid) | J24: 详单 | K24: 无 | L24: 无
B25: pci | C25: smallint | D25: 物理层小区ID | E25: A | F25: =B25 -> pci | G25: 直取 | J25: 详单 | K25: 无 | L25: 无
B26: srsrp | C26: smallint | D26: 主小区RSRP | E26: A | F26: rsrp | G26: 直取 | J26: 详单 | K26: 无 | L26: 无
B27: srsrq | C27: double | D27: 主小区RSRQ | E27: A | F27: rsrq | G27: 直取 | J27: 详单 | K27: 无 | L27: 无
B28: dlearfcn | C28: int | D28: 下行频点号 | E28: A | F28: dlearfcn | G28: 直取 | J28: 详单 | K28: 无 | L28: 无
B29: npci | C29: smallint | D29: 邻区物理层小区ID | E29: A | F29: npci | G29: 直取 | J29: 详单 | K29: 无 | L29: 无
B30: nrsrp | C30: smallint | D30: 邻小区RSRP | E30: A | G30: nrsrp-140 | J30: 详单 | K30: 无 | L30: 无
B31: nrsrq | C31: double | D31: 邻小区RSRQ | E31: A | G31: (nrsrq-40)/2 | J31: 详单 | K31: 无 | L31: 无
B32: ndlearfcn | C32: int | D32: 邻区下行频点号 | E32: A | F32: ndlearfcn | G32: 直取 | J32: 详单 | K32: 无 | L32: 无
B33: ncellkey | C33: string | D33: 邻区cellkey | E33: A | G33: 数组拆分后：concat(nenodebid,"_",ncellid) | J33: 详单 | K33: 无 | L33: 无
B34: scelllon | C34: double | D34: 主小区经度 | E34: B|B1 | G34: 使用cellkey关联工参回填 | J34: 详单 | K34: 无 | L34: 无
B35: scelllat | C35: double | D35: 主小区纬度 | E35: B|B1 | G35: 使用cellkey关联工参回填 | J35: 详单 | K35: 无 | L35: 无
B36: ncelllon | C36: double | D36: 邻区经度 | E36: B|B1 | G36: 使用ncellkey关联工参回填 | J36: 详单 | K36: 无 | L36: 无
B37: ncelllat | C37: double | D37: 邻区纬度 | E37: B|B1 | G37: 使用ncellkey关联工参回填 | J37: 详单 | K37: 无 | L37: 无
B38: mrlon | C38: double | D38: 终端上报MR时的经度 | E38: A | F38: mrlon | G38: 直取 | J38: 详单 | K38: 无 | L38: 无
B39: mrlat | C39: double | D39: 终端上报MR时的纬度 | E39: A | F39: mrlat | G39: 直取 | J39: 详单 | K39: 无 | L39: 无
B40: is_weakcover | C40: int | D40: 是否弱覆盖采样点 | E40: A | G40: case when rsrp <-110 then 1 else 0 end | J40: 详单 | K40: 无 | L40: 无
B41: snearfcnflag | C41: int | D41: 主邻频点是否相同 | E41: A | G41: 同频判断：case when dlearfcn=nearfcn then 1 else 0 end | J41: 详单 | K41: 无 | L41: 无
B42: overlapsrsrpflag | C42: int | D42: 重叠覆盖-主RSRP大于等于等于门限：-105dBm | E42: A | G42: 主小区RSRP值大于等于-105dBm：case when rsrp>=-105 then 1 else 0 end) | J42: 详单 | K42: 无 | L42: 无
B43: overlapsnrsrpflag | C43: int | D43: 重叠覆盖-主邻RSRP之差小于等于门限：6dBm | E43: A | G43: 主小区RSRP-邻小区RSRP<=6dBm：case when rsrp - (nrsrp-140) <=6 then 1 else 0 end | J43: 详单 | K43: 无 | L43: 无
...

Sheet 5
B1: =HYPERLINK("#导航!a2","返回") -> 返回
B3: 目标表基本信息描述
B4: 主题域 | C4: 目标表英文名 | D4: 目标表中文名 | E4: 数据频度 | F4: 模型主键 | G4: 数据描述 | H4: 推送数据库
B5: / | C5: ods_lte_mro_q_location | D5: 4G电联经纬度详单表 | E5: hour | I5: =VLOOKUP(C5,导航!F:Q,12,0) -> 升级
B7: 源表基本信息描述
B8: 来源系统 | C8: 源表英文名 | D8: 源表中文名 | E8: 别名 | F8: 任务描述 | G8: 备注 | H8: 是否主表
C9: fact_lte_mro_usrbackfill_q | D9: 4G电联MRO用户回填详单表 | E9: A | G9: 过滤条件：data_source=0
B12: 详细字段信息
B13: 详细字段信息
B14: PDM字段英文名 | C14: PDM字段类型 | D14: PDM字段中文名（说明） | E14: 源表名 | F14: 源字段英文名 | G14: 算法加工逻辑 | H14: 关联与过滤条件 | I14: 备注 | J14: 字段属性 | K14: 单位 | L14: 取值范围
B15: datetime | C15: string | D15: 测量时间 | F15: datetime | G15: 直取 | J15: 详单 | K15: 无 | L15: 无
B16: imsi | C16: string | D16: 用户IMSI | F16: imsi | G16: 直取 | J16: 详单 | K16: 无 | L16: 无
B17: mdn | C17: string | D17: 用户号码 | F17: msisdn | G17: 直取 | J17: 详单 | K17: 无 | L17: 无
B18: imei | C18: string | D18: 用户imei号 | F18: imei | G18: 直取 | J18: 详单 | K18: 无 | L18: 无
B19: enodebid | C19: int | D19: 基站ID | F19: enodebid | G19: 直取 | J19: 详单 | K19: 无 | L19: 无
B20: cellid | C20: int | D20: 小区ID | F20: cellid | G20: 直取 | J20: 详单 | K20: 无 | L20: 无
B21: provincecode | C21: int | D21: 省编码 | F21: p_provincecode | G21: 直取 | J21: 详单 | K21: 无 | L21: 无
B22: mrlon | C22: double | D22: MR经度 | F22: mrlon | G22: 直取 | J22: 详单 | K22: 无 | L22: 无
B23: mrlat | C23: double | D23: MR纬度 | F23: mrlat | G23: 直取 | J23: 详单 | K23: 无 | L23: 无
B24: locationtype | C24: int | D24: 定位类型 | F24: locationtype | G24: 直取 | J24: 详单 | K24: 无 | L24: 无
B25: ta | C25: int | D25: TADV值 | F25: ta | G25: 直取 | I25: 新增字段 | J25: 详单 | K25: 无 | L25: 无
B26: rsrp | C26: int | D26: RSRP | F26: rsrp | G26: 直取 | I26: 新增字段 | J26: 详单 | K26: 无 | L26: 无
B27: p_provincecode | C27: int | D27: 省分区
B28: p_date | C28: string | D28: 天分区
B29: p_hour | C29: int | D29: 小时分区
B30: p_region | C30: int | D30: 厂家分区：100001:中兴|100002:华为|100003:诺基亚|100004:爱立信|100005:大唐 | F30: vendor | G30: 直取
B31: p_quarter | C31: int | D31: 15分钟分区

Sheet 7
B1: =HYPERLINK("#导航!a2","返回") -> 返回
B3: 目标表基本信息描述
B4: 主题域 | C4: 目标表英文名 | D4: 目标表中文名 | E4: 数据频度 | F4: 模型主键 | G4: 数据描述 | H4: 推送数据库
B5: 覆盖分析 | C5: aggr_lte_sncell_problem_h | D5: MR数据主邻小区对覆盖问题分析汇聚小时表(重叠覆盖与MOD3) | E5: hour | I5: =VLOOKUP(C5,导航!F:Q,12,0) -> 新建
B7: 源表基本信息描述
B8: 来源系统 | C8: 源表英文名 | D8: 源表中文名 | E8: 别名 | F8: 任务描述 | G8: 备注 | H8: 是否主表
C9: fact_lte_mro_neighbor_q | D9: 4GMR邻区详单表 | E9: A | F9: 过滤条件：(is_mod3interfer=1) or (is_overlap=1 and snearfcnflag=1 and overlapsrsrpflag=1 and overlapsnrsrpflag=1) or (is_mod3interfer_custom=1) | G9: 1、A left join C/C1，回填主邻小区信息 2、根据重叠覆盖或者MOD3干扰邻区对信息通过主邻小区进行重叠覆盖MR采样点统计、平均RSRP计算 | H9: 是
C10: lte_cm_projdata | D10: 4G电信小区工参 | E10: C
C11: lte_cucc_cm_projdata | D11: 4G联通小区工参 | E11: C1
B14: 详细字段信息
B15: PDM字段英文名 | C15: PDM字段类型 | D15: PDM字段中文名（说明） | E15: 源表名 | F15: 源字段英文名 | G15: 算法加工逻辑 | H15: 关联与过滤条件 | I15: 备注 | J15: 字段属性 | K15: 单位 | L15: 取值范围
B16: day | C16: string | D16: 天 | E16: A | F16: p_date | J16: 维度 | K16: 无 | L16: 无
B17: hour | C17: int | D17: 小时分区 | E17: A | F17: p_hour | J17: 维度 | K17: 无 | L17: 无
B18: provincecode | C18: int | D18: 省分区 | E18: A | F18: p_provincecode | G18: 直取 | J18: 维度 | K18: 无 | L18: 无
B19: citycode | C19: int | D19: 市id | E19: C|C1 | F19: C：citycode C1：citycode | G19: 主小区关联工参回填 | J19: 维度 | K19: 无 | L19: 无
B20: districtcode | C20: int | D20: 区id | E20: C|C1 | F20: C：districtcode C1：districtcode | G20: 主小区关联工参回填 | J20: 维度 | K20: 无 | L20: 无
B21: province_name | C21: string | D21: 省名称 | E21: C|C1 | F21: C：province C1：province_name | G21: 主小区关联工参回填 | J21: 维度 | K21: 无 | L21: 无
B22: city_name | C22: string | D22: 市名称 | E22: C|C1 | F22: C：city C1：city_name | G22: 主小区关联工参回填 | J22: 维度 | K22: 无 | L22: 无
B23: district_name | C23: string | D23: 区名称 | E23: C|C1 | F23: C：district C1：district_name | G23: 主小区关联工参回填 | J23: 维度 | K23: 无 | L23: 无
B24: is_agps | C24: int | D24: 是否AGPS采样点（0：否；1：是） | E24: A | G24: case when locationtype=0 then 1 else 0 end | J24: 维度 | K24: 无 | L24: 无
B25: cellkey | C25: string | D25: 小区cellkey | E25: A | F25: cellkey | G25: 直取 | J25: 维度 | K25: 无 | L25: 无
B26: freq | C26: string | D26: 小区频段 | E26: A | G26: case WHEN dlearfcn >= 0 AND dlearfcn <= 599 THEN '2.1G' WHEN dlearfcn >= 1200 AND dlearfcn <= 1949 THEN '1.8G' WHEN dlearfcn >= 2400 AND dlearfcn <= 2649 THEN '800M' WHEN dlearfcn >= 3450 AND dlearfcn <= 3799 THEN '900M' | J26: 维度 | K26: 无 | L26: 无
B27: cell_name | C27: string | D27: 小区名称 | E27: C|C1 | F27: C：cellname C1：cell_name | G27: 主小区关联工参回填 | J27: 维度 | K27: 无 | L27: 无
B28: cell_lon | C28: double | D28: 小区经度 | E28: C|C1 | F28: C：celllon C1：cell_lon | G28: 主小区关联工参回填 | J28: 维度 | K28: 无 | L28: 无
B29: cell_lat | C29: double | D29: 小区纬度 | E29: C|C1 | F29: C：celllat C1：cell_lat | G29: 主小区关联工参回填 | J29: 维度 | K29: 无 | L29: 无
B30: azimuth | C30: int | D30: 小区方位角 | E30: C|C1 | F30: C：azimuth C1：azimuth | G30: 主小区关联工参回填 | J30: 维度 | K30: 无 | L30: 无
B31: indoor_flag | C31: int | D31: 邻小区室内外 | E31: C|C1 | F31: C：CASE WHEN covertype = 2 THEN 1 ELSE 0 END C1：indoor_flag | G31: 主小区关联工参回填 | J31: 维度 | K31: 无 | L31: 无
B32: vendor | C32: string | D32: 邻小区厂商 | E32: C|C1 | F32: C：vendor C1：vendor | G32: 主小区关联工参回填 | J32: 维度 | K32: 无 | L32: 无
B33: pci | C33: int | D33: 邻小区pci | E33: C|C1 | F33: C：pci C1：pci | G33: 主小区关联工参回填 | J33: 维度 | K33: 无 | L33: 无
B34: ncellkey | C34: string | D34: 邻区cellkey | E34: A | F34: ncellkey | G34: 直取 | J34: 维度 | K34: 无 | L34: 无
B35: nfreq | C35: string | D35: 邻小区频段 | E35: A | G35: case WHEN ndlearfcn >= 0 AND dlearfcn <= 599 THEN '2.1G' WHEN ndlearfcn >= 1200 AND dlearfcn <= 1949 THEN '1.8G' WHEN ndlearfcn >= 2400 AND dlearfcn <= 2649 THEN '800M' WHEN ndlearfcn >= 3450 AND dlearfcn <= 3799 THEN '900M' | J35: 维度 | K35: 无 | L35: 无
B36: ncell_name | C36: string | D36: 邻小区名称 | E36: C|C1 | F36: C：cellname C1：cell_name | G36: 邻小区关联工参回填 | J36: 维度 | K36: 无 | L36: 无
B37: ncell_lon | C37: double | D37: 邻小区经度 | E37: C|C1 | F37: C：celllon C1：cell_lon | G37: 邻小区关联工参回填 | J37: 维度 | K37: 无 | L37: 无
B38: ncell_lat | C38: double | D38: 邻小区纬度 | E38: C|C1 | F38: C：celllat C1：cell_lat | G38: 邻小区关联工参回填 | J38: 维度 | K38: 无 | L38: 无
B39: nazimuth | C39: int | D39: 邻小区方位角 | E39: C|C1 | F39: C：azimuth C1：azimuth | G39: 邻小区关联工参回填 | J39: 维度 | K39: 无 | L39: 无
B40: nindoor_flag | C40: int | D40: 邻小区室内外 | E40: C|C1 | F40: C：CASE WHEN covertype = 2 THEN 1 ELSE 0 END C1：indoor_flag | G40: 邻小区关联工参回填 | J40: 维度 | K40: 无 | L40: 无
B41: nvendor | C41: string | D41: 邻小区厂商 | E41: C|C1 | F41: C：vendor C1：vendor | G41: 邻小区关联工参回填 | J41: 维度 | K41: 无 | L41: 无
B42: npci | C42: int | D42: 邻小区pci | E42: C|C1 | F42: C：pci C1：pci | G42: 邻小区关联工参回填 | J42: 维度 | K42: 无 | L42: 无
B43: prbplem_type | C43: int | D43: 问题类型 0：重叠覆盖+MOD3干扰+自定义MOD3干扰； 1：重叠覆盖+MOD3干扰； 2：重叠覆盖+自定义MOD3干扰 3：MOD3干扰+自定义MOD3干扰 4：重叠覆盖 5：MOD3干扰 6：自定义MOD3干扰 | E43: A | G43: 以mrkey,cellkey分组 1、满足sum(is_overlap)>0 and sum(is_mod3interfer)>0 and sum(is_mod3interfer_custom)>0则赋值为0 2、满足sum(is_overlap)>0 and sum(is_mod3interfer)>0则赋值为1； 3、满足sum(is_overlap)>0 and sum(is_mod3interfer_custom)>0则赋值为2； 4、满足sum(is_mod3interfer)>0 and sum(is_mod3interfer_custom)>0则赋值为3 5、满足sum(is_overlap)>0则赋值为4 6、满足sum(is_mod3interfer)>0则赋值为5 7、满足sum(is_mod3interfer_custom)>0则赋值为6 | I43: 算法升级 | J43: 维度 | K43: 无 | L43: 无
B44: problem_scell_avgrsrp | C44: double | D44: 覆盖质差主小区平均RSRP | E44: A | G44: avg(srsrp) | J44: 指标 | K44: 无 | L44: [-140,-43]
...

Sheet 8
B1: =HYPERLINK("#导航!a2","返回") -> 返回
B3: 目标表基本信息描述
B4: 主题域 | C4: 目标表英文名 | D4: 目标表中文名 | E4: 数据频度 | F4: 模型主键 | G4: 数据描述 | H4: 推送数据库
B5: 覆盖分析 | C5: aggr_lte_sncell_problem_d | D5: MR数据主邻小区对覆盖问题分析汇聚天表(重叠覆盖与MOD3) | E5: day | I5: =VLOOKUP(C5,导航!F:Q,12,0) -> 新建
B7: 源表基本信息描述
B8: 来源系统 | C8: 源表英文名 | D8: 源表中文名 | E8: 别名 | F8: 任务描述 | G8: 备注 | H8: 是否主表
C9: aggr_lte_sncell_problem_h | D9: MR数据主邻小区对覆盖问题分析汇聚小时表(重叠覆盖与MOD3) | E9: A | H9: 是
B14: 详细字段信息
B15: PDM字段英文名 | C15: PDM字段类型 | D15: PDM字段中文名（说明） | E15: 源表名 | F15: 源字段英文名 | G15: 算法加工逻辑 | H15: 关联与过滤条件 | I15: 备注 | J15: 字段属性 | K15: 单位 | L15: 取值范围
B16: day | C16: string | D16: 天 | E16: A | F16: p_date | J16: 维度 | K16: 无 | L16: 无
B17: provincecode | C17: int | D17: 省分区 | E17: A | F17: provincecode | G17: 直取 | J17: 维度 | K17: 无 | L17: 无
B18: citycode | C18: int | D18: 市id | E18: A | F18: citycode | G18: 直取 | J18: 维度 | K18: 无 | L18: 无
B19: districtcode | C19: int | D19: 区id | E19: A | F19: districtcode | G19: 直取 | J19: 维度 | K19: 无 | L19: 无
B20: province_name | C20: string | D20: 省名称 | E20: A | F20: province_name | G20: 直取 | J20: 维度 | K20: 无 | L20: 无
B21: city_name | C21: string | D21: 市名称 | E21: A | F21: city_name | G21: 直取 | J21: 维度 | K21: 无 | L21: 无
B22: district_name | C22: string | D22: 区名称 | E22: A | F22: district_name | G22: 直取 | J22: 维度 | K22: 无 | L22: 无
B23: is_agps_mr | C23: int | D23: 是否AGPS采样点（0：否；1：是） | E23: A | F23: is_agps_mr | G23: 直取 | J23: 维度 | K23: 无 | L23: 无
B24: cellkey | C24: string | D24: 小区cellkey | E24: A | F24: cellkey | G24: 直取 | J24: 维度 | K24: 无 | L24: 无
B25: freq | C25: string | D25: 小区频段 | E25: A | F25: freq | G25: 直取 | J25: 维度 | K25: 无 | L25: 无
B26: cell_name | C26: string | D26: 小区名称 | E26: A | F26: cell_name | G26: 直取 | J26: 维度 | K26: 无 | L26: 无
B27: cell_lon | C27: double | D27: 小区经度 | E27: A | F27: cell_lon | G27: 直取 | J27: 维度 | K27: 无 | L27: 无
B28: cell_lat | C28: double | D28: 小区纬度 | E28: A | F28: cell_lat | G28: 直取 | J28: 维度 | K28: 无 | L28: 无
... B42: prbplem_type | C42: int | D42: 问题类型 0：重叠覆盖+MOD3干扰+自定义MOD3干扰； 1：重叠覆盖+MOD3干扰； 2：重叠覆盖+自定义MOD3干扰 3：MOD3干扰+自定义MOD3干扰 4：重叠覆盖 5：MOD3干扰 6：自定义MOD3干扰 | E42: A | F42: prbplem_type | G42: 直取 | J42: 维度 | K42: 无 | L42: 无
B43: problem_scell_avgrsrp | C43: double | D43: 覆盖质差主小区平均RSRP | E43: A | G43: sum(problem_scell_avgrsrp*problem_mr_cnt)/sum(problem_mr_cnt) | J43: 指标 | K43: 无 | L43: [-140,-43]
B44: problem_ncell_avgrsrp | C44: double | D44: 覆盖质差邻小区平均RSRP | E44: A | G44: sum(problem_ncell_avgrsrp*problem_mr_cnt)/sum(problem_mr_cnt) | J44: 指标 | K44: 无 | L44: [-140,-43]
B45: problem_mr_cnt | C45: bigint | D45: 覆盖质差MR采样点数 | E45: A | G45: sum(problem_mr_cnt) | J45: 指标 | K45: 无 | L45: >=0
B46: data_source | C46: int | D46: 电信承建：0 联通承建：1 | E46: A | F46: data_source | G46: 直取 | I46: 新增字段 | J46: 维度 | K46: 无 | L46: 无
B47: plmn | C47: string | D47: UE接入E-utran网络使用的PLMN号。 | E47: A | F47: =B47 -> plmn | G47: 直取 | I47: 新增字段 | J47: 维度 | K47: 无 | L47: 无
B48: p_provincecode | C48: int | D48: 省分区
B49: p_date | C49: string | D49: 天分区

Sheet 12
B1: =HYPERLINK("#导航!a2","返回") -> 返回
B3: 目标表基本信息描述
B4: 主题域 | C4: 目标表英文名 | D4: 目标表中文名 | E4: 数据频度 | F4: 模型主键 | G4: 数据描述 | H4: 推送数据库
B5: 覆盖分析 | C5: aggr_lte_coverage_problem_usrcelgrd_q | D5: 4G MR主小区覆盖问题汇聚指标15分钟表 | E5: quarter | I5: =VLOOKUP(C5,导航!F:Q,12,0) -> 新建
B7: 源表基本信息描述
B8: 来源系统 | C8: 源表英文名 | D8: 源表中文名 | E8: 别名 | F8: 任务描述 | G8: 备注 | H8: 是否主表
C9: fact_lte_mro_neighbor_q | D9: 4G电联MRO邻区事实表 | E9: A | H9: 是
B11: 详细字段信息
B12: 详细字段信息
B13: PDM字段英文名 | C13: PDM字段类型 | D13: PDM字段中文名（说明） | E13: 源表名 | F13: 源字段英文名 | G13: 算法加工逻辑 | H13: 关联与过滤条件 | I13: 备注 | J13: 字段属性 | K13: 单位 | L13: 取值范围
A14: =ROW()-1 -> 13 | B14: plmn | C14: string | D14: UE接入E-utran网络使用的PLMN号。 | E14: A | F14: =B14 -> plmn | G14: 直取 | J14: 维度 | K14: 无 | L14: 无
B15: data_source | C15: int | D15: 数据类型标识，根据数据来源打标。 电信承建：0 联通承建：1 | E15: A | F15: data_source | G15: 直取 | J15: 维度 | K15: 无 | L15: 无
B16: imsi | C16: string | D16: 业务过程用户IMSI号码 | E16: A | F16: =B16 -> imsi | G16: 直取 | J16: 维度 | K16: 无 | L16: 无
B17: msisdn | C17: string | D17: 电话号码 | E17: A | F17: =B17 -> msisdn | G17: 直取 | J17: 维度 | K17: 无 | L17: 无
B18: imei | C18: string | D18: 用户终端imei | E18: A | F18: =B18 -> imei | G18: 直取 | J18: 维度 | K18: 无 | L18: 无
B19: cellkey | C19: string | D19: 小区cellkey | E19: A | F19: cellkey | G19: 直取 | J19: 维度 | K19: 无 | L19: 无
B20: is_agps | C20: int | D20: 是否AGPS采样点（0：否；1：是） | E20: A | G20: case when locationtype=0 then 1 else 0 end | J20: 维度 | K20: 无 | L20: 无
B21: regionid | C21: int | D21: 栅格编号 | E21: A | F21: regionid | G21: 直取 | J21: 维度 | K21: 无 | L21: 无
B22: x_offset_20 | C22: int | D22: X轴20米偏移 | E22: A | F22: x_offset_20 | G22: 直取 | J22: 维度 | K22: 无 | L22: 无
B23: y_offset_20 | C23: int | D23: Y轴20米偏移 | E23: A | F23: y_offset_20 | G23: 直取 | J23: 维度 | K23: 无 | L23: 无
B24: pci | C24: smallint | D24: 物理层小区ID | E24: A | F24: =B24 -> pci | G24: 直取 | J24: 维度 | K24: 无 | L24: 无
B25: dlearfcn | C25: int | D25: 下行频点号 | E25: A | F25: dlearfcn | G25: 直取 | J25: 维度 | K25: 无 | L25: 无
B26: rsrp_total | C26: bigint | D26: 主小区总RSRP值 | E26: A | G26: 以cellkey及mrkey分组，取max(srsrp)，再求和 | J26: 指标 | K26: 无 | L26: <=0
B27: rsrp_cnt | C27: int | D27: 总采样点数量 | E27: A | G27: 以cellkey及mrkey分组后，再计数 | J27: 指标 | K27: 无 | L27: >=0
B28: weakcover_cnt | C28: int | D28: 弱覆盖采样点数量 | E28: A | G28: 以cellkey及mrkey分组后，取max(is_weakcover)，再求和 | J28: 指标 | K28: 无 | L28: >=0
B29: overlap_cnt | C29: int | D29: 重叠覆盖采样点数量 | E29: A | G29: 以cellkey及mrkey分组后，取max(is_overlap)，再求和 | J29: 指标 | K29: 无 | L29: >=0
B30: mod3interfer_cnt | C30: int | D30: MOD3干扰采样点数量 | E30: A | G30: 以cellkey及mrkey分组后，取max(is_mod3interfer)，再求和 | J30: 指标 | K30: 无 | L30: >=0
B31: overshoot_cnt | C31: int | D31: 过覆盖采样点数量 | E31: A | G31: 以cellkey及mrkey分组后，取max(is_overshoot)，再求和 | J31: 指标 | K31: 无 | L31: >=0
B32: bad_mr_cnt | C32: int | D32: 质差MR采样点数量 | E32: A | G32: 以cellkey及mrkey分组后，case when sum(is_weakcover+is_overlap+is_mod3interfer+is_overshoot)>0 then 1 else 0 end，再求和 | J32: 指标 | K32: 无 | L32: >=0
B33: scellmrdis | C33: int | D33: mr到主小区间距离 | E33: A | G33: 以cellkey及mrkey分组后，取max(scellmrdis)，再求和 | J33: 指标 | K33: 无 | L33: >=0
B34: scellmrdis_cnt | C34: int | D34: mr到主小区间有效距离的MR数目 | E34: A | G34: 以cellkey及mrkey分组后，取max(scellmrdis)>0则计数1，再求和 | J34: 指标 | K34: 无 | L34: >=0
B35: weakcover_totalrsrp | C35: int | D35: 弱覆盖采样点总RSRP值 | E35: A | G35: 1、以cellkey及mrkey分组后，取max(is_weakcover)； 2、若max(is_weakcover)=1，则取srsrp值，最后再求和 | J35: 指标 | K35: 无 | L35: <=0
B36: overlap_totalrsrp | C36: int | D36: 重叠覆盖采样点总RSRP值 | E36: A | G36: 1、以cellkey及mrkey分组后，取max(is_overlap)； 2、若max(is_overlap)=1，则取srsrp值，最后再求和 | J36: 指标 | K36: 无 | L36: <=0
B37: mod3interfer_totalrsrp | C37: int | D37: MOD3干扰采样点总RSRP值 | E37: A | G37: 1、以cellkey及mrkey分组后，取max(is_mod3interfer)； 2、若max(is_mod3interfer)=1，则取srsrp值，最后再求和 | J37: 指标 | K37: 无 | L37: <=0
... B50: overshootmrdismult_level3mrcount | C50: bigint | D50: 过覆盖MR站间距倍数在[3.5,+∞)范围内的MR数目 | E50: A | G50: sum(case when is_overshoot=1 and overshootmrtoscelldistss>=3.5 then 1 else 0 end) | J50: 指标 | K50: 无 | L50: >=0
B51: mod3interfer_custom_cnt | C51: int | D51: 自定义MOD3干扰采样点数量 | E51: A | G51: 以cellkey及mrkey分组后，取max(is_mod3interfer_custom)，再求和 | I51: 新增字段 | J51: 指标 | K51: 无 | L51: >=0
B52: mod3interfer_custom_totalrsrp | C52: int | D52: 自定义MOD3干扰采样点总RSRP值 | E52: A | G52: 1、以cellkey及mrkey分组后，取max(is_mod3interfer_custom)； 2、若max(is_mod3interfer_custom)=1，则取srsrp值，最后再求和 | I52: 新增字段 | J52: 指标 | K52: 无 | L52: <=0
B53: p_provincecode | C53: int | D53: 省分区
B54: p_date | C54: string | D54: 天分区
B55: p_hour | C55: int | D55: 小时分区
...

Sheet 13
B1: =HYPERLINK("#导航!a2","返回") -> 返回
B3: 目标表基本信息描述
B4: 主题域 | C4: 目标表英文名 | D4: 目标表中文名 | E4: 数据频度 | F4: 模型主键 | G4: 数据描述 | H4: 推送数据库
B5: 覆盖分析 | C5: aggr_lte_coverage_base_q | D5: 4G MR用户小区栅格覆盖指标15分钟表(无问题打标) | E5: quarter | I5: =VLOOKUP(C5,导航!F:Q,12,0) -> 新建
B7: 源表基本信息描述
B8: 来源系统 | C8: 源表英文名 | D8: 源表中文名 | E8: 别名 | F8: 任务描述 | G8: 备注 | H8: 是否主表
C9: fact_lte_mro_usrbackfill_q | D9: 4G电联MRO用户回填详单表 | E9: A
C10: lte_cm_projdata | D10: 电信4G工参 | E10: B
C11: lte_cucc_cm_projdata | D11: 联通4G工参 | E11: B1
B13: 详细字段信息
B14: 详细字段信息
B15: PDM字段英文名 | C15: PDM字段类型 | D15: PDM字段中文名（说明） | E15: 源表名 | F15: 源字段英文名 | G15: 算法加工逻辑 | H15: 关联与过滤条件 | I15: 备注 | J15: 字段属性 | K15: 单位 | L15: 取值范围
B16: day | C16: string | D16: 日期 | E16: A | F16: p_date | G16: 直取 | J16: 维度 | K16: 无 | L16: 无
B17: hour | C17: int | D17: 小时 | E17: A | F17: p_hour | G17: 直取 | J17: 维度 | K17: 无 | L17: 无
B18: quarter | C18: int | D18: 刻度 | E18: A | F18: p_quarter | G18: 直取 | J18: 维度 | K18: 无 | L18: 无
B19: cellkey | C19: string | D19: 小区唯一标识 | E19: A | F19: cellkey | G19: 直取 | J19: 维度 | K19: 无 | L19: 无
B20: dlearfcn | C20: int | D20: 下行频点号 | E20: A | F20: dlearfcn | G20: 直取 | J20: 维度 | K20: 无 | L20: 无
B21: freq | C21: string | D21: 频段 | E21: A | G21: case WHEN dlearfcn >= 0 AND dlearfcn <= 599 THEN '2.1G' WHEN dlearfcn >= 1200 AND dlearfcn <= 1949 THEN '1.8G' WHEN dlearfcn >= 2400 AND dlearfcn <= 2649 THEN '800M' WHEN dlearfcn >= 3450 AND dlearfcn <= 3799 THEN '900M' | J21: 维度 | K21: 无 | L21: 无
B22: citycode | C22: int | D22: 城市编码 | E22: B|B1 | F22: citycode | G22: 直取 | J22: 维度 | K22: 无 | L22: 无
B23: districtcode | C23: int | D23: 区县编码 | E23: B|B1 | F23: districtcode | G23: 直取 | J23: 维度 | K23: 无 | L23: 无
B24: province_name | C24: string | D24: 省名称 | E24: B|B1 | F24: province_name | G24: 直取 | J24: 维度 | K24: 无 | L24: 无
B25: city_name | C25: string | D25: 城市名称 | E25: B|B1 | F25: city_name | G25: 直取 | J25: 维度 | K25: 无 | L25: 无
B26: district_name | C26: string | D26: 区县名称 | E26: B|B1 | F26: district_name | G26: 直取 | J26: 维度 | K26: 无 | L26: 无
B27: rattypeid | C27: int | D27: 频点所属制式：6:LTEFDD 7:LTETDD 8:NB-IOT 14:IP-Integrate 255:Plat | E27: A | F27: rattypeid | G27: 直接赋值：6 | J27: 维度 | K27: 无 | L27: 无
B28: imsi | C28: string | D28: 用户IMSI号 | E28: A | F28: =B28 -> imsi | G28: 直取 | J28: 维度 | K28: 无 | L28: 无
B29: msisdn | C29: string | D29: 电话号码 | E29: A | F29: =B29 -> msisdn | G29: 直取 | J29: 维度 | K29: 无 | L29: 无
B30: imei | C30: string | D30: 终端业务过程用户终端IMEI号码 | E30: A | F30: =B30 -> imei | G30: 直取 | J30: 维度 | K30: 无 | L30: 无
B31: is_agps | C31: int | D31: 是否AGPS采样点（0：否；1：是） | E31: A | G31: case when locationtype=0 then 1 else 0 end | J31: 维度 | K31: 无 | L31: 无
B32: regionid | C32: int | D32: 栅格编码 | E32: A | F32: =B32 -> regionid | G32: 直取 | J32: 维度 | K32: 无 | L32: 无
B33: x_offset_20 | C33: int | D33: 栅格坐标x轴偏移 | E33: A | F33: =B33 -> x_offset_20 | G33: 直取 | J33: 维度 | K33: 无 | L33: 无
B34: y_offset_20 | C34: int | D34: 栅格坐标y轴偏移 | E34: A | F34: =B34 -> y_offset_20 | G34: 直取 | J34: 维度 | K34: 无 | L34: 无
B35: center_lon | C35: double | D35: 栅格中心经度 | E35: A | G35: 栅格转经纬度 | J35: 维度 | K35: 无 | L35: 无
B36: center_lat | C36: double | D36: 栅格中心纬度 | E36: A | G36: 栅格转经纬度 | J36: 维度 | K36: 无 | L36: 无
B37: plmn | C37: string | D37: UE接入E-utran网络使用的PLMN号。 | E37: A | F37: =B37 -> plmn | G37: 直取 | J37: 维度 | K37: 无 | L37: 无
B38: data_source | C38: int | D38: 数据类型标识，根据数据来源打标。 电信承建：0 联通承建：1 | E38: A | F38: data_source | G38: 直取 | J38: 维度 | K38: 无 | L38: 无
B39: positionmark | C39: int | D39: 室内外位置区分结果，0：室内，1：室外，2:未知 | E39: A | F39: =B39 -> positionmark | G39: 直取 | J39: 维度 | K39: 无 | L39: 无
B40: mrlon_total | C40: double | D40: MR经度总值 | E40: A | G40: sum(case when mrlon>=73 and mrlon<=136 and mrlat>=2 and mrlat<=54 then mrlon else 0 end) | J40: 指标 | K40: 无 | L40: >=0
B41: mrlat_total | C41: double | D41: MR纬度总值 | E41: A | G41: sum(case when mrlon>=73 and mrlon<=136 and mrlat>=2 and mrlat<=54 then mrlat else 0 end) | J41: 指标 | K41: 无 | L41: >=0
B42: validlonlat_totalcnt | C42: bigint | D42: 经纬度有效的MR数目 | E42: A | G42: sum(case when mrlon>=73 and mrlon<=136 and mrlat>=2 and mrlat<=54 then 1 else 0 end) | J42: 指标 | K42: 无 | L42: >=0
B43: mrlon_avg | C43: double | D43: MR平均经度 | E43: A | G43: sum(case when mrlon>=73 and mrlon<=136 and mrlat>=2 and mrlat<=54 then mrlon else 0 end) / sum(case when mrlon>=73 and mrlon<=136 and mrlat>=2 and mrlat<=54 then 1 else 0 end) | J43: 指标 | K43: 无 | L43: [73,136]
...

Sheet 14
B1: =HYPERLINK("#导航!a2","返回") -> 返回
B3: 目标表基本信息描述
B4: 主题域 | C4: 目标表英文名 | D4: 目标表中文名 | E4: 数据频度 | F4: 模型主键 | G4: 数据描述 | H4: 推送数据库
B5: 覆盖分析 | C5: aggr_lte_coverage_base_usr_refactor_q | D5: 4G MR用户小区栅格覆盖指标15分钟表 | E5: quarter | I5: =VLOOKUP(C5,导航!F:Q,12,0) -> 升级
B7: 源表基本信息描述
B8: 来源系统 | C8: 源表英文名 | D8: 源表中文名 | E8: 别名 | F8: 任务描述 | G8: 备注 | H8: 是否主表
C9: aggr_lte_coverage_base_q | D9: 4G MR用户小区栅格覆盖指标15分钟表(无问题打标) | E9: A | F9: A left join B，关联条件：plmn+data_source+cellkey+msisdn +imsi+imei+regionid+x_offset_20+y_offset_20+is_agps | H9: 是
C10: aggr_lte_coverage_problem_usrcelgrd_q | D10: 4G MR主小区覆盖问题汇聚指标15分钟表 | E10: B
B12: 详细字段信息
B13: 详细字段信息
B14: PDM字段英文名 | C14: PDM字段类型 | D14: PDM字段中文名（说明） | E14: 源表名 | F14: 源字段英文名 | G14: 算法加工逻辑 | H14: 关联与过滤条件 | I14: 备注 | J14: 字段属性 | K14: 单位 | L14: 取值范围
B15: provincecode | C15: int | D15: 省编码 | E15: A | F15: p_provincecode | G15: 直取 | J15: 维度 | K15: 无 | L15: 无
B16: day | C16: string | D16: 日期 | E16: A | F16: p_date | G16: 直取 | J16: 维度 | K16: 无 | L16: 无
B17: hour | C17: int | D17: 小时 | E17: A | F17: p_hour | G17: 直取 | J17: 维度 | K17: 无 | L17: 无
B18: quarter | C18: int | D18: 15分钟 | E18: A | F18: p_quarter | G18: 直取 | J18: 维度 | K18: 无 | L18: 无
B19: cellkey | C19: string | D19: 小区cellkey | E19: A | F19: cellkey | G19: 直取 | J19: 维度 | K19: 无 | L19: 无
B20: dlearfcn | C20: int | D20: 下行频点 | E20: A | F20: dlearfcn | G20: 直取 | J20: 维度 | K20: 无 | L20: 无
B21: rattypeid | C21: int | D21: 频点所属制式：6:LTEFDD 7:LTETDD 8:NB-IOT 14:IP-Integrate 255:Plat | E21: A | F21: rattypeid | G21: 直取 | J21: 维度 | K21: 无 | L21: 无
B22: imsi | C22: string | D22: 用户imsi | E22: A | F22: imsi | G22: 直取 | J22: 维度 | K22: 无 | L22: 无
B23: regionid | C23: int | D23: 栅格编码 | E23: A | F23: regionid | G23: 直取 | J23: 维度 | K23: 无 | L23: 无
B24: x_offset_20 | C24: int | D24: 栅格坐标x轴偏移 | E24: A | F24: x_offset_20 | G24: 直取 | J24: 维度 | K24: 无 | L24: 无
B25: y_offset_20 | C25: int | D25: 栅格坐标y轴偏移 | E25: A | F25: y_offset_20 | G25: 直取 | J25: 维度 | K25: 无 | L25: 无
B26: period_totalmrcount | C26: bigint | D26: 周期性MR数目 | E26: A | G26: sum(mr_period_totalcnt) | J26: 指标 | K26: 无 | L26: >=0
B27: totalrsrp | C27: bigint | D27: RSRP总值 | E27: A | G27: sum(rsrp_total) | J27: 指标 | K27: 无 | L27: <0
B28: avgrsrp | C28: double | D28: RSRP平均值 | E28: A | G28: sum(rsrp_total)/sum(rsrp_cnt) | J28: 指标 | K28: 无 | L28: [-140,-43]
B29: rsrpcount | C29: bigint | D29: RSRP有效数目 | E29: A | G29: sum(rsrp_cnt) | J29: 指标 | K29: 无 | L29: >=0
B30: rsrp_level1mrcount | C30: bigint | D30: RSRP在[-75,+∞）范围内的MR数目 | E30: A | G30: sum(rsrp_cnt_f75_f43) | J30: 指标 | K30: 无 | L30: >=0
B31: rsrp_level2mrcount | C31: bigint | D31: RSRP在[-85,-75）范围内的MR数目 | E31: A | G31: sum(rsrp_cnt_f80_f75+rsrp_cnt_f85_f80) | J31: 指标 | K31: 无 | L31: >=0
B32: rsrp_level3mrcount | C32: bigint | D32: RSRP在[-95,-85）范围内的MR数目 | E32: A | G32: sum(rsrp_cnt_f90_f85+rsrp_cnt_f95_f90) | J32: 指标 | K32: 无 | L32: >=0
B33: rsrp_level4mrcount | C33: bigint | D33: RSRP在[-100,-95）范围内的MR数目 | E33: A | G33: sum(rsrp_cnt_f100_f95) | J33: 指标 | K33: 无 | L33: >=0
B34: rsrp_level5mrcount | C34: bigint | D34: RSRP在[-105,-100）范围内的MR数目 | E34: A | G34: sum(rsrp_cnt_f105_f100) | J34: 指标 | K34: 无 | L34: >=0
B35: rsrp_level6mrcount | C35: bigint | D35: RSRP在[-115,-105）范围内的MR数目 | E35: A | G35: sum(rsrp_cnt_f110_f105+rsrp_cnt_f112_f110+rsrp_cnt_f115_f112) | J35: 指标 | K35: 无 | L35: >=0
B36: rsrp_level7mrcount | C36: bigint | D36: RSRP在（-∞,-115）范围内的MR数目 | E36: A | G36: sum(rsrp_cnt_f120_f115+rsrp_cnt_f140_f120) | J36: 指标 | K36: 无 | L36: >=0
B37: rsrpgoodcount | C37: bigint | D37: RSRP优良数目(>=-105) | E37: A | G37: sum(rsrp_good_cnt_f105) | J37: 指标 | K37: 无 | L37: >=0
... B50: dlsinrgoodratio | C50: double | D50: ULSINR优良比(>=0) | E50: A | G50: sum(ulsinr_good_cnt_0)/sum(ulsinr_cnt) | J50: 指标 | K50: 无 | L50: [0,1]
B51: totalidlersrp | C51: bigint | D51: RSRP总值 | G51: 置空 | J51: 指标 | K51: 无 | L51: 空
B52: avgidlersrp | C52: double | D52: RSRP平均值 | G52: 置空 | J52: 指标 | K52: 无 | L52: 空
B53: idlersrpcount | C53: bigint | D53: RSRP有效的MR数目 | G53: 置空 | J53: 指标 | K53: 无 | L53: 空
B54: idlersrp_level1mrcount | C54: bigint | D54: RSRP在[-75;+∞)范围内的MR数目 | G54: 置空 | J54: 指标 | K54: 无 | L54: 空
B55: idlersrp_level2mrcount | C55: bigint | D55: RSRP在[-85;-75)范围内的MR数目 | G55: 置空 | J55: 指标 | K55: 无 | L55: 空
...

Sheet 15
B1: =HYPERLINK("#导航!a2","返回") -> 返回
B3: 目标表基本信息描述
B4: 主题域 | C4: 目标表英文名 | D4: 目标表中文名 | E4: 数据频度 | F4: 模型主键 | G4: 数据描述 | H4: 推送数据库
B5: 覆盖分析 | C5: aggr_lte_coverage_base_usr_refactor_h | D5: 4G MR用户小区栅格覆盖指标小时表 | E5: hour | I5: =VLOOKUP(C5,导航!F:Q,12,0) -> 升级
B7: 源表基本信息描述
B8: 来源系统 | C8: 源表英文名 | D8: 源表中文名 | E8: 别名 | F8: 任务描述 | G8: 备注 | H8: 是否主表
C9: aggr_lte_coverage_base_usr_refactor_q | D9: 4G MR用户小区栅格覆盖指标15分钟表 | E9: A
B12: 详细字段信息
B13: 详细字段信息
B14: PDM字段英文名 | C14: PDM字段类型 | D14: PDM字段中文名（说明） | E14: 源表名 | F14: 源字段英文名 | G14: 算法加工逻辑 | H14: 关联与过滤条件 | I14: 备注 | J14: 字段属性 | K14: 单位 | L14: 取值范围
B15: provincecode | C15: int | D15: 省编码 | E15: A | F15: p_provincecode | G15: 直取 | J15: 维度 | K15: 无 | L15: 无
B16: day | C16: string | D16: 日期 | E16: A | F16: p_date | G16: 直取 | J16: 维度 | K16: 无 | L16: 无
B17: hour | C17: int | D17: 小时 | E17: A | F17: p_hour | G17: 直取 | J17: 维度 | K17: 无 | L17: 无
B18: cellkey | C18: string | D18: 小区cellkey | E18: A | F18: cellkey | G18: 直取 | J18: 维度 | K18: 无 | L18: 无
B19: dlearfcn | C19: int | D19: 下行频点 | E19: A | F19: dlearfcn | G19: 直取 | J19: 维度 | K19: 无 | L19: 无
B20: rattypeid | C20: int | D20: 频点所属制式：6:LTEFDD 7:LTETDD 8:NB-IOT 14:IP-Integrate 255:Plat | E20: A | F20: rattypeid | G20: 直取 | J20: 维度 | K20: 无 | L20: 无
B21: imsi | C21: string | D21: 用户imsi | E21: A | F21: imsi | G21: 直取 | J21: 维度 | K21: 无 | L21: 无
B22: regionid | C22: int | D22: 栅格编码 | E22: A | F22: regionid | G22: 直取 | J22: 维度 | K22: 无 | L22: 无
B23: x_offset_20 | C23: int | D23: 栅格坐标x轴偏移 | E23: A | F23: x_offset_20 | G23: 直取 | J23: 维度 | K23: 无 | L23: 无
B24: y_offset_20 | C24: int | D24: 栅格坐标y轴偏移 | E24: A | F24: y_offset_20 | G24: 直取 | J24: 维度 | K24: 无 | L24: 无
B25: period_totalmrcount | C25: bigint | D25: 周期性MR数目 | E25: A | G25: sum(period_totalmrcount) | J25: 指标 | K25: 无 | L25: >=0
B26: totalrsrp | C26: bigint | D26: RSRP总值 | E26: A | G26: sum(totalrsrp) | J26: 指标 | K26: 无 | L26: <0
B27: avgrsrp | C27: double | D27: RSRP平均值 | E27: A | G27: sum(totalrsrp)/sum(rsrpcount) | J27: 指标 | K27: 无 | L27: [-140,-43]
B28: rsrpcount | C28: bigint | D28: RSRP有效数目 | E28: A | G28: sum(rsrpcount) | J28: 指标 | K28: 无 | L28: >=0
B29: rsrp_level1mrcount | C29: bigint | D29: RSRP在[-75,+∞）范围内的MR数目 | E29: A | G29: sum(rsrp_level1mrcount) | J29: 指标 | K29: 无 | L29: >=0
B30: rsrp_level2mrcount | C30: bigint | D30: RSRP在[-85,-75）范围内的MR数目 | E30: A | G30: sum(rsrp_level2mrcount) | J30: 指标 | K30: 无 | L30: >=0
B31: rsrp_level3mrcount | C31: bigint | D31: RSRP在[-95,-85）范围内的MR数目 | E31: A | G31: sum(rsrp_level3mrcount) | J31: 指标 | K31: 无 | L31: >=0
B32: rsrp_level4mrcount | C32: bigint | D32: RSRP在[-100,-95）范围内的MR数目 | E32: A | G32: sum(rsrp_level4mrcount) | J32: 指标 | K32: 无 | L32: >=0
B33: rsrp_level5mrcount | C33: bigint | D33: RSRP在[-105,-100）范围内的MR数目 | E33: A | G33: sum(rsrp_level5mrcount) | J33: 指标 | K33: 无 | L33: >=0
B34: rsrp_level6mrcount | C34: bigint | D34: RSRP在[-115,-105）范围内的MR数目 | E34: A | G34: sum(rsrp_level6mrcount) | J34: 指标 | K34: 无 | L34: >=0
B35: rsrp_level7mrcount | C35: bigint | D35: RSRP在（-∞,-115）范围内的MR数目 | E35: A | G35: sum(rsrp_level7mrcount) | J35: 指标 | K35: 无 | L35: >=0
B36: rsrpgoodcount | C36: bigint | D36: RSRP优良数目(>=-105) | E36: A | G36: sum(rsrpgoodcount) | J36: 指标 | K36: 无 | L36: >=0
... B49: dlsinrgoodratio | C49: double | D49: ULSINR优良比(>=0) | E49: A | G49: sum(dlsinrgoodcount)/sum(dlsinrcount) | J49: 指标 | K49: 无 | L49: [0,1]
B50: totalidlersrp | C50: bigint | D50: RSRP总值 | G50: 置空 | J50: 指标 | K50: 无 | L50: 空
B51: avgidlersrp | C51: double | D51: RSRP平均值 | G51: 置空 | J51: 指标 | K51: 无 | L51: 空
B52: idlersrpcount | C52: bigint | D52: RSRP有效的MR数目 | G52: 置空 | J52: 指标 | K52: 无 | L52: 空
B53: idlersrp_level1mrcount | C53: bigint | D53: RSRP在[-75;+∞)范围内的MR数目 | G53: 置空 | J53: 指标 | K53: 无 | L53: 空
B54: idlersrp_level2mrcount | C54: bigint | D54: RSRP在[-85;-75)范围内的MR数目 | G54: 置空 | J54: 指标 | K54: 无 | L54: 空
B55: idlersrp_level3mrcount | C55: bigint | D55: RSRP在[-95;-85)范围内的MR数目 | G55: 置空 | J55: 指标 | K55: 无 | L55: 空
B56: idlersrp_level4mrcount | C56: bigint | D56: RSRP在[-100;-95)范围内的MR数目 | G56: 置空 | J56: 指标 | K56: 无 | L56: 空
...

Sheet 17
B1: =HYPERLINK("#导航!a2","返回") -> 返回
B3: 目标表基本信息描述
B4: 主题域 | C4: 目标表英文名 | D4: 目标表中文名 | E4: 数据频度 | F4: 模型主键 | G4: 数据描述 | H4: 推送数据库
B5: 覆盖分析 | C5: aggr_lte_coverage_base_refactor_h | D5: 4G MR小区栅格覆盖指标小时表 | E5: hour | I5: =VLOOKUP(C5,导航!F:Q,12,0) -> 升级
B7: 源表基本信息描述
B8: 来源系统 | C8: 源表英文名 | D8: 源表中文名 | E8: 别名 | F8: 任务描述 | G8: 备注 | H8: 是否主表
C9: aggr_lte_coverage_base_usr_refactor_h | D9: 4G MR用户小区栅格覆盖指标小时表 | E9: A
B12: 详细字段信息
B13: 详细字段信息
B14: PDM字段英文名 | C14: PDM字段类型 | D14: PDM字段中文名（说明） | E14: 源表名 | F14: 源字段英文名 | G14: 算法加工逻辑 | H14: 关联与过滤条件 | I14: 备注 | J14: 字段属性 | K14: 单位 | L14: 取值范围
B15: day | C15: string | D15: 日期 | F15: day | G15: 直取 | J15: 维度 | K15: 无 | L15: 无
B16: hour | C16: int | D16: 小时 | F16: hour | G16: 直取 | J16: 维度 | K16: 无 | L16: 无
B17: cellkey | C17: string | D17: 小区cellkey | F17: cellkey | G17: 直取 | J17: 维度 | K17: 无 | L17: 无
B18: dlearfcn | C18: int | D18: 下行频点 | F18: dlearfcn | G18: 直取 | J18: 维度 | K18: 无 | L18: 无
B19: rattypeid | C19: int | D19: 频点所属制式：6:LTEFDD 7:LTETDD 8:NB-IOT 14:IP-Integrate 255:Plat | F19: rattypeid | G19: 直取 | J19: 维度 | K19: 无 | L19: 无
B20: regionid | C20: int | D20: 栅格编码 | F20: regionid | G20: 直取 | J20: 维度 | K20: 无 | L20: 无
B21: x_offset | C21: int | D21: 栅格坐标x轴偏移 | F21: x_offset_20 | G21: 直取 | J21: 维度 | K21: 无 | L21: 无
B22: y_offset | C22: int | D22: 栅格坐标y轴偏移 | F22: y_offset_20 | G22: 直取 | J22: 维度 | K22: 无 | L22: 无
B23: positionmark | C23: int | D23: 室内外位置区分结果，0：室内，1：室外，2:未知 | F23: positionmark | G23: 直取 | J23: 维度 | K23: 无 | L23: 无
B24: totalmrlon | C24: double | D24: MR经度总值 | E24: A | G24: sum(totalmrlon) | J24: 指标 | K24: 无 | L24: >=0
B25: totalmrlat | C25: double | D25: MR纬度总值 | E25: A | G25: sum(totalmrlat) | J25: 指标 | K25: 无 | L25: >=0
B26: validlonlat_totalmrcount | C26: bigint | D26: 经纬度有效的MR数目 | E26: A | G26: sum(validlonlat_totalmrcount) | J26: 指标 | K26: 无 | L26: >=0
B27: avgmrlon | C27: double | D27: MR平均经度 | E27: A | G27: sum(totalmrlon)/sum(validlonlat_totalmrcount) | J27: 指标 | K27: 无 | L27: [73,136]
B28: avgmrlat | C28: double | D28: MR平均纬度 | E28: A | G28: sum(totalmrlat)/sum(validlonlat_totalmrcount) | J28: 指标 | K28: 无 | L28: [2,54]
