Workbook
Name DT.10: #REF!
Name DT.11: #REF!
Name vlookup: #REF!
Name 主小区MR详细信息AGPS: #REF!
Name 主小区MR详细信息全量室内外: #REF!

Sheet 0
A1: p_date | B1: p_hour | C1: p_quarter | D1: 类型 | E1: 维度 | F1: 维度说明 | G1: 省份 | H1: 汇聚后记录数 | I1: 时间粒度 | J1: 增加质差定界维度后汇聚记录数
A2: 45735 | B2: 10 | C2: 0 | D2: dns | E2: 详单数据 | F2: 详单数据 | G2: 110000 | H2: 592369026 | I2: quarter
A3: 45735 | B3: 10 | C3: 0 | D3: dns | E3: interface,supi,msisdn,pei,home_province,rattype,ncgi_ecgi,dnn_apn,upfip,servicetype,gnbip,l4protocol,5qi,nssai_sst,nssai_sd,sourceip_type | F3: 基础全维度(含sourceip_type) | G3: 110000 | H3: 48687010 | I3: quarter
A4: 45735 | B4: 10 | C4: 0 | D4: dns | E4: interface,supi,msisdn,pei,home_province,rattype,ncgi_ecgi,dnn_apn,upfip,servicetype,gnbip,l4protocol,5qi,nssai_sst,nssai_sd | F4: 基础全维度(不含sourceip_type) | G4: 110000 | H4: 45759090 | I4: quarter
A5: 45735 | B5: 10 | C5: 0 | D5: dns | E5: usr|app|cel | F5: 用户小区app | G5: 110000 | H5: 37997730 | I5: quarter
A6: 45735 | B6: 10 | C6: / | D6: dns | E6: interface,supi,msisdn,pei,home_province,rattype,ncgi_ecgi,dnn_apn,upfip,servicetype,gnbip,l4protocol,5qi,nssai_sst,nssai_sd,sourceip_type | F6: 基础全维度(含sourceip_type) | G6: 110000 | H6: 155526310 | I6: hour
A7: 45735 | B7: 10 | C7: / | D7: dns | E7: usr|app|cel | F7: 用户小区app | G7: 110000 | H7: 110357808 | I7: hour
A8: 45735 | B8: 10 | C8: 0 | D8: other | E8: 详单数据 | F8: 详单数据 | G8: 110000 | H8: 398259579 | I8: quarter
A9: 45735 | B9: 10 | C9: 0 | D9: other | E9: interface,supi,msisdn,pei,home_province,rattype,ncgi_ecgi,dnn_apn,upfip,servicetype,gnbip,l4protocol,5qi,nssai_sst,nssai_sd,sourceip_type | F9: 基础全维度(含sourceip_type) | G9: 110000 | H9: 37922501 | I9: quarter | J9: 40308104 | K9: =J9/H9 -> 1.0629073
A10: 45735 | B10: 10 | C10: 0 | D10: other | E10: interface,supi,msisdn,pei,home_province,rattype,ncgi_ecgi,dnn_apn,upfip,servicetype,gnbip,l4protocol,5qi,nssai_sst,nssai_sd | F10: 基础全维度(不含sourceip_type) | G10: 110000 | H10: 30356434 | I10: quarter
A11: 45735 | B11: 10 | C11: 0 | D11: other | E11: usr|app|cel | F11: 用户小区app | G11: 110000 | H11: 18777303 | I11: quarter
A12: 45735 | B12: 10 | C12: / | D12: other | E12: interface,supi,msisdn,pei,home_province,rattype,ncgi_ecgi,dnn_apn,upfip,servicetype,gnbip,l4protocol,5qi,nssai_sst,nssai_sd,sourceip_type | F12: 基础全维度(含sourceip_type) | G12: 110000 | H12: 111340755 | I12: hour
A13: 45735 | B13: 10 | C13: / | D13: other | E13: usr|app|cel | F13: 用户小区app | G13: 110000 | H13: 46973226 | I13: hour
A14: 45735 | B14: 10 | C14: / | D14: http | E14: interface,supi,msisdn,pei,home_province,rattype,ncgi_ecgi,dnn_apn,upfip,servicetype,gnbip,l4protocol,5qi,nssai_sst,nssai_sd,sourceip_type | F14: 基础全维度(含sourceip_type) | G14: 110000 | H14: 50135986 | I14: hour
A15: 45735 | B15: 10 | C15: / | D15: http | E15: usr|app|cel | F15: 用户小区app | G15: 110000 | H15: 30660131 | I15: hour
A16: 45735 | B16: 10 | C16: / | D16: https | E16: interface,supi,msisdn,pei,home_province,rattype,ncgi_ecgi,dnn_apn,upfip,servicetype,gnbip,l4protocol,5qi,nssai_sst,nssai_sd,sourceip_type | F16: 基础全维度(含sourceip_type) | G16: 110000 | H16: 146683745 | I16: hour
A17: 45735 | B17: 10 | C17: / | D17: https | E17: usr|app|cel | F17: 用户小区app | G17: 110000 | H17: 90059602 | I17: hour
A18: 45735 | B18: 10 | C18: / | D18: video | E18: interface,supi,msisdn,pei,home_province,rattype,ncgi_ecgi,dnn_apn,upfip,servicetype,gnbip,l4protocol,5qi,nssai_sst,nssai_sd,video_resolution,video_type,sourceip_type | F18: 基础全维度(含sourceip_type) | G18: 110000 | H18: 4946010 | I18: hour
A19: 45735 | B19: 10 | C19: / | D19: video | E19: usr|app|cel | F19: 用户小区app | G19: 110000 | H19: 2467043 | I19: hour
A20: 45735 | B20: 10 | C20: / | D20: N1N2 | E20: p_date,p_hour,p_provincecode,interface,supi,pei,msisdn,rat,home_province,amf_ip_add,gnb_ip_add,other_cell_id,s_nssai_sst,s_nssai_sd,ci,pdu_session_dnn,procedure_type,procedure_status,problem_demarcation,problem_position,failure_cause_type,failure_cause,keyword | F20: 基础全维度(增加procedure_type,procedure_status,keyword,failure_cause_type,failure_cause,问题定界,问题定位维度) | G20: 110000 | H20: 85862767 | I20: hour | J20: =H20/H23 -> 1.717041 | K20: 285973344 | L20: =K20/H20 -> 3.3305862
A21: 45735 | B21: 10 | C21: / | D21: N1N2 | E21: p_date,p_hour,p_provincecode,interface,supi,pei,msisdn,rat,home_province,amf_ip_add,gnb_ip_add,other_cell_id,s_nssai_sst,s_nssai_sd,ci,pdu_session_dnn,procedure_type,procedure_status,problem_demarcation,problem_position,failure_cause_type,failure_cause | F21: 基础全维度(增加procedure_type,procedure_status,failure_cause_type,failure_cause,问题定界,问题定位维度) | G21: 110000 | H21: 81525903 | I21: hour
A22: 45735 | B22: 10 | C22: / | D22: N1N2 | E22: interface,supi,pei,msisdn,rat,home_province,amf_ip_add,gnb_ip_add,other_cell_id,s_nssai_sst,s_nssai_sd,ci,pdu_session_dnn | F22: 基础全维度(增加procedure_type,procedure_status维度) | G22: 110000 | H22: 76910353 | I22: hour
A23: 45735 | B23: 10 | C23: / | D23: N1N2 | E23: interface,supi,pei,msisdn,rat,home_province,amf_ip_add,gnb_ip_add,other_cell_id,s_nssai_sst,s_nssai_sd,ci,pdu_session_dnn | F23: 基础全维度 | G23: 110000 | H23: 50006242 | I23: hour
A24: 45735 | B24: 10 | C24: / | D24: N1N2 | E24: interface,supi,pei,msisdn,home_province,ci | F24: 用户小区 | G24: 110000 | H24: 26938820 | I24: hour

Sheet 导航
A1: 编号 | B1: 索引 | C1: 项目名称 | D1: 数据层级 | E1: 主题域 | F1: 表英文名 | G1: 表中文名 | H1: 数据描述 | I1: 汇聚维度 | J1: 数据时间粒度 | K1: 最小时间分区 | L1: 计算位置 | M1: 是否同步 | N1: 生命周期（存储周期单位：天） | O1: 前向表 | P1: 支撑应用/系统 | Q1: 新建/升级 新建(升级)：表结构与字段沿用原表，表名称进行调整 | R1: 备注 | S1: 同步数据库
A2: 0.1 | B2: =HYPERLINK("#"&A2&"!A1",A2) -> 0.1 | C2: 网络数据处理系统 | D2: 维度层 | E2: 数据感知 | F2: cfg_topweb_first_screen_host_list | G2: TOP网址首屏时延分析配置表 | H2: TOP网址首屏时延分析配置表 | I2: / | J2: / | K2: / | L2: 前置 | M2: 否 | N2: / | O2: / | P2: / | Q2: 新建
A3: 0.2 | B3: =HYPERLINK("#"&A3&"!A1",A3) -> 0.2 | C3: 网络数据处理系统 | D3: 维度层 | E3: 数据感知 | F3: cfg_http_status_type | G3: http-status状态码表 | H3: http-status状态码表 | I3: / | J3: / | K3: / | L3: 前置 | M3: 否 | N3: / | O3: / | P3: / | Q3: 新建
A4: 0.3 | B4: =HYPERLINK("#"&A4&"!A1",A4) -> 0.3 | C4: 网络数据处理系统 | D4: 整合层 | E4: / | F4: fact_5gdpi_5gmro_ott_h | G4: 5G OTT定位指纹库清洗小时表 | I4: / | J4: 详单 | K4: 小时 | L4: 前置 | M4: 否 | N4: 360 | O4: ods_5gdpi_http_e2e_telecom_origin_q、fact_nr_cm_projdata、ods_nr_mro_northctcc_q | Q4: 升级 | R4: 先不上线，待割接时直接升级
A5: 1 | B5: =HYPERLINK("#"&A5&"!A1",A5) -> 1 | C5: 网络数据处理系统 | D5: 整合层 | E5: / | F5: fact_nr_dpi_http_q | G5: 5G_DPI_http整合层15分钟表 | H5: 5G_DPI_http整合层15分钟表 | I5: 详单 | J5: 详单 | K5: 15分钟 | L5: 前置 | M5: 否 | N5: 3 | O5: ods_5gdpi_http_e2e_telecom_origin_q、fact_nr_cm_projdata、lte_cm_projdata、lte_cucc_cm_projdata、cfg_topweb_first_screen_host_list、cfg_http_status_type | Q5: 新建
A6: 2 | B6: =HYPERLINK("#"&A6&"!A1",A6) -> 2 | C6: 网络数据处理系统 | D6: 中间层 | E6: 数据感知 | F6: aggr_nr_dpi_http_base_q | G6: 5G_DPI_http基础维度15分钟表 | H6: 5G_DPI_http基础维度15分钟表 | I6: 用户|小区|app|dnn|切片|源IP类型 | J6: 15分钟 | K6: 15分钟 | L6: 前置 | M6: 是 | N6: 前置:7；核心:14 | O6: fact_nr_dpi_http_q | Q6: 新建
A7: 3 | B7: =HYPERLINK("#"&A7&"!A1",A7) -> 3 | C7: 网络数据处理系统 | D7: 中间层 | E7: 数据感知 | F7: aggr_nr_dpi_http_base_h | G7: 5G_DPI_http基础维度小时表 | H7: 5G_DPI_http基础维度小时表 | I7: 用户|小区|app|dnn|切片|源IP类型 | J7: 小时 | K7: 小时 | L7: 核心 | M7: / | N7: 14 | O7: aggr_nr_dpi_http_base_q | Q7: 新建
A8: 4 | B8: =HYPERLINK("#"&A8&"!A1",A8) -> 4 | C8: 网络数据处理系统 | D8: 中间层 | E8: 数据感知 | F8: aggr_nr_dpi_http_index_reduce_base_h | G8: 5G_DPI_http基础维度指标裁剪小时表 | H8: 5G_DPI_http基础维度指标裁剪小时表 | I8: 用户|小区|app|dnn|切片|源IP类型 | J8: 小时 | K8: 小时 | L8: 核心 | M8: / | N8: 14 | O8: aggr_nr_dpi_http_base_h | P8: 移动业务感知保障系统 | Q8: 新建(升级) | R8: 沿用共享移动业务感知保障系统表aggr_5gdpi_http_base_reduce_h表结构及字段名称
A9: 5 | B9: =HYPERLINK("#"&A9&"!A1",A9) -> 5 | C9: 网络数据处理系统 | D9: 中间层 | E9: 数据感知 | F9: aggr_nr_dpi_http_usrappcel_h | G9: 5G_DPI_http用户小区app维度小时表 | H9: 5G_DPI_http用户小区app维度小时表 | I9: 用户|小区|app | J9: 小时 | K9: 小时 | L9: 核心 | M9: / | N9: 14 | O9: aggr_nr_dpi_http_base_h | Q9: 新建
A10: 5.1 | B10: =HYPERLINK("#"&A10&"!A1",A10) -> 5.1 | C10: 网络数据处理系统 | D10: 中间层 | E10: 数据感知 | F10: aggr_nr_dpi_http_usrapp_h | G10: 5G_DPI_http用户app维度小时表 | H10: 5G_DPI_http用户app维度小时表 | I10: 用户|app | J10: 小时 | K10: 小时 | L10: 核心 | M10: / | N10: 14 | O10: aggr_nr_dpi_http_usrappcel_h | Q10: 新建
A11: 5.2 | B11: =HYPERLINK("#"&A11&"!A1",A11) -> 5.2 | C11: 网络数据处理系统 | D11: 中间层 | E11: 数据感知 | F11: aggr_nr_dpi_http_usrapp_d | G11: 5G_DPI_http用户app维度天表 | H11: 5G_DPI_http用户app维度天表 | I11: 用户|app | J11: 天 | K11: 天 | L11: 核心 | M11: / | N11: 30 | O11: aggr_nr_dpi_http_usrapp_h | Q11: 新建
A12: 6 | B12: =HYPERLINK("#"&A12&"!A1",A12) -> 6 | C12: 网络数据处理系统 | D12: 中间层 | E12: 数据感知 | F12: aggr_nr_iov_http_usrappcel_refactor_h | G12: 5G_DPI_http车联网用户小区app维度小时表 | H12: 5G_DPI_http车联网用户小区app维度小时表 | I12: 用户|小区|app | J12: 小时 | K12: 小时 | L12: 核心 | M12: / | N12: 14 | O12: aggr_nr_dpi_http_usrappcel_h、cfg_dpi_servicetype、cfg_iov_usr_list | P12: 5G定制网 | Q12: 新建(升级) | R12: 沿用共享给5G定制网表aggr_nr_iov_http_usrappcel_h表结构及字段名称
A13: 7 | B13: =HYPERLINK("#"&A13&"!A1",A13) -> 7 | C13: 网络数据处理系统 | D13: 中间层 | E13: 数据感知 | F13: aggr_nr_dpi_http_appcel_h | G13: 5G_DPI_http小区app维度小时表 | H13: 5G_DPI_http小区app维度小时表 | I13: 小区|app | J13: 小时 | K13: 小时 | L13: 核心 | M13: / | N13: 14 | O13: aggr_nr_dpi_http_usrappcel_h | Q13: 新建
A14: 8 | B14: =HYPERLINK("#"&A14&"!A1",A14) -> 8 | C14: 网络数据处理系统 | D14: 中间层 | E14: 数据感知 | F14: aggr_nr_dpi_http_appcel_d | G14: 5G_DPI_http小区app维度天表 | H14: 5G_DPI_http小区app维度天表 | I14: 小区|app | J14: 天 | K14: 天 | L14: 核心 | M14: / | N14: 30 | O14: aggr_nr_dpi_http_appcel_h | Q14: 新建
A15: 9 | B15: =HYPERLINK("#"&A15&"!A1",A15) -> 9 | C15: 网络数据处理系统 | D15: 中间层 | E15: 数据感知 | F15: aggr_nr_dpi_http_cel_d | G15: 5G_DPI_http小区维度天表 | H15: 5G_DPI_http小区维度天表 | I15: 小区 | J15: 天 | K15: 天 | L15: 核心 | M15: / | N15: 30 | O15: aggr_nr_dpi_http_appcel_d | Q15: 新建
A16: 10 | B16: =HYPERLINK("#"&A16&"!A1",A16) -> 10 | C16: 网络数据处理系统 | D16: 中间层 | E16: 数据感知 | F16: aggr_nr_dpi_http_index_reduce_cel_d | G16: 5G_DPI_http小区维度指标裁剪天表 | H16: 5G_DPI_http小区维度指标裁剪天表 | I16: 小区 | J16: 天 | K16: 天 | L16: 核心 | M16: / | N16: 30 | O16: aggr_nr_dpi_http_cel_d | P16: 5GR | Q16: 新建(升级) | R16: 沿用共享给5GR系统表aggr_5gdpi_http_e2e_d表结构及字段名称
A17: 11 | B17: =HYPERLINK("#"&A17&"!A1",A17) -> 11 | C17: 网络数据处理系统 | D17: 中间层 | E17: 数据感知 | F17: aggr_nr_dpi_web_appcel_h | G17: 5G_DPI_web小区app维度小时表 | H17: 5G_DPI_web小区app维度小时表 | I17: 小区|app | J17: 小时 | K17: 小时 | L17: 核心 | M17: / | N17: 14 | O17: aggr_nr_dpi_http_appcel_h | P17: 建维优 | Q17: 新建
A18: 12 | B18: =HYPERLINK("#"&A18&"!A1",A18) -> 12 | C18: 网络数据处理系统 | D18: 中间层 | E18: 数据感知 | F18: aggr_nr_dpi_web_appcel_d | G18: 5G_DPI_web小区app维度天表 | H18: 5G_DPI_web小区app维度天表 | I18: 小区|app | J18: 天 | K18: 天 | L18: 核心 | M18: / | N18: 30 | O18: aggr_nr_dpi_web_appcel_h | P18: 建维优 | Q18: 新建 | R18: 沿用表aggr_5g_web_usrappcel_e2e_d字段名称
A19: 13 | B19: =HYPERLINK("#"&A19&"!A1",A19) -> 13 | C19: 网络数据处理系统 | D19: 中间层 | E19: 数据感知 | F19: aggr_nr_dpi_web_cel_d | G19: 5G_DPI_web小区维度天表 | H19: 5G_DPI_web小区维度天表 | I19: 小区 | J19: 天 | K19: 天 | L19: 核心 | M19: / | N19: 30 | O19: aggr_nr_dpi_web_appcel_d | P19: 建维优、共建共享 | Q19: 新建 | R19: 沿用共享给共建共享表aggr_5g_web_cel_e2e_d字段名称，但表结构存在变化（删减与添加）
A20: 14 | B20: =HYPERLINK("#"&A20&"!A1",A20) -> 14 | C20: 网络数据处理系统 | D20: 中间层 | E20: 数据感知 | F20: aggr_nr_dpi_im_appcel_h | G20: 5G_DPI_im小区app维度小时表 | H20: 5G_DPI_im小区app维度小时表 | I20: 小区|app | J20: 小时 | K20: 小时 | L20: 核心 | M20: / | N20: 14 | O20: aggr_nr_dpi_http_appcel_h | P20: 建维优 | Q20: 新建
A21: 15 | B21: =HYPERLINK("#"&A21&"!A1",A21) -> 15 | C21: 网络数据处理系统 | D21: 中间层 | E21: 数据感知 | F21: aggr_nr_dpi_im_appcel_d | G21: 5G_DPI_im小区app维度天表 | H21: 5G_DPI_im小区app维度天表 | I21: 小区|app | J21: 天 | K21: 天 | L21: 核心 | M21: / | N21: 30 | O21: aggr_nr_dpi_im_appcel_h | P21: 建维优 | Q21: 新建 | R21: 沿用表aggr_5g_im_usrappcel_e2e_d字段名称
A22: 16 | B22: =HYPERLINK("#"&A22&"!A1",A22) -> 16 | C22: 网络数据处理系统 | D22: 中间层 | E22: 数据感知 | F22: aggr_nr_dpi_im_cel_d | G22: 5G_DPI_im小区维度天表 | H22: 5G_DPI_im小区维度天表 | I22: 小区 | J22: 天 | K22: 天 | L22: 核心 | M22: / | N22: 30 | O22: aggr_nr_dpi_im_appcel_d | P22: 建维优、共建共享 | Q22: 新建 | R22: 沿用共享给共建共享表aggr_5g_im_cel_e2e_d字段名称，但表结构存在变化（删减与添加）
A23: 17 | B23: =HYPERLINK("#"&A23&"!A1",A23) -> 17 | C23: 网络数据处理系统 | D23: 中间层 | E23: 数据感知 | F23: aggr_nr_dpi_game_appcel_h | G23: 5G_DPI_game小区app维度小时表 | H23: 5G_DPI_game小区app维度小时表 | I23: 小区|app | J23: 小时 | K23: 小时 | L23: 核心 | M23: / | N23: 14 | O23: aggr_nr_dpi_http_appcel_h | P23: 建维优 | Q23: 新建
A24: 18 | B24: =HYPERLINK("#"&A24&"!A1",A24) -> 18 | C24: 网络数据处理系统 | D24: 中间层 | E24: 数据感知 | F24: aggr_nr_dpi_game_appcel_d | G24: 5G_DPI_game小区app维度天表 | H24: 5G_DPI_game小区app维度天表 | I24: 小区|app | J24: 天 | K24: 天 | L24: 核心 | M24: / | N24: 30 | O24: aggr_nr_dpi_game_appcel_h | Q24: 新建 | R24: 沿用表aggr_5g_game_usrappcel_e2e_d字段名称
A25: 19 | B25: =HYPERLINK("#"&A25&"!A1",A25) -> 19 | C25: 网络数据处理系统 | D25: 中间层 | E25: 数据感知 | F25: aggr_nr_dpi_game_cel_d | G25: 5G_DPI_game小区维度天表 | H25: 5G_DPI_game小区维度天表 | I25: 小区 | J25: 天 | K25: 天 | L25: 核心 | M25: / | N25: 30 | O25: aggr_nr_dpi_game_appcel_d | P25: 建维优、共建共享 | Q25: 新建 | R25: 对应共享给共建共享表aggr_5g_game_cel_e2e_d字段名称，但表结构存在变化（删减与添加）
A26: 20 | B26: =HYPERLINK("#"&A26&"!A1",A26) -> 20 | C26: 网络数据处理系统 | D26: 中间层 | E26: 数据感知 | F26: aggr_nr_dpi_http_apptype_usrcel_h | G26: 5G_DPI_http协议app类型用户小区维度小时表 | H26: 5G_DPI_http协议app类型用户小区维度小时表 | I26: 用户|小区|app类型 | J26: 小时 | K26: 小时 | L26: 核心 | M26: / | N26: 14 | O26: aggr_nr_dpi_http_usrappcel_h | Q26: 新建
A27: 21 | B27: =HYPERLINK("#"&A27&"!A1",A27) -> 21 | C27: 网络数据处理系统 | D27: 中间层 | E27: 数据感知 | F27: aggr_nr_dpi_web_usrcel_d | G27: 5G_DPI_web用户小区维度天表 | H27: 5G_DPI_web用户小区维度天表 | I27: 用户|小区 | J27: 天 | K27: 天 | L27: 核心 | M27: / | N27: 30 | O27: aggr_nr_dpi_http_apptype_usrcel_h | P27: 建维优 | Q27: 新建 | R27: 沿用表aggr_5g_web_usrappcel_e2e_d字段名称
A28: 22 | B28: =HYPERLINK("#"&A28&"!A1",A28) -> 22 | C28: 网络数据处理系统 | D28: 中间层 | E28: 数据感知 | F28: aggr_nr_dpi_web_usr_d | G28: 5G_DPI_web用户维度天表 | H28: 5G_DPI_web用户维度天表 | I28: 用户 | J28: 天 | K28: 天 | L28: 核心 | M28: / | N28: 30 | O28: aggr_nr_dpi_web_usrcel_d | P28: 建维优 | Q28: 新建 | R28: 沿用表aggr_5g_web_usr_e2e_d字段名称
A29: 23 | B29: =HYPERLINK("#"&A29&"!A1",A29) -> 23 | C29: 网络数据处理系统 | D29: 中间层 | E29: 数据感知 | F29: aggr_nr_dpi_im_usrcel_d | G29: 5G_DPI_im用户小区维度天表 | H29: 5G_DPI_im用户小区维度天表 | I29: 用户|小区 | J29: 天 | K29: 天 | L29: 核心 | M29: / | N29: 30 | O29: aggr_nr_dpi_http_apptype_usrcel_h | P29: 建维优 | Q29: 新建 | R29: 沿用表aggr_5g_im_usrappcel_e2e_d字段名称
A30: 24 | B30: =HYPERLINK("#"&A30&"!A1",A30) -> 24 | C30: 网络数据处理系统 | D30: 中间层 | E30: 数据感知 | F30: aggr_nr_dpi_im_usr_d | G30: 5G_DPI_im用户维度天表 | H30: 5G_DPI_im用户维度天表 | I30: 用户 | J30: 天 | K30: 天 | L30: 核心 | M30: / | N30: 30 | O30: aggr_nr_dpi_im_usrcel_d | P30: 建维优 | Q30: 新建 | R30: 沿用表aggr_5g_im_usr_e2e_d字段名称
A31: 25 | B31: =HYPERLINK("#"&A31&"!A1",A31) -> 25 | C31: 网络数据处理系统 | D31: 中间层 | E31: 数据感知 | F31: aggr_nr_wechat_payment_usrcel_d | G31: 5G微信支付用户小区天表 | H31: 5G微信支付用户小区天表 | I31: 用户|小区 | J31: 天 | K31: 天 | L31: 核心 | M31: / | N31: 30 | O31: aggr_nr_dpi_im_usrcel_d、fact_nr_cm_projdata、lte_cm_projdata、lte_cucc_cm_projdata | P31: 建维优 | Q31: 新建(升级) | R31: 沿用表aggr_5g_wechat_scan_code_payment_noc_usrcel_d表结构与字段名称
A32: 26 | B32: =HYPERLINK("#"&A32&"!A1",A32) -> 26 | C32: 网络数据处理系统 | D32: 中间层 | E32: 数据感知 | F32: aggr_nr_dpi_game_usrcel_d | G32: 5G_DPI_game用户小区维度天表 | H32: 5G_DPI_game用户小区维度天表 | I32: 用户|小区 | J32: 天 | K32: 天 | L32: 核心 | M32: / | N32: 30 | O32: aggr_nr_dpi_http_apptype_usrcel_h | P32: 建维优 | Q32: 新建 | R32: 沿用表aggr_5g_game_usrappcel_e2e_d字段名称
A33: 27 | B33: =HYPERLINK("#"&A33&"!A1",A33) -> 27 | C33: 网络数据处理系统 | D33: 中间层 | E33: 数据感知 | F33: aggr_nr_dpi_game_usr_d | G33: 5G_DPI_game用户维度天表 | H33: 5G_DPI_game用户维度天表 | I33: 用户 | J33: 天 | K33: 天 | L33: 核心 | M33: / | N33: 30 | O33: aggr_nr_dpi_game_usrcel_d | P33: 建维优 | Q33: 新建 | R33: 沿用表aggr_5g_game_usr_e2e_d字段名称
A34: 28 | B34: =HYPERLINK("#"&A34&"!A1",A34) -> 28 | C34: 网络数据处理系统 | D34: 中间层 | E34: 数据感知 | F34: aggr_nr_dpi_http_apptype_usrappcel_q | G34: 5G_DPI_app类型用户小区app维度15分钟表 | H34: 5G_DPI_app类型用户小区app维度15分钟表 | I34: 用户|小区|app | J34: 15分钟 | K34: 15分钟 | L34: 核心 | M34: / | N34: 14 | O34: aggr_nr_dpi_http_base_q | Q34: 新建
A35: 29 | B35: =HYPERLINK("#"&A35&"!A1",A35) -> 29 | C35: 网络数据处理系统 | D35: 中间层 | E35: 数据感知 | F35: aggr_nr_dpi_web_usrappcel_q | G35: 5G_DPI_web类型用户小区app维度15分钟表 | H35: 5G_DPI_web类型用户小区app维度15分钟表 | I35: 用户|小区|app | J35: 15分钟 | K35: 15分钟 | L35: 核心 | M35: / | N35: 14 | O35: aggr_nr_dpi_http_apptype_usrappcel_q | Q35: 新建
A36: 30 | B36: =HYPERLINK("#"&A36&"!A1",A36) -> 30 | C36: 网络数据处理系统 | D36: 中间层 | E36: 数据感知 | F36: aggr_nr_dpi_im_usrappcel_q | G36: 5G_DPI_im类型用户小区app维度15分钟表 | H36: 5G_DPI_im类型用户小区app维度15分钟表 | I36: 用户|小区|app | J36: 15分钟 | K36: 15分钟 | L36: 核心 | M36: / | N36: 14 | O36: aggr_nr_dpi_http_apptype_usrappcel_q | Q36: 新建
A37: 31 | B37: =HYPERLINK("#"&A37&"!A1",A37) -> 31 | C37: 网络数据处理系统 | D37: 中间层 | E37: 数据感知 | F37: aggr_nr_dpi_game_usrappcel_q | G37: 5G_DPI_game类型用户小区app维度15分钟表 | H37: 5G_DPI_game类型用户小区app维度15分钟表 | I37: 用户|小区|app | J37: 15分钟 | K37: 15分钟 | L37: 核心 | M37: / | N37: 14 | O37: aggr_nr_dpi_http_apptype_usrappcel_q | Q37: 新建
A38: 32 | B38: =HYPERLINK("#"&A38&"!A1",A38) -> 32 | C38: 网络数据处理系统 | D38: 中间层 | E38: 数据感知 | F38: aggr_nr_web_usrappcelarea_d | G38: 5G_web类型用户小区区域app维度天表 | H38: 5G_web类型用户小区区域app维度天 | I38: 用户|小区|区域|app | J38: 15分钟 | K38: 天 | L38: 核心 | M38: / | N38: 30 | O38: aggr_nr_usrareatime_cel_refactor_d、aggr_nr_dpi_web_usrappcel_q | P38: 建维优 | Q38: 新建(升级) | R38: 只上线用户级感知13省份，沿用表aggr_nr_usrarea_web_cel_d表结构与字段名称
A39: 34 | B39: =HYPERLINK("#"&A39&"!A1",A39) -> 34 | C39: 网络数据处理系统 | D39: 中间层 | E39: 高铁优化 | F39: aggr_nr_web_highspeedrail_usrcel_h | G39: 高铁5G web业务用户小区小时表 | H39: 高铁5G web业务用户小区小时表 | I39: 用户|小区 | J39: 小时 | K39: 小时 | L39: 核心 | M39: / | N39: 14 | O39: aggr_highspeedrail_usrlist_d、aggr_nr_dpi_web_usrappcel_q | Q39: 新建(升级) | R39: 沿用表aggr_nr_highspeedrail_web_base_h表结构与字段名称
A40: 35 | B40: =HYPERLINK("#"&A40&"!A1",A40) -> 35 | C40: 网络数据处理系统 | D40: 中间层 | E40: 数据感知 | F40: aggr_nr_im_usrappcelarea_d | G40: 5G_im类型用户小区区域app维度天表 | H40: 5G_im类型用户小区区域app维度天 | I40: 用户|小区|区域|app | J40: 15分钟 | K40: 天 | L40: 核心 | M40: / | N40: 30 | O40: aggr_nr_usrareatime_cel_refactor_d、aggr_nr_dpi_im_usrappcel_q | P40: 建维优 | Q40: 新建(升级) | R40: 只上线用户级感知13省份，沿用表aggr_nr_usrarea_im_cel_d表结构与字段名称
...

Sheet 0.1
B1: =HYPERLINK("#"&"导航应用"&"!B1","返回") -> 返回
B2: 目标表基本信息描述
B3: 主题域 | C3: 目标表英文名 | D3: 目标表中文名 | E3: 数据频度 | F3: 模型主键 | G3: 数据描述 | H3: 推送数据库
C4: cfg_topweb_first_screen_host_list | D4: TOP网址首屏时延分析URL配置表 | E4: 维表
B6: 源表基本信息描述
B7: 来源系统 | C7: 源表英文名 | D7: 源表中文名 | E7: 别名 | F7: 任务描述 | G7: 备注 | H7: 是否主表
E8: A | H8: 是
E9: B
B11: 详细字段信息
B12: PDM字段英文名 | C12: PDM字段类型 | D12: PDM字段中文名（说明） | E12: 源表名 | F12: 源字段英文名 | G12: 算法加工逻辑 | H12: 关联与过滤条件 | I12: 备注 | J12: 字段属性 | K12: 单位 | L12: 取值范围
B13: host_id | C13: int | D13: 网址ID | J13: 配置表 | K13: 无 | L13: 无
B14: host | C14: string | D14: 网址 | J14: 配置表 | K14: 无 | L14: 无
B17: 维表数据
B19: host_id | C19: host
B20: 1 | C20: m.weibo.cn
B21: 2 | C21: xw.qq.com
B22: 3 | C22: m.jd.com
B23: 4 | C23: m.360.com
B24: 5 | C24: 3g.163.com/touch
B25: 6 | C25: 189.cn
B26: 7 | C26: sina.cn
B27: 8 | C27: m.sohu.com
B28: 9 | C28: m.taobao.com
B29: 10 | C29: m.baidu.com
B30: 11 | C30: www.apple.com/cn
B31: 12 | C31: i.ifeng.com
... B98: 79 | C98: www.eastmoney.com

Sheet 0.2
B1: =HYPERLINK("#导航!a2","返回") -> 返回
B2: 目标表基本信息描述
B3: 主题域 | C3: 目标表英文名 | D3: 目标表中文名 | E3: 数据频度 | F3: 模型主键 | G3: 数据描述 | H3: 推送数据库
B4: dpi | C4: cfg_http_status_type | D4: http-status状态码表 | E4: 维表 | F4: status_code | G4: 4G/5G httpstatus码相同
B6: 源表基本信息描述
B7: 来源系统 | C7: 源表英文名 | D7: 源表中文名 | E7: 别名 | F7: 任务描述 | G7: 备注 | H7: 是否主表
E8: A | H8: 是
E9: B
B11: 详细字段信息
B12: PDM字段英文名 | C12: PDM字段类型 | D12: PDM字段中文名（说明） | E12: 源表名 | F12: 源字段英文名 | G12: 算法加工逻辑 | H12: 关联与过滤条件 | I12: 备注 | J12: 字段属性 | K12: 单位 | L12: 取值范围
B13: status_code | C13: int | D13: HTTP状态码
B14: status_explain | C14: string | D14: HTTP状态码描述
B15: problem_demarcation | C15: string | D15: HTTP状态码问题定界
B16: problem_position | C16: string | D16: HTTP状态码问题定位
B17: normal_flag | C17: int | D17: 正常话单标志（1：正常，0：异常）
B21: 维表数据
B22: status_code | C22: status_explain | D22: problem_demarcation | E22: problem_position | F22: normal_flag
B23: HTTP状态码 | C23: HTTP状态码描述 | D23: HTTP状态码问题定界 | E23: HTTP状态码问题定位 | F23: 是否正常
B24: 200 | C24: 成功(200) | E24: 成功 | F24: 1
B25: 201 | C25: 已创建(201) | E25: 已创建 | F25: 1
B26: 202 | C26: 已接受(202) | E26: 已接受 | F26: 1
B27: 203 | C27: 非权威性信息(203) | E27: 非权威性信息 | F27: 1
B28: 204 | C28: 无内容(204) | E28: 无内容 | F28: 1
B29: 205 | C29: 重置内容(205) | E29: 重置内容 | F29: 1
B30: 206 | C30: 部分内容(206) | E30: 部分内容 | F30: 1
B31: 302 | C31: 对象已移动(302) | E31: 对象已移动 | F31: 1
B32: 304 | C32: 未修改(304) | E32: 未修改 | F32: 1
B33: 306 | C33: 临时重定向(306) | E33: 临时重定向 | F33: 1
B34: 400 | C34: 错误的请求(400) | D34: 用户 | E34: 错误的请求 | F34: 0
B35: 401 | C35: 访问被拒绝(401) | D35: 用户 | E35: 访问被拒绝 | F35: 0
B36: 403 | C36: 禁止访问(403) | D36: 用户 | E36: 禁止访问 | F36: 0
B37: 404 | C37: 未找到(404) | D37: 用户 | E37: 未找到 | F37: 0
B38: 405 | C38: 方法不被允许(405) | D38: 用户 | E38: 方法不被允许 | F38: 0
B39: 406 | C39: 不接受所请求页面的 MIME 类型(406) | D39: 用户 | E39: 不接受所请求页面的 MIME 类型 | F39: 0
B40: 407 | C40: 要求进行代理身份验证(407) | D40: 用户 | E40: 要求进行代理身份验证 | F40: 0
B41: 408 | C41: 请求超时(408) | D41: 用户 | E41: 请求超时 | F41: 0
B42: 412 | C42: 前提条件失败(412) | D42: 用户 | E42: 前提条件失败 | F42: 0
B43: 413 | C43: 请求实体太大(413) | D43: 用户 | E43: 请求实体太大 | F43: 0
B44: 414 | C44: 请求URI太长(414) | D44: 用户 | E44: 请求URI太长 | F44: 0
B45: 415 | C45: 不支持的媒体类型(415) | D45: 用户 | E45: 不支持的媒体类型 | F45: 0
...

Sheet 0.3
B1: =HYPERLINK("#导航!a2","返回") -> 返回
B3: 目标表基本信息描述
B4: 主题域 | C4: 目标表英文名 | D4: 目标表中文名 | E4: 数据频度 | F4: 模型主键 | G4: 数据描述 | H4: 推送数据库
B5: / | C5: fact_5gdpi_5gmro_ott_h | D5: 5G OTT定位指纹库清洗小时表 | E5: 小时
B7: 源表基本信息描述
B8: 来源系统 | C8: 源表英文名 | D8: 源表中文名 | E8: 别名 | F8: 任务描述 | G8: 备注 | H8: 是否主表
C9: ods_5gdpi_http_e2e_telecom_origin_q | D9: 5G_DPI_http贴源层详单表 | E9: A | G9: 将输入表ods_5gdpi_http_e2e_telecom_q调整为ods_5gdpi_http_e2e_telecom_origin_q，算法逻辑不变 | H9: 是
C10: fact_nr_cm_projdata | D10: 5G电联工参表 | E10: B
C11: ods_nr_mro_northctcc_q | D11: 5G MR用户回填15分钟表 | E11: C
B13: 详细字段信息
B14: 详细字段信息
B15: PDM字段英文名 | C15: PDM字段类型 | D15: PDM字段中文名（说明） | E15: 源表名 | F15: 源字段英文名 | G15: 算法加工逻辑 | H15: 关联与过滤条件 | I15: 备注 | J15: 字段属性 | K15: 单位 | L15: 取值范围
B16: imsi | C16: string | D16: 国际移动用户识别码 | E16: A | F16: supi | G16: 直取 | J16: 详单 | K16: 无 | L16: 无
B17: msisdn | C17: string | D17: 用户号码 | E17: A | F17: msisdn | G17: 直取 | J17: 详单 | K17: 无 | L17: 无
B18: gnbid | C18: bigint | D18: 基站ID | E18: A | G18: cast((substr(ncgi_ecgi,6)/4096) as bigint) | J18: 详单 | K18: 无 | L18: 无
B19: cellid | C19: int | D19: 小区ID | E19: A | G19: cast((substr(ncgi_ecgi,6)%4096) as bigint) | J19: 详单 | K19: 无 | L19: 无
B20: starttime | C20: timestamp | D20: 开始时间 | E20: A | G20: cast(from_unixtime(unix_timestamp(starttime,'yyyyMMddHHmmss'),'yyyy-MM-dd HH:mm:ss') as TIMESTAMP) | J20: 详单 | K20: 无 | L20: 无
B21: endtime | C21: timestamp | D21: 结束时间 | E21: A | G21: cast(from_unixtime(unix_timestamp(endtime,'yyyyMMddHHmmss'),'yyyy-MM-dd HH:mm:ss') as TIMESTAMP) | J21: 详单 | K21: 无 | L21: 无
B22: nrscssrsrp | C22: int | D22: NR服务小区的SSB参考信号接收功率 | E22: C | F22: nrscssrsrp | G22: 直取 | J22: 详单 | K22: 无 | L22: 无
B23: nrscssrsrq | C23: double | D23: NR服务小区的SSB参考信号接收质量 | E23: C | F23: nrscssrsrq | G23: 直取 | J23: 详单 | K23: 无 | L23: 无
B24: nrscsssinr | C24: double | D24: NR服务小区的SSB参考信号信噪比 | E24: C | F24: nrscsssinr | G24: 直取 | J24: 详单 | K24: 无 | L24: 无
B25: lon | C25: string | D25: 经度 | E25: A | G25: regexp_extract(destination_url,'11\\d\\.\\d{4,}|12\\d\\.\\d{4,}',0) | J25: 详单 | K25: 无 | L25: 无
B26: lat | C26: string | D26: 纬度 | E26: A | G26: regexp_extract(destination_url,'[2-4]\\d\\.\\d{4,}',0) | J26: 详单 | K26: 无 | L26: 无
B27: web_url | C27: string | D27: 网址url信息 | E27: A | G27: split(destination_url,'/')[2] | J27: 详单 | K27: 无 | L27: 无
B28: nrsctadv | C28: int | D28: NR服务小区的时间提前量 | E28: C | F28: nrsctadv | G28: 直取 | J28: 详单 | K28: 无 | L28: 无
B29: nrngnbid | C29: array<int> | D29: NR已定义邻区关系和未定义邻区关系小区的5G基站标识 | E29: C | F29: nrngnbid | G29: 直取 | J29: 详单 | K29: 无 | L29: 无
B30: nrncellid | C30: array<int> | D30: NR已定义邻区关系和未定义邻区关系小区的5G小区标识 | E30: C | F30: nrncellid | G30: 直取 | J30: 详单 | K30: 无 | L30: 无
B31: nrncssrsrp | C31: array<int> | D31: 5G小区5G邻区RSRP | E31: C | F31: nrncssrsrp | G31: 直取 | J31: 详单 | K31: 无 | L31: 无
B32: nrncssrsrq | C32: array<int> | D32: 5G小区5G邻区RSRQ | E32: C | F32: nrncssrsrq | G32: 直取 | J32: 详单 | K32: 无 | L32: 无
B33: nrncsssinr | C33: array<int> | D33: 5G小区5G邻区SINR | E33: C | F33: nrncsssinr | G33: 直取 | J33: 详单 | K33: 无 | L33: 无
B34: nrncarfcn | C34: array<int> | D34: NR已定义邻区关系和未定义邻区关系的邻区载波号 | E34: C | F34: nrncarfcn | G34: 直取 | J34: 详单 | K34: 无 | L34: 无
B35: nrncpci | C35: array<int> | D35: NR已定义邻区关系和未定义邻区关系的物理小区识别码 | E35: C | F35: nrncpci | G35: 直取 | J35: 详单 | K35: 无 | L35: 无
B36: nrscarfcn | C36: bigint | D36: NR服务小区载波号 | E36: C | F36: nrscarfcn | G36: 直取 | J36: 详单 | K36: 无 | L36: 无
B37: datetime | C37: string | D37: 测量时间 | E37: C | F37: datetime | G37: 直取 | J37: 详单 | K37: 无 | L37: 无
B38: differencetime | C38: int | D38: 时间差 | E38: AC | G38: t1.time1-t2.time2 | J38: 详单 | K38: 无 | L38: 无
B39: haoa | C39: int | D39: 水平方位 | E39: C | F39: haoa | G39: 直取 | J39: 详单 | K39: 无 | L39: 无
B40: vaoa | C40: int | D40: 垂直方位 | E40: C | F40: vaoa | G40: 直取 | J40: 详单 | K40: 无 | L40: 无
B41: nrscssbeamid | C41: smallint | D41: NR服务小区的SSB波束号 | E41: C | F41: nrscssbeamid | G41: 直取 | J41: 详单 | K41: 无 | L41: 无
B42: dis | C42: double | D42: 距离 | E42: C | F42: dis | G42: 直取 | J42: 详单 | K42: 无 | L42: 无
B43: freq | C43: string | D43: 频点 | E43: C | F43: freq | G43: 直取 | J43: 详单 | K43: 无 | L43: 无
...

Sheet 1
B1: =HYPERLINK("#导航!a2","返回") -> 返回
B3: 目标表基本信息描述
B4: 主题域 | C4: 目标表英文名 | D4: 目标表中文名 | E4: 数据频度 | F4: 模型主键 | G4: 数据描述 | H4: 推送数据库
B5: / | C5: fact_nr_dpi_http_q | D5: 5G_DPI_http整合层15分钟表 | E5: quarter
B7: 源表基本信息描述
B8: 来源系统 | C8: 源表英文名 | D8: 源表中文名 | E8: 别名 | F8: 任务描述 | G8: 备注 | H8: 是否主表
C9: ods_5gdpi_http_e2e_telecom_origin_q | D9: 5G_DPI_http贴源层详单表 | E9: A | H9: 是
C10: fact_nr_cm_projdata | D10: 5G电联工参表 | E10: B1 | G10: A.cellkey=B1.cellkey
C11: lte_cm_projdata | D11: 4G电信工参 | E11: B2 | G11: A.cellkey=B2.reportcellkey
C12: lte_cucc_cm_projdata | D12: 4G联通工参 | E12: B3 | G12: A.cellkey=B3.cellkey
C13: cfg_topweb_first_screen_host_list | D13: TOP网址首屏时延分析URL配置表 | E13: C | G13: A.host=C.host
C14: cfg_http_status_type | D14: http-status状态码表 | E14: D | G14: A.httpstatus=D.status_code
B16: 详细字段信息
B17: 详细字段信息
B18: PDM字段英文名 | C18: PDM字段类型 | D18: PDM字段中文名（说明） | E18: 源表名 | F18: 源字段英文名 | G18: 算法加工逻辑 | H18: 关联与过滤条件 | I18: 备注 | J18: 字段属性 | K18: 单位 | L18: 取值范围
B19: interface | C19: int | D19: 接口 | E19: A | G19: 直取 | J19: 详单 | K19: 无 | L19: 无
B20: supi | C20: string | D20: 永久用户标识 | E20: A | G20: 直取 | J20: 详单 | K20: 无 | L20: 无
B21: msisdn | C21: string | D21: 用户号码 | E21: A | G21: regexp_replace(trim(msisdn),'^86','') | J21: 详单 | K21: 无 | L21: 无
B22: pei | C22: string | D22: 永久设备标识 | E22: A | F22: pei | G22: 直取 | J22: 详单 | K22: 无 | L22: 无
B23: dnn_apn | C23: string | D23: 网络接入标识 | E23: A | F23: dnn_apn | G23: 直取 | J23: 详单 | K23: 无 | L23: 无
B24: destinationip | C24: string | D24: 用户访问的目标IPv4或IPv6地址 | E24: A | F24: destinationip | G24: 直取 | J24: 详单 | K24: 无 | L24: 无
B25: destinationport | C25: int | D25: 用户访问的目标端口号 | E25: A | F25: destinationport | G25: 直取 | J25: 详单 | K25: 无 | L25: 无
B26: sourceip | C26: string | D26: 用户访问外部网络时使用的IPv4或IPv6地址 | E26: A | F26: sourceip | G26: 直取 | J26: 详单 | K26: 无 | L26: 无
B27: sourceport | C27: int | D27: 用户访问外部网络时使用的端口号 | E27: A | F27: sourceport | G27: 直取 | J27: 详单 | K27: 无 | L27: 无
B28: upfip | C28: string | D28: UPF的IPv4或IPv6地址 | E28: A | F28: upfip | G28: 直取 | J28: 详单 | K28: 无 | L28: 无
B29: ncgi_ecgi | C29: string | D29: NCGI：NR 小区全局标识符，MCC+MNC+NRCELLID； | E29: A | F29: ncgi_ecgi | G29: 直取 | I29: ncgi_ecgi： 4601131689682943 | J29: 详单 | K29: 无 | L29: 无
B30: tai | C30: string | D30: 跟踪区标识 | E30: A | F30: tai | G30: 直取 | I30: tai：460-11-8527873 | J30: 详单 | K30: 无 | L30: 无
B31: visitedplmnid | C31: string | D31: 拜访网络标识 | E31: A | F31: visitedplmnid | G31: 直取 | J31: 详单 | K31: 无 | L31: 无
B32: rattype | C32: int | D32: 用户所接入的网络类型 | E32: A | F32: rattype | G32: 直取 | J32: 详单 | K32: 无 | L32: 无
B33: protocolid | C33: int | D33: 协议类型，参见附录J | E33: A | F33: protocolid | G33: 直取 | J33: 详单 | K33: 无 | L33: 无
B34: servicetype | C34: string | D34: 业务应用 | E34: A | G34: case when destination_url like '%short.pay.weixin.qq.com%' then 88888888 else servicetype end | J34: 详单 | K34: 无 | L34: 无
B35: starttime | C35: string | D35: 业务流开始时间，格式为YYYYMMDDhhmmss（24小时制），如果开启中间记录模式，每条记录都填写相同的开始时间。 | E35: A | F35: starttime | G35: 直取 | J35: 详单 | K35: 无 | L35: 无
B36: endtime | C36: string | D36: 业务流结束时间，格式为YYYYMMDDhhmmss（24小时制），如果开启中间记录模式，只在最后一条记录填写结束时间。 | E36: A | F36: endtime | G36: 直取 | J36: 详单 | K36: 无 | L36: 无
B37: duration | C37: bigint | D37: 持续时间，单位毫秒 | E37: A | F37: duration | G37: 直取 | J37: 详单 | K37: 无 | L37: 无
B38: inputoctets | C38: bigint | D38: 发给用户的业务字节数 | E38: A | F38: inputoctets | G38: 直取 | J38: 详单 | K38: 无 | L38: 无
B39: outputoctets | C39: bigint | D39: 用户发出的业务字节数 | E39: A | F39: outputoctets | G39: 直取 | J39: 详单 | K39: 无 | L39: 无
B40: inputpacket | C40: bigint | D40: 发给用户的业务数据包数量 | E40: A | F40: inputpacket | G40: 直取 | J40: 详单 | K40: 无 | L40: 无
B41: outputpacket | C41: bigint | D41: 用户发出的业务数据包数量 | E41: A | F41: outputpacket | G41: 直取 | J41: 详单 | K41: 无 | L41: 无
B42: pduconnectionid | C42: string | D42: PDU连接的ID标识号 | E42: A | F42: pduconnectionid | G42: 直取 | J42: 详单 | K42: 无 | L42: 无
B43: recordclosecause | C43: int | D43: 记录关闭原因 | E43: A | F43: recordclosecause | G43: 直取 | J43: 详单 | K43: 无 | L43: 无
...

Sheet 2
B1: =HYPERLINK("#导航!a2","返回") -> 返回
B3: 目标表基本信息描述
B4: 主题域 | C4: 目标表英文名 | D4: 目标表中文名 | E4: 数据频度 | F4: 模型主键 | G4: 数据描述 | H4: 推送数据库
B5: 数据感知 | C5: aggr_nr_dpi_http_base_q | D5: 5G_DPI_http基础维度15分钟表 | E5: quarter
B7: 源表基本信息描述
B8: 来源系统 | C8: 源表英文名 | D8: 源表中文名 | E8: 别名 | F8: 任务描述 | G8: 备注 | H8: 是否主表
C9: fact_nr_dpi_http_q | D9: 5G_DPI_http整合层15分钟表 | E9: A | H9: 是
B11: 详细字段信息
B12: 详细字段信息
B13: PDM字段英文名 | C13: PDM字段类型 | D13: PDM字段中文名（说明） | E13: 源表名 | F13: 源字段英文名 | G13: 算法加工逻辑 | H13: 关联与过滤条件 | I13: 备注 | J13: 字段属性 | K13: 单位 | L13: 取值范围
B14: day | C14: string | D14: 日期 | E14: A | F14: p_date | G14: 直取 | J14: 维度 | K14: 无 | L14: yyyy-mm-dd
B15: hour | C15: int | D15: 小时 | E15: A | F15: p_hour | G15: 直取 | J15: 维度 | K15: 无 | L15: 0~23
B16: quarter | C16: int | D16: 15分钟 | E16: A | F16: p_quarter | G16: 直取 | J16: 维度 | K16: 无 | L16: 0~3
B17: interface | C17: int | D17: 接口类型 | E17: A | F17: interface | G17: 直取 | J17: 维度 | K17: 无 | L17: <=101
B18: rattype | C18: int | D18: 网络类型（4G：6；5G：10） | E18: A | F18: rattype | G18: 直取 | J18: 维度 | K18: 无 | L18: 6,10
B19: provincecode | C19: int | D19: 省编码 | E19: A | F19: p_provincecode | G19: 直取 | J19: 维度 | K19: 无 | L19: 6位数编码
B20: citycode | C20: int | D20: 市编码 | E20: A | F20: citycode | G20: 直取 | J20: 维度 | K20: 无 | L20: 6位数编码
B21: districtcode | C21: int | D21: 区编码 | E21: A | F21: districtcode | G21: 直取 | J21: 维度 | K21: 无 | L21: 6位数编码
B22: province | C22: string | D22: 省名称 | E22: A | F22: province | G22: 直取 | J22: 维度 | K22: 无 | L22: 无
B23: city | C23: string | D23: 地市名称 | E23: A | F23: city | G23: 直取 | J23: 维度 | K23: 无 | L23: 无
B24: district | C24: string | D24: 区县名称 | E24: A | F24: district | G24: 直取 | J24: 维度 | K24: 无 | L24: 无
B25: cellkey | C25: string | D25: 小区cellkey | E25: A | F25: cellkey | G25: 直取 | J25: 维度 | K25: 无 | L25: 无
... B46: httpstatus_position | C46: string | D46: http状态码原因定位 | E46: A | F46: httpstatus_position | G46: 直取 | J46: 维度 | K46: 无 | L46: 0,1
B47: abnormal_cnt | C47: bigint | D47: 质差话单数量 | E47: A | G47: sum(is_abnormal) | J47: 指标 | K47: 无 | L47: >=0
B48: record_cnt | C48: bigint | D48: 记录数 | E48: A | G48: count(1) | J48: 指标 | K48: 无 | L48: >=0
B49: speedlimit_cnt | C49: bigint | D49: 限速记录数 | E49: A | G49: sum(case when (ul_session_ambr>0 and ul_session_ambr<5000) or (dl_session_ambr>0 and dl_session_ambr<5000) then 1 else 0 end) | J49: 指标 | K49: 无 | L49: >=0
B50: duration | C50: bigint | D50: 持续时间，单位毫秒 | E50: A | G50: sum(duration) | J50: 指标 | K50: ms | L50: >=0
B51: outputoctets | C51: bigint | D51: 上行流量(byte) | E51: A | G51: sum(outputoctets) | J51: 指标 | K51: byte | L51: >=0
B52: inputoctets | C52: bigint | D52: 下行流量(byte) | E52: A | G52: sum(inputoctets) | J52: 指标 | K52: byte | L52: >=0
B53: outputoctets_above500_cnt | C53: bigint | D53: 上行大包条数(>=500KB) | E53: A | G53: sum(case when outputoctets>=500*1024 then 1 else 0 end) | J53: 指标 | K53: 无 | L53: >=0
B54: outputoctets_above500_highdelay_cnt | C54: bigint | D54: 上行大包高时延条数（>100ms） | E54: A | G54: sum(case when outputoctets>=500*1024 and tcpsetupresponsedelay>100 then 1 else 0 end) | J54: 指标 | K54: 无 | L54: >=0
B55: ul_above500_throughput_low_cnt | C55: bigint | D55: 上行大包低速率条数(<1M) | E55: A | G55: sum(case when outputoctets>=500*1024 and outputoctets/ul_data_transduration*8*1000/1024/1024<1 then 1 else 0 end) | J55: 指标 | K55: 无 | L55: >=0
B56: inputoctets_above500_cnt | C56: bigint | D56: 下行大包条数(>=500KB) | E56: A | G56: sum(case when inputoctets>=500*1024 then 1 else 0 end) | J56: 指标 | K56: 无 | L56: >=0
B57: inputoctets_above500_highdelay_cnt | C57: bigint | D57: 下行大包高时延条数（>100ms） | E57: A | G57: sum(case when inputoctets>=500*1024 and tcpsetupackdelay>100 then 1 else 0 end) | J57: 指标 | K57: 无 | L57: >=0
B58: dl_above500_throughput_low_cnt | C58: bigint | D58: 下行大包低速率条数(<1M) | E58: A | G58: sum(case when inputoctets>=500*1024 and inputoctets/dl_data_transduration*8*1000/1024/1024<1 then 1 else 0 end) | J58: 指标 | K58: 无 | L58: >=0
... B150: wellgamedelay_cnt | C150: bigint | D150: 游戏交互时延良好次数 | E150: A | G150: sum(case when tcpsetupdelay>100 and tcpsetupdelay<=120 then 1 else 0 end) | J150: 指标 | K150: 无 | L150: >=0
B151: min_starttime | C151: string | D151: 最小开始时间 | E151: A | G151: min(starttime) | I151: 20250415101139 | J151: 指标 | K151: 无 | L151: >0
B152: max_endtime | C152: string | D152: 最大结束时间 | E152: A | G152: max(endtime) | I152: 20250415101024 | J152: 指标 | K152: 无 | L152: >0
B153: p_provincecode | C153: int | D153: 省分区
B154: p_date | C154: string | D154: 天分区
...

Sheet 3
B1: =HYPERLINK("#导航!a2","返回") -> 返回
B3: 目标表基本信息描述
B4: 主题域 | C4: 目标表英文名 | D4: 目标表中文名 | E4: 数据频度 | F4: 模型主键 | G4: 数据描述 | H4: 推送数据库
B5: 数据感知 | C5: aggr_nr_dpi_http_base_h | D5: 5G_DPI_http基础维度小时表 | E5: hour
B7: 源表基本信息描述
B8: 来源系统 | C8: 源表英文名 | D8: 源表中文名 | E8: 别名 | F8: 任务描述 | G8: 备注 | H8: 是否主表
C9: aggr_nr_dpi_http_base_q | D9: 5G_DPI_http基础维度15分钟表 | E9: A | H9: 是
B11: 详细字段信息
B12: 详细字段信息
B13: PDM字段英文名 | C13: PDM字段类型 | D13: PDM字段中文名（说明） | E13: 源表名 | F13: 源字段英文名 | G13: 算法加工逻辑 | H13: 关联与过滤条件 | I13: 备注 | J13: 字段属性 | K13: 单位 | L13: 取值范围
B14: day | C14: string | D14: 日期 | E14: A | F14: p_date | G14: 直取 | J14: 维度 | K14: 无 | L14: yyyy-mm-dd
B15: hour | C15: int | D15: 小时 | E15: A | F15: p_hour | G15: 直取 | J15: 维度 | K15: 无 | L15: 0~23
B16: interface | C16: int | D16: 接口类型 | E16: A | F16: interface | G16: 直取 | J16: 维度 | K16: 无 | L16: <=101
B17: rattype | C17: int | D17: 网络类型（4G：6；5G：10） | E17: A | F17: rattype | G17: 直取 | J17: 维度 | K17: 无 | L17: 6,10
B18: provincecode | C18: int | D18: 省编码 | E18: A | F18: provincecode | G18: 直取 | J18: 维度 | K18: 无 | L18: 6位数编码
B19: citycode | C19: int | D19: 市编码 | E19: A | F19: citycode | G19: 直取 | J19: 维度 | K19: 无 | L19: 6位数编码
B20: districtcode | C20: int | D20: 区编码 | E20: A | F20: districtcode | G20: 直取 | J20: 维度 | K20: 无 | L20: 6位数编码
B21: province | C21: string | D21: 省名称 | E21: A | F21: province | G21: 直取 | J21: 维度 | K21: 无 | L21: 无
B22: city | C22: string | D22: 地市名称 | E22: A | F22: city | G22: 直取 | J22: 维度 | K22: 无 | L22: 无
B23: district | C23: string | D23: 区县名称 | E23: A | F23: district | G23: 直取 | J23: 维度 | K23: 无 | L23: 无
B24: cellkey | C24: string | D24: 小区cellkey | E24: A | F24: cellkey | G24: 直取 | J24: 维度 | K24: 无 | L24: 无
B25: tai | C25: string | D25: 跟踪区标识 | E25: A | F25: tai | G25: 直取 | J25: 维度 | K25: 无 | L25: 无
... B45: httpstatus_position | C45: string | D45: http状态码原因定位 | E45: A | F45: httpstatus_position | G45: 直取 | J45: 维度 | K45: 无 | L45: 0,1
B46: abnormal_cnt | C46: bigint | D46: 质差话单数量 | E46: A | G46: sum(abnormal_cnt) | J46: 指标 | K46: 无 | L46: >=0
B47: record_cnt | C47: bigint | D47: 记录数 | E47: A | G47: sum(record_cnt) | J47: 指标 | K47: 无 | L47: >=0
B48: speedlimit_cnt | C48: bigint | D48: 限速记录数 | E48: A | G48: sum(speedlimit_cnt) | J48: 指标 | K48: 无 | L48: >=0
B49: duration | C49: bigint | D49: 持续时间，单位毫秒 | E49: A | G49: sum(duration) | J49: 指标 | K49: ms | L49: >=0
B50: outputoctets | C50: bigint | D50: 上行流量(byte) | E50: A | G50: sum(outputoctets) | J50: 指标 | K50: byte | L50: >=0
B51: inputoctets | C51: bigint | D51: 下行流量(byte) | E51: A | G51: sum(inputoctets) | J51: 指标 | K51: byte | L51: >=0
B52: outputoctets_above500_cnt | C52: bigint | D52: 上行大包条数(>=500KB) | E52: A | G52: sum(outputoctets_above500_cnt) | J52: 指标 | K52: 无 | L52: >=0
B53: outputoctets_above500_highdelay_cnt | C53: bigint | D53: 上行大包高时延条数（>100ms） | E53: A | G53: sum(outputoctets_above500_highdelay_cnt) | J53: 指标 | K53: 无 | L53: >=0
B54: ul_above500_throughput_low_cnt | C54: bigint | D54: 上行大包低速率条数(<1M) | E54: A | G54: sum(ul_above500_throughput_low_cnt) | J54: 指标 | K54: 无 | L54: >=0
B55: inputoctets_above500_cnt | C55: bigint | D55: 下行大包条数(>=500KB) | E55: A | G55: sum(inputoctets_above500_cnt) | J55: 指标 | K55: 无 | L55: >=0
B56: inputoctets_above500_highdelay_cnt | C56: bigint | D56: 下行大包高时延条数（>100ms） | E56: A | G56: sum(inputoctets_above500_highdelay_cnt) | J56: 指标 | K56: 无 | L56: >=0
B57: dl_above500_throughput_low_cnt | C57: bigint | D57: 下行大包低速率条数(<1M) | E57: A | G57: sum(dl_above500_throughput_low_cnt) | J57: 指标 | K57: 无 | L57: >=0
... B149: wellgamedelay_cnt | C149: bigint | D149: 游戏交互时延良好次数 | E149: A | G149: sum(wellgamedelay_cnt) | J149: 指标 | K149: 无 | L149: >=0
B150: min_starttime | C150: string | D150: 最小开始时间 | E150: A | G150: min(min_starttime) | I150: 20250415101139 | J150: 指标 | K150: 无 | L150: >0
B151: max_endtime | C151: string | D151: 最大结束时间 | E151: A | G151: max(max_endtime) | I151: 20250415101024 | J151: 指标 | K151: 无 | L151: >0
B152: p_provincecode | C152: int | D152: 省分区
B153: p_date | C153: string | D153: 天分区
...

Sheet 4
B1: =HYPERLINK("#导航!a2","返回") -> 返回
B3: 目标表基本信息描述
B4: 主题域 | C4: 目标表英文名 | D4: 目标表中文名 | E4: 数据频度 | F4: 模型主键 | G4: 数据描述 | H4: 推送数据库
B5: 数据感知 | C5: aggr_nr_dpi_http_index_reduce_base_h | D5: 5G_DPI_http基础维度指标裁剪小时表 | E5: hour
B7: 源表基本信息描述
B8: 来源系统 | C8: 源表英文名 | D8: 源表中文名 | E8: 别名 | F8: 任务描述 | G8: 备注 | H8: 是否主表
C9: aggr_nr_dpi_http_base_h | D9: 5G_DPI_http基础维度小时表 | E9: A | H9: 是
B11: 详细字段信息
B12: 详细字段信息
B13: PDM字段英文名 | C13: PDM字段类型 | D13: PDM字段中文名（说明） | E13: 源表名 | F13: 源字段英文名 | G13: 算法加工逻辑 | H13: 关联与过滤条件 | I13: 备注 | J13: 字段属性 | K13: 单位 | L13: 取值范围
B14: day | C14: string | D14: 上报时间，具体到天 | F14: p_date | G14: 直取 | J14: 维度 | K14: 无 | L14: 无
B15: hour | C15: int | D15: 小时 | F15: p_hour | G15: 直取 | J15: 维度 | K15: 无 | L15: 无
B16: provincecode | C16: int | D16: 拜访地省份 | F16: p_provincecode | G16: 直取 | J16: 维度 | K16: 无 | L16: 无
B17: citycode | C17: int | D17: 拜访地地市 | F17: citycode | G17: 直取 | J17: 维度 | K17: 无 | L17: 无
B18: interface | C18: int | D18: 接口 | F18: interface | G18: 直取 | J18: 维度 | K18: 无 | L18: 无
B19: rattype | C19: int | D19: 无线接入类型 | F19: RATType | G19: 直取 | J19: 维度 | K19: 无 | L19: 无
B20: nodebid | C20: bigint | D20: 4G eNodeBID/5G gNBID | G20: split(cellkey,"_")[0] | J20: 维度 | K20: 无 | L20: 无
B21: cellid | C21: bigint | D21: 小区ID | G21: split(cellkey,"_")[1] | J21: 维度 | K21: 无 | L21: 无
B22: cellkey | C22: string | D22: 小区cellkey | F22: cellkey | G22: 直取 | J22: 维度 | K22: 无 | L22: 无
B23: home_province | C23: string | D23: 归属省份 | F23: home_province | G23: 直取 | J23: 维度 | K23: 无 | L23: 无
B24: imsi_supi | C24: string | D24: 永久用户标识，永久用户标识。4G 填写用户IMSI。 | F24: supi | G24: 直取 | J24: 维度 | K24: 无 | L24: 无
B25: msisdn | C25: string | D25: MS International PSTN/ISDN Number (ISDN) | F25: msisdn | G25: 直取 | J25: 维度 | K25: 无 | L25: 无
B26: pei | C26: string | D26: 永久设备标识 | F26: pei | G26: 直取 | J26: 维度 | K26: 无 | L26: 无
B27: nssai_sst | C27: string | D27: Slice Service Type (SST) | F27: NSSAI_SST | G27: 直取 | J27: 维度 | K27: 无 | L27: 无
B28: nssai_sd | C28: string | D28: Slice Differentiator（SD） | F28: NSSAI_SD | G28: 直取 | J28: 维度 | K28: 无 | L28: 无
B29: dnn_apn | C29: string | D29: 网络接入标识 | F29: dnn_apn | G29: 直取 | J29: 维度 | K29: 无 | L29: 无
B30: upfip | C30: string | D30: UPF的IPv4或IPv6地址 | F30: upfip | G30: 直取 | J30: 维度 | K30: 无 | L30: 无
B31: gnbip | C31: string | D31: gNB的IPv4或IPv6地址 | F31: gnbip | G31: 直取 | J31: 维度 | K31: 无 | L31: 无
B32: servicetype | C32: int | D32: 业务应用 | F32: ServiceType | G32: 直取 | J32: 维度 | K32: 无 | L32: 无
B33: sourceip_type | C33: string | D33: 用户访问外部网络时使用的IP类型（IPv4/IPv6） | F33: sourceip_type | G33: 直取 | J33: 维度 | K33: 无 | L33: 无
B34: outputoctets_sum | C34: bigint | D34: 上行流量(byte) | G34: sum(outputoctets) | J34: 指标 | K34: byte | L34: >=0
B35: inputoctets_sum | C35: bigint | D35: 下行流量(byte) | G35: sum(inputoctets) | J35: 指标 | K35: byte | L35: >=0
B36: outputoctets_above500_cnt_sum | C36: bigint | D36: 上行大包条数(>=500KB) | G36: sum(outputoctets_above500_cnt) | J36: 指标 | K36: 无 | L36: >=0
B37: outputoctets_above500_highdelay_sum | C37: bigint | D37: 上行大包高时延条数（>100ms） | G37: sum(outputoctets_above500_highdelay_cnt) | J37: 指标 | K37: 无 | L37: >=0
B38: ul_above500_throughput_low_cnt_sum | C38: bigint | D38: 上行大包低速率条数(<1M) | G38: sum(ul_above500_throughput_low_cnt) | J38: 指标 | K38: 无 | L38: >=0
B39: inputoctets_above500_cnt_sum | C39: bigint | D39: 下行大包条数(>=500KB) | G39: sum(inputoctets_above500_cnt) | J39: 指标 | K39: 无 | L39: >=0
B40: inputoctets_above500_highdelay_sum | C40: bigint | D40: 下行大包高时延条数（>100ms） | G40: sum(inputoctets_above500_highdelay_cnt) | J40: 指标 | K40: 无 | L40: >=0
B41: dl_above500_throughput_low_cnt_sum | C41: bigint | D41: 下行大包低速率条数(<1M) | G41: sum(dl_above500_throughput_low_cnt) | J41: 指标 | K41: 无 | L41: >=0
B42: dl_above500_throughput_inferior_cnt_sum | C42: bigint | D42: 下行大包低速率条数(<3M) | G42: sum(dl_above500_throughput_inferior_cnt) | J42: 指标 | K42: 无 | L42: >=0
B43: inputpacket_sum | C43: bigint | D43: 发给用户的业务数据包数量 | G43: sum(inputpacket) | J43: 指标 | K43: 无 | L43: >=0
...

Sheet 5
B1: =HYPERLINK("#导航!a2","返回") -> 返回
B3: 目标表基本信息描述
B4: 主题域 | C4: 目标表英文名 | D4: 目标表中文名 | E4: 数据频度 | F4: 模型主键 | G4: 数据描述 | H4: 推送数据库
B5: 数据感知 | C5: aggr_nr_dpi_http_usrappcel_h | D5: 5G_DPI_http用户小区app维度小时表 | E5: hour
B7: 源表基本信息描述
B8: 来源系统 | C8: 源表英文名 | D8: 源表中文名 | E8: 别名 | F8: 任务描述 | G8: 备注 | H8: 是否主表
C9: aggr_nr_dpi_http_base_h | D9: 5G_DPI_http基础维度小时表 | E9: A | H9: 是
B11: 详细字段信息
B12: 详细字段信息
B13: PDM字段英文名 | C13: PDM字段类型 | D13: PDM字段中文名（说明） | E13: 源表名 | F13: 源字段英文名 | G13: 算法加工逻辑 | H13: 关联与过滤条件 | I13: 备注 | J13: 字段属性 | K13: 单位 | L13: 取值范围
B14: day | C14: string | D14: 日期 | E14: A | F14: p_date | G14: 直取 | J14: 维度 | K14: 无 | L14: yyyy-mm-dd
B15: hour | C15: int | D15: 小时 | E15: A | F15: p_hour | G15: 直取 | J15: 维度 | K15: 无 | L15: 0~23
B16: interface | C16: int | D16: 接口类型 | E16: A | F16: interface | G16: 直取 | J16: 维度 | K16: 无 | L16: <=101
B17: provincecode | C17: int | D17: 省编码 | E17: A | F17: provincecode | G17: 直取 | J17: 维度 | K17: 无 | L17: 6位数编码
B18: citycode | C18: int | D18: 市编码 | E18: A | F18: citycode | G18: 直取 | J18: 维度 | K18: 无 | L18: 6位数编码
B19: districtcode | C19: int | D19: 区编码 | E19: A | F19: districtcode | G19: 直取 | J19: 维度 | K19: 无 | L19: 6位数编码
B20: province | C20: string | D20: 省名称 | E20: A | F20: province | G20: 直取 | J20: 维度 | K20: 无 | L20: 无
B21: city | C21: string | D21: 地市名称 | E21: A | F21: city | G21: 直取 | J21: 维度 | K21: 无 | L21: 无
B22: district | C22: string | D22: 区县名称 | E22: A | F22: district | G22: 直取 | J22: 维度 | K22: 无 | L22: 无
B23: cellkey | C23: string | D23: 小区cellkey | E23: A | F23: cellkey | G23: 直取 | J23: 维度 | K23: 无 | L23: 无
B24: tai | C24: string | D24: 跟踪区标识 | E24: A | F24: tai | G24: 直取 | J24: 维度 | K24: 无 | L24: 无
B25: gnbip | C25: string | D25: gNB的IPv4或IPv6地址 | E25: A | F25: gnbip | G25: 直取 | J25: 维度 | K25: 无 | L25: 无
... B31: home_province | C31: string | D31: 归属省份 | E31: A | F31: home_province | G31: 直取 | J31: 维度 | K31: 无 | L31: 6位数编码
B32: abnormal_cnt | C32: bigint | D32: 质差话单数量 | E32: A | G32: sum(abnormal_cnt) | J32: 指标 | K32: 无 | L32: >=0
B33: record_cnt | C33: bigint | D33: 记录数 | E33: A | G33: sum(record_cnt) | J33: 指标 | K33: 无 | L33: >=0
B34: speedlimit_cnt | C34: bigint | D34: 限速记录数 | E34: A | G34: sum(speedlimit_cnt) | J34: 指标 | K34: 无 | L34: >=0
B35: duration | C35: bigint | D35: 持续时间，单位毫秒 | E35: A | G35: sum(duration) | J35: 指标 | K35: ms | L35: >=0
B36: outputoctets | C36: bigint | D36: 上行流量(byte) | E36: A | G36: sum(outputoctets) | J36: 指标 | K36: byte | L36: >=0
B37: inputoctets | C37: bigint | D37: 下行流量(byte) | E37: A | G37: sum(inputoctets) | J37: 指标 | K37: byte | L37: >=0
B38: outputoctets_above500_cnt | C38: bigint | D38: 上行大包条数(>=500KB) | E38: A | G38: sum(outputoctets_above500_cnt) | J38: 指标 | K38: 无 | L38: >=0
B39: inputoctets_above500_cnt | C39: bigint | D39: 下行大包条数(>=500KB) | E39: A | G39: sum(inputoctets_above500_cnt) | J39: 指标 | K39: 无 | L39: >=0
B40: outputpacket | C40: bigint | D40: 上行包数 | E40: A | G40: sum(outputpacket) | J40: 指标 | K40: 无 | L40: >=0
B41: inputpacket | C41: bigint | D41: 下行包数 | E41: A | G41: sum(inputpacket) | J41: 指标 | K41: 无 | L41: >=0
B42: ultcpreorderingpacket | C42: bigint | D42: 上行TCP乱序报文数，L4协议，非TCP传输时，此字段填0 | E42: A | G42: sum(ultcpreorderingpacket) | J42: 指标 | K42: 无 | L42: >=0
B43: dltcpreorderingpacket | C43: bigint | D43: 下行TCP乱序报文数，非TCP传输时，此字段填0 | E43: A | G43: sum(dltcpreorderingpacket) | J43: 指标 | K43: 无 | L43: >=0
... B127: wellgamedelay_cnt | C127: bigint | D127: 游戏交互时延良好次数 | E127: A | G127: sum(wellgamedelay_cnt) | J127: 指标 | K127: 无 | L127: >=0
B128: min_starttime | C128: string | D128: 最小开始时间 | E128: A | G128: min(min_starttime) | I128: 20250415101139 | J128: 指标 | K128: 无 | L128: >0
B129: max_endtime | C129: string | D129: 最大结束时间 | E129: A | G129: max(max_endtime) | I129: 20250415101024 | J129: 指标 | K129: 无 | L129: >0
B130: p_provincecode | C130: int | D130: 省分区
B131: p_date | C131: string | D131: 天分区
...

Sheet 5.1
B1: =HYPERLINK("#导航!a2","返回") -> 返回
B3: 目标表基本信息描述
B4: 主题域 | C4: 目标表英文名 | D4: 目标表中文名 | E4: 数据频度 | F4: 模型主键 | G4: 数据描述 | H4: 推送数据库
B5: 数据感知 | C5: aggr_nr_dpi_http_usrapp_h | D5: 5G_DPI_http用户app维度小时表 | E5: hour
B7: 源表基本信息描述
B8: 来源系统 | C8: 源表英文名 | D8: 源表中文名 | E8: 别名 | F8: 任务描述 | G8: 备注 | H8: 是否主表
C9: aggr_nr_dpi_http_usrappcel_h | D9: 5G_DPI_http用户小区app维度小时表 | E9: A | H9: 是
B11: 详细字段信息
B12: 详细字段信息
B13: PDM字段英文名 | C13: PDM字段类型 | D13: PDM字段中文名（说明） | E13: 源表名 | F13: 源字段英文名 | G13: 算法加工逻辑 | H13: 关联与过滤条件 | I13: 备注 | J13: 字段属性 | K13: 单位 | L13: 取值范围
B14: day | C14: string | D14: 日期 | E14: A | F14: p_date | G14: 直取 | J14: 维度 | K14: 无 | L14: yyyy-mm-dd
B15: hour | C15: int | D15: 小时 | E15: A | F15: p_hour | G15: 直取 | J15: 维度 | K15: 无 | L15: 0~23
B16: interface | C16: int | D16: 接口类型 | E16: A | F16: interface | G16: 直取 | J16: 维度 | K16: 无 | L16: <=101
B17: provincecode | C17: int | D17: 省编码 | E17: A | F17: provincecode | G17: 直取 | J17: 维度 | K17: 无 | L17: 6位数编码
B18: citycode | C18: int | D18: 市编码 | E18: A | F18: citycode | G18: 直取 | J18: 维度 | K18: 无 | L18: 6位数编码
B19: districtcode | C19: int | D19: 区编码 | E19: A | F19: districtcode | G19: 直取 | J19: 维度 | K19: 无 | L19: 6位数编码
B20: province | C20: string | D20: 省名称 | E20: A | F20: province | G20: 直取 | J20: 维度 | K20: 无 | L20: 无
B21: city | C21: string | D21: 地市名称 | E21: A | F21: city | G21: 直取 | J21: 维度 | K21: 无 | L21: 无
B22: district | C22: string | D22: 区县名称 | E22: A | F22: district | G22: 直取 | J22: 维度 | K22: 无 | L22: 无
B23: supi | C23: string | D23: 用户imsi | E23: A | F23: supi | G23: 直取 | J23: 维度 | K23: 无 | L23: 无
B24: msisdn | C24: string | D24: 用户号码 | E24: A | F24: msisdn | G24: 直取 | J24: 维度 | K24: 无 | L24: 无
B25: pei | C25: string | D25: 用户终端 | E25: A | F25: pei | G25: 直取 | J25: 维度 | K25: 无 | L25: 无
... B27: business_type | C27: string | D27: 业务类型（im、web、game、video、other） | E27: A | F27: business_type | G27: 直取 | J27: 维度 | K27: 无 | L27: im,web,game,video,other
B28: abnormal_cnt | C28: bigint | D28: 质差话单数量 | E28: A | G28: sum(abnormal_cnt) | J28: 指标 | K28: 无 | L28: >=0
B29: record_cnt | C29: bigint | D29: 记录数 | E29: A | G29: sum(record_cnt) | J29: 指标 | K29: 无 | L29: >=0
B30: speedlimit_cnt | C30: bigint | D30: 限速记录数 | E30: A | G30: sum(speedlimit_cnt) | J30: 指标 | K30: 无 | L30: >=0
B31: duration | C31: bigint | D31: 持续时间，单位毫秒 | E31: A | G31: sum(duration) | J31: 指标 | K31: ms | L31: >=0
B32: outputoctets | C32: bigint | D32: 上行流量(byte) | E32: A | G32: sum(outputoctets) | J32: 指标 | K32: byte | L32: >=0
B33: inputoctets | C33: bigint | D33: 下行流量(byte) | E33: A | G33: sum(inputoctets) | J33: 指标 | K33: byte | L33: >=0
B34: outputoctets_above500_cnt | C34: bigint | D34: 上行大包条数(>=500KB) | E34: A | G34: sum(outputoctets_above500_cnt) | J34: 指标 | K34: 无 | L34: >=0
B35: inputoctets_above500_cnt | C35: bigint | D35: 下行大包条数(>=500KB) | E35: A | G35: sum(inputoctets_above500_cnt) | J35: 指标 | K35: 无 | L35: >=0
B36: outputpacket | C36: bigint | D36: 上行包数 | E36: A | G36: sum(outputpacket) | J36: 指标 | K36: 无 | L36: >=0
B37: inputpacket | C37: bigint | D37: 下行包数 | E37: A | G37: sum(inputpacket) | J37: 指标 | K37: 无 | L37: >=0
B38: ultcpreorderingpacket | C38: bigint | D38: 上行TCP乱序报文数，L4协议，非TCP传输时，此字段填0 | E38: A | G38: sum(ultcpreorderingpacket) | J38: 指标 | K38: 无 | L38: >=0
B39: dltcpreorderingpacket | C39: bigint | D39: 下行TCP乱序报文数，非TCP传输时，此字段填0 | E39: A | G39: sum(dltcpreorderingpacket) | J39: 指标 | K39: 无 | L39: >=0
... B123: wellgamedelay_cnt | C123: bigint | D123: 游戏交互时延良好次数 | E123: A | G123: sum(wellgamedelay_cnt) | J123: 指标 | K123: 无 | L123: >=0
B124: min_starttime | C124: string | D124: 最小开始时间 | E124: A | G124: min(min_starttime) | I124: 20250415101139 | J124: 指标 | K124: 无 | L124: >0
B125: max_endtime | C125: string | D125: 最大结束时间 | E125: A | G125: max(max_endtime) | I125: 20250415101024 | J125: 指标 | K125: 无 | L125: >0
B126: p_provincecode | C126: int | D126: 省分区
B127: p_date | C127: string | D127: 天分区
...

Sheet 5.2
B1: =HYPERLINK("#导航!a2","返回") -> 返回
B3: 目标表基本信息描述
B4: 主题域 | C4: 目标表英文名 | D4: 目标表中文名 | E4: 数据频度 | F4: 模型主键 | G4: 数据描述 | H4: 推送数据库
B5: 数据感知 | C5: aggr_nr_dpi_http_usrapp_d | D5: 5G_DPI_http用户app维度天表 | E5: day
B7: 源表基本信息描述
B8: 来源系统 | C8: 源表英文名 | D8: 源表中文名 | E8: 别名 | F8: 任务描述 | G8: 备注 | H8: 是否主表
C9: aggr_nr_dpi_http_usrapp_h | D9: 5G_DPI_http用户app维度小时表 | E9: A | H9: 是
B11: 详细字段信息
B12: 详细字段信息
B13: PDM字段英文名 | C13: PDM字段类型 | D13: PDM字段中文名（说明） | E13: 源表名 | F13: 源字段英文名 | G13: 算法加工逻辑 | H13: 关联与过滤条件 | I13: 备注 | J13: 字段属性 | K13: 单位 | L13: 取值范围
B14: day | C14: string | D14: 日期 | E14: A | F14: p_date | G14: 直取 | J14: 维度 | K14: 无 | L14: yyyy-mm-dd
B15: interface | C15: int | D15: 接口类型 | E15: A | F15: interface | G15: 直取 | J15: 维度 | K15: 无 | L15: <=101
B16: provincecode | C16: int | D16: 省编码 | E16: A | F16: provincecode | G16: 直取 | J16: 维度 | K16: 无 | L16: 6位数编码
B17: citycode | C17: int | D17: 市编码 | E17: A | F17: citycode | G17: 直取 | J17: 维度 | K17: 无 | L17: 6位数编码
B18: districtcode | C18: int | D18: 区编码 | E18: A | F18: districtcode | G18: 直取 | J18: 维度 | K18: 无 | L18: 6位数编码
B19: province | C19: string | D19: 省名称 | E19: A | F19: province | G19: 直取 | J19: 维度 | K19: 无 | L19: 无
B20: city | C20: string | D20: 地市名称 | E20: A | F20: city | G20: 直取 | J20: 维度 | K20: 无 | L20: 无
B21: district | C21: string | D21: 区县名称 | E21: A | F21: district | G21: 直取 | J21: 维度 | K21: 无 | L21: 无
B22: supi | C22: string | D22: 用户imsi | E22: A | F22: supi | G22: 直取 | J22: 维度 | K22: 无 | L22: 无
B23: msisdn | C23: string | D23: 用户号码 | E23: A | F23: msisdn | G23: 直取 | J23: 维度 | K23: 无 | L23: 无
B24: pei | C24: string | D24: 用户终端 | E24: A | F24: pei | G24: 直取 | J24: 维度 | K24: 无 | L24: 无
B25: servicetype | C25: string | D25: 业务应用 | E25: A | F25: servicetype | G25: 直取 | J25: 维度 | K25: 无 | L25: 无
B26: business_type | C26: string | D26: 业务类型（im、web、game、video、other） | E26: A | F26: business_type | G26: 直取 | J26: 维度 | K26: 无 | L26: im,web,game,video,other
B27: abnormal_cnt | C27: bigint | D27: 质差话单数量 | E27: A | G27: sum(abnormal_cnt) | J27: 指标 | K27: 无 | L27: >=0
B28: record_cnt | C28: bigint | D28: 记录数 | E28: A | G28: sum(record_cnt) | J28: 指标 | K28: 无 | L28: >=0
B29: speedlimit_cnt | C29: bigint | D29: 限速记录数 | E29: A | G29: sum(speedlimit_cnt) | J29: 指标 | K29: 无 | L29: >=0
B30: duration | C30: bigint | D30: 持续时间，单位毫秒 | E30: A | G30: sum(duration) | J30: 指标 | K30: ms | L30: >=0
B31: outputoctets | C31: bigint | D31: 上行流量(byte) | E31: A | G31: sum(outputoctets) | J31: 指标 | K31: byte | L31: >=0
B32: inputoctets | C32: bigint | D32: 下行流量(byte) | E32: A | G32: sum(inputoctets) | J32: 指标 | K32: byte | L32: >=0
B33: outputoctets_above500_cnt | C33: bigint | D33: 上行大包条数(>=500KB) | E33: A | G33: sum(outputoctets_above500_cnt) | J33: 指标 | K33: 无 | L33: >=0
B34: inputoctets_above500_cnt | C34: bigint | D34: 下行大包条数(>=500KB) | E34: A | G34: sum(inputoctets_above500_cnt) | J34: 指标 | K34: 无 | L34: >=0
B35: outputpacket | C35: bigint | D35: 上行包数 | E35: A | G35: sum(outputpacket) | J35: 指标 | K35: 无 | L35: >=0
B36: inputpacket | C36: bigint | D36: 下行包数 | E36: A | G36: sum(inputpacket) | J36: 指标 | K36: 无 | L36: >=0
B37: ultcpreorderingpacket | C37: bigint | D37: 上行TCP乱序报文数，L4协议，非TCP传输时，此字段填0 | E37: A | G37: sum(ultcpreorderingpacket) | J37: 指标 | K37: 无 | L37: >=0
B38: dltcpreorderingpacket | C38: bigint | D38: 下行TCP乱序报文数，非TCP传输时，此字段填0 | E38: A | G38: sum(dltcpreorderingpacket) | J38: 指标 | K38: 无 | L38: >=0
... B122: wellgamedelay_cnt | C122: bigint | D122: 游戏交互时延良好次数 | E122: A | G122: sum(wellgamedelay_cnt) | J122: 指标 | K122: 无 | L122: >=0
B123: min_starttime | C123: string | D123: 最小开始时间 | E123: A | G123: min(min_starttime) | I123: 20250415101139 | J123: 指标 | K123: 无 | L123: >0
B124: max_endtime | C124: string | D124: 最大结束时间 | E124: A | G124: max(max_endtime) | I124: 20250415101024 | J124: 指标 | K124: 无 | L124: >0
B125: p_provincecode | C125: int | D125: 省分区
B126: p_date | C126: string | D126: 天分区

Sheet 6
B1: =HYPERLINK("#导航!a2","返回") -> 返回
B3: 目标表基本信息描述
B4: 主题域 | C4: 目标表英文名 | D4: 目标表中文名 | E4: 数据频度 | F4: 模型主键 | G4: 数据描述 | H4: 推送数据库
B5: 数据感知 | C5: aggr_nr_iov_http_usrappcel_refactor_h | D5: 5G_DPI_http车联网用户小区app维度小时表 | E5: hour
B7: 源表基本信息描述
B8: 来源系统 | C8: 源表英文名 | D8: 源表中文名 | E8: 别名 | F8: 任务描述 | G8: 备注 | H8: 是否主表
C9: aggr_nr_dpi_http_usrappcel_h | D9: 5G_DPI_http用户小区app维度小时表 | E9: A | H9: 是
C10: cfg_dpi_servicetype | D10: DPI业务码表 | E10: B | F10: A left join B，关联条件：A.servicetype = B.servicetype
C11: cfg_iov_usr_list | D11: 车联网用户清单配置表 | E11: C | F11: A inner join C，关联条件：A.msisdn = C.msisdn
B13: 详细字段信息
B14: 详细字段信息
B15: PDM字段英文名 | C15: PDM字段类型 | D15: PDM字段中文名（说明） | E15: 源表名 | F15: 源字段英文名 | G15: 算法加工逻辑 | H15: 关联与过滤条件 | I15: 备注 | J15: 字段属性 | K15: 单位 | L15: 取值范围
B16: day | C16: string | D16: 日期 | E16: A | F16: p_date | G16: 直取 | H16: =VLOOKUP(F16,'5'!B:L,1,0) -> p_date | J16: 维度 | K16: 无 | L16: 无
B17: hour | C17: int | D17: 小时 | E17: A | F17: p_hour | G17: 直取 | H17: =VLOOKUP(F17,'5'!B:L,1,0) -> p_hour | J17: 维度 | K17: 无 | L17: 无
B18: interface | C18: int | D18: 接口类型 | E18: A | F18: interface | G18: 直取 | H18: =VLOOKUP(F18,'5'!B:L,1,0) -> interface | J18: 维度 | K18: 无 | L18: 无
B19: provincecode | C19: int | D19: 省编码 | E19: A | F19: p_provincecode | G19: 直取 | H19: =VLOOKUP(F19,'5'!B:L,1,0) -> p_provincecode | J19: 维度 | K19: 无 | L19: 无
B20: citycode | C20: int | D20: 市编码 | E20: A | F20: city | G20: 直取 | H20: =VLOOKUP(F20,'5'!B:L,1,0) -> city | J20: 维度 | K20: 无 | L20: 无
B21: districtcode | C21: int | D21: 区县编码 | E21: A | F21: districtcode | G21: 直取 | H21: =VLOOKUP(F21,'5'!B:L,1,0) -> districtcode | J21: 维度 | K21: 无 | L21: 无
B22: cellkey | C22: string | D22: 小区唯一标识："小区基站号"_"小区编号" | E22: A | F22: cellkey | G22: 直取 | H22: =VLOOKUP(F22,'5'!B:L,1,0) -> cellkey | J22: 维度 | K22: 无 | L22: 无
B23: imsi | C23: string | D23: 国际移动用户识别码 | E23: A | F23: supi | G23: 直取 | H23: =VLOOKUP(F23,'5'!B:L,1,0) -> supi | J23: 维度 | K23: 无 | L23: 无
B24: msisdn | C24: string | D24: 用户号码 | E24: A | F24: msisdn | G24: 直取 | H24: =VLOOKUP(F24,'5'!B:L,1,0) -> msisdn | J24: 维度 | K24: 无 | L24: 无
B25: imei | C25: string | D25: 终端识别码 | E25: A | F25: pei | G25: 直取 | H25: =VLOOKUP(F25,'5'!B:L,1,0) -> pei | J25: 维度 | K25: 无 | L25: 无
B26: servicetype | C26: string | D26: 业务应用分类ID | E26: A | F26: servicetype | G26: 直取 | H26: =VLOOKUP(F26,'5'!B:L,1,0) -> servicetype | J26: 维度 | K26: 无 | L26: 无
B27: app_type | C27: string | D27: 业务应用大类 | E27: A | G27: substr(servicetype,1,2) | J27: 维度 | K27: 无 | L27: 无
B28: app_name | C28: string | D28: 业务名称 | E28: B | F28: servicetype_name | G28: 直取 | J28: 维度 | K28: 无 | L28: 无
B29: min_starttime | C29: string | D29: 最小开始时间 | E29: A | G29: min(min_starttime) | J29: 指标 | K29: 无 | L29: 无
B30: max_endtime | C30: string | D30: 最大结束时间 | E30: A | G30: max(max_endtime) | J30: 指标 | K30: 无 | L30: 无
B31: total_cnt | C31: bigint | D31: 总话单数 | E31: A | G31: sum(record_cnt) | J31: 指标 | K31: 无 | L31: >=0
B32: abnormal_cnt | C32: bigint | D32: 总质差话单数 | E32: A | G32: sum(abnormal_cnt) | J32: 指标 | K32: 无 | L32: >=0
B33: abnormal_rate | C33: double | D33: 总质差话单占比 | E33: A | G33: sum(abnormal_cnt)/sum(record_cnt) | J33: 指标 | K33: 无 | L33: [0,1]
B34: duration | C34: bigint | D34: 业务时长(ms) | E34: A | G34: sum(duration) | J34: 指标 | K34: ms | L34: >=0
B35: flux | C35: bigint | D35: 业务流量(byte) | E35: A | G35: sum(nvl(outputoctets,0)+nvl(inputoctets,0)) | J35: 指标 | K35: byte | L35: >=0
B36: p_provincecode | C36: int | D36: 省分区
B37: p_date | C37: string | D37: 天分区
B38: p_hour | C38: int | D38: 小时分区

Sheet 7
B1: =HYPERLINK("#导航!a2","返回") -> 返回
B3: 目标表基本信息描述
B4: 主题域 | C4: 目标表英文名 | D4: 目标表中文名 | E4: 数据频度 | F4: 模型主键 | G4: 数据描述 | H4: 推送数据库
B5: 数据感知 | C5: aggr_nr_dpi_http_appcel_h | D5: 5G_DPI_http小区app维度小时表 | E5: hour
B7: 源表基本信息描述
B8: 来源系统 | C8: 源表英文名 | D8: 源表中文名 | E8: 别名 | F8: 任务描述 | G8: 备注 | H8: 是否主表
C9: aggr_nr_dpi_http_usrappcel_h | D9: 5G_DPI_http用户小区app维度小时表 | E9: A | H9: 是
B11: 详细字段信息
B12: 详细字段信息
B13: PDM字段英文名 | C13: PDM字段类型 | D13: PDM字段中文名（说明） | E13: 源表名 | F13: 源字段英文名 | G13: 算法加工逻辑 | H13: 关联与过滤条件 | I13: 备注 | J13: 字段属性 | K13: 单位 | L13: 取值范围
B14: day | C14: string | D14: 日期 | E14: A | F14: p_date | G14: 直取 | J14: 维度 | K14: 无 | L14: yyyy-mm-dd
B15: hour | C15: int | D15: 小时 | E15: A | F15: p_hour | G15: 直取 | J15: 维度 | K15: 无 | L15: 0~23
B16: interface | C16: int | D16: 接口类型 | E16: A | F16: interface | G16: 直取 | J16: 维度 | K16: 无 | L16: <=101
B17: provincecode | C17: int | D17: 省编码 | E17: A | F17: provincecode | G17: 直取 | J17: 维度 | K17: 无 | L17: 6位数编码
B18: citycode | C18: int | D18: 市编码 | E18: A | F18: citycode | G18: 直取 | J18: 维度 | K18: 无 | L18: 6位数编码
B19: districtcode | C19: int | D19: 区编码 | E19: A | F19: districtcode | G19: 直取 | J19: 维度 | K19: 无 | L19: 6位数编码
B20: province | C20: string | D20: 省名称 | E20: A | F20: province | G20: 直取 | J20: 维度 | K20: 无 | L20: 无
B21: city | C21: string | D21: 地市名称 | E21: A | F21: city | G21: 直取 | J21: 维度 | K21: 无 | L21: 无
B22: district | C22: string | D22: 区县名称 | E22: A | F22: district | G22: 直取 | J22: 维度 | K22: 无 | L22: 无
B23: cellkey | C23: string | D23: 小区cellkey | E23: A | F23: cellkey | G23: 直取 | J23: 维度 | K23: 无 | L23: 无
B24: servicetype | C24: string | D24: 业务应用 | E24: A | F24: servicetype | G24: 直取 | J24: 维度 | K24: 无 | L24: 无
B25: business_type | C25: string | D25: 业务类型（im、web、game、video、other） | E25: A | F25: business_type | G25: 直取 | J25: 维度 | K25: 无 | L25: im,web,game,video,other
B26: abnormal_cnt | C26: bigint | D26: 质差话单数量 | E26: A | G26: sum(abnormal_cnt) | J26: 指标 | K26: 无 | L26: >=0
B27: record_cnt | C27: bigint | D27: 记录数 | E27: A | G27: sum(record_cnt) | J27: 指标 | K27: 无 | L27: >=0
B28: speedlimit_cnt | C28: bigint | D28: 限速记录数 | E28: A | G28: sum(speedlimit_cnt) | J28: 指标 | K28: 无 | L28: >=0
B29: duration | C29: bigint | D29: 持续时间，单位毫秒 | E29: A | G29: sum(duration) | J29: 指标 | K29: ms | L29: >=0
B30: outputoctets | C30: bigint | D30: 上行流量(byte) | E30: A | G30: sum(outputoctets) | J30: 指标 | K30: byte | L30: >=0
B31: inputoctets | C31: bigint | D31: 下行流量(byte) | E31: A | G31: sum(inputoctets) | J31: 指标 | K31: byte | L31: >=0
B32: outputoctets_above500_cnt | C32: bigint | D32: 上行大包条数(>=500KB) | E32: A | G32: sum(outputoctets_above500_cnt) | J32: 指标 | K32: 无 | L32: >=0
B33: inputoctets_above500_cnt | C33: bigint | D33: 下行大包条数(>=500KB) | E33: A | G33: sum(inputoctets_above500_cnt) | J33: 指标 | K33: 无 | L33: >=0
B34: outputpacket | C34: bigint | D34: 上行包数 | E34: A | G34: sum(outputpacket) | J34: 指标 | K34: 无 | L34: >=0
B35: inputpacket | C35: bigint | D35: 下行包数 | E35: A | G35: sum(inputpacket) | J35: 指标 | K35: 无 | L35: >=0
