Workbook
Name DT.10: #REF!
Name DT.11: #REF!
Name vlookup: #REF!
Name 主小区MR详细信息AGPS: #REF!
Name 主小区MR详细信息全量室内外: #REF!

Sheet 0
A1: p_date | B1: p_hour | C1: p_quarter | D1: 类型 | E1: 维度 | F1: 维度说明 | G1: 省份 | H1: 汇聚后记录数 | I1: 时间粒度 | J1: 增加质差定界维度后汇聚记录数
A2: 45735 | B2: 10 | C2: 0 | D2: dns | E2: 详单数据 | F2: 详单数据 | G2: 110000 | H2: 592369026 | I2: quarter
A3: 45735 | B3: 10 | C3: 0 | D3: dns | E3: interface,supi,msisdn,pei,home_province,rattype,ncgi_ecgi,dnn_apn,upfip,servicetype,gnbip,l4protocol,5qi,nssai_sst,nssai_sd,sourceip_type | F3: 基础全维度(含sourceip_type) | G3: 110000 | H3: 48687010 | I3: quarter
A4: 45735 | B4: 10 | C4: 0 | D4: dns | E4: interface,supi,msisdn,pei,home_province,rattype,ncgi_ecgi,dnn_apn,upfip,servicetype,gnbip,l4protocol,5qi,nssai_sst,nssai_sd | F4: 基础全维度(不含sourceip_type) | G4: 110000 | H4: 45759090 | I4: quarter
A5: 45735 | B5: 10 | C5: 0 | D5: dns | E5: usr|app|cel | F5: 用户小区app | G5: 110000 | H5: 37997730 | I5: quarter
A6: 45735 | B6: 10 | C6: / | D6: dns | E6: interface,supi,msisdn,pei,home_province,rattype,ncgi_ecgi,dnn_apn,upfip,servicetype,gnbip,l4protocol,5qi,nssai_sst,nssai_sd,sourceip_type | F6: 基础全维度(含sourceip_type) | G6: 110000 | H6: 155526310 | I6: hour
A7: 45735 | B7: 10 | C7: / | D7: dns | E7: usr|app|cel | F7: 用户小区app | G7: 110000 | H7: 110357808 | I7: hour
A8: 45735 | B8: 10 | C8: 0 | D8: other | E8: 详单数据 | F8: 详单数据 | G8: 110000 | H8: 398259579 | I8: quarter
A9: 45735 | B9: 10 | C9: 0 | D9: other | E9: interface,supi,msisdn,pei,home_province,rattype,ncgi_ecgi,dnn_apn,upfip,servicetype,gnbip,l4protocol,5qi,nssai_sst,nssai_sd,sourceip_type | F9: 基础全维度(含sourceip_type) | G9: 110000 | H9: 37922501 | I9: quarter | J9: 40308104 | K9: =J9/H9 -> 1.0629073
A10: 45735 | B10: 10 | C10: 0 | D10: other | E10: interface,supi,msisdn,pei,home_province,rattype,ncgi_ecgi,dnn_apn,upfip,servicetype,gnbip,l4protocol,5qi,nssai_sst,nssai_sd | F10: 基础全维度(不含sourceip_type) | G10: 110000 | H10: 30356434 | I10: quarter
A11: 45735 | B11: 10 | C11: 0 | D11: other | E11: usr|app|cel | F11: 用户小区app | G11: 110000 | H11: 18777303 | I11: quarter
A12: 45735 | B12: 10 | C12: / | D12: other | E12: interface,supi,msisdn,pei,home_province,rattype,ncgi_ecgi,dnn_apn,upfip,servicetype,gnbip,l4protocol,5qi,nssai_sst,nssai_sd,sourceip_type | F12: 基础全维度(含sourceip_type) | G12: 110000 | H12: 111340755 | I12: hour
A13: 45735 | B13: 10 | C13: / | D13: other | E13: usr|app|cel | F13: 用户小区app | G13: 110000 | H13: 46973226 | I13: hour
A14: 45735 | B14: 10 | C14: / | D14: http | E14: interface,supi,msisdn,pei,home_province,rattype,ncgi_ecgi,dnn_apn,upfip,servicetype,gnbip,l4protocol,5qi,nssai_sst,nssai_sd,sourceip_type | F14: 基础全维度(含sourceip_type) | G14: 110000 | H14: 50135986 | I14: hour
A15: 45735 | B15: 10 | C15: / | D15: http | E15: usr|app|cel | F15: 用户小区app | G15: 110000 | H15: 30660131 | I15: hour
A16: 45735 | B16: 10 | C16: / | D16: https | E16: interface,supi,msisdn,pei,home_province,rattype,ncgi_ecgi,dnn_apn,upfip,servicetype,gnbip,l4protocol,5qi,nssai_sst,nssai_sd,sourceip_type | F16: 基础全维度(含sourceip_type) | G16: 110000 | H16: 146683745 | I16: hour
A17: 45735 | B17: 10 | C17: / | D17: https | E17: usr|app|cel | F17: 用户小区app | G17: 110000 | H17: 90059602 | I17: hour
A18: 45735 | B18: 10 | C18: / | D18: video | E18: interface,supi,msisdn,pei,home_province,rattype,ncgi_ecgi,dnn_apn,upfip,servicetype,gnbip,l4protocol,5qi,nssai_sst,nssai_sd,video_resolution,video_type,sourceip_type | F18: 基础全维度(含sourceip_type) | G18: 110000 | H18: 4946010 | I18: hour
A19: 45735 | B19: 10 | C19: / | D19: video | E19: usr|app|cel | F19: 用户小区app | G19: 110000 | H19: 2467043 | I19: hour
A20: 45735 | B20: 10 | C20: / | D20: N1N2 | E20: p_date,p_hour,p_provincecode,interface,supi,pei,msisdn,rat,home_province,amf_ip_add,gnb_ip_add,other_cell_id,s_nssai_sst,s_nssai_sd,ci,pdu_session_dnn,procedure_type,procedure_status,problem_demarcation,problem_position,failure_cause_type,failure_cause,keyword | F20: 基础全维度(增加procedure_type,procedure_status,keyword,failure_cause_type,failure_cause,问题定界,问题定位维度) | G20: 110000 | H20: 85862767 | I20: hour | J20: =H20/H23 -> 1.717041 | K20: 285973344 | L20: =K20/H20 -> 3.3305862
A21: 45735 | B21: 10 | C21: / | D21: N1N2 | E21: p_date,p_hour,p_provincecode,interface,supi,pei,msisdn,rat,home_province,amf_ip_add,gnb_ip_add,other_cell_id,s_nssai_sst,s_nssai_sd,ci,pdu_session_dnn,procedure_type,procedure_status,problem_demarcation,problem_position,failure_cause_type,failure_cause | F21: 基础全维度(增加procedure_type,procedure_status,failure_cause_type,failure_cause,问题定界,问题定位维度) | G21: 110000 | H21: 81525903 | I21: hour
A22: 45735 | B22: 10 | C22: / | D22: N1N2 | E22: interface,supi,pei,msisdn,rat,home_province,amf_ip_add,gnb_ip_add,other_cell_id,s_nssai_sst,s_nssai_sd,ci,pdu_session_dnn | F22: 基础全维度(增加procedure_type,procedure_status维度) | G22: 110000 | H22: 76910353 | I22: hour
A23: 45735 | B23: 10 | C23: / | D23: N1N2 | E23: interface,supi,pei,msisdn,rat,home_province,amf_ip_add,gnb_ip_add,other_cell_id,s_nssai_sst,s_nssai_sd,ci,pdu_session_dnn | F23: 基础全维度 | G23: 110000 | H23: 50006242 | I23: hour
A24: 45735 | B24: 10 | C24: / | D24: N1N2 | E24: interface,supi,pei,msisdn,home_province,ci | F24: 用户小区 | G24: 110000 | H24: 26938820 | I24: hour

Sheet Sheet1
A1: 表英文名 | B1: 表中文名 | C1: 最小时间分区 | D1: 计算位置 | E1: 是否同步 | F1: 生命周期（存储周期单位：天） | G1: 备注
A2: aggr_nr_dpi_dns_base_q | B2: 5G_DPI_dns基础维度15分钟表 | C2: 15分钟 | D2: 前置 | E2: 是 | F2: 前置：7；核心：14
A3: aggr_nr_dpi_dns_usrappcel_q | B3: 5G_DPI_dns用户小区app维度15分钟表 | C3: 15分钟 | D3: 核心 | E3: / | F3: 14
A4: aggr_nr_dpi_dns_base_h | B4: 5G_DPI_dns基础维度小时表 | C4: 小时 | D4: 核心 | E4: / | F4: 14
A5: aggr_nr_usrarea_dns_cel_refactor_d | B5: 5G_DPI_dns用户小区区域维度天表 | C5: 天 | D5: 核心 | E5: / | F5: 30
A6: aggr_nr_dpi_dns_usrcel_h | B6: 5G_DPI_dns用户小区维度小时表 | C6: 小时 | D6: 核心 | E6: / | F6: 14
A7: aggr_nr_dpi_dns_cel_h | B7: 5G_DPI_dns小区维度小时表 | C7: 小时 | D7: 核心 | E7: / | F7: 14
A8: aggr_nr_dpi_dns_cel_d | B8: 5G_DPI_dns小区维度天表 | C8: 天 | D8: 核心 | E8: / | F8: 30
A9: aggr_nr_dpi_other_base_q | B9: 5G_DPI_other基础维度15分钟表 | C9: 15分钟 | D9: 前置 | E9: 是 | F9: 前置：7；核心：14
A10: aggr_nr_dpi_other_base_h | B10: 5G_DPI_other基础维度小时表 | C10: 小时 | D10: 核心 | E10: / | F10: 14
A11: aggr_nr_dpi_other_base_reduce_h | B11: 5G_DPI_other基础维度共享小时表 | C11: 小时 | D11: 核心 | E11: / | F11: 14
A12: aggr_nr_other_usrappcel_h | B12: 5G_DPI_other用户小区app维度小时表 | C12: 小时 | D12: 核心 | E12: / | F12: 14
A13: aggr_nr_iov_other_usrappcel_refactor_h | B13: 车联网用户5G_DPI_other用户小区app维度小时表 | C13: 小时 | D13: 核心 | E13: / | F13: 14
A14: fact_nr_dpi_n1n2_q | B14: 5G_DPI_N1N2整合层15分钟表 | C14: 15分钟 | D14: 前置 | E14: 否 | F14: 3
A15: aggr_nr_dpi_n1n2_base_q | B15: 5G_DPI_N1N2基础维度15分钟汇聚表(含定界定位) | C15: 15分钟 | D15: 前置 | E15: 是 | F15: 前置：7；核心：14
A16: aggr_nr_resident_usrcel_h | B16: 5G_DPI_N1N2用户驻留小区小时表 | C16: 小时 | D16: 核心 | E16: / | F16: 14
A17: aggr_nr_resident_usrcel_d | B17: 5G_DPI_N1N2用户驻留小区天表 | C17: 天 | D17: 核心 | E17: / | F17: 30
A18: aggr_nr_resident_usrcel_wd | B18: 5G_DPI_N1N2用户常驻小区滚动周表 | C18: 天 | D18: 核心 | E18: / | F18: 30
A19: aggr_nr_dpi_n1n2_failcause_base_h | B19: N1N2接口失败原因基础小时表 | C19: 小时 | D19: 核心 | E19: / | F19: 14
A20: aggr_nr_n1n2_failcause_base_refactor_h | B20: N1N2接口失败原因基础共享小时表 | C20: 小时 | D20: 核心 | E20: / | F20: 14
A21: aggr_nr_dpi_n1n2_base_h | B21: 5G_DPI_N1N2基础维度小时汇聚表(无定界定位) | C21: 小时 | D21: 核心 | E21: / | F21: 14
A22: aggr_nr_dpi_n1n2_index_reduce_base_h | B22: 5G_DPI_N1N2基础维度指标裁剪共享小时表 | C22: 小时 | D22: 核心 | E22: / | F22: 14
A23: aggr_nr_dpi_n1n2_usrcel_h | B23: 5G_DPI_N1N2用户小区维度小时表 | C23: 小时 | D23: 核心 | E23: / | F23: 14
A24: aggr_nr_iov_attach_usrcel_refactor_h | B24: 车联网用户5G_DPI_N1N2用户小区维度附着指标小时表 | C24: 小时 | D24: 核心 | E24: / | F24: 14
A25: aggr_nr_dpi_n1n2_usrcel_d | B25: 5G_DPI_N1N2用户小区维度天表 | C25: 小时 | D25: 核心 | E25: / | F25: 30
A26: aggr_nr_dpi_n1n2_cel_d | B26: 5G_DPI_N1N2小区维度天表 | C26: 天 | D26: 核心 | E26: / | F26: 30
A27: aggr_nr_dpi_n1n2_usr_d | B27: 5G_DPI_N1N2用户维度天表 | C27: 天 | D27: 核心 | E27: / | F27: 30
A28: aggr_nr_copycard_usrgnb_refactor_h | B28: 反诈复制卡用户接入基站清单 | C28: 小时 | D28: 核心 | E28: / | F28: 360 | G28: 数据量很小，反诈要求保存时间长
A29: fact_5g_user_ci_list_refactor_h | B29: 5G DPI主要接口用户小区小时表 | C29: 小时 | D29: 核心 | E29: / | F29: 14

Sheet 导航
A1: 内部编号 | B1: 索引 | C1: 项目名称 | D1: 数据层级 | E1: 主题域 | F1: 表英文名 | G1: 表中文名 | H1: 数据描述 | I1: 汇聚维度 | J1: 数据时间粒度 | K1: 最小时间分区 | L1: 计算位置 | M1: 是否同步 | N1: 生命周期（存储周期单位：天） | O1: 前向表 | P1: 支撑应用/系统 | Q1: 新建/升级 | R1: 备注 | S1: 同步数据库
A2: 1 | B2: =HYPERLINK("#"&A2&"!A1",A2) -> 1 | C2: 网络数据处理系统 | D2: 中间层 | E2: 数据感知 | F2: aggr_nr_dpi_dns_base_q | G2: 5G_DPI_dns基础维度15分钟表 | H2: 5G_DPI_dns基础维度15分钟表 | I2: 用户|小区|app|dnn|切片|源IP类型 | J2: 15分钟 | K2: 15分钟 | L2: 前置 | M2: 是 | N2: 7 | O2: ods_5gdpi_dns_e2e_telecom_origin_q、fact_nr_cm_projdata、lte_cm_projdata、lte_cucc_cm_projdata | Q2: 新建
A3: 0.1 | B3: =HYPERLINK("#"&A3&"!A1",A3) -> 0.1 | C3: 网络数据处理系统 | D3: 整合层 | E3: / | F3: fact_5gdpi_n1n2_customweb_e2e_telecom_h | G3: SA控制面N1N2接口事实表 | H3: =G3 -> SA控制面N1N2接口事实表 | O3: ods_5gdpi_n1n2_e2e_telecom_5min | Q3: 无变更
A4: 0.2 | B4: =HYPERLINK("#"&A4&"!A1",A4) -> 0.2 | C4: 网络数据处理系统 | D4: 整合层 | E4: / | F4: fact_5gdpi_n26_customweb_e2e_telecom_h | G4: SA控制面N26接口事实表 | H4: =G4 -> SA控制面N26接口事实表 | O4: ods_5gdpi_n26_e2e_telecom_q | Q4: 无变更
A5: 0.3 | B5: =HYPERLINK("#"&A5&"!A1",A5) -> 0.3 | C5: 网络数据处理系统 | D5: 整合层 | E5: / | F5: fact_5gdpi_https_customweb_e2e_telecom_h | G5: SA用户面https定制网事实表 | H5: =G5 -> SA用户面https定制网事实表 | O5: ods_5gdpi_https_e2e_telecom_q | Q5: 无变更
A6: 0.4 | B6: =HYPERLINK("#"&A6&"!A1",A6) -> 0.4 | C6: 网络数据处理系统 | D6: 整合层 | E6: / | F6: fact_5gdpi_http_customweb_e2e_telecom_h | G6: SA用户面http定制网事实表 | H6: =G6 -> SA用户面http定制网事实表 | O6: ods_5gdpi_http_e2e_telecom_origin_q | Q6: 无变更
A7: 0.5 | B7: =HYPERLINK("#"&A7&"!A1",A7) -> 0.5 | C7: 网络数据处理系统 | D7: 整合层 | E7: / | F7: fact_5gdpi_email_customweb_e2e_telecom_h | G7: SA用户面email定制网事实表 | H7: =G7 -> SA用户面email定制网事实表 | O7: ods_5gdpi_email_e2e_telecom_q | Q7: 无变更
A8: 0.6 | B8: =HYPERLINK("#"&A8&"!A1",A8) -> 0.6 | C8: 网络数据处理系统 | D8: 整合层 | E8: / | F8: fact_5gdpi_dns_customweb_e2e_telecom_h | G8: SA用户面dns定制网事实表 | H8: =G8 -> SA用户面dns定制网事实表 | O8: ods_5gdpi_dns_e2e_telecom_origin_q | Q8: 无变更
A9: 0.7 | B9: =HYPERLINK("#"&A9&"!A1",A9) -> 0.7 | C9: 网络数据处理系统 | D9: 整合层 | E9: / | F9: fact_5gdpi_coap_customweb_e2e_telecom_h | G9: SA用户面coap定制网事实表 | H9: =G9 -> SA用户面coap定制网事实表 | O9: ods_5gdpi_coap_e2e_telecom_q | Q9: 无变更
A10: 0.8 | B10: =HYPERLINK("#"&A10&"!A1",A10) -> 0.8 | C10: 网络数据处理系统 | D10: 整合层 | E10: / | F10: fact_5gdpi_ftp_customweb_e2e_telecom_h | G10: SA用户面ftp定制网事实表 | H10: =G10 -> SA用户面ftp定制网事实表 | O10: ods_5gdpi_ftp_e2e_telecom_q | Q10: 无变更
A11: 0.9 | B11: =HYPERLINK("#"&A11&"!A1",A11) -> 0.9 | C11: 网络数据处理系统 | D11: 整合层 | E11: / | F11: fact_5gdpi_mqtt_customweb_e2e_telecom_h | G11: SA用户面mqtt定制网事实表 | H11: =G11 -> SA用户面mqtt定制网事实表 | O11: ods_5gdpi_mqtt_e2e_telecom_q | Q11: 无变更
A12: 1.2 | B12: =HYPERLINK("#"&A12&"!A1",A12) -> 1.2 | C12: 网络数据处理系统 | D12: 整合层 | E12: / | F12: fact_5gdpi_other_customweb_e2e_telecom_h | G12: SA用户面other定制网事实表 | H12: =G12 -> SA用户面other定制网事实表 | O12: ods_5gdpi_other_e2e_telecom_q | Q12: 无变更
A13: 1.3 | B13: =HYPERLINK("#"&A13&"!A1",A13) -> 1.3 | C13: 网络数据处理系统 | D13: 整合层 | E13: / | F13: fact_5gdpi_video_customweb_e2e_telecom_h | G13: SA用户面video定制网事实表 | H13: =G13 -> SA用户面video定制网事实表 | O13: ods_5gdpi_video_e2e_telecom_origin_q | Q13: 无变更
A14: 1.4 | B14: =HYPERLINK("#"&A14&"!A1",A14) -> 1.4 | C14: 网络数据处理系统 | D14: 整合层 | E14: / | F14: fact_5gdpi_game_customweb_e2e_telecom_h | G14: SA用户面game定制网事实表 | H14: =G14 -> SA用户面game定制网事实表 | O14: ods_5gdpi_game_e2e_telecom_q | Q14: 无变更
A15: 1.1 | B15: =HYPERLINK("#"&A15&"!A1",A15) -> 1.1 | C15: 网络数据处理系统 | D15: 中间层 | E15: 数据感知 | F15: aggr_nr_dpi_dns_usrappcel_q | G15: 5G_DPI_dns用户小区app维度15分钟表 | H15: 5G_DPI_dns用户小区app维度15分钟表 | I15: 用户|小区|app | J15: 15分钟 | K15: 15分钟 | L15: 核心 | M15: / | N15: 14 | O15: aggr_nr_dpi_dns_base_q | Q15: 新建
A16: 2 | B16: =HYPERLINK("#"&A16&"!A1",A16) -> 2 | C16: 网络数据处理系统 | D16: 中间层 | E16: 数据感知 | F16: aggr_nr_dpi_dns_base_h | G16: 5G_DPI_dns基础维度小时表 | H16: 5G_DPI_dns基础维度小时表 | I16: 用户|小区|app|dnn|切片|源IP类型 | J16: 小时 | K16: 小时 | L16: 核心 | M16: / | N16: 14 | O16: aggr_nr_dpi_dns_base_q | P16: 移动业务感知保障系统 | Q16: 新建 | R16: 对应共享给移动业务感知保障系统aggr_5gdpi_dns_e2e_telecom_share_h
A17: 3 | B17: =HYPERLINK("#"&A17&"!A1",A17) -> 3 | C17: 网络数据处理系统 | D17: 中间层 | E17: 用户级感知 | F17: aggr_nr_usrarea_dns_cel_refactor_d | G17: 5G_DPI_dns用户小区区域维度天表 | H17: 5G_DPI_dns用户小区区域维度天表 | I17: 用户|小区|app|区域 | J17: 15分钟 | K17: 天 | L17: 核心 | M17: / | N17: 30 | O17: aggr_nr_usrareatime_cel_refactor_d、aggr_nr_dpi_dns_usrappcel_q | P17: 建维优 | Q17: 新建(升级) | R17: 只上线用户级感知省份，对应现网aggr_nr_usrarea_dns_cel_d表，字段名称未修改，与现网表字段名称一致
A18: 4 | B18: =HYPERLINK("#"&A18&"!A1",A18) -> 4 | C18: 网络数据处理系统 | D18: 中间层 | E18: 数据感知 | F18: aggr_nr_dpi_dns_usrcel_h | G18: 5G_DPI_dns用户小区维度小时表 | H18: 5G_DPI_dns用户小区维度小时表 | I18: 用户|小区 | J18: 小时 | K18: 小时 | L18: 核心 | M18: / | N18: 14 | O18: aggr_nr_dpi_dns_base_h | Q18: 新建
A19: 5 | B19: =HYPERLINK("#"&A19&"!A1",A19) -> 5 | C19: 网络数据处理系统 | D19: 中间层 | E19: 数据感知 | F19: aggr_nr_dpi_dns_cel_h | G19: 5G_DPI_dns小区维度小时表 | H19: 5G_DPI_dns小区维度小时表 | I19: 小区 | J19: 小时 | K19: 小时 | L19: 核心 | M19: / | N19: 14 | O19: aggr_nr_dpi_dns_usrcel_h | Q19: 新建
A20: 6 | B20: =HYPERLINK("#"&A20&"!A1",A20) -> 6 | C20: 网络数据处理系统 | D20: 中间层 | E20: 数据感知 | F20: aggr_nr_dpi_dns_cel_d | G20: 5G_DPI_dns小区维度天表 | H20: 5G_DPI_dns小区维度天表 | I20: 小区 | J20: 天 | K20: 天 | L20: 核心 | M20: / | N20: 30 | O20: aggr_nr_dpi_dns_cel_h | Q20: 新建 | R20: 对应共享给5GR的表aggr_5gdpi_dns_e2e_telecom_share_d，字段名称与表结构已调整，字段与现网对应关系已标记
A21: 7 | B21: =HYPERLINK("#"&A21&"!A1",A21) -> 7 | C21: 网络数据处理系统 | D21: 中间层 | E21: 数据感知 | F21: aggr_nr_dpi_other_base_q | G21: 5G_DPI_other基础维度15分钟表 | H21: 5G_DPI_other基础维度15分钟表 | I21: 用户|小区|app|dnn|切片|源IP类型 | J21: 15分钟 | K21: 15分钟 | L21: 前置 | M21: 是 | N21: 7 | O21: ods_5gdpi_other_e2e_telecom_q、fact_nr_cm_projdata、lte_cm_projdata、lte_cucc_cm_projdata | Q21: 新建
A22: 8 | B22: =HYPERLINK("#"&A22&"!A1",A22) -> 8 | C22: 网络数据处理系统 | D22: 中间层 | E22: 数据感知 | F22: aggr_nr_dpi_other_base_h | G22: 5G_DPI_other基础维度小时表 | H22: 5G_DPI_other基础维度小时表 | I22: 用户|小区|app|dnn|切片|源IP类型|定界|切片 | J22: 小时 | K22: 小时 | L22: 核心 | M22: / | N22: 14 | O22: aggr_nr_dpi_other_base_q | Q22: 新建
A23: 8.1 | B23: =HYPERLINK("#"&A23&"!A1",A23) -> 8.1 | C23: 网络数据处理系统 | D23: 中间层 | E23: 数据感知 | F23: aggr_nr_dpi_other_base_reduce_h | G23: 5G_DPI_other基础维度共享小时表 | H23: 5G_DPI_other基础维度共享小时表 | I23: 用户|小区|app|dnn|切片|源IP类型 | J23: 小时 | K23: 小时 | L23: 核心 | M23: / | N23: 14 | O23: aggr_nr_dpi_other_base_h | Q23: 新建(升级) | R23: 对应共享给移动业务感知保障系统aggr_5gdpi_other_base_h，字段名称与现网一致,表结构存在字段删减
A24: 9 | B24: =HYPERLINK("#"&A24&"!A1",A24) -> 9 | C24: 网络数据处理系统 | D24: 中间层 | E24: 数据感知 | F24: aggr_nr_other_usrappcel_h | G24: 5G_DPI_other用户小区app维度小时表 | H24: 5G_DPI_other用户小区app维度小时表 | I24: 用户|小区|app | J24: 小时 | K24: 小时 | L24: 核心 | M24: / | N24: 14 | O24: aggr_nr_dpi_other_base_h | Q24: 新建
A25: 10 | B25: =HYPERLINK("#"&A25&"!A1",A25) -> 10 | C25: 网络数据处理系统 | D25: 中间层 | E25: 数据感知 | F25: aggr_nr_iov_other_usrappcel_refactor_h | G25: 车联网用户5G_DPI_other用户小区app维度小时表 | H25: 车联网用户5G_DPI_other用户小区app维度小时表 | I25: 用户|小区|app | J25: 小时 | K25: 小时 | L25: 核心 | M25: / | N25: 14 | O25: aggr_nr_other_usrappcel_h、cfg_dpi_servicetype、cfg_iov_usr_list | Q25: 新建(升级) | R25: 对应共享给车联网aggr_nr_iov_other_usrappcel_h，字段名称及表结构与现网一致
A26: 11.1 | B26: =HYPERLINK("#"&A26&"!A1",A26) -> 11.1 | C26: 网络数据处理系统 | D26: 维度层 | E26: 信令感知 | F26: cfg_n1n2_cause_code_list | G26: n1n2定界定位编码表 | H26: n1n2定界定位编码表 | I26: / | J26: / | K26: / | L26: 前置 | M26: 否 | N26: / | O26: / | Q26: 升级 | R26: 现网表结构已存在，但数据有重复，需对数据删除重复项
A27: 11.2 | B27: =HYPERLINK("#"&A27&"!A1",A27) -> 11.2 | C27: 网络数据处理系统 | D27: 维度层 | E27: 信令感知 | F27: cfg_n1n2_keyword_type | G27: n1n2关键字编码 | H27: n1n2关键字编码 | I27: / | J27: / | K27: / | L27: 前置 | M27: 否 | N27: / | O27: / | Q27: 升级
A28: 11.3 | B28: =HYPERLINK("#"&A28&"!A1",A28) -> 11.3 | C28: 网络数据处理系统 | D28: 维度层 | E28: 信令感知 | F28: cfg_45g_procedure_type | G28: 45G流程码维表 | H28: 45G流程码维表 | I28: / | J28: / | K28: / | L28: 前置 | M28: 否 | N28: / | O28: / | Q28: 升级
A29: 11 | B29: =HYPERLINK("#"&A29&"!A1",A29) -> 11 | C29: 网络数据处理系统 | D29: 整合层 | E29: / | F29: fact_nr_dpi_n1n2_q | G29: 5G_DPI_N1N2整合层15分钟表 | H29: 5G_DPI_N1N2整合层15分钟表 | I29: 详单 | J29: 15分钟 | K29: 15分钟 | L29: 前置 | M29: 否 | N29: 3 | O29: ods_5gdpi_n1n2_e2e_telecom_5min、cfg_45g_procedure_type、cfg_n1n2_cause_code_list、cfg_n1n2_keyword_type、fact_nr_cm_projdata | Q29: 新建
A30: 12 | B30: =HYPERLINK("#"&A30&"!A1",A30) -> 12 | C30: 网络数据处理系统 | D30: 中间层 | E30: 信令感知 | F30: aggr_nr_dpi_n1n2_base_q | G30: 5G_DPI_N1N2基础维度15分钟汇聚表(含定界定位) | H30: 5G_DPI_N1N2基础维度15分钟汇聚表(含定界定位) | I30: 用户|小区|DNN|切片|切换目标小区|流程编码|流程状态|失败原因|keyword|定界|定位 | J30: 15分钟 | K30: 15分钟 | L30: 前置 | M30: 是 | N30: 7 | O30: fact_nr_dpi_n1n2_q | Q30: 新建
A31: 13 | B31: =HYPERLINK("#"&A31&"!A1",A31) -> 13 | C31: 网络数据处理系统 | D31: 中间层 | E31: 用户常驻 | F31: aggr_nr_resident_usrcel_h | G31: 5G_DPI_N1N2用户驻留小区小时表 | H31: 5G_DPI_N1N2用户驻留小区小时表 | I31: 用户|小区 | J31: 小时 | K31: 小时 | L31: 核心 | M31: / | N31: 14 | O31: aggr_nr_dpi_n1n2_base_q、cfg_city | Q31: 新建 | R31: 对应现网aggr_5g_resident_celusr_h
A32: 14 | B32: =HYPERLINK("#"&A32&"!A1",A32) -> 14 | C32: 网络数据处理系统 | D32: 中间层 | E32: 用户常驻 | F32: aggr_nr_resident_usrcel_d | G32: 5G_DPI_N1N2用户驻留小区天表 | H32: 5G_DPI_N1N2用户驻留小区天表 | I32: 用户|小区 | J32: 天 | K32: 天 | L32: 核心 | M32: / | N32: 30 | O32: aggr_nr_resident_usrcel_h | Q32: 新建 | R32: 对应现网aggr_5g_resident_celusr_d
A33: 15 | B33: =HYPERLINK("#"&A33&"!A1",A33) -> 15 | C33: 网络数据处理系统 | D33: 中间层 | E33: 用户常驻 | F33: aggr_nr_resident_usrcel_wd | G33: 5G_DPI_N1N2用户常驻小区滚动周表 | H33: 5G_DPI_N1N2用户常驻小区滚动周表 | I33: 用户|小区 | J33: 天 | K33: 天 | L33: 核心 | M33: / | N33: 30 | O33: aggr_nr_resident_usrcel_d | Q33: 新建 | R33: 对应现网共享核心系统的aggr_5g_resident_celusr_w，字段名称存在变更（字段顺序无变化，相同含义的字段依然占据相同位置），字段与现网对应关系已标记
A34: 16 | B34: =HYPERLINK("#"&A34&"!A1",A34) -> 16 | C34: 网络数据处理系统 | D34: 中间层 | E34: 信令感知 | F34: aggr_nr_dpi_n1n2_failcause_base_h | G34: N1N2接口失败原因基础小时表 | H34: N1N2接口失败原因基础小时表 | I34: 用户|小区|DNN|切片|切换目标小区|流程编码|流程状态|失败原因|keyword|定界|定位 | J34: 小时 | K34: 小时 | L34: 核心 | M34: / | N34: 14 | O34: aggr_nr_dpi_n1n2_base_q | Q34: 新建
A35: 17 | B35: =HYPERLINK("#"&A35&"!A1",A35) -> 17 | C35: 网络数据处理系统 | D35: 中间层 | E35: 信令感知 | F35: aggr_nr_n1n2_failcause_base_refactor_h | G35: N1N2接口失败原因基础共享小时表 | H35: N1N2接口失败原因基础共享小时表 | I35: 用户|小区|DNN|切片|流程编码|失败原因 | J35: 小时 | K35: 小时 | L35: 核心 | M35: / | N35: 14 | O35: aggr_nr_dpi_n1n2_failcause_base_h | Q35: 新建(升级) | R35: 对应共享给移动业务感知保障系统aggr_nr_n1n2_failcause_base_h，字段名称及表结构无变化
A36: 18 | B36: =HYPERLINK("#"&A36&"!A1",A36) -> 18 | C36: 网络数据处理系统 | D36: 中间层 | E36: 信令感知 | F36: aggr_nr_dpi_n1n2_base_h | G36: 5G_DPI_N1N2基础维度小时汇聚表(无定界定位) | H36: 5G_DPI_N1N2基础维度小时汇聚表(无定界定位) | I36: 用户|小区|DNN|切片|切换目标小区 | J36: 小时 | K36: 小时 | L36: 核心 | M36: / | N36: 14 | O36: aggr_nr_dpi_n1n2_base_q、cfg_city | Q36: 新建
A37: 19 | B37: =HYPERLINK("#"&A37&"!A1",A37) -> 19 | C37: 网络数据处理系统 | D37: 中间层 | E37: 信令感知 | F37: aggr_nr_dpi_n1n2_index_reduce_base_h | G37: 5G_DPI_N1N2基础维度指标裁剪共享小时表 | H37: 5G_DPI_N1N2基础维度指标裁剪共享小时表 | I37: 用户|小区|DNN|切片|切换目标小区 | J37: 小时 | K37: 小时 | L37: 核心 | M37: / | N37: 14 | O37: aggr_nr_dpi_n1n2_base_h | Q37: 新建(升级) | R37: 对应共享给移动业务感知保障系统aggr_5gdpi_n1n2_multi_reduce_h，字段名称及表结构无变化
A38: 20 | B38: =HYPERLINK("#"&A38&"!A1",A38) -> 20 | C38: 网络数据处理系统 | D38: 中间层 | E38: 信令感知 | F38: aggr_nr_dpi_n1n2_usrcel_h | G38: 5G_DPI_N1N2用户小区维度小时表 | H38: 5G_DPI_N1N2用户小区维度小时表 | I38: 用户|小区 | J38: 小时 | K38: 小时 | L38: 核心 | M38: / | N38: 14 | O38: aggr_nr_dpi_n1n2_base_h | Q38: 新建
A39: 21 | B39: =HYPERLINK("#"&A39&"!A1",A39) -> 21 | C39: 网络数据处理系统 | D39: 中间层 | E39: 信令感知 | F39: aggr_nr_iov_attach_usrcel_refactor_h | G39: 车联网用户5G_DPI_N1N2用户小区维度附着指标小时表 | H39: 车联网用户5G_DPI_N1N2用户小区维度附着指标小时表 | I39: 用户|小区 | J39: 小时 | K39: 小时 | L39: 核心 | M39: / | N39: 14 | O39: aggr_nr_dpi_n1n2_usrcel_h、cfg_iov_usr_list | Q39: 新建(升级) | R39: 对应共享给车联网aggr_nr_iov_attach_usrcel_h，字段名称及表结构无变化
A40: 22 | B40: =HYPERLINK("#"&A40&"!A1",A40) -> 22 | C40: 网络数据处理系统 | D40: 中间层 | E40: 信令感知 | F40: aggr_nr_dpi_n1n2_usrcel_d | G40: 5G_DPI_N1N2用户小区维度天表 | H40: 5G_DPI_N1N2小区维度小时表 | I40: 小区 | J40: 小时 | K40: 小时 | L40: 核心 | M40: / | N40: 30 | O40: aggr_nr_dpi_n1n2_usrcel_h | Q40: 新建
...

Sheet 1
B1: =HYPERLINK("#导航!a2","返回") -> 返回
B3: 目标表基本信息描述
B4: 主题域 | C4: 目标表英文名 | D4: 目标表中文名 | E4: 数据频度 | F4: 模型主键 | G4: 数据描述 | H4: 推送数据库
B5: 数据感知 | C5: aggr_nr_dpi_dns_base_q | D5: 5G_DPI_dns基础维度15分钟表 | E5: quarter
B7: 源表基本信息描述
B8: 来源系统 | C8: 源表英文名 | D8: 源表中文名 | E8: 别名 | F8: 任务描述 | G8: 备注 | H8: 是否主表
C9: ods_5gdpi_dns_e2e_telecom_origin_q | D9: 5G_DPI_dns贴源层详单表 | E9: A | H9: 是
C10: fact_nr_cm_projdata | D10: 5G电联工参 | E10: B1 | G10: 按照cellkey去重后关联
C11: lte_cm_projdata | D11: 4G电信工参 | E11: B2 | G11: 按照reportcellkey去重后关联
C12: lte_cucc_cm_projdata | D12: 4G联通工参 | E12: B3 | G12: 按照cellkey去重后关联
B14: 详细字段信息
B15: 详细字段信息
B16: PDM字段英文名 | C16: PDM字段类型 | D16: PDM字段中文名（说明） | E16: 源表名 | F16: 源字段英文名 | G16: 算法加工逻辑 | H16: 关联与过滤条件 | I16: 备注 | J16: 字段属性 | K16: 单位 | L16: 取值范围
B17: day | C17: string | D17: 日期 | E17: A | F17: p_date | G17: 直取 | J17: 维度 | K17: 无 | L17: yyyy-mm-dd
B18: hour | C18: int | D18: 小时 | E18: A | F18: p_hour | G18: 直取 | J18: 维度 | K18: 无 | L18: 0~23
B19: quarter | C19: int | D19: 15分钟 | E19: A | F19: p_quarter | G19: 直取 | J19: 维度 | K19: 无 | L19: 0~3
B20: interface | C20: int | D20: 接口类型 | E20: A | F20: interface | G20: 直取 | J20: 维度 | K20: 无 | L20: <=101
B21: rattype | C21: int | D21: 网络类型（4G：6；5G：10） | E21: A | F21: rattype | G21: 直取 | J21: 维度 | K21: 无 | L21: 6,10
B22: provincecode | C22: int | D22: 省编码 | E22: A | F22: p_provincecode | G22: 直取 | J22: 维度 | K22: 无 | L22: 6位数编码
B23: citycode | C23: int | D23: 市编码 | E23: B1|B2|B3 | F23: citycode | G23: 关联工参回填 | J23: 维度 | K23: 无 | L23: 6位数编码
B24: districtcode | C24: int | D24: 区编码 | E24: B1|B2|B3 | F24: districtcode | G24: 关联工参回填 | J24: 维度 | K24: 无 | L24: 6位数编码
B25: province | C25: string | D25: 省名称 | E25: B1|B2|B3 | F25: B1/B2：province B3：province_name | G25: 关联工参回填 | J25: 维度 | K25: 无 | L25: 无
B26: city | C26: string | D26: 地市名称 | E26: B1|B2|B3 | F26: B1/B2：city B3：city_name | G26: 关联工参回填 | J26: 维度 | K26: 无 | L26: 无
B27: district | C27: string | D27: 区县名称 | E27: B1|B2|B3 | F27: B1/B2：district B3：district_name | G27: 关联工参回填 | J27: 维度 | K27: 无 | L27: 无
B28: cellname | C28: string | D28: 小区名称 | E28: B1|B2|B3 | F28: B1/B2：cellname B3：cell_name | G28: 关联工参回填 | J28: 维度 | K28: 无 | L28: 无
B29: cellkey | C29: string | D29: 小区cellkey | E29: A | G29: case when interface=1 then int(substring(ncgi_ecgi,6)/256) when (interface=100 or interface=101) then int(substring(ncgi_ecgi,6)/4096) else null end as gnbid case when interface=1 then int(substring(ncgi_ecgi,6)%256) when (interface=100 or interface=101) then int(substring(ncgi_ecgi,6)%4096) else null end as cellid | I29: ncgi_ecgi： 4601131689682943 | J29: 维度 | K29: 无 | L29: 无
B30: tai | C30: string | D30: 跟踪区标识 | E30: A | F30: tai | G30: 直取 | I30: tai：460-11-8527873 | J30: 维度 | K30: 无 | L30: 无
B31: supi | C31: string | D31: 用户imsi | E31: A | F31: supi | G31: 直取 | J31: 维度 | K31: 无 | L31: 无
B32: msisdn | C32: string | D32: 用户号码 | E32: A | G32: regexp_replace(trim(msisdn),'^86','') | J32: 维度 | K32: 无 | L32: 无
B33: pei | C33: string | D33: 用户终端 | E33: A | F33: pei | G33: 直取 | J33: 维度 | K33: 无 | L33: 无
B34: dnn_apn | C34: string | D34: 网络接入技术 | E34: A | F34: dnn_apn | G34: 直取 | J34: 维度 | K34: 无 | L34: 无
B35: upfip | C35: string | D35: UPF的IPv4或IPv6地址 | E35: A | F35: upfip | G35: 直取 | J35: 维度 | K35: 无 | L35: 无
B36: servicetype | C36: string | D36: 业务应用 | E36: A | F36: servicetype | G36: 直取 | J36: 维度 | K36: 无 | L36: 无
B37: gnbip | C37: string | D37: gNB的IPv4或IPv6地址 | E37: A | F37: gnbip | G37: 直取 | J37: 维度 | K37: 无 | L37: 无
B38: home_province | C38: string | D38: 归属省份 | E38: A | F38: home_province | G38: 直取 | J38: 维度 | K38: 无 | L38: 6位数编码
B39: nssai_sst | C39: string | D39: Slice Service Type (SST) | E39: A | F39: nssai_sst | G39: 直取 | J39: 维度 | K39: 无 | L39: 无
B40: nssai_sd | C40: string | D40: Slice Differentiator（SD） | E40: A | F40: nssai_sd | G40: 直取 | J40: 维度 | K40: 无 | L40: 无
B41: l4protocol | C41: int | D41: L4协议类型： 0：TCP；1：UDP | E41: A | F41: l4protocol | G41: 直取 | J41: 维度 | K41: 无 | L41: 0,1
B42: five_qi | C42: int | D42: 服务质量等级标识 | E42: A | F42: 5qi | G42: 直取 | J42: 维度 | K42: 无 | L42: 无
B43: sourceip_type | C43: string | D43: 用户访问外部网络时使用的IP类型（IPv4/IPv6） | E43: A | G43: 根据sourceip字段结果识别 | I43: case when sourceIP regexp '^((25[0-5]|2[0-4]\\d|[01]?\\d\\d?)\\.){3}(25[0-5]|2[0-4]\\d|[01]?\\d\\d?)$' then 'ipv4' when sourceIP regexp '^([\\da-fA-F]{1,4}:){7}[\\da-fA-F]{1,4}$' then 'ipv6' else '' end as sourceip_type | J43: 维度 | K43: 无 | L43: 无
...

Sheet 0.1
B1: =HYPERLINK("#导航!a2","返回") -> 返回
B3: 目标表基本信息描述
B4: 主题域 | C4: 目标表英文名 | D4: 目标表中文名 | E4: 数据频度 | F4: 模型主键 | G4: 数据描述 | H4: 推送数据库
C5: fact_5gdpi_n1n2_customweb_e2e_telecom_h | D5: SA控制面N1N2接口事实表 | E5: hour
B7: 源表基本信息描述
B8: 来源系统 | C8: 源表英文名 | D8: 源表中文名 | E8: 别名 | F8: 任务描述 | G8: 备注 | H8: 是否主表
C9: ods_5gdpi_n1n2_e2e_telecom_5min | D9: 5G_DPI_n1n2贴源层详表 | E9: A | H9: 是
B11: 详细字段信息
B12: 详细字段信息
B13: PDM字段英文名 | C13: PDM字段类型 | D13: PDM字段中文名（说明） | E13: 源表名 | F13: 源字段英文名 | G13: 算法加工逻辑 | H13: 关联与过滤条件 | I13: 备注 | J13: 字段属性 | K13: 单位 | L13: 取值范围
B14: Interface | C14: int | D14: 必填字段。接口类型： 1：S1-U 2：S1-MME 3：S6a 4：S11 6：S5-C 14：L2TP 16：Gm信令面 28：Gm接口VoLTE会话xDR（Gm Session xDR） 29：Gm接口VoLTE切片xDR（Gm Slice xDR） 31：S1-U接口VoLTE切片xDR（S1-U Slice xDR） 35：Radius 50：N1N2 51：N4 52：N5 53：N7 54：N8 55：N10 56：N11 57：N12 58：N14 59：N15 66：N16 60：N22 61：N26 62：N40 63：N13 100：User Plane（5G SA指N3接口） | E14: A | F14: =B14 -> Interface | G14: 直取 | J14: 详单 | K14: 无 | L14: 无
B15: SUPI | C15: string | D15: 永久用户标识。4G 填写用户IMSI。 | E15: A | F15: =B15 -> SUPI | G15: 直取 | J15: 详单 | K15: 无 | L15: 无
B16: MSISDN | C16: string | D16: 用户号码。 | E16: A | F16: =B16 -> MSISDN | G16: 直取 | J16: 详单 | K16: 无 | L16: 无
B17: Procedure_Type | C17: int | D17: 流程类型编码，具体取值如下： 0： Registration 1： De-registration 2： Service Request 3： UE Configuration Update 4： SMS 30： PDU Session Establishment 31： PDU Session Modification 32： PDU Session Release 60： N2 HO Out 61： N2 HO In 62： N2 HO Cancel 63： Xn HO 64： UE Context Release 73： UE Capability Info Indication 74： UE Radio Capability Check 75： Trace Start 76： Deactivate Trace 77： Cell traffic Trace 78： NG Reset 79： Error indication 80： NG Setup 81： RAN Configuration Update 82： AMF Configuration Update 83： Overload Start 84： Overload Stop | E17: A | F17: =B17 -> Procedure_Type | G17: 直取 | J17: 详单 | K17: 无 | L17: 无
B18: Procedure_Start_Time | C18: bigint | D18: 业务流程开始时间，UTC时间，从1970/1/1 00:00:00开始到当前的毫秒数。 | E18: A | F18: =B18 -> Procedure_Start_Time | G18: 直取 | J18: 详单 | K18: 无 | L18: 无
B19: Procedure_End_Time | C19: bigint | D19: 业务流程结束时间，UTC时间，从1970/1/1 00:00:00开始到当前的毫秒数。 | E19: A | F19: =B19 -> Procedure_End_Time | G19: 直取 | J19: 详单 | K19: 无 | L19: 无
B20: Procedure_Status | C20: int | D20: 流程状态 1：成功； 2：失败； 3：超时 | E20: A | F20: =B20 -> Procedure_Status | G20: 直取 | J20: 详单 | K20: 无 | L20: 无
B21: Failure_Cause_Type | C21: int | D21: 标识流程失败响应消息中cause字段所对应的Cause Group。 失败原因类型，对于5G NAS流程： 1：5GMM 2：5GSM 对于NGAP流程： 1：Radio Network Layer 2：Transport Layer 3：NAS 4：Protocol 5：Misc 对于SMS流程： 1：CP Cause 2：RP Cause | E21: A | F21: =B21 -> Failure_Cause_Type | G21: 直取 | J21: 详单 | K21: 无 | L21: 无
B22: Failure_Cause | C22: int | D22: 流程失败响应消息中的值。 CauseValue，规范参见： > 5GMM具体CauseValue取值参见3GPP 24.501第9.11.3.2节Table 9.11.3.2.1； > 5GSM具体CauseValue取值参见3GPP 24.501第9.11.4.2节Table 9.11.4.2.1； > NGAP具体CauseValue取值参见3GPP 38.413第9.3.1.2节； 详见5.3.2.2.16 | E22: A | F22: =B22 -> Failure_Cause | G22: 直取 | J22: 详单 | K22: 无 | L22: 无
B23: AMF_IP_Add | C23: string | D23: AMF信令面的IP地址； | E23: A | F23: =B23 -> AMF_IP_Add | G23: 直取 | J23: 详单 | K23: 无 | L23: 无
B24: gNB_IP_Add | C24: string | D24: gNodeB信令面的IP地址； | E24: A | F24: =B24 -> gNB_IP_Add | G24: 直取 | J24: 详单 | K24: 无 | L24: 无
B25: PDU_Session_DNN | C25: string | D25: 第1个Date Network Name,取值参考23.003 9.1节 | E25: A | F25: =B25 -> PDU_Session_DNN | G25: 直取 | J25: 详单 | K25: 无 | L25: 无
... B35: s_nssai_sd | C35: string | D35: 网络切片选择辅助信息（切片差分器）。若有多个切片，以“,”分隔。 | E35: A | F35: =B35 -> s_nssai_sd | G35: 直取 | J35: 详单 | K35: 无 | L35: 无
B36: p_provincecode | C36: int | D36: 省分区
B37: p_date | C37: string | D37: 天分区
B38: p_hour | C38: int | D38: 小时分区

Sheet 0.2
B1: =HYPERLINK("#导航!a2","返回") -> 返回
B3: 目标表基本信息描述
B4: 主题域 | C4: 目标表英文名 | D4: 目标表中文名 | E4: 数据频度 | F4: 模型主键 | G4: 数据描述 | H4: 推送数据库
C5: fact_5gdpi_n26_customweb_e2e_telecom_h | D5: SA控制面N26接口事实表 | E5: hour
B7: 源表基本信息描述
B8: 来源系统 | C8: 源表英文名 | D8: 源表中文名 | E8: 别名 | F8: 任务描述 | G8: 备注 | H8: 是否主表
C9: ods_5gdpi_n26_e2e_telecom_q | D9: 5G_DPI_n26贴源层详表 | E9: A | H9: 是
B11: 详细字段信息
B12: 详细字段信息
B13: PDM字段英文名 | C13: PDM字段类型 | D13: PDM字段中文名（说明） | E13: 源表名 | F13: 源字段英文名 | G13: 算法加工逻辑 | H13: 关联与过滤条件 | I13: 备注 | J13: 字段属性 | K13: 单位 | L13: 取值范围
B14: Interface | C14: int | D14: 必填字段。接口类型： 1：S1-U 2：S1-MME 3：S6a 4：S11 6：S5-C 14：L2TP 16：Gm信令面 28：Gm接口VoLTE会话xDR（Gm Session xDR） 29：Gm接口VoLTE切片xDR（Gm Slice xDR） 31：S1-U接口VoLTE切片xDR（S1-U Slice xDR） 35：Radius 50：N1N2 51：N4 52：N5 53：N7 54：N8 55：N10 56：N11 57：N12 58：N14 59：N15 66：N16 60：N22 61：N26 62：N40 63：N13 100：User Plane（5G SA指N3接口） | E14: A | F14: =B14 -> Interface | G14: 直取 | J14: 详单 | K14: 无 | L14: 无
B15: SUPI | C15: string | D15: 永久用户标识。4G 填写用户IMSI。 | E15: A | F15: =B15 -> SUPI | G15: 直取 | J15: 详单 | K15: 无 | L15: 无
B16: MSISDN | C16: string | D16: 用户号码。 | E16: A | F16: =B16 -> MSISDN | G16: 直取 | J16: 详单 | K16: 无 | L16: 无
B17: Procedure_Type | C17: int | D17: 流程类型编码，具体取值如下： 21：Identification Request 22：Context Request 23：Forward Relocation Request 24：Forward Relocation Complete Notification 26：Relocation Cancel Request 27：Configuration Transfer Tunnel | E17: A | F17: =B17 -> Procedure_Type | G17: 直取 | J17: 详单 | K17: 无 | L17: 无
B18: Procedure_Start_Time | C18: bigint | D18: 业务流程开始时间，UTC时间，从1970/1/1 00:00:00开始到当前的毫秒数。 | E18: A | F18: =B18 -> Procedure_Start_Time | G18: 直取 | J18: 详单 | K18: 无 | L18: 无
B19: Procedure_End_Time | C19: bigint | D19: 业务流程结束时间，UTC时间，从1970/1/1 00:00:00开始到当前的毫秒数。 | E19: A | F19: =B19 -> Procedure_End_Time | G19: 直取 | J19: 详单 | K19: 无 | L19: 无
B20: Procedure_Status | C20: int | D20: 流程状态 1：成功； 2：失败； 3：超时； 【处理方式】初始HTTP Request消息后，如果在时间T（默认值为10S）： 收到2XX Response，赋值为1； 收到3XX、4XX、5XX Response，赋值2； 没有收到任何Response消息则赋值3。 | E20: A | F20: =B20 -> Procedure_Status | G20: 直取 | J20: 详单 | K20: 无 | L20: 无
B21: Failure_Cause | C21: int | D21: 首条HTTP Request消息的类型 1：POST 2：PUT 3：GET 4：PATCH 5：DELETE 参见3GPP 29.274第8.4节中Table 8.4-1 | E21: A | F21: =B21 -> Failure_Cause | G21: 直取 | J21: 详单 | K21: 无 | L21: 无
B22: APN | C22: string | D22: APN | E22: A | F22: =B22 -> APN | G22: 直取 | J22: 详单 | K22: 无 | L22: 无
B23: pei | C23: string | D23: 永久设备标识。4G填写IMEI/IMEISV。保持信令抽取的原样，无需进行IMEI和IMEISV间的转化。 | E23: A | F23: =B23 -> pei | G23: 直取 | J23: 详单 | K23: 无 | L23: 无
B24: mme_address | C24: string | D24: MME信令面IP地址。 | E24: A | F24: =B24 -> mme_address | G24: 直取 | J24: 详单 | K24: 无 | L24: 无
B25: amf_address | C25: string | D25: AMF信令面IP地址。 | E25: A | F25: =B25 -> amf_address | G25: 直取 | J25: 详单 | K25: 无 | L25: 无
... B29: cell_id | C29: bigint | D29: 当前小区的ECI | E29: A | F29: =B29 -> cell_id | G29: 直取 | J29: 详单 | K29: 无 | L29: 无
B30: p_provincecode | C30: int | D30: 省分区
B31: p_date | C31: string | D31: 天分区
B32: p_hour | C32: int | D32: 小时分区

Sheet 0.3
B1: =HYPERLINK("#导航!a2","返回") -> 返回
B3: 目标表基本信息描述
B4: 主题域 | C4: 目标表英文名 | D4: 目标表中文名 | E4: 数据频度 | F4: 模型主键 | G4: 数据描述 | H4: 推送数据库
C5: fact_5gdpi_https_customweb_e2e_telecom_h | D5: SA用户面https定制网事实表 | E5: hour
B7: 源表基本信息描述
B8: 来源系统 | C8: 源表英文名 | D8: 源表中文名 | E8: 别名 | F8: 任务描述 | G8: 备注 | H8: 是否主表
C9: ods_5gdpi_https_e2e_telecom_q | D9: 5G_DPI_https贴源层详表 | E9: A | H9: 是
B11: 详细字段信息
B12: 详细字段信息
B13: PDM字段英文名 | C13: PDM字段类型 | D13: PDM字段中文名（说明） | E13: 源表名 | F13: 源字段英文名 | G13: 算法加工逻辑 | H13: 关联与过滤条件 | I13: 备注 | J13: 字段属性 | K13: 单位 | L13: 取值范围
B14: interface | C14: int | D14: 必填字段。接口类型： 1：S1-U 2：S1-MME 3：S6a 4：S11 6：S5-C 14：L2TP 16：Gm信令面 28：Gm接口VoLTE会话xDR（Gm Session xDR） 29：Gm接口VoLTE切片xDR（Gm Slice xDR） 31：S1-U接口VoLTE切片xDR（S1-U Slice xDR） 35：Radius 50：N1N2 51：N4 52：N5 53：N7 54：N8 55：N10 56：N11 57：N12 58：N14 59：N15 66：N16 60：N22 61：N26 62：N40 63：N13 100：User Plane（5G SA指N3接口） | E14: A | F14: =B14 -> interface | G14: 直取 | J14: 详单 | K14: 无 | L14: 无
B15: supi | C15: string | D15: 永久用户标识 | E15: A | F15: =B15 -> supi | G15: 直取 | J15: 详单 | K15: 无 | L15: 无
B16: msisdn | C16: string | D16: 用户号码 | E16: A | F16: =B16 -> msisdn | G16: 直取 | J16: 详单 | K16: 无 | L16: 无
B17: destinationip | C17: string | D17: 用户访问的目标IPv4或IPv6地址 | E17: A | F17: =B17 -> destinationip | G17: 直取 | J17: 详单 | K17: 无 | L17: 无
B18: destinationport | C18: int | D18: 用户访问的目标端口号 | E18: A | F18: =B18 -> destinationport | G18: 直取 | J18: 详单 | K18: 无 | L18: 无
B19: sourceip | C19: string | D19: 用户访问外部网络时使用的IPv4或IPv6地址 | E19: A | F19: =B19 -> sourceip | G19: 直取 | J19: 详单 | K19: 无 | L19: 无
B20: sourceport | C20: int | D20: 用户访问外部网络时使用的端口号 | E20: A | F20: =B20 -> sourceport | G20: 直取 | J20: 详单 | K20: 无 | L20: 无
B21: upfip | C21: string | D21: UPF的IPv4或IPv6地址 | E21: A | F21: =B21 -> upfip | G21: 直取 | J21: 详单 | K21: 无 | L21: 无
B22: ncgi_ecgi | C22: string | D22: NCGI：NR 小区全局标识符，MCC+MNC+NRCELLID； ECGI：E-UTRAN 小区全局标识符，MCC+MNC+CELLID； | E22: A | F22: =B22 -> ncgi_ecgi | G22: 直取 | J22: 详单 | K22: 无 | L22: 无
B23: protocolid | C23: int | D23: 协议类型 | E23: A | F23: =B23 -> protocolid | G23: 直取 | J23: 详单 | K23: 无 | L23: 无
B24: starttime | C24: string | D24: 业务流开始时间，格式为YYYYMMDDhhmmss（24小时制），如果开启中间记录模式，每条记录都填写相同的开始时间。 | E24: A | F24: =B24 -> starttime | G24: 直取 | J24: 详单 | K24: 无 | L24: 无
B25: endtime | C25: string | D25: 业务流结束时间，格式为YYYYMMDDhhmmss（24小时制），如果开启中间记录模式，只在最后一条记录填写结束时间。 | E25: A | F25: =B25 -> endtime | G25: 直取 | J25: 详单 | K25: 无 | L25: 无
... B66: sum_hand_shake_delay | C66: bigint | D66: 加密握手总时延，单位毫秒 | E66: A | F66: =B66 -> sum_hand_shake_delay | G66: 直取 | J66: 详单 | K66: 无 | L66: 无
B67: p_provincecode | C67: int | D67: 省分区
B68: p_date | C68: string | D68: 天分区
B69: p_hour | C69: int | D69: 小时分区

Sheet 0.4
B1: =HYPERLINK("#导航!a2","返回") -> 返回
B3: 目标表基本信息描述
B4: 主题域 | C4: 目标表英文名 | D4: 目标表中文名 | E4: 数据频度 | F4: 模型主键 | G4: 数据描述 | H4: 推送数据库
C5: fact_5gdpi_http_customweb_e2e_telecom_h | D5: SA用户面http定制网事实表 | E5: hour
B7: 源表基本信息描述
B8: 来源系统 | C8: 源表英文名 | D8: 源表中文名 | E8: 别名 | F8: 任务描述 | G8: 备注 | H8: 是否主表
C9: ods_5gdpi_http_e2e_telecom_origin_q | D9: 5G_DPI_http贴源层详表 | E9: A | H9: 是
B11: 详细字段信息
B12: 详细字段信息
B13: PDM字段英文名 | C13: PDM字段类型 | D13: PDM字段中文名（说明） | E13: 源表名 | F13: 源字段英文名 | G13: 算法加工逻辑 | H13: 关联与过滤条件 | I13: 备注 | J13: 字段属性 | K13: 单位 | L13: 取值范围
B14: interface | C14: int | D14: 必填字段。接口类型： 1：S1-U 2：S1-MME 3：S6a 4：S11 6：S5-C 14：L2TP 16：Gm信令面 28：Gm接口VoLTE会话xDR（Gm Session xDR） 29：Gm接口VoLTE切片xDR（Gm Slice xDR） 31：S1-U接口VoLTE切片xDR（S1-U Slice xDR） 35：Radius 50：N1N2 51：N4 52：N5 53：N7 54：N8 55：N10 56：N11 57：N12 58：N14 59：N15 66：N16 60：N22 61：N26 62：N40 63：N13 100：User Plane（5G SA指N3接口） | E14: A | F14: =B14 -> interface | G14: 直取 | J14: 详单 | K14: 无 | L14: 无
B15: supi | C15: string | D15: 永久用户标识 | E15: A | F15: =B15 -> supi | G15: 直取 | J15: 详单 | K15: 无 | L15: 无
B16: msisdn | C16: string | D16: 用户号码 | E16: A | F16: =B16 -> msisdn | G16: 直取 | J16: 详单 | K16: 无 | L16: 无
B17: destinationip | C17: string | D17: 用户访问的目标IPv4或IPv6地址 | E17: A | F17: =B17 -> destinationip | G17: 直取 | J17: 详单 | K17: 无 | L17: 无
B18: destinationport | C18: int | D18: 用户访问的目标端口号 | E18: A | F18: =B18 -> destinationport | G18: 直取 | J18: 详单 | K18: 无 | L18: 无
B19: sourceip | C19: string | D19: 用户访问外部网络时使用的IPv4或IPv6地址 | E19: A | F19: =B19 -> sourceip | G19: 直取 | J19: 详单 | K19: 无 | L19: 无
B20: sourceport | C20: int | D20: 用户访问外部网络时使用的端口号 | E20: A | F20: =B20 -> sourceport | G20: 直取 | J20: 详单 | K20: 无 | L20: 无
B21: upfip | C21: string | D21: UPF的IPv4或IPv6地址 | E21: A | F21: =B21 -> upfip | G21: 直取 | J21: 详单 | K21: 无 | L21: 无
B22: ncgi_ecgi | C22: string | D22: NCGI：NR 小区全局标识符，MCC+MNC+NRCELLID； ECGI：E-UTRAN 小区全局标识符，MCC+MNC+CELLID； | E22: A | F22: =B22 -> ncgi_ecgi | G22: 直取 | J22: 详单 | K22: 无 | L22: 无
B23: protocolid | C23: int | D23: 协议类型 | E23: A | F23: =B23 -> protocolid | G23: 直取 | J23: 详单 | K23: 无 | L23: 无
B24: starttime | C24: string | D24: 业务流开始时间，格式为YYYYMMDDhhmmss（24小时制），如果开启中间记录模式，每条记录都填写相同的开始时间。 | E24: A | F24: =B24 -> starttime | G24: 直取 | J24: 详单 | K24: 无 | L24: 无
B25: endtime | C25: string | D25: 业务流结束时间，格式为YYYYMMDDhhmmss（24小时制），如果开启中间记录模式，只在最后一条记录填写结束时间。 | E25: A | F25: =B25 -> endtime | G25: 直取 | J25: 详单 | K25: 无 | L25: 无
... B67: dnsflow_id | C67: bigint | D67: HTTP流与DNS流的关联ID。无关联流时，此字段填写0 | E67: A | F67: =B67 -> dnsflow_id | G67: 直取 | J67: 详单 | K67: 无 | L67: 无
B68: p_provincecode | C68: int | D68: 省分区
B69: p_date | C69: string | D69: 天分区
B70: p_hour | C70: int | D70: 小时分区

Sheet 0.5
B1: =HYPERLINK("#导航!a2","返回") -> 返回
B3: 目标表基本信息描述
B4: 主题域 | C4: 目标表英文名 | D4: 目标表中文名 | E4: 数据频度 | F4: 模型主键 | G4: 数据描述 | H4: 推送数据库
C5: fact_5gdpi_email_customweb_e2e_telecom_h | D5: SA用户面email定制网事实表 | E5: hour
B7: 源表基本信息描述
B8: 来源系统 | C8: 源表英文名 | D8: 源表中文名 | E8: 别名 | F8: 任务描述 | G8: 备注 | H8: 是否主表
C9: ods_5gdpi_email_e2e_telecom_q | D9: 5G_DPI_email贴源层详表 | E9: A | H9: 是
B11: 详细字段信息
B12: 详细字段信息
B13: PDM字段英文名 | C13: PDM字段类型 | D13: PDM字段中文名（说明） | E13: 源表名 | F13: 源字段英文名 | G13: 算法加工逻辑 | H13: 关联与过滤条件 | I13: 备注 | J13: 字段属性 | K13: 单位 | L13: 取值范围
B14: interface | C14: int | D14: 必填字段。接口类型： 1：S1-U 2：S1-MME 3：S6a 4：S11 6：S5-C 14：L2TP 16：Gm信令面 28：Gm接口VoLTE会话xDR（Gm Session xDR） 29：Gm接口VoLTE切片xDR（Gm Slice xDR） 31：S1-U接口VoLTE切片xDR（S1-U Slice xDR） 35：Radius 50：N1N2 51：N4 52：N5 53：N7 54：N8 55：N10 56：N11 57：N12 58：N14 59：N15 66：N16 60：N22 61：N26 62：N40 63：N13 100：User Plane（5G SA指N3接口） | E14: A | F14: =B14 -> interface | G14: 直取 | J14: 详单 | K14: 无 | L14: 无
B15: supi | C15: string | D15: 永久用户标识 | E15: A | F15: =B15 -> supi | G15: 直取 | J15: 详单 | K15: 无 | L15: 无
B16: msisdn | C16: string | D16: 用户号码 | E16: A | F16: =B16 -> msisdn | G16: 直取 | J16: 详单 | K16: 无 | L16: 无
B17: destinationip | C17: string | D17: 用户访问的目标IPv4或IPv6地址 | E17: A | F17: =B17 -> destinationip | G17: 直取 | J17: 详单 | K17: 无 | L17: 无
B18: destinationport | C18: int | D18: 用户访问的目标端口号 | E18: A | F18: =B18 -> destinationport | G18: 直取 | J18: 详单 | K18: 无 | L18: 无
B19: sourceip | C19: string | D19: 用户访问外部网络时使用的IPv4或IPv6地址 | E19: A | F19: =B19 -> sourceip | G19: 直取 | J19: 详单 | K19: 无 | L19: 无
B20: sourceport | C20: int | D20: 用户访问外部网络时使用的端口号 | E20: A | F20: =B20 -> sourceport | G20: 直取 | J20: 详单 | K20: 无 | L20: 无
B21: upfip | C21: string | D21: UPF的IPv4或IPv6地址 | E21: A | F21: =B21 -> upfip | G21: 直取 | J21: 详单 | K21: 无 | L21: 无
B22: ncgi_ecgi | C22: string | D22: NCGI：NR 小区全局标识符，MCC+MNC+NRCELLID； ECGI：E-UTRAN 小区全局标识符，MCC+MNC+CELLID； | E22: A | F22: =B22 -> ncgi_ecgi | G22: 直取 | J22: 详单 | K22: 无 | L22: 无
B23: protocolid | C23: int | D23: 协议类型 | E23: A | F23: =B23 -> protocolid | G23: 直取 | J23: 详单 | K23: 无 | L23: 无
B24: starttime | C24: string | D24: 业务流开始时间，格式为YYYYMMDDhhmmss（24小时制），如果开启中间记录模式，每条记录都填写相同的开始时间。 | E24: A | F24: =B24 -> starttime | G24: 直取 | J24: 详单 | K24: 无 | L24: 无
B25: endtime | C25: string | D25: 业务流结束时间，格式为YYYYMMDDhhmmss（24小时制），如果开启中间记录模式，只在最后一条记录填写结束时间。 | E25: A | F25: =B25 -> endtime | G25: 直取 | J25: 详单 | K25: 无 | L25: 无
... B58: status | C58: int | D58: 状态PROCEDURE_STATUS=1 成功 | E58: A | F58: =B58 -> status | G58: 直取 | J58: 详单 | K58: 无 | L58: 无
B59: p_provincecode | C59: int | D59: 省分区
B60: p_date | C60: string | D60: 天分区
B61: p_hour | C61: int | D61: 小时分区

Sheet 0.6
B1: =HYPERLINK("#导航!a2","返回") -> 返回
B3: 目标表基本信息描述
B4: 主题域 | C4: 目标表英文名 | D4: 目标表中文名 | E4: 数据频度 | F4: 模型主键 | G4: 数据描述 | H4: 推送数据库
C5: fact_5gdpi_dns_customweb_e2e_telecom_h | D5: SA用户面dns定制网事实表 | E5: hour
B7: 源表基本信息描述
B8: 来源系统 | C8: 源表英文名 | D8: 源表中文名 | E8: 别名 | F8: 任务描述 | G8: 备注 | H8: 是否主表
C9: ods_5gdpi_dns_e2e_telecom_origin_q | D9: 5G_DPI_dns贴源层详表 | E9: A | H9: 是
B11: 详细字段信息
B12: 详细字段信息
B13: PDM字段英文名 | C13: PDM字段类型 | D13: PDM字段中文名（说明） | E13: 源表名 | F13: 源字段英文名 | G13: 算法加工逻辑 | H13: 关联与过滤条件 | I13: 备注 | J13: 字段属性 | K13: 单位 | L13: 取值范围
B14: interface | C14: int | D14: 必填字段。接口类型： 1：S1-U 2：S1-MME 3：S6a 4：S11 6：S5-C 14：L2TP 16：Gm信令面 28：Gm接口VoLTE会话xDR（Gm Session xDR） 29：Gm接口VoLTE切片xDR（Gm Slice xDR） 31：S1-U接口VoLTE切片xDR（S1-U Slice xDR） 35：Radius 50：N1N2 51：N4 52：N5 53：N7 54：N8 55：N10 56：N11 57：N12 58：N14 59：N15 66：N16 60：N22 61：N26 62：N40 63：N13 100：User Plane（5G SA指N3接口） | E14: A | F14: =B14 -> interface | G14: 直取 | J14: 详单 | K14: 无 | L14: 无
B15: supi | C15: string | D15: 永久用户标识 | E15: A | F15: =B15 -> supi | G15: 直取 | J15: 详单 | K15: 无 | L15: 无
B16: msisdn | C16: string | D16: 用户号码 | E16: A | F16: =B16 -> msisdn | G16: 直取 | J16: 详单 | K16: 无 | L16: 无
B17: destinationip | C17: string | D17: 用户访问的目标IPv4或IPv6地址 | E17: A | F17: =B17 -> destinationip | G17: 直取 | J17: 详单 | K17: 无 | L17: 无
B18: destinationport | C18: int | D18: 用户访问的目标端口号 | E18: A | F18: =B18 -> destinationport | G18: 直取 | J18: 详单 | K18: 无 | L18: 无
B19: sourceip | C19: string | D19: 用户访问外部网络时使用的IPv4或IPv6地址 | E19: A | F19: =B19 -> sourceip | G19: 直取 | J19: 详单 | K19: 无 | L19: 无
B20: sourceport | C20: int | D20: 用户访问外部网络时使用的端口号 | E20: A | F20: =B20 -> sourceport | G20: 直取 | J20: 详单 | K20: 无 | L20: 无
B21: upfip | C21: string | D21: UPF的IPv4或IPv6地址 | E21: A | F21: =B21 -> upfip | G21: 直取 | J21: 详单 | K21: 无 | L21: 无
B22: ncgi_ecgi | C22: string | D22: NCGI：NR 小区全局标识符，MCC+MNC+NRCELLID； ECGI：E-UTRAN 小区全局标识符，MCC+MNC+CELLID； | E22: A | F22: =B22 -> ncgi_ecgi | G22: 直取 | J22: 详单 | K22: 无 | L22: 无
B23: protocolid | C23: int | D23: 协议类型 | E23: A | F23: =B23 -> protocolid | G23: 直取 | J23: 详单 | K23: 无 | L23: 无
B24: starttime | C24: string | D24: 业务流开始时间，格式为YYYYMMDDhhmmss（24小时制），如果开启中间记录模式，每条记录都填写相同的开始时间。 | E24: A | F24: =B24 -> starttime | G24: 直取 | J24: 详单 | K24: 无 | L24: 无
B25: endtime | C25: string | D25: 业务流结束时间，格式为YYYYMMDDhhmmss（24小时制），如果开启中间记录模式，只在最后一条记录填写结束时间。 | E25: A | F25: =B25 -> endtime | G25: 直取 | J25: 详单 | K25: 无 | L25: 无
... B65: response_number | C65: int | D65: response_number | E65: A | F65: =B65 -> response_number | G65: 直取 | J65: 详单 | K65: 无 | L65: 无
B66: p_provincecode | C66: int | D66: 省分区
B67: p_date | C67: string | D67: 天分区
B68: p_hour | C68: int | D68: 小时分区

Sheet 0.7
B1: =HYPERLINK("#导航!a2","返回") -> 返回
B3: 目标表基本信息描述
B4: 主题域 | C4: 目标表英文名 | D4: 目标表中文名 | E4: 数据频度 | F4: 模型主键 | G4: 数据描述 | H4: 推送数据库
C5: fact_5gdpi_coap_customweb_e2e_telecom_h | D5: SA用户面coap定制网事实表 | E5: hour
B7: 源表基本信息描述
B8: 来源系统 | C8: 源表英文名 | D8: 源表中文名 | E8: 别名 | F8: 任务描述 | G8: 备注 | H8: 是否主表
C9: ods_5gdpi_coap_e2e_telecom_q | D9: 5G_DPI_coap贴源层详表 | E9: A | H9: 是
B11: 详细字段信息
B12: 详细字段信息
B13: PDM字段英文名 | C13: PDM字段类型 | D13: PDM字段中文名（说明） | E13: 源表名 | F13: 源字段英文名 | G13: 算法加工逻辑 | H13: 关联与过滤条件 | I13: 备注 | J13: 字段属性 | K13: 单位 | L13: 取值范围
B14: interface | C14: int | D14: 必填字段。接口类型： 1：S1-U 2：S1-MME 3：S6a 4：S11 6：S5-C 14：L2TP 16：Gm信令面 28：Gm接口VoLTE会话xDR（Gm Session xDR） 29：Gm接口VoLTE切片xDR（Gm Slice xDR） 31：S1-U接口VoLTE切片xDR（S1-U Slice xDR） 35：Radius 50：N1N2 51：N4 52：N5 53：N7 54：N8 55：N10 56：N11 57：N12 58：N14 59：N15 66：N16 60：N22 61：N26 62：N40 63：N13 100：User Plane（5G SA指N3接口） | E14: A | F14: =B14 -> interface | G14: 直取 | J14: 详单 | K14: 无 | L14: 无
B15: supi | C15: string | D15: 永久用户标识 | E15: A | F15: =B15 -> supi | G15: 直取 | J15: 详单 | K15: 无 | L15: 无
B16: msisdn | C16: string | D16: 用户号码 | E16: A | F16: =B16 -> msisdn | G16: 直取 | J16: 详单 | K16: 无 | L16: 无
B17: destinationip | C17: string | D17: 用户访问的目标IPv4或IPv6地址 | E17: A | F17: =B17 -> destinationip | G17: 直取 | J17: 详单 | K17: 无 | L17: 无
B18: destinationport | C18: int | D18: 用户访问的目标端口号 | E18: A | F18: =B18 -> destinationport | G18: 直取 | J18: 详单 | K18: 无 | L18: 无
B19: sourceip | C19: string | D19: 用户访问外部网络时使用的IPv4或IPv6地址 | E19: A | F19: =B19 -> sourceip | G19: 直取 | J19: 详单 | K19: 无 | L19: 无
B20: sourceport | C20: int | D20: 用户访问外部网络时使用的端口号 | E20: A | F20: =B20 -> sourceport | G20: 直取 | J20: 详单 | K20: 无 | L20: 无
B21: upfip | C21: string | D21: UPF的IPv4或IPv6地址 | E21: A | F21: =B21 -> upfip | G21: 直取 | J21: 详单 | K21: 无 | L21: 无
B22: ncgi_ecgi | C22: string | D22: NCGI：NR 小区全局标识符，MCC+MNC+NRCELLID； ECGI：E-UTRAN 小区全局标识符，MCC+MNC+CELLID； | E22: A | F22: =B22 -> ncgi_ecgi | G22: 直取 | J22: 详单 | K22: 无 | L22: 无
B23: protocolid | C23: int | D23: 协议类型 | E23: A | F23: =B23 -> protocolid | G23: 直取 | J23: 详单 | K23: 无 | L23: 无
B24: starttime | C24: string | D24: 业务流开始时间，格式为YYYYMMDDhhmmss（24小时制），如果开启中间记录模式，每条记录都填写相同的开始时间。 | E24: A | F24: =B24 -> starttime | G24: 直取 | J24: 详单 | K24: 无 | L24: 无
B25: endtime | C25: string | D25: 业务流结束时间，格式为YYYYMMDDhhmmss（24小时制），如果开启中间记录模式，只在最后一条记录填写结束时间。 | E25: A | F25: =B25 -> endtime | G25: 直取 | J25: 详单 | K25: 无 | L25: 无
... B64: destination_uri | C64: string | D64: 用户访问的目标的URI。 | E64: A | F64: =B64 -> destination_uri | G64: 直取 | J64: 详单 | K64: 无 | L64: 无
B65: p_provincecode | C65: int | D65: 省分区
B66: p_date | C66: string | D66: 天分区
B67: p_hour | C67: int | D67: 小时分区

Sheet 0.8
B1: =HYPERLINK("#导航!a2","返回") -> 返回
B3: 目标表基本信息描述
B4: 主题域 | C4: 目标表英文名 | D4: 目标表中文名 | E4: 数据频度 | F4: 模型主键 | G4: 数据描述 | H4: 推送数据库
C5: fact_5gdpi_ftp_customweb_e2e_telecom_h | D5: SA用户面ftp定制网事实表 | E5: hour
B7: 源表基本信息描述
B8: 来源系统 | C8: 源表英文名 | D8: 源表中文名 | E8: 别名 | F8: 任务描述 | G8: 备注 | H8: 是否主表
C9: ods_5gdpi_ftp_e2e_telecom_q | D9: 5G_DPI_ftp贴源层详表 | E9: A | H9: 是
B11: 详细字段信息
B12: 详细字段信息
B13: PDM字段英文名 | C13: PDM字段类型 | D13: PDM字段中文名（说明） | E13: 源表名 | F13: 源字段英文名 | G13: 算法加工逻辑 | H13: 关联与过滤条件 | I13: 备注 | J13: 字段属性 | K13: 单位 | L13: 取值范围
B14: interface | C14: int | D14: 必填字段。接口类型： 1：S1-U 2：S1-MME 3：S6a 4：S11 6：S5-C 14：L2TP 16：Gm信令面 28：Gm接口VoLTE会话xDR（Gm Session xDR） 29：Gm接口VoLTE切片xDR（Gm Slice xDR） 31：S1-U接口VoLTE切片xDR（S1-U Slice xDR） 35：Radius 50：N1N2 51：N4 52：N5 53：N7 54：N8 55：N10 56：N11 57：N12 58：N14 59：N15 66：N16 60：N22 61：N26 62：N40 63：N13 100：User Plane（5G SA指N3接口） | E14: A | F14: =B14 -> interface | G14: 直取 | J14: 详单 | K14: 无 | L14: 无
B15: supi | C15: string | D15: 永久用户标识 | E15: A | F15: =B15 -> supi | G15: 直取 | J15: 详单 | K15: 无 | L15: 无
B16: msisdn | C16: string | D16: 用户号码 | E16: A | F16: =B16 -> msisdn | G16: 直取 | J16: 详单 | K16: 无 | L16: 无
B17: destinationip | C17: string | D17: 用户访问的目标IPv4或IPv6地址 | E17: A | F17: =B17 -> destinationip | G17: 直取 | J17: 详单 | K17: 无 | L17: 无
B18: destinationport | C18: int | D18: 用户访问的目标端口号 | E18: A | F18: =B18 -> destinationport | G18: 直取 | J18: 详单 | K18: 无 | L18: 无
B19: sourceip | C19: string | D19: 用户访问外部网络时使用的IPv4或IPv6地址 | E19: A | F19: =B19 -> sourceip | G19: 直取 | J19: 详单 | K19: 无 | L19: 无
B20: sourceport | C20: int | D20: 用户访问外部网络时使用的端口号 | E20: A | F20: =B20 -> sourceport | G20: 直取 | J20: 详单 | K20: 无 | L20: 无
B21: upfip | C21: string | D21: UPF的IPv4或IPv6地址 | E21: A | F21: =B21 -> upfip | G21: 直取 | J21: 详单 | K21: 无 | L21: 无
B22: ncgi_ecgi | C22: string | D22: NCGI：NR 小区全局标识符，MCC+MNC+NRCELLID； ECGI：E-UTRAN 小区全局标识符，MCC+MNC+CELLID； | E22: A | F22: =B22 -> ncgi_ecgi | G22: 直取 | J22: 详单 | K22: 无 | L22: 无
B23: protocolid | C23: int | D23: 协议类型 | E23: A | F23: =B23 -> protocolid | G23: 直取 | J23: 详单 | K23: 无 | L23: 无
B24: starttime | C24: string | D24: 业务流开始时间，格式为YYYYMMDDhhmmss（24小时制），如果开启中间记录模式，每条记录都填写相同的开始时间。 | E24: A | F24: =B24 -> starttime | G24: 直取 | J24: 详单 | K24: 无 | L24: 无
B25: endtime | C25: string | D25: 业务流结束时间，格式为YYYYMMDDhhmmss（24小时制），如果开启中间记录模式，只在最后一条记录填写结束时间。 | E25: A | F25: =B25 -> endtime | G25: 直取 | J25: 详单 | K25: 无 | L25: 无
... B61: delay | C61: bigint | D61: 时延 | E61: A | F61: =B61 -> delay | G61: 直取 | J61: 详单 | K61: 无 | L61: 无
B62: p_provincecode | C62: int | D62: 省分区
B63: p_date | C63: string | D63: 天分区
B64: p_hour | C64: int | D64: 小时分区

Sheet 0.9
B1: =HYPERLINK("#导航!a2","返回") -> 返回
B3: 目标表基本信息描述
B4: 主题域 | C4: 目标表英文名 | D4: 目标表中文名 | E4: 数据频度 | F4: 模型主键 | G4: 数据描述 | H4: 推送数据库
C5: fact_5gdpi_mqtt_customweb_e2e_telecom_h | D5: SA用户面mqtt定制网事实表 | E5: hour
B7: 源表基本信息描述
B8: 来源系统 | C8: 源表英文名 | D8: 源表中文名 | E8: 别名 | F8: 任务描述 | G8: 备注 | H8: 是否主表
C9: ods_5gdpi_mqtt_e2e_telecom_q | D9: 5G_DPI_mqtt贴源层详表 | E9: A | H9: 是
B11: 详细字段信息
B12: 详细字段信息
B13: PDM字段英文名 | C13: PDM字段类型 | D13: PDM字段中文名（说明） | E13: 源表名 | F13: 源字段英文名 | G13: 算法加工逻辑 | H13: 关联与过滤条件 | I13: 备注 | J13: 字段属性 | K13: 单位 | L13: 取值范围
B14: interface | C14: int | D14: 必填字段。接口类型： 1：S1-U 2：S1-MME 3：S6a 4：S11 6：S5-C 14：L2TP 16：Gm信令面 28：Gm接口VoLTE会话xDR（Gm Session xDR） 29：Gm接口VoLTE切片xDR（Gm Slice xDR） 31：S1-U接口VoLTE切片xDR（S1-U Slice xDR） 35：Radius 50：N1N2 51：N4 52：N5 53：N7 54：N8 55：N10 56：N11 57：N12 58：N14 59：N15 66：N16 60：N22 61：N26 62：N40 63：N13 100：User Plane（5G SA指N3接口） | E14: A | F14: =B14 -> interface | G14: 直取 | J14: 详单 | K14: 无 | L14: 无
B15: supi | C15: string | D15: 永久用户标识 | E15: A | F15: =B15 -> supi | G15: 直取 | J15: 详单 | K15: 无 | L15: 无
B16: msisdn | C16: string | D16: 用户号码 | E16: A | F16: =B16 -> msisdn | G16: 直取 | J16: 详单 | K16: 无 | L16: 无
B17: destinationip | C17: string | D17: 用户访问的目标IPv4或IPv6地址 | E17: A | F17: =B17 -> destinationip | G17: 直取 | J17: 详单 | K17: 无 | L17: 无
B18: destinationport | C18: int | D18: 用户访问的目标端口号 | E18: A | F18: =B18 -> destinationport | G18: 直取 | J18: 详单 | K18: 无 | L18: 无
B19: sourceip | C19: string | D19: 用户访问外部网络时使用的IPv4或IPv6地址 | E19: A | F19: =B19 -> sourceip | G19: 直取 | J19: 详单 | K19: 无 | L19: 无
B20: sourceport | C20: int | D20: 用户访问外部网络时使用的端口号 | E20: A | F20: =B20 -> sourceport | G20: 直取 | J20: 详单 | K20: 无 | L20: 无
B21: upfip | C21: string | D21: UPF的IPv4或IPv6地址 | E21: A | F21: =B21 -> upfip | G21: 直取 | J21: 详单 | K21: 无 | L21: 无
B22: ncgi_ecgi | C22: string | D22: NCGI：NR 小区全局标识符，MCC+MNC+NRCELLID； ECGI：E-UTRAN 小区全局标识符，MCC+MNC+CELLID； | E22: A | F22: =B22 -> ncgi_ecgi | G22: 直取 | J22: 详单 | K22: 无 | L22: 无
B23: protocolid | C23: int | D23: 协议类型 | E23: A | F23: =B23 -> protocolid | G23: 直取 | J23: 详单 | K23: 无 | L23: 无
B24: starttime | C24: string | D24: 业务流开始时间，格式为YYYYMMDDhhmmss（24小时制），如果开启中间记录模式，每条记录都填写相同的开始时间。 | E24: A | F24: =B24 -> starttime | G24: 直取 | J24: 详单 | K24: 无 | L24: 无
B25: endtime | C25: string | D25: 业务流结束时间，格式为YYYYMMDDhhmmss（24小时制），如果开启中间记录模式，只在最后一条记录填写结束时间。 | E25: A | F25: =B25 -> endtime | G25: 直取 | J25: 详单 | K25: 无 | L25: 无
... B62: respdelay | C62: bigint | D62: 响应时延，单位毫秒 | E62: A | F62: =B62 -> respdelay | G62: 直取 | J62: 详单 | K62: 无 | L62: 无
B63: p_provincecode | C63: int | D63: 省分区
B64: p_date | C64: string | D64: 天分区
B65: p_hour | C65: int | D65: 小时分区

Sheet 1.2
B1: =HYPERLINK("#导航!a2","返回") -> 返回
B3: 目标表基本信息描述
B4: 主题域 | C4: 目标表英文名 | D4: 目标表中文名 | E4: 数据频度 | F4: 模型主键 | G4: 数据描述 | H4: 推送数据库
C5: fact_5gdpi_other_customweb_e2e_telecom_h | D5: SA用户面other定制网事实表 | E5: hour
B7: 源表基本信息描述
B8: 来源系统 | C8: 源表英文名 | D8: 源表中文名 | E8: 别名 | F8: 任务描述 | G8: 备注 | H8: 是否主表
C9: ods_5gdpi_other_e2e_telecom_q | D9: 5G_DPI_other贴源层详表 | E9: A | H9: 是
B11: 详细字段信息
B12: 详细字段信息
B13: PDM字段英文名 | C13: PDM字段类型 | D13: PDM字段中文名（说明） | E13: 源表名 | F13: 源字段英文名 | G13: 算法加工逻辑 | H13: 关联与过滤条件 | I13: 备注 | J13: 字段属性 | K13: 单位 | L13: 取值范围
B14: interface | C14: int | D14: 必填字段。接口类型： 1：S1-U 2：S1-MME 3：S6a 4：S11 6：S5-C 14：L2TP 16：Gm信令面 28：Gm接口VoLTE会话xDR（Gm Session xDR） 29：Gm接口VoLTE切片xDR（Gm Slice xDR） 31：S1-U接口VoLTE切片xDR（S1-U Slice xDR） 35：Radius 50：N1N2 51：N4 52：N5 53：N7 54：N8 55：N10 56：N11 57：N12 58：N14 59：N15 66：N16 60：N22 61：N26 62：N40 63：N13 100：User Plane（5G SA指N3接口） | E14: A | F14: =B14 -> interface | G14: 直取 | J14: 详单 | K14: 无 | L14: 无
B15: supi | C15: string | D15: 永久用户标识 | E15: A | F15: =B15 -> supi | G15: 直取 | J15: 详单 | K15: 无 | L15: 无
B16: msisdn | C16: string | D16: 用户号码 | E16: A | F16: =B16 -> msisdn | G16: 直取 | J16: 详单 | K16: 无 | L16: 无
B17: destinationip | C17: string | D17: 用户访问的目标IPv4或IPv6地址 | E17: A | F17: =B17 -> destinationip | G17: 直取 | J17: 详单 | K17: 无 | L17: 无
B18: destinationport | C18: int | D18: 用户访问的目标端口号 | E18: A | F18: =B18 -> destinationport | G18: 直取 | J18: 详单 | K18: 无 | L18: 无
B19: sourceip | C19: string | D19: 用户访问外部网络时使用的IPv4或IPv6地址 | E19: A | F19: =B19 -> sourceip | G19: 直取 | J19: 详单 | K19: 无 | L19: 无
B20: sourceport | C20: int | D20: 用户访问外部网络时使用的端口号 | E20: A | F20: =B20 -> sourceport | G20: 直取 | J20: 详单 | K20: 无 | L20: 无
B21: upfip | C21: string | D21: UPF的IPv4或IPv6地址 | E21: A | F21: =B21 -> upfip | G21: 直取 | J21: 详单 | K21: 无 | L21: 无
B22: ncgi_ecgi | C22: string | D22: NCGI：NR 小区全局标识符，MCC+MNC+NRCELLID； ECGI：E-UTRAN 小区全局标识符，MCC+MNC+CELLID； | E22: A | F22: =B22 -> ncgi_ecgi | G22: 直取 | J22: 详单 | K22: 无 | L22: 无
B23: protocolid | C23: int | D23: 协议类型 | E23: A | F23: =B23 -> protocolid | G23: 直取 | J23: 详单 | K23: 无 | L23: 无
B24: starttime | C24: string | D24: 业务流开始时间，格式为YYYYMMDDhhmmss（24小时制），如果开启中间记录模式，每条记录都填写相同的开始时间。 | E24: A | F24: =B24 -> starttime | G24: 直取 | J24: 详单 | K24: 无 | L24: 无
B25: endtime | C25: string | D25: 业务流结束时间，格式为YYYYMMDDhhmmss（24小时制），如果开启中间记录模式，只在最后一条记录填写结束时间。 | E25: A | F25: =B25 -> endtime | G25: 直取 | J25: 详单 | K25: 无 | L25: 无
... B57: dl_session_ambr | C57: bigint | D57: 下行聚合最大比特率，kbps | E57: A | F57: =B57 -> dl_session_ambr | G57: 直取 | J57: 详单 | K57: 无 | L57: 无
B58: p_provincecode | C58: int | D58: 省分区
B59: p_date | C59: string | D59: 天分区
B60: p_hour | C60: int | D60: 小时分区

Sheet 1.3
B1: =HYPERLINK("#导航!a2","返回") -> 返回
B3: 目标表基本信息描述
B4: 主题域 | C4: 目标表英文名 | D4: 目标表中文名 | E4: 数据频度 | F4: 模型主键 | G4: 数据描述 | H4: 推送数据库
C5: fact_5gdpi_video_customweb_e2e_telecom_h | D5: SA用户面video定制网事实表 | E5: hour
B7: 源表基本信息描述
B8: 来源系统 | C8: 源表英文名 | D8: 源表中文名 | E8: 别名 | F8: 任务描述 | G8: 备注 | H8: 是否主表
C9: ods_5gdpi_video_e2e_telecom_origin_q | D9: 5G_DPI_video贴源层详表 | E9: A | H9: 是
B11: 详细字段信息
B12: 详细字段信息
B13: PDM字段英文名 | C13: PDM字段类型 | D13: PDM字段中文名（说明） | E13: 源表名 | F13: 源字段英文名 | G13: 算法加工逻辑 | H13: 关联与过滤条件 | I13: 备注 | J13: 字段属性 | K13: 单位 | L13: 取值范围
B14: interface | C14: int | D14: 必填字段。接口类型： 1：S1-U 2：S1-MME 3：S6a 4：S11 6：S5-C 14：L2TP 16：Gm信令面 28：Gm接口VoLTE会话xDR（Gm Session xDR） 29：Gm接口VoLTE切片xDR（Gm Slice xDR） 31：S1-U接口VoLTE切片xDR（S1-U Slice xDR） 35：Radius 50：N1N2 51：N4 52：N5 53：N7 54：N8 55：N10 56：N11 57：N12 58：N14 59：N15 66：N16 60：N22 61：N26 62：N40 63：N13 100：User Plane（5G SA指N3接口） | E14: A | F14: =B14 -> interface | G14: 直取 | J14: 详单 | K14: 无 | L14: 无
B15: supi | C15: string | D15: 永久用户标识 | E15: A | F15: =B15 -> supi | G15: 直取 | J15: 详单 | K15: 无 | L15: 无
B16: msisdn | C16: string | D16: 用户号码 | E16: A | F16: =B16 -> msisdn | G16: 直取 | J16: 详单 | K16: 无 | L16: 无
B17: destinationip | C17: string | D17: 用户访问的目标IPv4或IPv6地址 | E17: A | F17: =B17 -> destinationip | G17: 直取 | J17: 详单 | K17: 无 | L17: 无
B18: destinationport | C18: int | D18: 用户访问的目标端口号 | E18: A | F18: =B18 -> destinationport | G18: 直取 | J18: 详单 | K18: 无 | L18: 无
B19: sourceip | C19: string | D19: 用户访问外部网络时使用的IPv4或IPv6地址 | E19: A | F19: =B19 -> sourceip | G19: 直取 | J19: 详单 | K19: 无 | L19: 无
B20: sourceport | C20: int | D20: 用户访问外部网络时使用的端口号 | E20: A | F20: =B20 -> sourceport | G20: 直取 | J20: 详单 | K20: 无 | L20: 无
B21: upfip | C21: string | D21: UPF的IPv4或IPv6地址 | E21: A | F21: =B21 -> upfip | G21: 直取 | J21: 详单 | K21: 无 | L21: 无
B22: ncgi_ecgi | C22: string | D22: NCGI：NR 小区全局标识符，MCC+MNC+NRCELLID； ECGI：E-UTRAN 小区全局标识符，MCC+MNC+CELLID； | E22: A | F22: =B22 -> ncgi_ecgi | G22: 直取 | J22: 详单 | K22: 无 | L22: 无
B23: protocolid | C23: int | D23: 协议类型 | E23: A | F23: =B23 -> protocolid | G23: 直取 | J23: 详单 | K23: 无 | L23: 无
B24: starttime | C24: string | D24: 业务流开始时间，格式为YYYYMMDDhhmmss（24小时制），如果开启中间记录模式，每条记录都填写相同的开始时间。 | E24: A | F24: =B24 -> starttime | G24: 直取 | J24: 详单 | K24: 无 | L24: 无
B25: endtime | C25: string | D25: 业务流结束时间，格式为YYYYMMDDhhmmss（24小时制），如果开启中间记录模式，只在最后一条记录填写结束时间。 | E25: A | F25: =B25 -> endtime | G25: 直取 | J25: 详单 | K25: 无 | L25: 无
... B72: video_resolution | C72: string | D72: 视频分辨率 | E72: A | F72: =B72 -> video_resolution | G72: 直取 | J72: 详单 | K72: 无 | L72: 无
B73: p_provincecode | C73: int | D73: 省分区
B74: p_date | C74: string | D74: 天分区
B75: p_hour | C75: int | D75: 小时分区

Sheet 1.4
B1: =HYPERLINK("#导航!a2","返回") -> 返回
B3: 目标表基本信息描述
B4: 主题域 | C4: 目标表英文名 | D4: 目标表中文名 | E4: 数据频度 | F4: 模型主键 | G4: 数据描述 | H4: 推送数据库
C5: fact_5gdpi_game_customweb_e2e_telecom_h | D5: SA用户面game定制网事实表 | E5: hour
B7: 源表基本信息描述
B8: 来源系统 | C8: 源表英文名 | D8: 源表中文名 | E8: 别名 | F8: 任务描述 | G8: 备注 | H8: 是否主表
C9: ods_5gdpi_game_e2e_telecom_q | D9: 5G_DPI_game贴源层详表 | E9: A | H9: 是
B11: 详细字段信息
B12: 详细字段信息
B13: PDM字段英文名 | C13: PDM字段类型 | D13: PDM字段中文名（说明） | E13: 源表名 | F13: 源字段英文名 | G13: 算法加工逻辑 | H13: 关联与过滤条件 | I13: 备注 | J13: 字段属性 | K13: 单位 | L13: 取值范围
B14: interface | C14: int | D14: 必填字段。接口类型： 1：S1-U 2：S1-MME 3：S6a 4：S11 6：S5-C 14：L2TP 16：Gm信令面 28：Gm接口VoLTE会话xDR（Gm Session xDR） 29：Gm接口VoLTE切片xDR（Gm Slice xDR） 31：S1-U接口VoLTE切片xDR（S1-U Slice xDR） 35：Radius 50：N1N2 51：N4 52：N5 53：N7 54：N8 55：N10 56：N11 57：N12 58：N14 59：N15 66：N16 60：N22 61：N26 62：N40 63：N13 100：User Plane（5G SA指N3接口） | E14: A | F14: =B14 -> interface | G14: 直取 | J14: 详单 | K14: 无 | L14: 无
B15: supi | C15: string | D15: 永久用户标识 | E15: A | F15: =B15 -> supi | G15: 直取 | J15: 详单 | K15: 无 | L15: 无
B16: msisdn | C16: string | D16: 用户号码 | E16: A | F16: =B16 -> msisdn | G16: 直取 | J16: 详单 | K16: 无 | L16: 无
B17: destinationip | C17: string | D17: 用户访问的目标IPv4或IPv6地址 | E17: A | F17: =B17 -> destinationip | G17: 直取 | J17: 详单 | K17: 无 | L17: 无
B18: destinationport | C18: int | D18: 用户访问的目标端口号 | E18: A | F18: =B18 -> destinationport | G18: 直取 | J18: 详单 | K18: 无 | L18: 无
B19: sourceip | C19: string | D19: 用户访问外部网络时使用的IPv4或IPv6地址 | E19: A | F19: =B19 -> sourceip | G19: 直取 | J19: 详单 | K19: 无 | L19: 无
B20: sourceport | C20: int | D20: 用户访问外部网络时使用的端口号 | E20: A | F20: =B20 -> sourceport | G20: 直取 | J20: 详单 | K20: 无 | L20: 无
B21: upfip | C21: string | D21: UPF的IPv4或IPv6地址 | E21: A | F21: =B21 -> upfip | G21: 直取 | J21: 详单 | K21: 无 | L21: 无
B22: ncgi_ecgi | C22: string | D22: NCGI：NR 小区全局标识符，MCC+MNC+NRCELLID； ECGI：E-UTRAN 小区全局标识符，MCC+MNC+CELLID； | E22: A | F22: =B22 -> ncgi_ecgi | G22: 直取 | J22: 详单 | K22: 无 | L22: 无
B23: protocolid | C23: int | D23: 协议类型 | E23: A | F23: =B23 -> protocolid | G23: 直取 | J23: 详单 | K23: 无 | L23: 无
B24: starttime | C24: string | D24: 业务流开始时间，格式为YYYYMMDDhhmmss（24小时制），如果开启中间记录模式，每条记录都填写相同的开始时间。 | E24: A | F24: =B24 -> starttime | G24: 直取 | J24: 详单 | K24: 无 | L24: 无
B25: endtime | C25: string | D25: 业务流结束时间，格式为YYYYMMDDhhmmss（24小时制），如果开启中间记录模式，只在最后一条记录填写结束时间。 | E25: A | F25: =B25 -> endtime | G25: 直取 | J25: 详单 | K25: 无 | L25: 无
... B58: avg_delay | C58: bigint | D58: 平均时延 | E58: A | F58: =B58 -> avg_delay | G58: 直取 | J58: 详单 | K58: 无 | L58: 无
B59: p_provincecode | C59: int | D59: 省分区
B60: p_date | C60: string | D60: 天分区
B61: p_hour | C61: int | D61: 小时分区

Sheet 1.1
B1: =HYPERLINK("#导航!a2","返回") -> 返回
B3: 目标表基本信息描述
B4: 主题域 | C4: 目标表英文名 | D4: 目标表中文名 | E4: 数据频度 | F4: 模型主键 | G4: 数据描述 | H4: 推送数据库
B5: 数据感知 | C5: aggr_nr_dpi_dns_usrappcel_q | D5: 5G_DPI_dns用户小区app维度15分钟表 | E5: quarter
B7: 源表基本信息描述
B8: 来源系统 | C8: 源表英文名 | D8: 源表中文名 | E8: 别名 | F8: 任务描述 | G8: 备注 | H8: 是否主表
C9: aggr_nr_dpi_dns_base_q | D9: 5G_DPI_dns基础维度15分钟表 | E9: A | H9: 是
B11: 详细字段信息
B12: 详细字段信息
B13: PDM字段英文名 | C13: PDM字段类型 | D13: PDM字段中文名（说明） | E13: 源表名 | F13: 源字段英文名 | G13: 算法加工逻辑 | H13: 关联与过滤条件 | I13: 备注 | J13: 字段属性 | K13: 单位 | L13: 取值范围
B14: day | C14: string | D14: 日期 | E14: A | F14: p_date | G14: 直取 | I14: 对应字段：date | J14: 维度 | K14: 无 | L14: yyyy-mm-dd
B15: hour | C15: int | D15: 小时 | E15: A | F15: p_hour | G15: 直取 | I15: 对应字段：hour | J15: 维度 | K15: 无 | L15: 0~23
B16: interface | C16: int | D16: 接口类型 | E16: A | F16: interface | G16: 直取 | I16: 对应字段：interface | J16: 维度 | K16: 无 | L16: 1100101
B17: provincecode | C17: int | D17: 省编码 | E17: A | F17: p_provincecode | G17: 直取 | I17: 对应字段：provincecode | J17: 维度 | K17: 无 | L17: 6位数编码
B18: citycode | C18: int | D18: 市编码 | E18: A | F18: citycode | G18: 直取 | I18: 对应字段：citycode | J18: 维度 | K18: 无 | L18: 6位数编码
B19: districtcode | C19: int | D19: 区编码 | E19: A | F19: districtcode | G19: 直取 | I19: 对应字段：districtcode | J19: 维度 | K19: 无 | L19: 6位数编码
B20: province | C20: string | D20: 省名称 | E20: A | F20: province | G20: 直取 | I20: 对应字段：province | J20: 维度 | K20: 无 | L20: 无
B21: city | C21: string | D21: 地市名称 | E21: A | F21: city | G21: 直取 | I21: 对应字段：city | J21: 维度 | K21: 无 | L21: 无
B22: district | C22: string | D22: 区县名称 | E22: A | F22: district | G22: 直取 | I22: 对应字段：district | J22: 维度 | K22: 无 | L22: 无
B23: cellkey | C23: string | D23: 小区cellkey | E23: A | F23: cellkey | G23: 直取 | I23: 对应字段：cell_key | J23: 维度 | K23: 无 | L23: 无
B24: supi | C24: string | D24: 用户imsi | E24: A | F24: supi | G24: 直取 | I24: 对应字段：supi | J24: 维度 | K24: 无 | L24: 无
B25: msisdn | C25: string | D25: 用户号码 | E25: A | F25: msisdn | G25: 直取 | I25: 对应字段：msisdn | J25: 维度 | K25: 无 | L25: 无
B26: pei | C26: string | D26: 用户终端 | E26: A | F26: pei | G26: 直取 | I26: 对应字段：pei | J26: 维度 | K26: 无 | L26: 无
