Workbook

Sheet 0
A1: RSRP原始值 | B1: 采样点数 | C1: 实际值-含换算公式 | F1: RSRQ原始值 | G1: 采样点数 | H1: 实际值-含换算公式 | K1: SINR原始值 | L1: 采样点数 | M1: 实际值-含换算公式
A2: 0 | B2: 19 | C2: =A2-156 -> -156 | F2: 0 | G2: 5816 | H2: =F2/2-43 -> -43 | K2: 0 | L2: 1163 | M2: =K2/2-23 -> -23
A3: 1 | B3: 276 | C3: =A3-156 -> -155 | F3: 1 | G3: 554 | H3: =F3/2-43 -> -42.5 | K3: 1 | L3: 95 | M3: =K3/2-23 -> -22.5
A4: 2 | B4: 76 | C4: =A4-156 -> -154 | F4: 2 | G4: 269 | H4: =F4/2-43 -> -42 | K4: 2 | L4: 120 | M4: =K4/2-23 -> -22
A5: 3 | B5: 89 | C5: =A5-156 -> -153 | F5: 3 | G5: 308 | H5: =F5/2-43 -> -41.5 | K5: 3 | L5: 125 | M5: =K5/2-23 -> -21.5
A6: 4 | B6: 98 | C6: =A6-156 -> -152 | F6: 4 | G6: 323 | H6: =F6/2-43 -> -41 | K6: 4 | L6: 147 | M6: =K6/2-23 -> -21
A7: 5 | B7: 95 | C7: =A7-156 -> -151 | F7: 5 | G7: 307 | H7: =F7/2-43 -> -40.5 | K7: 5 | L7: 162 | M7: =K7/2-23 -> -20.5
A8: 6 | B8: 87 | C8: =A8-156 -> -150 | F8: 6 | G8: 323 | H8: =F8/2-43 -> -40 | K8: 6 | L8: 200 | M8: =K8/2-23 -> -20
A9: 7 | B9: 545 | C9: =A9-156 -> -149 | F9: 7 | G9: 425 | H9: =F9/2-43 -> -39.5 | K9: 7 | L9: 217 | M9: =K9/2-23 -> -19.5
A10: 8 | B10: 120 | C10: =A10-156 -> -148 | F10: 8 | G10: 308 | H10: =F10/2-43 -> -39 | K10: 8 | L10: 309 | M10: =K10/2-23 -> -19
A11: 9 | B11: 127 | C11: =A11-156 -> -147 | F11: 9 | G11: 309 | H11: =F11/2-43 -> -38.5 | K11: 9 | L11: 373 | M11: =K11/2-23 -> -18.5
A12: 10 | B12: 138 | C12: =A12-156 -> -146 | F12: 10 | G12: 289 | H12: =F12/2-43 -> -38 | K12: 10 | L12: 391 | M12: =K12/2-23 -> -18
A13: 11 | B13: 142 | C13: =A13-156 -> -145 | F13: 11 | G13: 341 | H13: =F13/2-43 -> -37.5 | K13: 11 | L13: 483 | M13: =K13/2-23 -> -17.5
... A129: 127 | B129: 75 | C129: =A129-156 -> -29 | F129: 127 | G129: 3945 | H129: =F129/2-43 -> 20.5 | K129: 127 | L129: 1566 | M129: =K129/2-23 -> 40.5

Sheet 导航
A1: 内部编号 | B1: 索引 | C1: 项目名称 | D1: 数据层级 | E1: 主题域 | F1: 表英文名 | G1: 表中文名 | H1: 数据描述 | I1: 汇聚维度 | J1: 数据时间粒度 | K1: 最小时间分区 | L1: 计算位置 | M1: 是否同步 | N1: 生命周期（存储周期单位：天） | O1: 前向表 | P1: 支撑应用/系统 | Q1: 新建/升级 | R1: 备注(最终变更点) | S1: 同步数据库
A2: 1 | B2: =HYPERLINK("#"&A2&"!A1",A2) -> 1 | C2: 网络数据处理系统 | D2: 接口层 | E2: / | F2: ods_nr_mro_northctcc_temp_new | G2: 5G电联MRO解析详单表 | H2: 5G电联MRO解析详单表 | I2: / | J2: 详单 | K2: 15分钟 | L2: 前置 | N2: 3 | O2: 原始数据解析 | Q2: 无变更 | R2: 无变更
A3: 2 | B3: =HYPERLINK("#"&A3&"!A1",A3) -> 2 | C3: 网络数据处理系统 | D3: 整合层 | E3: / | F3: ods_nr_mro_northctcc_location | G3: 5G电联MRO位置定位详单表 | H3: 5G电联MRO位置定位详单表 | I3: / | J3: 详单 | K3: 15分钟 | L3: 前置 | N3: 3 | O3: ods_nr_mro_northctcc_temp_new | Q3: 无变更 | R3: 无变更
A4: 3 | B4: =HYPERLINK("#"&A4&"!A1",A4) -> 3 | C4: 网络数据处理系统 | D4: 整合层 | E4: / | F4: ods_nr_mro_northctcc_q | G4: 5G电联MRO用户回填详单表 | H4: 5G电联MRO用户回填详单表 | I4: / | J4: 详单 | K4: 15分钟 | L4: 前置 | M4: 是 | N4: 3 | O4: ods_nr_mro_northctcc_location、ods_5gdpi_n1n2_e2e_telecom_5min | Q4: 升级 | R4: 增加4个字段
A5: 4 | B5: =HYPERLINK("#"&A5&"!A1",A5) -> 4 | C5: 网络数据处理系统 | D5: 整合层 | E5: / | F5: ods_nr_mro_northctcc_reduce | G5: 5G电联MRO详单字段裁剪表 | H5: 5G电联MRO详单字段裁剪表 | I5: / | J5: 详单 | K5: 15分钟 | L5: 核心 | N5: 3 | O5: ods_nr_mro_northctcc_q | Q5: 无变更 | R5: 无变更
A6: 5 | B6: =HYPERLINK("#"&A6&"!A1",A6) -> 5 | C6: 网络数据处理系统 | D6: 整合层 | E6: / | F6: fact_nr_mro_neighbor_nr_q | G6: 5G电联MRO邻区事实表(5G邻区) | H6: 5G电联MRO邻区事实表(5G邻区) | I6: / | J6: 详单 | K6: 15分钟 | L6: 核心 | N6: 3 | O6: ods_nr_mro_northctcc_q、fact_nr_cm_projdata | Q6: 新建
A7: 6 | B7: =HYPERLINK("#"&A7&"!A1",A7) -> 6 | C7: 网络数据处理系统 | D7: 中间层 | E7: / | F7: aggr_nr_sncell_problem_h | G7: MR数据主邻小区对覆盖问题分析汇聚小时表(重叠覆盖与MOD30) | H7: MR数据主邻小区对覆盖问题分析汇聚小时表(重叠覆盖与MOD30) | I7: 邻区对 | J7: 小时 | K7: 小时 | L7: 核心 | N7: 14 | O7: fact_nr_mro_neighbor_nr_q、fact_nr_cm_projdata | Q7: 新建
A8: 7 | B8: =HYPERLINK("#"&A8&"!A1",A8) -> 7 | C8: 网络数据处理系统 | D8: 中间层 | E8: / | F8: aggr_nr_sncell_problem_d | G8: MR数据主邻小区对覆盖问题分析汇聚天表(重叠覆盖与MOD30) | H8: MR数据主邻小区对覆盖问题分析汇聚天表(重叠覆盖与MOD30) | I8: 邻区对 | J8: 天 | K8: 天 | L8: 核心 | N8: 30 | O8: aggr_nr_sncell_problem_h | P8: 建维优 | Q8: 新建
A9: 8 | B9: =HYPERLINK("#"&A9&"!A1",A9) -> 8 | C9: 网络数据处理系统 | D9: 中间层 | E9: 覆盖分析 | F9: aggr_nr_coverage_problem_usrcelgrd_q | G9: 5G MR主小区覆盖问题汇聚指标15分钟表 | H9: 5G MR主小区覆盖问题汇聚指标15分钟表 | I9: 用户小区栅格 | J9: 15分钟 | K9: 15分钟 | L9: 核心 | N9: 14 | O9: fact_nr_mro_neighbor_nr_q | Q9: 新建
A10: 9 | B10: =HYPERLINK("#"&A10&"!A1",A10) -> 9 | C10: 网络数据处理系统 | D10: 中间层 | E10: 覆盖分析 | F10: aggr_nr_coverage_base_q | G10: 5G MR用户小区栅格覆盖指标15分钟表(无问题打标) | H10: 5G MR用户小区栅格覆盖指标15分钟表(无问题打标) | I10: 用户小区栅格 | J10: 15分钟 | K10: 15分钟 | L10: 核心 | N10: 14 | O10: ods_nr_mro_northctcc_q、fact_nr_cm_projdata | Q10: 新建
A11: 10 | B11: =HYPERLINK("#"&A11&"!A1",A11) -> 10 | C11: 网络数据处理系统 | D11: 中间层 | E11: 覆盖分析 | F11: aggr_nr_coverage_base_usr_refactor_q | G11: 5G MR用户小区栅格覆盖指标15分钟表 | H11: 5G MR用户小区栅格覆盖指标15分钟表 | I11: 用户小区栅格 | J11: 15分钟 | K11: 15分钟 | L11: 核心 | N11: 14 | O11: aggr_nr_coverage_base_q、aggr_nr_coverage_problem_usrcelgrd_q | P11: 建维优 | Q11: 升级
A12: 11 | B12: =HYPERLINK("#"&A12&"!A1",A12) -> 11 | C12: 网络数据处理系统 | D12: 中间层 | E12: 覆盖分析 | F12: aggr_nr_coverage_base_usr_refactor_h | G12: 5G MR用户小区栅格覆盖指标小时表 | H12: 5G MR用户小区栅格覆盖指标小时表 | I12: 用户小区栅格 | J12: 小时 | K12: 小时 | L12: 核心 | N12: 14 | O12: aggr_nr_coverage_base_usr_refactor_q | P12: 建维优 | Q12: 升级
A13: 13 | B13: =HYPERLINK("#"&A13&"!A1",A13) -> 13 | C13: 网络数据处理系统 | D13: 中间层 | E13: 覆盖分析 | F13: aggr_nr_coverage_reduce_usrcelgrd_q | G13: 5G MR用户小区栅格覆盖指标裁剪15分钟表 | H13: 5G MR用户小区栅格覆盖指标裁剪15分钟表 | I13: 用户小区栅格 | J13: 15分钟 | K13: 15分钟 | L13: 核心 | N13: 14 | O13: aggr_nr_coverage_base_usr_refactor_q | Q13: 新建
A14: 14 | B14: =HYPERLINK("#"&A14&"!A1",A14) -> 14 | C14: 网络数据处理系统 | D14: 中间层 | E14: 覆盖分析 | F14: aggr_nr_coverage_reduce_usrcelgrd_h | G14: 5G MR用户小区栅格覆盖指标裁剪小时表 | H14: 5G MR用户小区栅格覆盖指标裁剪小时表 | I14: 用户小区栅格 | J14: 小时 | K14: 小时 | L14: 核心 | N14: 14 | O14: aggr_nr_coverage_reduce_usrcelgrd_q | Q14: 新建
A15: 15 | B15: =HYPERLINK("#"&A15&"!A1",A15) -> 15 | C15: 网络数据处理系统 | D15: 中间层 | E15: 用户常驻 | F15: aggr_nr_coverage_resident_usrgrd_d | G15: 5G MR用户常驻栅格覆盖指标天表 | H15: 5G MR用户常驻栅格覆盖指标天表 | I15: 用户小区栅格 | J15: 天 | K15: 天 | L15: 核心 | N15: 30 | O15: aggr_nr_coverage_reduce_usrcelgrd_h | Q15: 新建
A16: 16 | B16: =HYPERLINK("#"&A16&"!A1",A16) -> 16 | C16: 网络数据处理系统 | D16: 中间层 | E16: 用户常驻 | F16: aggr_nr_usrareagrd_d | G16: 5G用户区域栅格聚区天表 | H16: 5G用户区域栅格聚区天表 | I16: 用户区域栅格 | J16: 天 | K16: 天 | L16: 核心 | N16: 30 | O16: aggr_nr_coverage_resident_usrgrd_d | Q16: 新建
A17: 17 | B17: =HYPERLINK("#"&A17&"!A1",A17) -> 17 | C17: 网络数据处理系统 | D17: 中间层 | E17: 用户级感知 | F17: aggr_nr_usrareatime_cel_refactor_d | G17: 5G MR用户聚区区域用户小区天表 | H17: 5G MR用户聚区区域用户小区天表 | I17: 用户小区栅格 | J17: 15分钟 | K17: 天 | L17: 核心 | N17: 30 | O17: aggr_nr_usrareagrd_d、aggr_nr_coverage_reduce_usrcelgrd_q | P17: 建维优 | Q17: 升级
A18: 17.1 | B18: =HYPERLINK("#"&A18&"!A1",A18) -> 17.1 | C18: 网络数据处理系统 | D18: 中间层 | E18: 用户级感知 | F18: aggr_nr_coverage_usrcelarea_refactor_d | G18: 5G MR用户小区区域覆盖天表 | H18: 5G MR用户小区区域覆盖天表 | I18: 用户小区区域 | J18: 天 | K18: 天 | L18: 核心 | N18: 30 | O18: aggr_nr_usrareatime_cel_refactor_d | P18: 建维优 | Q18: 升级
A19: 17.2 | B19: =HYPERLINK("#"&A19&"!A1",A19) -> 17.2 | C19: 网络数据处理系统 | D19: 中间层 | E19: 用户级感知 | F19: aggr_nr_usrarea_coverarea_refactor_d | G19: 5G MR用户区域覆盖天表 | H19: 5G MR用户区域覆盖天表 | I19: 用户区域 | J19: 天 | K19: 天 | L19: 核心 | N19: 30 | O19: aggr_nr_coverage_usrcelarea_refactor_d | P19: 建维优 | Q19: 升级
A20: 18 | B20: =HYPERLINK("#"&A20&"!A1",A20) -> 18 | C20: 网络数据处理系统 | D20: 中间层 | E20: 覆盖分析 | F20: aggr_nr_coverage_celgrd_refactor_h | G20: 5G MR小区栅格小时表 | H20: 5G MR小区栅格小时表 | I20: 小区栅格 | J20: 小时 | K20: 小时 | L20: 核心 | N20: 14 | O20: aggr_nr_coverage_base_usr_refactor_h | Q20: 升级
A21: 19 | B21: =HYPERLINK("#"&A21&"!A1",A21) -> 19 | C21: 网络数据处理系统 | D21: 中间层 | E21: 覆盖分析 | F21: aggr_nr_coverage_wide_usrcel_h | G21: 5G MR用户小区小时宽表 | H21: 5G MR用户小区小时宽表 | I21: 用户小区 | J21: 小时 | K21: 小时 | L21: 核心 | N21: 14 | O21: aggr_nr_coverage_base_usr_refactor_h | Q21: 新建
A22: 20 | B22: =HYPERLINK("#"&A22&"!A1",A22) -> 20 | C22: 网络数据处理系统 | D22: 中间层 | E22: 覆盖分析 | F22: aggr_nr_coverage_usrgrd_h | G22: 5G MR用户栅格小时表 | H22: 5G MR用户栅格小时表 | I22: 用户栅格 | J22: 小时 | K22: 小时 | L22: 核心 | N22: 14 | O22: aggr_nr_coverage_base_usr_refactor_h | P22: 建维优 | Q22: 新建
A23: 21 | B23: =HYPERLINK("#"&A23&"!A1",A23) -> 21 | C23: 网络数据处理系统 | D23: 中间层 | E23: 覆盖分析 | F23: aggr_nr_coverage_usrcel_refactor_h | G23: 5G MR用户小区小时共享表 | H23: 5G MR用户小区小时共享表 | I23: 用户小区 | J23: 小时 | K23: 小时 | L23: 核心 | N23: 14 | O23: aggr_nr_coverage_wide_usrcel_h | P23: 5G定制网 | Q23: 升级
A24: 22 | B24: =HYPERLINK("#"&A24&"!A1",A24) -> 22 | C24: 网络数据处理系统 | D24: 中间层 | E24: 覆盖分析 | F24: aggr_nr_coverage_usr_h | G24: 5G MR用户小时表 | H24: 5G MR用户小时表 | I24: 用户 | J24: 小时 | K24: 小时 | L24: 核心 | N24: 14 | O24: aggr_nr_coverage_wide_usrcel_h | Q24: 新建
A25: 23 | B25: =HYPERLINK("#"&A25&"!A1",A25) -> 23 | C25: 网络数据处理系统 | D25: 中间层 | E25: 覆盖分析 | F25: aggr_nr_coverage_cel_refactor_h | G25: 5G MR小区小时表 | H25: 5G MR用户小时表 | I25: 小区 | J25: 小时 | K25: 小时 | L25: 核心 | N25: 14 | O25: aggr_nr_coverage_celgrd_refactor_h | Q25: 升级
A26: 24 | B26: =HYPERLINK("#"&A26&"!A1",A26) -> 24 | C26: 网络数据处理系统 | D26: 中间层 | E26: 覆盖分析 | F26: aggr_nr_coverage_reduce_cel_h | G26: 5G MR小区小时共享表 | H26: 5G MR小区小时共享表 | I26: 小区 | J26: 小时 | K26: 小时 | L26: 核心 | N26: 14 | O26: aggr_nr_coverage_cel_refactor_h | P26: 移动业务感知保障系统 | Q26: 升级 | R26: 输入表变更(输入表使用了别名)
A27: 25 | B27: =HYPERLINK("#"&A27&"!A1",A27) -> 25 | C27: 网络数据处理系统 | D27: 中间层 | E27: 覆盖分析 | F27: aggr_nr_coverage_grd_refactor_h | G27: 5G MR栅格小时表 | H27: 5G MR栅格小时表 | I27: 栅格 | J27: 小时 | K27: 小时 | L27: 核心 | N27: 14 | O27: aggr_nr_coverage_celgrd_refactor_h | P27: 建维优 | Q27: 升级 | R27: 表名沿用，但字段重新设计了，需要删表重建
A28: 26 | B28: =HYPERLINK("#"&A28&"!A1",A28) -> 26 | C28: 网络数据处理系统 | D28: 中间层 | E28: 覆盖分析 | F28: aggr_nr_coverage_celgrd_refactor_d | G28: 5G MR小区栅格天表 | H28: 5G MR小区栅格天表 | I28: 小区栅格 | J28: 天 | K28: 天 | L28: 核心 | N28: 30 | O28: aggr_nr_coverage_celgrd_refactor_h | P28: 建维优 | Q28: 升级
A29: 27 | B29: =HYPERLINK("#"&A29&"!A1",A29) -> 27 | C29: 网络数据处理系统 | D29: 中间层 | E29: 覆盖分析 | F29: aggr_nr_coverage_cel_refactor_d | G29: 5G MR小区天表 | H29: 5G MR小区天表 | I29: 小区 | J29: 天 | K29: 天 | L29: 核心 | N29: 30 | O29: aggr_nr_coverage_celgrd_refactor_d | P29: 5GR、建维优 | Q29: 升级
A30: 28 | B30: =HYPERLINK("#"&A30&"!A1",A30) -> 28 | C30: 网络数据处理系统 | D30: 中间层 | E30: 覆盖分析 | F30: aggr_nr_coverage_rsrpsinr_cel_d | G30: 5G MR小区RSRP&SINR组合指标天表 | H30: 5G MR小区RSRP&SINR组合指标天表 | I30: 小区 | J30: 天 | K30: 天 | L30: 核心 | N30: 30 | O30: aggr_nr_coverage_cel_refactor_d | P30: 5GR | Q30: 升级 | R30: 输入表变更(输入表使用了别名)
A31: 29 | B31: =HYPERLINK("#"&A31&"!A1",A31) -> 29 | C31: 网络数据处理系统 | D31: 中间层 | E31: 覆盖分析 | F31: aggr_nr_coverage_cell_share_refactor_d | G31: 5G MR小区共享天表 | H31: 5G MR小区共享天表 | I31: 小区 | J31: 天 | K31: 天 | L31: 核心 | N31: 30 | O31: aggr_nr_coverage_cel_refactor_d | P31: 5GR | Q31: 升级 | R31: 输入表变更(输入表使用了别名)
A32: 30 | B32: =HYPERLINK("#"&A32&"!A1",A32) -> 30 | C32: 网络数据处理系统 | D32: 中间层 | E32: 覆盖分析 | F32: aggr_nr_coverage_grd_refactor_d | G32: 5G MR栅格天表 | H32: 5G MR栅格天表 | I32: 栅格 | J32: 天 | K32: 天 | L32: 核心 | N32: 30 | O32: aggr_nr_coverage_celgrd_refactor_d | P32: 5GR | Q32: 升级
A33: 31 | B33: =HYPERLINK("#"&A33&"!A1",A33) -> 31 | C33: 网络数据处理系统 | D33: 中间层 | E33: 覆盖分析 | F33: aggr_nr_coverage_rsrpsinr_grd_d | G33: 5G MR栅格RSRP&SINR组合指标天表 | H33: 5G MR栅格RSRP&SINR组合指标天表 | I33: 栅格 | J33: 天 | K33: 天 | L33: 核心 | N33: 30 | O33: aggr_nr_coverage_grd_refactor_d | P33: 5GR | Q33: 升级 | R33: 输入表变更(输入表使用了别名)
A34: 32 | B34: =HYPERLINK("#"&A34&"!A1",A34) -> 32 | C34: 网络数据处理系统 | D34: 中间层 | E34: 覆盖分析 | F34: aggr_nr_coverage_index_reduce_grd_d | G34: 5G MR栅格指标裁剪天表 | H34: 5G MR栅格指标裁剪天表 | I34: 栅格 | J34: 天 | K34: 天 | L34: 核心 | N34: 30 | O34: aggr_nr_coverage_grd_refactor_d | P34: 共建共享 | Q34: 升级
A35: 33 | B35: =HYPERLINK("#"&A35&"!A1",A35) -> 33 | C35: 网络数据处理系统 | D35: 中间层 | E35: 覆盖分析 | F35: aggr_nr_coverage_index_reduce_celgrd_d | G35: 5G MR小区栅格中心经纬度指标裁剪天表 | H35: 5G MR小区栅格中心经纬度指标裁剪天表 | I35: 小区栅格 | J35: 天 | K35: 天 | L35: 核心 | N35: 30 | O35: aggr_nr_coverage_celgrd_refactor_d | P35: 5G定制网 | Q35: 升级 | R35: 输入表变更(输入表使用了别名)
A36: 34 | B36: =HYPERLINK("#"&A36&"!A1",A36) -> 34 | C36: 网络数据处理系统 | D36: 中间层 | E36: 覆盖分析 | F36: aggr_nr_coverage_rsrp_celgrd_d | G36: 5G MR小区栅格RSRP指标共享天表 | H36: 5G MR小区栅格RSRP指标共享天表 | I36: 小区栅格 | J36: 天 | K36: 天 | L36: 核心 | N36: 30 | O36: aggr_nr_coverage_celgrd_refactor_d | P36: 核心系统,支撑基站节能 | Q36: 升级
A37: 35 | B37: =HYPERLINK("#"&A37&"!A1",A37) -> 35 | C37: 网络数据处理系统 | D37: 中间层 | E37: 覆盖分析 | F37: aggr_nr_coverage_usrcel_refactor_d | G37: 5G MR用户小区天表 | H37: 5G MR用户小区天表 | I37: 用户小区 | J37: 天 | K37: 天 | L37: 核心 | N37: 30 | O37: aggr_nr_coverage_wide_usrcel_h | Q37: 升级
A38: 36 | B38: =HYPERLINK("#"&A38&"!A1",A38) -> 36 | C38: 网络数据处理系统 | D38: 中间层 | E38: 覆盖分析 | F38: aggr_nr_coverage_usr_refactor_d | G38: 5G MR用户天表 | H38: 5G MR用户天表 | I38: 用户 | J38: 天 | K38: 天 | L38: 核心 | N38: 30 | O38: aggr_nr_coverage_usrcel_refactor_d | Q38: 升级
A39: 37 | B39: =HYPERLINK("#"&A39&"!A1",A39) -> 37 | C39: 网络数据处理系统 | D39: 中间层 | E39: 覆盖分析 | F39: aggr_nr_coverage_usrgrd_refactor_d | G39: 5G MR用户栅格天表 | H39: 5G MR用户栅格天表 | I39: 用户栅格 | J39: 天 | K39: 天 | L39: 核心 | N39: 30 | O39: aggr_nr_coverage_usrgrd_h | P39: 建维优 | Q39: 升级 | R39: 表名沿用，但字段重新设计了，需要删表重建
A40: 38 | B40: =HYPERLINK("#"&A40&"!A1",A40) -> 38 | C40: 网络数据处理系统 | D40: 中间层 | E40: 高铁优化 | F40: aggr_nr_highspeedrail_coverage_base_refactor_h | G40: 5G高铁用户小区栅格覆盖小时表 | H40: 5G高铁用户小区栅格覆盖小时表 | I40: 线路用户小区栅格 | J40: 小时 | K40: 小时 | L40: 核心 | N40: 14 | O40: aggr_highspeedrail_usrlist_d、aggr_nr_coverage_base_usr_refactor_q | P40: 建维优 | Q40: 升级

Sheet 1
B1: =HYPERLINK("#导航!a2","返回") -> 返回
B3: 目标表基本信息描述
B4: 主题域 | C4: 目标表英文名 | D4: 目标表中文名 | E4: 数据频度 | F4: 模型主键 | G4: 数据描述 | H4: 推送数据库
B5: / | C5: ods_nr_mro_northctcc_temp_new | D5: 5G电联MRO解析详单表 | E5: quarter
B7: 源表基本信息描述
B8: 来源系统 | C8: 源表英文名 | D8: 源表中文名 | E8: 别名 | F8: 任务描述 | G8: 备注 | H8: 是否主表
B11: 详细字段信息
B12: 详细字段信息
B13: PDM字段英文名 | C13: PDM字段类型 | D13: PDM字段中文名（说明） | E13: 源表名 | F13: 源表名 | G13: 源字段英文名 | H13: 算法加工逻辑 | I13: 关联与过滤条件 | J13: 备注 | K13: 字段属性 | L13: 单位 | M13: 取值范围
B14: datetime | C14: string | D14: 样本数据测量对象 UE 的样本测量时间 | K14: 详单 | L14: 无 | M14: 无
B15: gnbid | C15: bigint | D15: 5G基站标识 | K15: 详单 | L15: 无 | M15: 无
B16: cellid | C16: int | D16: 5G小区标识 | K16: 详单 | L16: 无 | M16: 无
B17: plmn | C17: array<int> | D17: UE接入NR服务小区的PLMN(公共陆地移动网) | K17: 详单 | L17: 无 | M17: 无
B18: nrscssrsrp | C18: array<int> | D18: NR 服务小区的 SSB 参考信 号接收功率 | K18: 详单 | L18: 无 | M18: 无
B19: nrscssrsrq | C19: array<int> | D19: NR 服务小区的 SSB 参考信号接收质量 | K19: 详单 | L19: 无 | M19: 无
B20: nrscsssinr | C20: array<int> | D20: NR 服务小区的 SSB 参考信号信噪比 | K20: 详单 | L20: 无 | M20: 无
B21: nrscssbeamid | C21: array<int> | D21: NR 服务小区的 SSB 波束号 | K21: 详单 | L21: 无 | M21: 无
B22: nrscarfcn | C22: array<int> | D22: NR 服务小区载波号 | K22: 详单 | L22: 无 | M22: 无
B23: nrscpci | C23: array<int> | D23: NR 服务小区的物理小区识别码 | K23: 详单 | L23: 无 | M23: 无
B24: nrsctadv | C24: array<int> | D24: NR 服务小区的时间提前量 | K24: 详单 | L24: 无 | M24: 无
B25: nrncellcount | C25: tinyint | D25: NR 服务小区的NR邻小区个数 | K25: 详单 | L25: 无 | M25: 无
... B60: vaoa | C60: array<int> | D60: 垂直AOA | K60: 详单 | L60: 无 | M60: 无
B61: p_provincecode | C61: int | D61: 省分区
B62: p_date | C62: string | D62: 天分区
B63: p_hour | C63: int | D63: 小时分区
B64: p_region | C64: int | D64: 厂家分区：100001:中兴|100002:华为|100003:诺基亚|100004:爱立信|100005:大唐
B65: p_quarter | C65: int | D65: 15分钟分区

Sheet 2
B1: =HYPERLINK("#导航!a2","返回") -> 返回
B3: 目标表基本信息描述
B4: 主题域 | C4: 目标表英文名 | D4: 目标表中文名 | E4: 数据频度 | F4: 模型主键 | G4: 数据描述 | H4: 推送数据库
B5: / | C5: ods_nr_mro_northctcc_location | D5: 5G电联MRO位置定位详单表 | E5: quarter
B7: 源表基本信息描述
B8: 来源系统 | C8: 源表英文名 | D8: 源表中文名 | E8: 别名 | F8: 任务描述 | G8: 备注 | H8: 是否主表
C9: ods_nr_mro_northctcc_temp_new | D9: 5G电联MRO解析详单表 | E9: A
B12: 详细字段信息
B13: 详细字段信息
B14: PDM字段英文名 | C14: PDM字段类型 | D14: PDM字段中文名（说明） | E14: 源表名 | F14: 源字段英文名 | G14: 算法加工逻辑 | H14: 关联与过滤条件 | I14: 备注 | J14: 字段属性 | K14: 单位 | L14: 取值范围
B15: datetime | C15: string | D15: 样本数据测量对象 UE 的样本测量时间 | J15: 详单 | K15: 无 | L15: 无
B16: gnbid | C16: bigint | D16: 5G基站标识 | J16: 详单 | K16: 无 | L16: 无
B17: cellid | C17: int | D17: 5G小区标识 | J17: 详单 | K17: 无 | L17: 无
B18: plmn | C18: string | D18: UE接入NR服务小区的PLMN(公共陆地移动网) | J18: 详单 | K18: 无 | L18: 无
B19: nrscssrsrp | C19: smallint | D19: NR 服务小区的 SSB 参考信 号接收功率 | J19: 详单 | K19: 无 | L19: 无
B20: nrscssrsrq | C20: smallint | D20: NR 服务小区的 SSB 参考信号接收质量 | J20: 详单 | K20: 无 | L20: 无
B21: nrscsssinr | C21: smallint | D21: NR 服务小区的 SSB 参考信号信噪比 | J21: 详单 | K21: 无 | L21: 无
B22: nrscssbeamid | C22: smallint | D22: NR 服务小区的 SSB 波束号 | J22: 详单 | K22: 无 | L22: 无
B23: nrscarfcn | C23: bigint | D23: NR 服务小区载波号 | J23: 详单 | K23: 无 | L23: 无
B24: nrscpci | C24: smallint | D24: NR 服务小区的物理小区识别码 | J24: 详单 | K24: 无 | L24: 无
B25: nrsctadv | C25: int | D25: NR 服务小区的时间提前量 | J25: 详单 | K25: 无 | L25: 无
B26: nrncellcount | C26: tinyint | D26: NR 服务小区的NR邻小区个数 | J26: 详单 | K26: 无 | L26: 无
... B62: ranuengapid | C62: bigint | D62: gNB UE应用协议标识 | J62: 详单 | K62: 无 | L62: 无
B63: p_provincecode | C63: int | D63: 省分区
B64: p_date | C64: string | D64: 天分区
B65: p_hour | C65: int | D65: 小时分区
B66: p_region | C66: int | D66: 厂家分区：100001:中兴|100002:华为|100003:诺基亚|100004:爱立信|100005:大唐
B67: p_quarter | C67: int | D67: 15分钟分区

Sheet 3
B1: =HYPERLINK("#导航!a2","返回") -> 返回
B3: 目标表基本信息描述
B4: 主题域 | C4: 目标表英文名 | D4: 目标表中文名 | E4: 数据频度 | F4: 模型主键 | G4: 数据描述 | H4: 推送数据库
B5: / | C5: ods_nr_mro_northctcc_q | D5: 5G电联MRO用户回填详单表 | E5: quarter | G5: 主小区RSRP/SINR/RSRQ值未转换，邻小区RSRP/SINR/RSRQ值未转换，做后向邻区表时需注意
B7: 源表基本信息描述
B8: 来源系统 | C8: 源表英文名 | D8: 源表中文名 | E8: 别名 | F8: 任务描述 | G8: 备注 | H8: 是否主表
C9: ods_nr_mro_northctcc_location | D9: 5G电联MRO位置定位详单表 | E9: A | F9: 关联回填用户信息，关联逻辑保持与现状一致（注意：对msisdn字段处理时，需要去掉86） | H9: 是
C10: ods_5gdpi_n1n2_e2e_telecom_5min | D10: 5G N1N2接口层详单表 | E10: B
B12: 详细字段信息
B13: 详细字段信息
B14: PDM字段英文名 | C14: PDM字段类型 | D14: PDM字段中文名（说明） | E14: 源表名 | F14: 源字段英文名 | G14: 算法加工逻辑 | H14: 关联与过滤条件 | I14: 备注 | J14: 字段属性 | K14: 单位 | L14: 取值范围
B15: datetime | C15: string | D15: 样本数据测量对象 UE 的样本测量时间 | E15: A | G15: concat_ws(' ',split(datetime,'T')) | J15: 详单 | K15: 无 | L15: 无
A16: =ROW()-1 -> 15 | B16: gnbid | C16: bigint | D16: 5G基站标识 | E16: A | F16: gnbid | G16: 直取 | J16: 详单 | K16: 无 | L16: 无
B17: cellid | C17: int | D17: 5G小区标识 | E17: A | F17: cellid | G17: 直取 | J17: 详单 | K17: 无 | L17: 无
B18: plmn | C18: string | D18: UE接入NR服务小区的PLMN(公共陆地移动网) | E18: A | F18: plmn | G18: 直取 | J18: 详单 | K18: 无 | L18: 无
B19: imsi | C19: string | D19: 用户imsi | E19: B | G19: 关联回填supi | J19: 详单 | K19: 无 | L19: 无
B20: imei | C20: string | D20: 用户imei | E20: B | G20: 关联回填pei | J20: 详单 | K20: 无 | L20: 无
B21: msisdn | C21: string | D21: 用户号码 | E21: B | G21: 关联回填msisdn，需要做去86的操作 | J21: 详单 | K21: 无 | L21: 无
B22: s_nssai_sst | C22: string | D22: 网络切片选择辅助信息（切片/服务类型） | E22: B | G22: 关联回填s_nssai_sst | J22: 详单 | K22: 无 | L22: 无
B23: s_nssai_sd | C23: string | D23: 网络切片选择辅助信息（切片差分器） | E23: B | G23: 关联回填s_nssai_sd | J23: 详单 | K23: 无 | L23: 无
B24: nrscssrsrp | C24: int | D24: NR 服务小区的 SSB 参考信 号接收功率 | E24: A | F24: nrscssrsrp | G24: 直取 | J24: 详单 | K24: 无 | L24: 无
B25: nrscssrsrq | C25: int | D25: NR 服务小区的 SSB 参考信号接收质量 | E25: A | F25: nrscssrsrq | G25: 直取 | J25: 详单 | K25: 无 | L25: 无
B26: nrscsssinr | C26: int | D26: NR 服务小区的 SSB 参考信号信噪比 | E26: A | F26: nrscsssinr | G26: 直取 | J26: 详单 | K26: 无 | L26: 无
B27: nrscssbeamid | C27: int | D27: NR 服务小区的 SSB 波束号 | E27: A | F27: nrscssbeamid | G27: 直取 | J27: 详单 | K27: 无 | L27: 无
B28: nrscarfcn | C28: bigint | D28: NR 服务小区载波号 | E28: A | F28: nrscarfcn | G28: 直取 | J28: 详单 | K28: 无 | L28: 无
B29: nrscpci | C29: int | D29: NR 服务小区的物理小区识别码 | E29: A | F29: nrscpci | G29: 直取 | J29: 详单 | K29: 无 | L29: 无
B30: nrsctadv | C30: int | D30: NR 服务小区的时间提前量 | E30: A | F30: nrsctadv | G30: 直取 | J30: 详单 | K30: 无 | L30: 无
B31: nrncellcount | C31: int | D31: NR 服务小区的NR邻小区个数 | E31: A | F31: nrncellcount | G31: 直取 | J31: 详单 | K31: 无 | L31: 无
B32: nrncssrsrp | C32: array<int> | D32: NR 已定义邻区关系和未定义邻区关系小区的 SSB 参考信号接收功率 | E32: A | F32: nrncssrsrp | G32: 直取 | J32: 详单 | K32: 无 | L32: 无
B33: nrncssrsrq | C33: array<int> | D33: NR 已定义邻区关系和未定义邻区关系小区的 SSB 参考信号接收质量 | E33: A | F33: nrncssrsrq | G33: 直取 | J33: 详单 | K33: 无 | L33: 无
B34: nrncsssinr | C34: array<int> | D34: NR 已定义邻区关系和未定义邻区关系小区的 SSB 参考信号信噪比 | E34: A | F34: nrncsssinr | G34: 直取 | J34: 详单 | K34: 无 | L34: 无
B35: nrncssbeamid | C35: array<int> | D35: NR 已定义邻区关系和未定义邻区关系的 SSB 波束号 | E35: A | F35: nrncssbeamid | G35: 直取 | J35: 详单 | K35: 无 | L35: 无
... B66: vaoa | C66: int | D66: 垂直AOA | E66: A | F66: vaoa | G66: 直取 | J66: 详单 | K66: 无 | L66: 无
B67: meastime | C67: bigint | D67: 测量时间戳 | E67: A | G67: 转换成时间戳。cast(concat(unix_timestamp(concat_ws(' ',split(datetime,'T'))), substring(datetime,21,3)) as bigint) | I67: 新增字段 | J67: 详单 | K67: 无 | L67: 无
B68: mrkey | C68: bigint | D68: MR采样点唯一标识 | E68: A | G68: cast(concat(substring(datetime,15,2), substring(datetime,18,2), substring(datetime,21,3), cast(rand()*100000000000 as bigint)) as bigint) | I68: 新增字段 | J68: 详单 | K68: 无 | L68: 无
B69: x_offset_20 | C69: int | D69: 栅格坐标x轴偏移_20米 | E69: A | G69: 1米转20米栅格 | J69: 详单 | K69: 无 | L69: 无
B70: y_offset_20 | C70: int | D70: 栅格坐标y轴偏移_20米 | E70: A | G70: 1米转20米栅格 | J70: 详单 | K70: 无 | L70: 无
B71: p_provincecode | C71: int | D71: 省分区
B72: p_date | C72: string | D72: 天分区
B73: p_hour | C73: int | D73: 小时分区
...

Sheet 4
B1: =HYPERLINK("#导航!a2","返回") -> 返回
B3: 目标表基本信息描述
B4: 主题域 | C4: 目标表英文名 | D4: 目标表中文名 | E4: 数据频度 | F4: 模型主键 | G4: 数据描述 | H4: 推送数据库
B5: / | C5: ods_nr_mro_northctcc_reduce | D5: 5G电联MRO用户回填详单表 | E5: quarter
B7: 源表基本信息描述
B8: 来源系统 | C8: 源表英文名 | D8: 源表中文名 | E8: 别名 | F8: 任务描述 | G8: 备注 | H8: 是否主表
C9: ods_nr_mro_northctcc_q | D9: 5G电联MRO用户回填详单表 | E9: A | H9: 是
B11: 详细字段信息
B12: 详细字段信息
B13: PDM字段英文名 | C13: PDM字段类型 | D13: PDM字段中文名（说明） | E13: 源表名 | F13: 源字段英文名 | G13: 算法加工逻辑 | H13: 关联与过滤条件 | I13: 备注 | J13: 字段属性 | K13: 单位 | L13: 取值范围
B14: datetime | C14: string | D14: 测量时间 | E14: A | F14: datetime | G14: 直取 | J14: 详单 | K14: 无 | L14: 无
A15: =ROW()-1 -> 14 | B15: imsi | C15: string | D15: 用户imsi | E15: A | F15: imsi | G15: 直取 | J15: 详单 | K15: 无 | L15: 无
B16: msisdn | C16: string | D16: 手机号吗 | E16: A | F16: msisdn | G16: 直取 | J16: 详单 | K16: 无 | L16: 无
B17: imei | C17: string | D17: 用户imei | E17: A | F17: imei | G17: 直取 | J17: 详单 | K17: 无 | L17: 无
B18: gnbid | C18: bigint | D18: 基站ID | E18: A | F18: gnbid | G18: 直取 | J18: 详单 | K18: 无 | L18: 无
B19: cellid | C19: int | D19: 小区ID | E19: A | F19: cellid | G19: 直取 | J19: 详单 | K19: 无 | L19: 无
B20: provincecode | C20: int | D20: 省编码 | E20: A | F20: p_provincecode | G20: 直取 | J20: 详单 | K20: 无 | L20: 无
B21: mrlon | C21: double | D21: MR经度 | E21: A | F21: mrlon | G21: 直取 | J21: 详单 | K21: 无 | L21: 无
B22: mrlat | C22: double | D22: MR纬度 | E22: A | F22: mrlat | G22: 直取 | J22: 详单 | K22: 无 | L22: 无
B23: locationtype | C23: int | D23: 定位类型 | E23: A | F23: locationtype | G23: 直取 | J23: 详单 | K23: 无 | L23: 无
B24: p_provincecode | C24: int | D24: 省分区
B25: p_date | C25: string | D25: 天分区
B26: p_hour | C26: int | D26: 小时分区
B27: p_region | C27: int | D27: 厂家分区：100001:中兴|100002:华为|100003:诺基亚|100004:爱立信|100005:大唐
B28: p_quarter | C28: int | D28: 15分钟分区

Sheet 5
B1: =HYPERLINK("#导航!a2","返回") -> 返回
B3: 目标表基本信息描述
B4: 主题域 | C4: 目标表英文名 | D4: 目标表中文名 | E4: 数据频度 | F4: 模型主键 | G4: 数据描述 | H4: 推送数据库
B5: / | C5: fact_nr_mro_neighbor_nr_q | D5: 5G电联MRO邻区事实表(5G邻区) | E5: quarter
B7: 源表基本信息描述
B8: 来源系统 | C8: 源表英文名 | D8: 源表中文名 | E8: 别名 | F8: 任务描述 | G8: 备注 | H8: 是否主表
C9: ods_nr_mro_northctcc_q | D9: 5G电联MRO用户回填详单表 | E9: A | H9: 是
C10: fact_nr_cm_projdata | D10: 5G电联工参 | E10: B | G10: 以cellkey进行去重后再参与计算
B12: 详细字段信息
B13: 详细字段信息
B14: PDM字段英文名 | C14: PDM字段类型 | D14: PDM字段中文名（说明） | E14: 源表名 | F14: 源字段英文名 | G14: 算法加工逻辑 | H14: 关联与过滤条件 | I14: 备注 | J14: 字段属性 | K14: 单位 | L14: 取值范围
B15: mrkey | C15: bigint | D15: MR的唯一主键 | E15: A | F15: mrkey | G15: 直取 | J15: 详单 | K15: 无 | L15: 无
A16: =ROW()-1 -> 15 | B16: plmn | C16: string | D16: UE接入NR服务小区的PLMN(公共陆地移动网) | E16: A | F16: plmn | G16: 直取 | J16: 详单 | K16: 无 | L16: 无
B17: data_source | C17: int | D17: 数据源类型 0：电信独享_电信用户 1：电信共享_电信用户 2：电信共享_联通用户 3：联通共享_电信用户 4：联通共享_联通用户 | E17: A | F17: data_source | G17: 直取 | J17: 详单 | K17: 无 | L17: 无
B18: imsi | C18: string | D18: 业务过程用户IMSI号码 | E18: A | F18: imsi | G18: 直取 | J18: 详单 | K18: 无 | L18: 无
B19: msisdn | C19: string | D19: 电话号码 | E19: A | F19: msisdn | G19: 直取 | J19: 详单 | K19: 无 | L19: 无
B20: imei | C20: string | D20: 用户终端imei | E20: A | F20: imei | G20: 直取 | J20: 详单 | K20: 无 | L20: 无
B21: gnbid | C21: int | D21: 主小区的基站ID | E21: A | F21: =B21 -> gnbid | G21: 直取 | J21: 详单 | K21: 无 | L21: 无
B22: cellid | C22: int | D22: 主小区ID | E22: A | F22: =B22 -> cellid | G22: 直取 | J22: 详单 | K22: 无 | L22: 无
B23: cellkey | C23: string | D23: 小区cellkey | E23: A | G23: concat(gnbid,"_",cellid) | J23: 详单 | K23: 无 | L23: 无
B24: arfcn | C24: int | D24: 下行频点号 | E24: A | F24: nrscarfcn | G24: 直取 | J24: 详单 | K24: 无 | L24: 无
B25: pci | C25: int | D25: 物理层小区ID | E25: A | F25: nrscpci | G25: 直取 | J25: 详单 | K25: 无 | L25: 无
B26: scssbeamid | C26: int | D26: 服务小区的 SSB 波束号 | E26: A | F26: nrscssbeamid | G26: 直取 | J26: 详单 | K26: 无 | L26: 无
B27: srsrp | C27: int | D27: 主小区RSRP | E27: A | G27: nrscssrsrp-156 | J27: 详单 | K27: 无 | L27: 无
B28: srsrq | C28: double | D28: 主小区RSRQ | E28: A | G28: nrscssrsrq/2-43 | J28: 详单 | K28: 无 | L28: 无
B29: ssinr | C29: double | D29: 主小区SINR | G29: nrscsssinr/2-23 | J29: 详单 | K29: 无 | L29: 无
B30: narfcn | C30: int | D30: 邻区下行频点号 | E30: A | F30: nrncarfcn | G30: 直取 | J30: 详单 | K30: 无 | L30: 无
B31: npci | C31: int | D31: 邻区物理层小区ID | E31: A | F31: nrncpci | G31: 直取 | J31: 详单 | K31: 无 | L31: 无
B32: ncssbeamid | C32: int | D32: 邻小区的 SSB 波束号 | E32: A | F32: nrncssbeamid | G32: 直取 | J32: 详单 | K32: 无 | L32: 无
B33: nrsrp | C33: int | D33: 邻小区RSRP | E33: A | G33: nrncssrsrp-156 | J33: 详单 | K33: 无 | L33: 无
B34: nrsrq | C34: double | D34: 邻小区RSRQ | E34: A | G34: nrncssrsrq/2-43 | J34: 详单 | K34: 无 | L34: 无
B35: nsinr | C35: double | D35: 邻小区SINR | E35: A | G35: nrncsssinr/2-23 | J35: 详单 | K35: 无 | L35: 无
B36: ncellkey | C36: string | D36: 邻区cellkey | E36: A | G36: 数组拆分后：concat(nrngnbid,"_",nrncellid) | J36: 详单 | K36: 无 | L36: 无
B37: scelllon | C37: double | D37: 主小区经度 | E37: B | G37: 使用cellkey关联工参回填 | J37: 详单 | K37: 无 | L37: 无
B38: scelllat | C38: double | D38: 主小区纬度 | E38: B | G38: 使用cellkey关联工参回填 | J38: 详单 | K38: 无 | L38: 无
B39: ncelllon | C39: double | D39: 邻区经度 | E39: B | G39: 使用ncellkey关联工参回填 | J39: 详单 | K39: 无 | L39: 无
B40: ncelllat | C40: double | D40: 邻区纬度 | E40: B | G40: 使用ncellkey关联工参回填 | J40: 详单 | K40: 无 | L40: 无
B41: mrlon | C41: double | D41: 终端上报MR时的经度 | E41: A | F41: mrlon | G41: 直取 | J41: 详单 | K41: 无 | L41: 无
B42: mrlat | C42: double | D42: 终端上报MR时的纬度 | E42: A | F42: mrlat | G42: 直取 | J42: 详单 | K42: 无 | L42: 无
B43: is_weakcover | C43: int | D43: 是否弱覆盖采样点 | E43: A | G43: case when nrscssrsrp-156 <-110 then 1 else 0 end | J43: 详单 | K43: 无 | L43: 无
...

Sheet 6
B1: =HYPERLINK("#导航!a2","返回") -> 返回
B3: 目标表基本信息描述
B4: 主题域 | C4: 目标表英文名 | D4: 目标表中文名 | E4: 数据频度 | F4: 模型主键 | G4: 数据描述 | H4: 推送数据库
B5: 覆盖分析 | C5: aggr_nr_sncell_problem_h | D5: MR数据主邻小区对覆盖问题分析汇聚小时表(重叠覆盖与MOD30) | E5: hour
B7: 源表基本信息描述
B8: 来源系统 | C8: 源表英文名 | D8: 源表中文名 | E8: 别名 | F8: 任务描述 | G8: 备注 | H8: 是否主表
C9: fact_nr_mro_neighbor_nr_q | D9: 5G电联MRO邻区事实表(5G邻区) | E9: A | F9: 过滤条件：(is_mod30interfer=1) or (is_overlap=1 and snearfcnflag=1 and overlapsrsrpflag=1 and overlapsnrsrpflag=1) | G9: 1、A left join C，回填主邻小区信息 2、根据重叠覆盖或者MOD3干扰邻区对信息通过主邻小区、栅格进行重叠覆盖MR采样点统计、平均RSRP计算 | H9: 是
C10: fact_nr_cm_projdata | D10: 5G电联小区工参 | E10: C
B13: 详细字段信息
B14: PDM字段英文名 | C14: PDM字段类型 | D14: PDM字段中文名（说明） | E14: 源表名 | F14: 源字段英文名 | G14: 算法加工逻辑 | H14: 关联与过滤条件 | I14: 备注 | J14: 字段属性 | K14: 单位 | L14: 取值范围
B15: day | C15: string | D15: 天 | E15: A | F15: p_date | J15: 维度 | K15: 无 | L15: 无
B16: hour | C16: int | D16: 小时分区 | E16: A | F16: p_hour | J16: 维度 | K16: 无 | L16: 无
B17: provincecode | C17: int | D17: 省分区 | E17: A | F17: p_provincecode | G17: 直取 | J17: 维度 | K17: 无 | L17: 无
B18: citycode | C18: int | D18: 市id | E18: C | F18: citycode | G18: 主小区关联工参回填 | J18: 维度 | K18: 无 | L18: 无
B19: districtcode | C19: int | D19: 区id | E19: C | F19: districtcode | G19: 主小区关联工参回填 | J19: 维度 | K19: 无 | L19: 无
B20: province_name | C20: string | D20: 省名称 | E20: C | F20: province | G20: 主小区关联工参回填 | J20: 维度 | K20: 无 | L20: 无
B21: city_name | C21: string | D21: 市名称 | E21: C | F21: city | G21: 主小区关联工参回填 | J21: 维度 | K21: 无 | L21: 无
B22: district_name | C22: string | D22: 区名称 | E22: C | F22: district | G22: 主小区关联工参回填 | J22: 维度 | K22: 无 | L22: 无
B23: cellkey | C23: string | D23: 小区标识 | E23: A | F23: cellkey | G23: 直取 | J23: 维度 | K23: 无 | L23: 无
B24: freq | C24: string | D24: 小区频段 | E24: A | G24: case when arfcn>100000 and substr(arfcn,1,1)=4 then '2.1G' when arfcn>100000 and substr(arfcn,1,1)=6 then '3.5G' when arfcn>100000 and substr(arfcn,1,2)=17 then '800M' when arfcn>100000 and (substr(arfcn,1,2)=18 or substr(arfcn,1,2)=19 then '900M' else 'other' end | J24: 维度 | K24: 无 | L24: 无
B25: cell_name | C25: string | D25: 小区名称 | E25: C | F25: cellname | G25: 主小区关联工参回填 | J25: 维度 | K25: 无 | L25: 无
B26: cell_lon | C26: double | D26: 小区经度 | E26: C | F26: cell_longitude | G26: 主小区关联工参回填 | J26: 维度 | K26: 无 | L26: 无
B27: cell_lat | C27: double | D27: 小区纬度 | E27: C | F27: cell_latitude | G27: 主小区关联工参回填 | J27: 维度 | K27: 无 | L27: 无
B28: azimuth | C28: int | D28: 小区方位角 | E28: C | F28: cell_azimuth | G28: 主小区关联工参回填 | J28: 维度 | K28: 无 | L28: 无
B29: ncellkey | C29: string | D29: 邻区cellkey | E29: A | F29: ncellkey | G29: 直取 | J29: 维度 | K29: 无 | L29: 无
B30: nfreq | C30: string | D30: 邻小区频段 | E30: A | G30: case when narfcn>100000 and substr(narfcn,1,1)=4 then '2.1G' when narfcn>100000 and substr(narfcn,1,1)=6 then '3.5G' when narfcn>100000 and substr(narfcn,1,2)=17 then '800M' when narfcn>100000 and (substr(narfcn,1,2)=18 or substr(narfcn,1,2)=19 then '900M' else 'other' end | J30: 维度 | K30: 无 | L30: 无
B31: ncell_name | C31: string | D31: 邻小区名称 | E31: C | F31: cellname | G31: 邻小区关联工参回填 | J31: 维度 | K31: 无 | L31: 无
B32: ncell_lon | C32: double | D32: 邻小区经度 | E32: C | F32: cell_longitude | G32: 邻小区关联工参回填 | J32: 维度 | K32: 无 | L32: 无
B33: ncell_lat | C33: double | D33: 邻小区纬度 | E33: C | F33: cell_latitude | G33: 邻小区关联工参回填 | J33: 维度 | K33: 无 | L33: 无
B34: nazimuth | C34: int | D34: 邻小区方位角 | E34: C | F34: cell_azimuth | G34: 邻小区关联工参回填 | J34: 维度 | K34: 无 | L34: 无
B35: prbplem_type | C35: int | D35: 问题类型 0：重叠覆盖+MOD30干扰+自定义MOD30干扰； 1：重叠覆盖+MOD30干扰； 2：重叠覆盖+自定义MOD30干扰 3：MOD30干扰+自定义MOD30干扰 4：重叠覆盖 5：MOD30干扰 6：自定义MOD30干扰 | E35: A | G35: 以mrkey,cellkey分组 1、满足sum(is_overlap)>0 and sum(is_mod30interfer)>0 and sum(is_mod30interfer_custom)>0则赋值为0 2、满足sum(is_overlap)>0 and sum(is_mod30interfer)>0则赋值为1； 3、满足sum(is_overlap)>0 and sum(is_mod30interfer_custom)>0则赋值为2； 4、满足sum(is_mod30interfer)>0 and sum(is_mod30interfer_custom)>0则赋值为3 5、满足sum(is_overlap)>0则赋值为4 6、满足sum(is_mod30interfer)>0则赋值为5 7、满足sum(is_mod30interfer_custom)>0则赋值为6 | I35: 算法升级 | J35: 维度 | K35: 无 | L35: 无
B36: problem_scell_avgrsrp | C36: double | D36: 覆盖质差主小区平均RSRP | E36: A | G36: avg(srsrp) | J36: 指标 | K36: 无 | L36: [-156,-29]
B37: problem_ncell_avgrsrp | C37: double | D37: 覆盖质差邻小区平均RSRP | E37: A | G37: avg(nrsrp) | J37: 指标 | K37: 无 | L37: [-156,-29]
B38: problem_mr_cnt | C38: bigint | D38: 覆盖质差MR采样点数 | E38: A | G38: count(*) | J38: 指标 | K38: 无 | L38: >=0
B39: pci | C39: int | D39: 主小区pci | E39: C | F39: pci | G39: cellkey关联工参回填 | J39: 维度 | K39: 无 | L39: 无
B40: vendor | C40: string | D40: 主小区厂商 | E40: C | F40: vendor | G40: cellkey关联工参回填 | J40: 维度 | K40: 无 | L40: 无
B41: npci | C41: int | D41: 邻小区pci | E41: C | F41: pci | G41: ncellkey关联工参回填 | J41: 维度 | K41: 无 | L41: 无
B42: nvendor | C42: string | D42: 邻小区厂商 | E42: C | F42: vendor | G42: ncellkey关联工参回填 | J42: 维度 | K42: 无 | L42: 无
B43: indoor_flag | C43: int | D43: 主小区覆盖类型 | E43: C | F43: indoor_flag | G43: cellkey关联工参回填 | J43: 维度 | K43: 无 | L43: 无
B44: nindoor_flag | C44: int | D44: 邻小区覆盖类型 | E44: C | F44: indoor_flag | G44: ncellkey关联工参回填 | J44: 维度 | K44: 无 | L44: 无
...

Sheet 7
B1: =HYPERLINK("#导航!a2","返回") -> 返回
B3: 目标表基本信息描述
B4: 主题域 | C4: 目标表英文名 | D4: 目标表中文名 | E4: 数据频度 | F4: 模型主键 | G4: 数据描述 | H4: 推送数据库
B5: 覆盖分析 | C5: aggr_nr_sncell_problem_d | D5: MR数据主邻小区对覆盖问题分析汇聚天表(重叠覆盖与MOD30) | E5: day
B7: 源表基本信息描述
B8: 来源系统 | C8: 源表英文名 | D8: 源表中文名 | E8: 别名 | F8: 任务描述 | G8: 备注 | H8: 是否主表
C9: aggr_nr_sncell_problem_h | D9: MR数据主邻小区对覆盖问题分析汇聚小时表(重叠覆盖与MOD30) | E9: A | H9: 是
B14: 详细字段信息
B15: PDM字段英文名 | C15: PDM字段类型 | D15: PDM字段中文名（说明） | E15: 源表名 | F15: 源字段英文名 | G15: 算法加工逻辑 | H15: 关联与过滤条件 | I15: 备注 | J15: 字段属性 | K15: 单位 | L15: 取值范围
B16: day | C16: string | D16: 天 | E16: A | F16: p_date | J16: 维度 | K16: 无 | L16: 无
B17: provincecode | C17: int | D17: 省分区 | E17: A | F17: provincecode | G17: 直取 | J17: 维度 | K17: 无 | L17: 无
B18: citycode | C18: int | D18: 市id | E18: A | F18: citycode | G18: 直取 | J18: 维度 | K18: 无 | L18: 无
B19: districtcode | C19: int | D19: 区id | E19: A | F19: districtcode | G19: 直取 | J19: 维度 | K19: 无 | L19: 无
B20: province_name | C20: string | D20: 省名称 | E20: A | F20: province_name | G20: 直取 | J20: 维度 | K20: 无 | L20: 无
B21: city_name | C21: string | D21: 市名称 | E21: A | F21: city_name | G21: 直取 | J21: 维度 | K21: 无 | L21: 无
B22: district_name | C22: string | D22: 区名称 | E22: A | F22: district_name | G22: 直取 | J22: 维度 | K22: 无 | L22: 无
B23: cellkey | C23: string | D23: 小区标识 | E23: A | F23: cellkey | G23: 直取 | J23: 维度 | K23: 无 | L23: 无
B24: freq | C24: string | D24: 小区频段 | E24: A | F24: freq | G24: 直取 | J24: 维度 | K24: 无 | L24: 无
B25: cell_name | C25: string | D25: 小区名称 | E25: A | F25: cell_name | G25: 直取 | J25: 维度 | K25: 无 | L25: 无
B26: cell_lon | C26: double | D26: 小区经度 | E26: A | F26: cell_lon | G26: 直取 | J26: 维度 | K26: 无 | L26: 无
B27: cell_lat | C27: double | D27: 小区纬度 | E27: A | F27: cell_lat | G27: 直取 | J27: 维度 | K27: 无 | L27: 无
B28: azimuth | C28: int | D28: 小区方位角 | E28: A | F28: azimuth | G28: 直取 | J28: 维度 | K28: 无 | L28: 无
... B35: prbplem_type | C35: int | D35: 问题类型 0：重叠覆盖+MOD30干扰+自定义MOD30干扰； 1：重叠覆盖+MOD30干扰； 2：重叠覆盖+自定义MOD30干扰 3：MOD30干扰+自定义MOD30干扰 4：重叠覆盖 5：MOD30干扰 6：自定义MOD30干扰 | E35: A | F35: prbplem_type | G35: 直取 | J35: 维度 | K35: 无 | L35: 无
B36: problem_scell_avgrsrp | C36: double | D36: 覆盖质差主小区平均RSRP | E36: A | G36: sum(problem_scell_avgrsrp*problem_mr_cnt)/sum(problem_mr_cnt) | J36: 指标 | K36: 无 | L36: [-156,-29]
B37: problem_ncell_avgrsrp | C37: double | D37: 覆盖质差邻小区平均RSRP | E37: A | G37: sum(problem_ncell_avgrsrp*problem_mr_cnt)/sum(problem_mr_cnt) | J37: 指标 | K37: 无 | L37: [-156,-29]
B38: problem_mr_cnt | C38: bigint | D38: 覆盖质差MR采样点数 | E38: A | G38: sum(problem_mr_cnt) | J38: 指标 | K38: 无 | L38: >=0
B39: pci | C39: int | D39: 主小区pci | E39: A | F39: pci | G39: 直取 | J39: 维度 | K39: 无 | L39: 无
B40: vendor | C40: string | D40: 主小区厂商 | E40: A | F40: vendor | G40: 直取 | J40: 维度 | K40: 无 | L40: 无
B41: npci | C41: int | D41: 邻小区pci | E41: A | F41: npci | G41: 直取 | J41: 维度 | K41: 无 | L41: 无
B42: nvendor | C42: string | D42: 邻小区厂商 | E42: A | F42: nvendor | G42: 直取 | J42: 维度 | K42: 无 | L42: 无
B43: indoor_flag | C43: int | D43: 主小区覆盖类型 | E43: A | F43: indoor_flag | G43: 直取 | J43: 维度 | K43: 无 | L43: 无
B44: nindoor_flag | C44: int | D44: 邻小区覆盖类型 | E44: A | F44: nindoor_flag | G44: 直取 | J44: 维度 | K44: 无 | L44: 无
B45: data_source | C45: int | D45: 数据源类型 0：电信独享_电信用户 1：电信共享_电信用户 2：电信共享_联通用户 3：联通共享_电信用户 4：联通共享_联通用户 | E45: A | F45: =B45 -> data_source | G45: 直取 | I45: 新增字段 | J45: 维度 | K45: 无 | L45: 无
B46: plmn | C46: string | D46: UE接入E-utran网络使用的PLMN号。 | E46: A | F46: =B46 -> plmn | G46: 直取 | I46: 新增字段 | J46: 维度 | K46: 无 | L46: 无
B47: p_provincecode | C47: int | D47: 省分区
B48: p_date | C48: string | D48: 天分区

Sheet 8
B1: =HYPERLINK("#导航!a2","返回") -> 返回
B3: 目标表基本信息描述
B4: 主题域 | C4: 目标表英文名 | D4: 目标表中文名 | E4: 数据频度 | F4: 模型主键 | G4: 数据描述 | H4: 推送数据库
B5: 覆盖分析 | C5: aggr_nr_coverage_problem_usrcelgrd_q | D5: 5G MR主小区覆盖问题汇聚指标15分钟表 | E5: quarter
B7: 源表基本信息描述
B8: 来源系统 | C8: 源表英文名 | D8: 源表中文名 | E8: 别名 | F8: 任务描述 | G8: 备注 | H8: 是否主表
C9: fact_nr_mro_neighbor_nr_q | D9: 5G电联MRO邻区事实表 | E9: A | H9: 是
B11: 详细字段信息
B12: 详细字段信息
B13: PDM字段英文名 | C13: PDM字段类型 | D13: PDM字段中文名（说明） | E13: 源表名 | F13: 源字段英文名 | G13: 算法加工逻辑 | H13: 关联与过滤条件 | I13: 备注 | J13: 字段属性 | K13: 单位 | L13: 取值范围
A14: =ROW()-1 -> 13 | B14: plmn | C14: string | D14: UE接入NR服务小区的PLMN(公共陆地移动网) | E14: A | F14: plmn | G14: 直取 | J14: 维度 | K14: 无 | L14: 无
B15: data_source | C15: int | D15: 数据源类型 0：电信独享_电信用户 1：电信共享_电信用户 2：电信共享_联通用户 3：联通共享_电信用户 4：联通共享_联通用户 | E15: A | F15: data_source | G15: 直取 | J15: 维度 | K15: 无 | L15: 无
B16: imsi | C16: string | D16: 业务过程用户IMSI号码 | E16: A | F16: imsi | G16: 直取 | J16: 维度 | K16: 无 | L16: 无
B17: msisdn | C17: string | D17: 电话号码 | E17: A | F17: msisdn | G17: 直取 | J17: 维度 | K17: 无 | L17: 无
B18: imei | C18: string | D18: 用户终端imei | E18: A | F18: imei | G18: 直取 | J18: 维度 | K18: 无 | L18: 无
B19: cellkey | C19: string | D19: 小区cellkey | E19: A | F19: cellkey | G19: 直取 | J19: 维度 | K19: 无 | L19: 无
B20: regionid | C20: int | D20: 栅格编号 | E20: A | F20: regionid | G20: 直取 | J20: 维度 | K20: 无 | L20: 无
B21: x_offset_20 | C21: int | D21: X轴20米偏移 | E21: A | F21: x_offset_20 | G21: 直取 | J21: 维度 | K21: 无 | L21: 无
B22: y_offset_20 | C22: int | D22: Y轴20米偏移 | E22: A | F22: y_offset_20 | G22: 直取 | J22: 维度 | K22: 无 | L22: 无
B23: pci | C23: int | D23: 物理层小区ID | E23: A | F23: pci | G23: 直取 | J23: 维度 | K23: 无 | L23: 无
B24: arfcn | C24: int | D24: 下行频点号 | E24: A | F24: arfcn | G24: 直取 | J24: 维度 | K24: 无 | L24: 无
B25: rsrp_total | C25: bigint | D25: 主小区总RSRP值 | E25: A | G25: 以cellkey及mrkey分组，取max(srsrp)，再求和 | J25: 指标 | K25: 无 | L25: <=0
B26: rsrp_cnt | C26: int | D26: 总采样点数量 | E26: A | G26: 以cellkey及mrkey分组后，再计数 | J26: 指标 | K26: 无 | L26: >=0
B27: weakcover_cnt | C27: int | D27: 弱覆盖采样点数量 | E27: A | G27: 以cellkey及mrkey分组后，取max(is_weakcover)，再求和 | J27: 指标 | K27: 无 | L27: >=0
B28: overlap_cnt | C28: int | D28: 重叠覆盖采样点数量 | E28: A | G28: 以cellkey及mrkey分组后，取max(is_overlap)，再求和 | J28: 指标 | K28: 无 | L28: >=0
B29: mod30interfer_cnt | C29: int | D29: MOD30干扰采样点数量 | E29: A | G29: 以cellkey及mrkey分组后，取max(is_mod30interfer)，再求和 | J29: 指标 | K29: 无 | L29: >=0
B30: overshoot_cnt | C30: int | D30: 过覆盖采样点数量 | E30: A | G30: 以cellkey及mrkey分组后，取max(is_overshoot)，再求和 | J30: 指标 | K30: 无 | L30: >=0
B31: bad_mr_cnt | C31: int | D31: 质差MR采样点数量 | E31: A | G31: 以cellkey及mrkey分组后，case when sum(is_weakcover+is_overlap+is_mod30interfer+is_overshoot)>0 then 1 else 0 end，再求和 | J31: 指标 | K31: 无 | L31: >=0
B32: scellmrdis | C32: int | D32: mr到主小区间距离 | E32: A | G32: 以cellkey及mrkey分组后，取max(scellmrdis)，再求和 | J32: 指标 | K32: 无 | L32: >=0
B33: scellmrdis_cnt | C33: int | D33: mr到主小区间有效距离的MR数目 | E33: A | G33: 以cellkey及mrkey分组后，取max(scellmrdis)>0则计数1，再求和 | J33: 指标 | K33: 无 | L33: >=0
B34: weakcover_totalrsrp | C34: int | D34: 弱覆盖采样点总RSRP值 | E34: A | G34: 1、以cellkey及mrkey分组后，取max(is_weakcover)； 2、若max(is_weakcover)=1，则取srsrp值，最后再求和 | J34: 指标 | K34: 无 | L34: <=0
B35: overlap_totalrsrp | C35: int | D35: 重叠覆盖采样点总RSRP值 | E35: A | G35: 1、以cellkey及mrkey分组后，取max(is_overlap)； 2、若max(is_overlap)=1，则取srsrp值，最后再求和 | J35: 指标 | K35: 无 | L35: <=0
B36: mod30interfer_totalrsrp | C36: int | D36: MOD30干扰采样点总RSRP值 | E36: A | G36: 1、以cellkey及mrkey分组后，取max(is_mod30interfer)； 2、若max(is_mod30interfer)=1，则取srsrp值，最后再求和 | J36: 指标 | K36: 无 | L36: <=0
B37: overshoot_totalrsrp | C37: int | D37: 过覆盖采样点总RSRP值 | E37: A | G37: 1、以cellkey及mrkey分组后，取max(is_overshoot)； 2、若max(is_overshoot)=1，则取srsrp值，最后再求和 | J37: 指标 | K37: 无 | L37: <=0
B38: mod30interfer_custom_cnt | C38: int | D38: 自定义MOD30干扰采样点数量 | E38: A | G38: 以cellkey及mrkey分组后，取max(is_mod30interfer_custom)，再求和 | I38: 新增字段 | J38: 指标 | K38: 无 | L38: >=0
B39: mod30interfer_custom_totalrsrp | C39: int | D39: 自定义MOD30干扰采样点总RSRP值 | E39: A | G39: 1、以cellkey及mrkey分组后，取max(is_mod30interfer_custom)； 2、若max(is_mod30interfer_custom)=1，则取srsrp值，最后再求和 | I39: 新增字段 | J39: 指标 | K39: 无 | L39: <=0
B40: p_provincecode | C40: int | D40: 省分区
B41: p_date | C41: string | D41: 天分区
B42: p_hour | C42: int | D42: 小时分区
B43: p_quarter | C43: int | D43: 15分钟分区

Sheet 9
B1: =HYPERLINK("#导航!a2","返回") -> 返回
B3: 目标表基本信息描述
B4: 主题域 | C4: 目标表英文名 | D4: 目标表中文名 | E4: 数据频度 | F4: 模型主键 | G4: 数据描述 | H4: 推送数据库
B5: 覆盖分析 | C5: aggr_nr_coverage_base_q | D5: 5G MR用户小区栅格覆盖指标15分钟表(无问题打标) | E5: quarter
B7: 源表基本信息描述
B8: 来源系统 | C8: 源表英文名 | D8: 源表中文名 | E8: 别名 | F8: 任务描述 | G8: 备注 | H8: 是否主表
C9: ods_nr_mro_northctcc_q | D9: 5G电联MRO用户回填详单表 | E9: A
C10: fact_nr_cm_projdata | D10: 5G电联工参 | E10: B
B12: 详细字段信息
B13: 详细字段信息
B14: PDM字段英文名 | C14: PDM字段类型 | D14: PDM字段中文名（说明） | E14: 源表名 | F14: 源字段英文名 | G14: 算法加工逻辑 | H14: 关联与过滤条件 | I14: 备注 | J14: 字段属性 | K14: 单位 | L14: 取值范围
B15: day | C15: string | D15: 日期 | E15: A | F15: p_date | G15: 直取 | J15: 维度 | K15: 无 | L15: 无
B16: hour | C16: int | D16: 小时 | E16: A | F16: p_hour | G16: 直取 | J16: 维度 | K16: 无 | L16: 无
B17: quarter | C17: int | D17: 刻度 | E17: A | F17: p_quarter | G17: 直取 | J17: 维度 | K17: 无 | L17: 无
B18: vendor | C18: string | D18: 厂家 | E18: A | G18: case when p_region=100001 then 'ZX' when p_region=100002 then 'HW' when p_region=100003 then 'NK' when p_region=100004 then 'ER' when p_region=100005 then 'DT' else '' end
B19: cellkey | C19: string | D19: 小区唯一标识 | E19: A | G19: concat(gnbid,"_",cellid) | J19: 维度 | K19: 无 | L19: 无
B20: arfcn | C20: int | D20: 下行频点号 | E20: A | F20: nrscarfcn | G20: 直取 | J20: 维度 | K20: 无 | L20: 无
B21: freq | C21: string | D21: 频段 | E21: A | G21: case when nrscarfcn>100000 and substr(nrscarfcn,1,1)=4 then '2.1G' when nrscarfcn>100000 and substr(nrscarfcn,1,1)=6 then '3.5G' when nrscarfcn>100000 and substr(nrscarfcn,1,1)=1 then '800M' else 'other' end | J21: 维度 | K21: 无 | L21: 无
B22: citycode | C22: int | D22: 城市编码 | E22: B | F22: citycode | G22: 直取 | J22: 维度 | K22: 无 | L22: 无
B23: districtcode | C23: int | D23: 区县编码 | E23: B | F23: districtcode | G23: 直取 | J23: 维度 | K23: 无 | L23: 无
B24: province_name | C24: string | D24: 省名称 | E24: B | F24: province | G24: 直取 | J24: 维度 | K24: 无 | L24: 无
B25: city_name | C25: string | D25: 城市名称 | E25: B | F25: city | G25: 直取 | J25: 维度 | K25: 无 | L25: 无
B26: district_name | C26: string | D26: 区县名称 | E26: B | F26: district | G26: 直取 | J26: 维度 | K26: 无 | L26: 无
B27: rattypeid | C27: int | D27: 网络制式 | G27: 直接赋值：10 | J27: 维度 | K27: 无 | L27: 无
B28: imsi | C28: string | D28: 用户IMSI号 | E28: A | F28: =B28 -> imsi | G28: 直取 | J28: 维度 | K28: 无 | L28: 无
B29: msisdn | C29: string | D29: 电话号码 | E29: A | F29: =B29 -> msisdn | G29: 直取 | J29: 维度 | K29: 无 | L29: 无
B30: imei | C30: string | D30: 终端业务过程用户终端IMEI号码 | E30: A | F30: =B30 -> imei | G30: 直取 | J30: 维度 | K30: 无 | L30: 无
B31: s_nssai_sst | C31: string | D31: 网络切片选择辅助信息（切片/服务类型） | E31: A | F31: s_nssai_sst | G31: 直取 | J31: 维度 | K31: 无 | L31: 无
B32: s_nssai_sd | C32: string | D32: 网络切片选择辅助信息（切片差分器） | E32: A | F32: s_nssai_sd | G32: 直取 | J32: 维度 | K32: 无 | L32: 无
B33: regionid | C33: int | D33: 栅格编码 | E33: A | F33: =B33 -> regionid | G33: 直取 | J33: 维度 | K33: 无 | L33: 无
B34: x_offset_20 | C34: int | D34: 栅格坐标x轴偏移 | E34: A | F34: =B34 -> x_offset_20 | G34: 直取 | J34: 维度 | K34: 无 | L34: 无
B35: y_offset_20 | C35: int | D35: 栅格坐标y轴偏移 | E35: A | F35: =B35 -> y_offset_20 | G35: 直取 | J35: 维度 | K35: 无 | L35: 无
B36: center_lon | C36: double | D36: 栅格中心经度 | E36: A | G36: 栅格转经纬度 | J36: 维度 | K36: 无 | L36: 无
B37: center_lat | C37: double | D37: 栅格中心纬度 | E37: A | G37: 栅格转经纬度 | J37: 维度 | K37: 无 | L37: 无
B38: left_up_lon | C38: double | D38: 栅格左上角经度 | E38: A | G38: 栅格转经纬度 | J38: 维度 | K38: 无 | L38: 无
B39: left_up_lat | C39: double | D39: 栅格左上角纬度 | E39: A | G39: 栅格转经纬度 | J39: 维度 | K39: 无 | L39: 无
B40: right_down_lon | C40: double | D40: 栅格右下角经度 | E40: A | G40: 栅格转经纬度 | J40: 维度 | K40: 无 | L40: 无
B41: right_down_lat | C41: double | D41: 栅格右下角纬度 | E41: A | G41: 栅格转经纬度 | J41: 维度 | K41: 无 | L41: 无
B42: plmn | C42: string | D42: UE接入NR服务小区的PLMN(公共陆地移动网) | E42: A | F42: =B42 -> plmn | G42: 直取 | J42: 维度 | K42: 无 | L42: 无
B43: data_source | C43: int | D43: 数据源类型 0：电信独享_电信用户 1：电信共享_电信用户 2：电信共享_联通用户 3：联通共享_电信用户 4：联通共享_联通用户 | E43: A | F43: data_source | G43: 直取 | J43: 维度 | K43: 无 | L43: 无
...

Sheet 10
B1: =HYPERLINK("#导航!a2","返回") -> 返回
B3: 目标表基本信息描述
B4: 主题域 | C4: 目标表英文名 | D4: 目标表中文名 | E4: 数据频度 | F4: 模型主键 | G4: 数据描述 | H4: 推送数据库
B5: 覆盖分析 | C5: aggr_nr_coverage_base_usr_refactor_q | D5: 5G MR用户小区栅格覆盖指标15分钟表 | E5: quarter
B7: 源表基本信息描述
B8: 来源系统 | C8: 源表英文名 | D8: 源表中文名 | E8: 别名 | F8: 任务描述 | G8: 备注 | H8: 是否主表
C9: aggr_nr_coverage_base_q | D9: 5G MR用户小区栅格覆盖指标15分钟表(无问题打标) | E9: A | F9: A left join B，关联条件：plmn+data_source+cellkey+msisdn +imsi+imei+regionid+x_offset_20+y_offset_20 | H9: 是
C10: aggr_nr_coverage_problem_usrcelgrd_q | D10: 5G MR主小区覆盖问题汇聚指标15分钟表 | E10: B
B12: 详细字段信息
B13: 详细字段信息
B14: PDM字段英文名 | C14: PDM字段类型 | D14: PDM字段中文名（说明） | E14: 源表名 | F14: 源字段英文名 | G14: 算法加工逻辑 | H14: 关联与过滤条件 | I14: 备注 | J14: 字段属性 | K14: 单位 | L14: 取值范围
B15: provincecode | C15: int | D15: 省编码 | E15: A | F15: p_provincecode | G15: 直取 | J15: 维度 | K15: 无 | L15: 无
B16: day | C16: string | D16: 日期 | E16: A | F16: p_date | G16: 直取 | J16: 维度 | K16: 无 | L16: 无
B17: hour | C17: int | D17: 小时 | E17: A | F17: p_hour | G17: 直取 | J17: 维度 | K17: 无 | L17: 无
B18: quarter | C18: int | D18: 15分钟 | E18: A | F18: p_quarter | G18: 直取 | J18: 维度 | K18: 无 | L18: 无
B19: cellkey | C19: string | D19: 小区cellkey | E19: A | F19: cellkey | G19: 直取 | J19: 维度 | K19: 无 | L19: 无
B20: arfcn | C20: int | D20: 频点 | E20: A | F20: arfcn | G20: 直取 | J20: 维度 | K20: 无 | L20: 无
B21: rattypeid | C21: int | D21: 网络类型 | E21: A | F21: rattypeid | G21: 直取 | J21: 维度 | K21: 无 | L21: 无
B22: imsi | C22: string | D22: 用户imsi | E22: A | F22: imsi | G22: 直取 | J22: 维度 | K22: 无 | L22: 无
B23: regionid | C23: int | D23: RegionID | E23: A | F23: regionid | G23: 直取 | J23: 维度 | K23: 无 | L23: 无
B24: x_offset_20 | C24: int | D24: 栅格坐标x轴偏移 | E24: A | F24: x_offset_20 | G24: 直取 | J24: 维度 | K24: 无 | L24: 无
B25: y_offset_20 | C25: int | D25: 栅格坐标y轴偏移 | E25: A | F25: y_offset_20 | G25: 直取 | J25: 维度 | K25: 无 | L25: 无
B26: period_totalmrcount | C26: bigint | D26: 周期性MR采样点数量 | E26: A | G26: sum(mr_period_totalcnt) | J26: 指标 | K26: 无 | L26: >=0
B27: totalssrsrp | C27: bigint | D27: 总SS-RSRP值 | E27: A | G27: sum(rsrp_total) | J27: 指标 | K27: 无 | L27: <0
B28: avgssrsrp | C28: double | D28: 平均SS-RSRP值 | E28: A | G28: sum(rsrp_total)/sum(rsrp_cnt) | J28: 指标 | K28: 无 | L28: [-156,-29]
B29: ssrsrpcount | C29: bigint | D29: SS-RSRP计数 | E29: A | G29: sum(rsrp_cnt) | J29: 指标 | K29: 无 | L29: >=0
B30: ssrsrp_level1mrcount | C30: bigint | D30: RSRP在[-75,+∞）范围内的MR数目 | E30: A | G30: sum(rsrp_cnt_f65_f29+rsrp_cnt_f70_f65+rsrp_cnt_f75_f70) | J30: 指标 | K30: 无 | L30: >=0
B31: ssrsrp_level2mrcount | C31: bigint | D31: RSRP在[-85,-75）范围内的MR数目 | E31: A | G31: sum(rsrp_cnt_f80_f75+rsrp_cnt_f85_f80) | J31: 指标 | K31: 无 | L31: >=0
B32: ssrsrp_level3mrcount | C32: bigint | D32: RSRP在[-95,-85）范围内的MR数目 | E32: A | G32: sum(rsrp_cnt_f90_f85+rsrp_cnt_f95_f90) | J32: 指标 | K32: 无 | L32: >=0
B33: ssrsrp_level4mrcount | C33: bigint | D33: RSRP在[-100,-95）范围内的MR数目 | E33: A | G33: sum(rsrp_cnt_f100_f95) | J33: 指标 | K33: 无 | L33: >=0
B34: ssrsrp_level5mrcount | C34: bigint | D34: RSRP在[-105,-100）范围内的MR数目 | E34: A | G34: sum(rsrp_cnt_f105_f100) | J34: 指标 | K34: 无 | L34: >=0
B35: ssrsrp_level6mrcount | C35: bigint | D35: RSRP在[-115,-105）范围内的MR数目 | E35: A | G35: sum(rsrp_cnt_f110_f105+rsrp_cnt_f112_f110+rsrp_cnt_f115_f112) | J35: 指标 | K35: 无 | L35: >=0
B36: ssrsrp_level7mrcount | C36: bigint | D36: RSRP在（-∞,-115）范围内的MR数目 | E36: A | G36: sum(rsrp_cnt_f120_f115+rsrp_cnt_f156_f120) | J36: 指标 | K36: 无 | L36: >=0
B37: ssrsrpgoodcount | C37: bigint | D37: RSRP优良数目(>=-105) | E37: A | G37: sum(rsrp_good_cnt_f105) | J37: 指标 | K37: 无 | L37: >=0
... B50: dlsinrgoodratio | C50: double | D50: ULSINR优良比(>=0) | E50: A | G50: sum(ulsinr_good_cnt_0)/sum(ulsinr_cnt) | J50: 指标 | K50: 无 | L50: [0,1]
B51: totalidlersrp | C51: bigint | D51: 总SS-RSRP值 | G51: 置空 | J51: 指标 | K51: 无 | L51: 空
B52: avgidlersrp | C52: double | D52: 平均SS-RSRP值 | G52: 置空 | J52: 指标 | K52: 无 | L52: 空
B53: idlersrpcount | C53: bigint | D53: SS-RSRP计数 | G53: 置空 | J53: 指标 | K53: 无 | L53: 空
B54: idlersrp_level1mrcount | C54: bigint | D54: RSRP在[-75,+∞）范围内的MR数目 | G54: 置空 | J54: 指标 | K54: 无 | L54: 空
B55: idlersrp_level2mrcount | C55: bigint | D55: RSRP在[-85,-75）范围内的MR数目 | G55: 置空 | J55: 指标 | K55: 无 | L55: 空
...

Sheet 11
B1: =HYPERLINK("#导航!a2","返回") -> 返回
B3: 目标表基本信息描述
B4: 主题域 | C4: 目标表英文名 | D4: 目标表中文名 | E4: 数据频度 | F4: 模型主键 | G4: 数据描述 | H4: 推送数据库
B5: 覆盖分析 | C5: aggr_nr_coverage_base_usr_refactor_h | D5: 5G MR用户小区栅格覆盖指标小时表 | E5: hour
B7: 源表基本信息描述
B8: 来源系统 | C8: 源表英文名 | D8: 源表中文名 | E8: 别名 | F8: 任务描述 | G8: 备注 | H8: 是否主表
C9: aggr_nr_coverage_base_usr_refactor_q | D9: 5G MR用户小区栅格覆盖指标15分钟表 | E9: A | H9: 是
B12: 详细字段信息
B13: 详细字段信息
B14: PDM字段英文名 | C14: PDM字段类型 | D14: PDM字段中文名（说明） | E14: 源表名 | F14: 源字段英文名 | G14: 算法加工逻辑 | H14: 关联与过滤条件 | I14: 备注 | J14: 字段属性 | K14: 单位 | L14: 取值范围
B15: provincecode | C15: int | D15: 省编码 | E15: A | F15: p_provincecode | G15: 直取 | J15: 维度 | K15: 无 | L15: 无
B16: day | C16: string | D16: 日期 | E16: A | F16: p_date | G16: 直取 | J16: 维度 | K16: 无 | L16: 无
B17: hour | C17: int | D17: 小时 | E17: A | F17: p_hour | G17: 直取 | J17: 维度 | K17: 无 | L17: 无
B18: cellkey | C18: string | D18: 小区cellkey | E18: A | F18: cellkey | G18: 直取 | J18: 维度 | K18: 无 | L18: 无
B19: arfcn | C19: int | D19: 频点 | E19: A | F19: arfcn | G19: 直取 | J19: 维度 | K19: 无 | L19: 无
B20: rattypeid | C20: int | D20: 网络类型 | E20: A | F20: rattypeid | G20: 直取 | J20: 维度 | K20: 无 | L20: 无
B21: imsi | C21: string | D21: 用户imsi | E21: A | F21: imsi | G21: 直取 | J21: 维度 | K21: 无 | L21: 无
B22: regionid | C22: int | D22: RegionID | E22: A | F22: regionid | G22: 直取 | J22: 维度 | K22: 无 | L22: 无
B23: x_offset_20 | C23: int | D23: 栅格坐标x轴偏移 | E23: A | F23: x_offset_20 | G23: 直取 | J23: 维度 | K23: 无 | L23: 无
B24: y_offset_20 | C24: int | D24: 栅格坐标y轴偏移 | E24: A | F24: y_offset_20 | G24: 直取 | J24: 维度 | K24: 无 | L24: 无
B25: period_totalmrcount | C25: bigint | D25: 周期性MR采样点数量 | E25: A | G25: sum(period_totalmrcount) | J25: 指标 | K25: 无 | L25: >=0
B26: totalssrsrp | C26: bigint | D26: 总SS-RSRP值 | E26: A | G26: sum(totalssrsrp) | J26: 指标 | K26: 无 | L26: <0
B27: avgssrsrp | C27: double | D27: 平均SS-RSRP值 | E27: A | G27: sum(totalssrsrp)/sum(ssrsrpcount) | J27: 指标 | K27: 无 | L27: [-156,-29]
B28: ssrsrpcount | C28: bigint | D28: SS-RSRP计数 | E28: A | G28: sum(ssrsrpcount) | J28: 指标 | K28: 无 | L28: >=0
B29: ssrsrp_level1mrcount | C29: bigint | D29: RSRP在[-75,+∞）范围内的MR数目 | E29: A | G29: sum(ssrsrp_level1mrcount) | J29: 指标 | K29: 无 | L29: >=0
B30: ssrsrp_level2mrcount | C30: bigint | D30: RSRP在[-85,-75）范围内的MR数目 | E30: A | G30: sum(ssrsrp_level2mrcount) | J30: 指标 | K30: 无 | L30: >=0
B31: ssrsrp_level3mrcount | C31: bigint | D31: RSRP在[-95,-85）范围内的MR数目 | E31: A | G31: sum(ssrsrp_level3mrcount) | J31: 指标 | K31: 无 | L31: >=0
B32: ssrsrp_level4mrcount | C32: bigint | D32: RSRP在[-100,-95）范围内的MR数目 | E32: A | G32: sum(ssrsrp_level4mrcount) | J32: 指标 | K32: 无 | L32: >=0
B33: ssrsrp_level5mrcount | C33: bigint | D33: RSRP在[-105,-100）范围内的MR数目 | E33: A | G33: sum(ssrsrp_level5mrcount) | J33: 指标 | K33: 无 | L33: >=0
B34: ssrsrp_level6mrcount | C34: bigint | D34: RSRP在[-115,-105）范围内的MR数目 | E34: A | G34: sum(ssrsrp_level6mrcount) | J34: 指标 | K34: 无 | L34: >=0
B35: ssrsrp_level7mrcount | C35: bigint | D35: RSRP在（-∞,-115）范围内的MR数目 | E35: A | G35: sum(ssrsrp_level7mrcount) | J35: 指标 | K35: 无 | L35: >=0
B36: ssrsrpgoodcount | C36: bigint | D36: RSRP优良数目(>=-105) | E36: A | G36: sum(ssrsrpgoodcount) | J36: 指标 | K36: 无 | L36: >=0
... B49: dlsinrgoodratio | C49: double | D49: ULSINR优良比(>=0) | E49: A | G49: sum(dlsinrgoodcount)/sum(dlsinrcount) | J49: 指标 | K49: 无 | L49: [0,1]
B50: totalidlersrp | C50: bigint | D50: 总SS-RSRP值 | G50: 置空 | J50: 指标 | K50: 无 | L50: 空
B51: avgidlersrp | C51: double | D51: 平均SS-RSRP值 | G51: 置空 | J51: 指标 | K51: 无 | L51: 空
B52: idlersrpcount | C52: bigint | D52: SS-RSRP计数 | G52: 置空 | J52: 指标 | K52: 无 | L52: 空
B53: idlersrp_level1mrcount | C53: bigint | D53: RSRP在[-75,+∞）范围内的MR数目 | G53: 置空 | J53: 指标 | K53: 无 | L53: 空
B54: idlersrp_level2mrcount | C54: bigint | D54: RSRP在[-85,-75）范围内的MR数目 | G54: 置空 | J54: 指标 | K54: 无 | L54: 空
B55: idlersrp_level3mrcount | C55: bigint | D55: RSRP在[-95,-85）范围内的MR数目 | G55: 置空 | J55: 指标 | K55: 无 | L55: 空
B56: idlersrp_level4mrcount | C56: bigint | D56: RSRP在[-100,-95）范围内的MR数目 | G56: 置空 | J56: 指标 | K56: 无 | L56: 空
...

Sheet 13
B1: =HYPERLINK("#导航!a2","返回") -> 返回
B3: 目标表基本信息描述
B4: 主题域 | C4: 目标表英文名 | D4: 目标表中文名 | E4: 数据频度 | F4: 模型主键 | G4: 数据描述 | H4: 推送数据库
B5: 覆盖分析 | C5: aggr_nr_coverage_reduce_usrcelgrd_q | D5: 5G MR用户小区栅格覆盖指标裁剪15分钟表 | E5: quarter
B7: 源表基本信息描述
B8: 来源系统 | C8: 源表英文名 | D8: 源表中文名 | E8: 别名 | F8: 任务描述 | G8: 备注 | H8: 是否主表
C9: aggr_nr_coverage_base_usr_refactor_q | D9: 5G MR用户小区栅格覆盖指标15分钟表 | E9: A | G9: 过滤条件：length(msisdn)>=11
B12: 详细字段信息
B13: 详细字段信息
B14: PDM字段英文名 | C14: PDM字段类型 | D14: PDM字段中文名（说明） | E14: 源表名 | F14: 源字段英文名 | G14: 算法加工逻辑 | H14: 关联与过滤条件 | I14: 备注 | J14: 字段属性 | K14: 单位 | L14: 取值范围
B15: provincecode | C15: int | D15: 省编码 | E15: A | F15: p_provincecode | G15: 直取 | J15: 维度 | K15: 无 | L15: 无
B16: day | C16: string | D16: 日期 | E16: A | F16: p_date | G16: 直取 | J16: 维度 | K16: 无 | L16: 无
B17: hour | C17: int | D17: 小时 | E17: A | F17: p_hour | G17: 直取 | J17: 维度 | K17: 无 | L17: 无
B18: quarter | C18: int | D18: 刻钟 | E18: A | F18: p_quarter | G18: 直取 | J18: 维度 | K18: 无 | L18: 无
B19: cellkey | C19: string | D19: 小区cellkey | E19: A | F19: cellkey | G19: 直取 | J19: 维度 | K19: 无 | L19: 无
B20: msisdn | C20: string | D20: 电话号码 | E20: A | F20: msisdn | G20: 直取 | J20: 维度 | K20: 无 | L20: 无
B21: imsi | C21: string | D21: 用户imsi | E21: A | F21: imsi | G21: 直取 | J21: 维度 | K21: 无 | L21: 无
B22: imei | C22: string | D22: 终端业务过程用户终端IMEI号码 | E22: A | F22: imei | G22: 直取 | J22: 维度 | K22: 无 | L22: 无
B23: regionid | C23: int | D23: 栅格编码 | E23: A | F23: regionid | G23: 直取 | J23: 维度 | K23: 无 | L23: 无
B24: x_offset_20 | C24: int | D24: 栅格坐标x轴偏移 | E24: A | F24: x_offset_20 | G24: 直取 | J24: 维度 | K24: 无 | L24: 无
B25: y_offset_20 | C25: int | D25: 栅格坐标y轴偏移 | E25: A | F25: y_offset_20 | G25: 直取 | J25: 维度 | K25: 无 | L25: 无
B26: period_totalmrcount | C26: bigint | D26: 周期性MR数目 | E26: A | G26: sum(period_totalmrcount) | J26: 指标 | K26: 无 | L26: >=0
B27: totalssrsrp | C27: bigint | D27: RSRP总值 | E27: A | G27: sum(totalssrsrp) | J27: 指标 | K27: 无 | L27: <0
B28: ssrsrpcount | C28: bigint | D28: RSRP有效数目 | E28: A | G28: sum(ssrsrpcount) | J28: 指标 | K28: 无 | L28: >=0
B29: ssrsrp_5div_level1mrcount | C29: bigint | D29: SS-RSRP在(-∞;-115)范围内的MR数目 | E29: A | G29: sum(ssrsrp_5div_level1mrcount) | J29: 指标 | K29: 无 | L29: >=0
B30: ssrsrp_5div_level2mrcount | C30: bigint | D30: SS-RSRP在[-115;-110)范围内的MR数目 | E30: A | G30: sum(ssrsrp_5div_level2mrcount) | J30: 指标 | K30: 无 | L30: >=0
B31: ssrsrp_5div_level3mrcount | C31: bigint | D31: SS-RSRP在[-110;-105)范围内的MR数目 | E31: A | G31: sum(ssrsrp_5div_level3mrcount) | J31: 指标 | K31: 无 | L31: >=0
B32: ssrsrp_5div_level4mrcount | C32: bigint | D32: SS-RSRP在[-105;-100)范围内的MR数目 | E32: A | G32: sum(ssrsrp_5div_level4mrcount) | J32: 指标 | K32: 无 | L32: >=0
B33: ssrsrp_5div_level5mrcount | C33: bigint | D33: SS-RSRP在[-100;-95)范围内的MR数目 | E33: A | G33: sum(ssrsrp_5div_level5mrcount) | J33: 指标 | K33: 无 | L33: >=0
B34: ssrsrp_5div_level6mrcount | C34: bigint | D34: SS-RSRP在[-95;-90)范围内的MR数目 | E34: A | G34: sum(ssrsrp_5div_level6mrcount) | J34: 指标 | K34: 无 | L34: >=0
B35: ssrsrp_5div_level7mrcount | C35: bigint | D35: SS-RSRP在[-90;-85)范围内的MR数目 | E35: A | G35: sum(ssrsrp_5div_level7mrcount) | J35: 指标 | K35: 无 | L35: >=0
B36: ssrsrp_5div_level8mrcount | C36: bigint | D36: SS-RSRP在[-85;-80)范围内的MR数目 | E36: A | G36: sum(ssrsrp_5div_level8mrcount) | J36: 指标 | K36: 无 | L36: >=0
B37: ssrsrp_5div_level9mrcount | C37: bigint | D37: SS-RSRP在[-80;-75)范围内的MR数目 | E37: A | G37: sum(ssrsrp_5div_level9mrcount) | J37: 指标 | K37: 无 | L37: >=0
... B118: validrsrp_sinr_totalmrcount | C118: bigint | D118: rsrq且SINR有效采样点个数 | E118: A | G118: sum(validrsrp_sinr_totalmrcount) | J118: 指标 | K118: 无 | L118: >=0
B119: p_provincecode | C119: int | D119: 省分区
B120: p_date | C120: string | D120: 天分区
B121: p_hour | C121: int | D121: 小时分区
B122: p_quarter | C122: int | D122: 15分钟分区

Sheet 14
B1: =HYPERLINK("#导航!a2","返回") -> 返回
B3: 目标表基本信息描述
B4: 主题域 | C4: 目标表英文名 | D4: 目标表中文名 | E4: 数据频度 | F4: 模型主键 | G4: 数据描述 | H4: 推送数据库
B5: 覆盖分析 | C5: aggr_nr_coverage_reduce_usrcelgrd_h | D5: 5G MR用户小区栅格覆盖指标裁剪小时表 | E5: hour
B7: 源表基本信息描述
B8: 来源系统 | C8: 源表英文名 | D8: 源表中文名 | E8: 别名 | F8: 任务描述 | G8: 备注 | H8: 是否主表
C9: aggr_nr_coverage_reduce_usrcelgrd_q | D9: 5G MR用户小区栅格覆盖指标裁剪15分钟表 | E9: A
B12: 详细字段信息
B13: 详细字段信息
B14: PDM字段英文名 | C14: PDM字段类型 | D14: PDM字段中文名（说明） | E14: 源表名 | F14: 源字段英文名 | G14: 算法加工逻辑 | H14: 关联与过滤条件 | I14: 备注 | J14: 字段属性 | K14: 单位 | L14: 取值范围
B15: provincecode | C15: int | D15: 省编码 | E15: A | F15: p_provincecode | G15: 直取 | J15: 维度 | K15: 无 | L15: 无
B16: day | C16: string | D16: 日期 | E16: A | F16: p_date | G16: 直取 | J16: 维度 | K16: 无 | L16: 无
B17: hour | C17: int | D17: 小时 | E17: A | F17: p_hour | G17: 直取 | J17: 维度 | K17: 无 | L17: 无
B18: cellkey | C18: string | D18: 小区cellkey | E18: A | F18: cellkey | G18: 直取 | J18: 维度 | K18: 无 | L18: 无
B19: msisdn | C19: string | D19: 电话号码 | E19: A | F19: msisdn | G19: 直取 | J19: 维度 | K19: 无 | L19: 无
B20: imsi | C20: string | D20: 用户imsi | E20: A | F20: imsi | G20: 直取 | J20: 维度 | K20: 无 | L20: 无
B21: imei | C21: string | D21: 终端业务过程用户终端IMEI号码 | E21: A | F21: imei | G21: 直取 | J21: 维度 | K21: 无 | L21: 无
B22: regionid | C22: int | D22: 栅格编码 | E22: A | F22: regionid | G22: 直取 | J22: 维度 | K22: 无 | L22: 无
B23: x_offset_20 | C23: int | D23: 栅格坐标x轴偏移 | E23: A | F23: x_offset_20 | G23: 直取 | J23: 维度 | K23: 无 | L23: 无
B24: y_offset_20 | C24: int | D24: 栅格坐标y轴偏移 | E24: A | F24: y_offset_20 | G24: 直取 | J24: 维度 | K24: 无 | L24: 无
B25: hour_quarter_list | C25: array | D25: 驻留时刻清单 | E25: A | G25: 将小时刻度拼接后按数组结果呈现 (hour1_quarter0,hour1_quarter1,hour1_quarter2,hour1_quarter3) | J25: 指标 | K25: 无 | L25: 无
B26: period_totalmrcount | C26: bigint | D26: 周期性MR数目 | E26: A | G26: sum(period_totalmrcount) | J26: 指标 | K26: 无 | L26: >=0
B27: totalssrsrp | C27: bigint | D27: RSRP总值 | E27: A | G27: sum(totalssrsrp) | J27: 指标 | K27: 无 | L27: <0
B28: ssrsrpcount | C28: bigint | D28: RSRP有效数目 | E28: A | G28: sum(ssrsrpcount) | J28: 指标 | K28: 无 | L28: >=0
B29: ssrsrp_5div_level1mrcount | C29: bigint | D29: SS-RSRP在(-∞;-115)范围内的MR数目 | E29: A | G29: sum(ssrsrp_5div_level1mrcount) | J29: 指标 | K29: 无 | L29: >=0
B30: ssrsrp_5div_level2mrcount | C30: bigint | D30: SS-RSRP在[-115;-110)范围内的MR数目 | E30: A | G30: sum(ssrsrp_5div_level2mrcount) | J30: 指标 | K30: 无 | L30: >=0
B31: ssrsrp_5div_level3mrcount | C31: bigint | D31: SS-RSRP在[-110;-105)范围内的MR数目 | E31: A | G31: sum(ssrsrp_5div_level3mrcount) | J31: 指标 | K31: 无 | L31: >=0
B32: ssrsrp_5div_level4mrcount | C32: bigint | D32: SS-RSRP在[-105;-100)范围内的MR数目 | E32: A | G32: sum(ssrsrp_5div_level4mrcount) | J32: 指标 | K32: 无 | L32: >=0
B33: ssrsrp_5div_level5mrcount | C33: bigint | D33: SS-RSRP在[-100;-95)范围内的MR数目 | E33: A | G33: sum(ssrsrp_5div_level5mrcount) | J33: 指标 | K33: 无 | L33: >=0
B34: ssrsrp_5div_level6mrcount | C34: bigint | D34: SS-RSRP在[-95;-90)范围内的MR数目 | E34: A | G34: sum(ssrsrp_5div_level6mrcount) | J34: 指标 | K34: 无 | L34: >=0
B35: ssrsrp_5div_level7mrcount | C35: bigint | D35: SS-RSRP在[-90;-85)范围内的MR数目 | E35: A | G35: sum(ssrsrp_5div_level7mrcount) | J35: 指标 | K35: 无 | L35: >=0
B36: ssrsrp_5div_level8mrcount | C36: bigint | D36: SS-RSRP在[-85;-80)范围内的MR数目 | E36: A | G36: sum(ssrsrp_5div_level8mrcount) | J36: 指标 | K36: 无 | L36: >=0
... B118: validrsrp_sinr_totalmrcount | C118: bigint | D118: rsrq且SINR有效采样点个数 | E118: A | G118: sum(sum(validrsrp_sinr_totalmrcount)) | J118: 指标 | K118: 无 | L118: >=0
B119: p_provincecode | C119: int | D119: 省分区
B120: p_date | C120: string | D120: 天分区
B121: p_hour | C121: int | D121: 小时分区

Sheet 15
B1: =HYPERLINK("#导航!a2","返回") -> 返回
B3: 目标表基本信息描述
B4: 主题域 | C4: 目标表英文名 | D4: 目标表中文名 | E4: 数据频度 | F4: 模型主键 | G4: 数据描述 | H4: 推送数据库
B5: 用户感知 | C5: aggr_nr_coverage_resident_usrgrd_d | D5: 5G MR用户常驻栅格驻留天表 | E5: day
B7: 源表基本信息描述
B8: 来源系统 | C8: 源表英文名 | D8: 源表中文名 | E8: 别名 | F8: 任务描述 | G8: 备注 | H8: 是否主表
C9: aggr_nr_coverage_reduce_usrcelgrd_h | D9: 5G MR用户小区栅格覆盖指标裁剪小时表 | E9: A | F9: 1、将aggr_nr_coverage_reduce_usrcelgrd_h按照用户小区进行天粒度汇聚，得到用户小区维度，指标包含驻留quarter数，不要用“LATERAL VIEW explode(hour_quarter_list)”，用UDF函数实现 2、筛选出驻留时刻数为>=9的用户小区对应关系 3、经过第二步之后，若存在用户驻留小区均不满足>=9条件，则取驻留时刻数最多的用户小区关系 4、通过2、3步骤之后，得到用户常驻小区清单 5、使用第4步结果用户常驻小区对应关系，与表A使用inner join关联，关联条件：用户+小区；关联后按照用户栅格进行汇聚
B12: 详细字段信息
B13: 详细字段信息
B14: PDM字段英文名 | C14: PDM字段类型 | D14: PDM字段中文名（说明） | E14: 源表名 | F14: 源字段英文名 | G14: 算法加工逻辑 | H14: 关联与过滤条件 | I14: 备注 | J14: 字段属性 | K14: 单位 | L14: 取值范围
